package FunMod.struturas;

import java.util.Random;

import cpw.mods.fml.common.registry.GameData;
import net.minecraft.block.Block;
import net.minecraft.init.Blocks;
import net.minecraft.world.World;
import net.minecraft.world.gen.feature.WorldGenerator;

public class WorldGenCasaDoPokemon extends WorldGenerator {
	public WorldGenCasaDoPokemon() {
	}

	protected Block[] GetValidSpawnBlocks() {
		return new Block[] { Blocks.stone, Blocks.grass, Blocks.dirt };
	}

	public boolean LocationIsValidSpawn(World world, int i, int j, int k) {
		int distanceToAir = 0;
		Block checkID = world.getBlock(i, j, k);

		while (checkID != Blocks.air) {
			distanceToAir++;
			checkID = world.getBlock(i, j + distanceToAir, k);
		}

		if (distanceToAir > 0) {
			return false;
		}
		j += distanceToAir - 1;

		Block blockID = world.getBlock(i, j, k);
		Block blockIDAbove = world.getBlock(i, j + 1, k);
		Block blockIDBelow = world.getBlock(i, j - 1, k);
		for (Block x : GetValidSpawnBlocks()) {
			if (blockIDAbove != Blocks.air) {
				return false;
			}
			if (blockID == x) {
				return true;
			} else if (blockID == Blocks.snow && blockIDBelow == x) {
				return true;
			}
		}
		return false;
	}

	public boolean generate(World world, Random rand, int i, int j, int k) {
		if (!LocationIsValidSpawn(world, i, j, k)
				|| !LocationIsValidSpawn(world, i + 4, j, k)
				|| !LocationIsValidSpawn(world, i + 4, j, k + 4)
				|| !LocationIsValidSpawn(world, i, j, k + 4)) {
			return false;
		}
		world.setBlock(i + 0, j + 0, k + 0, GameData.blockRegistry.getObjectById(2));
		world.setBlock(i + 0, j + 0, k + 1, GameData.blockRegistry.getObjectById(2));
		world.setBlock(i + 0, j + 0, k + 2, GameData.blockRegistry.getObjectById(2));
		world.setBlock(i + 0, j + 0, k + 3, GameData.blockRegistry.getObjectById(3));
		world.setBlock(i + 0, j + 0, k + 4, GameData.blockRegistry.getObjectById(3));
		world.setBlock(i + 0, j + 0, k + 5, GameData.blockRegistry.getObjectById(3));
		world.setBlock(i + 0, j + 0, k + 6, GameData.blockRegistry.getObjectById(3));
		world.setBlock(i + 0, j + 0, k + 7, GameData.blockRegistry.getObjectById(3));
		world.setBlock(i + 0, j + 0, k + 8, GameData.blockRegistry.getObjectById(3));
		world.setBlock(i + 0, j + 0, k + 9, GameData.blockRegistry.getObjectById(3));
		world.setBlock(i + 0, j + 0, k + 10, GameData.blockRegistry.getObjectById(3));
		world.setBlock(i + 0, j + 0, k + 11, GameData.blockRegistry.getObjectById(3));
		world.setBlock(i + 0, j + 0, k + 12, GameData.blockRegistry.getObjectById(3));
		world.setBlock(i + 0, j + 0, k + 13, GameData.blockRegistry.getObjectById(3));
		world.setBlock(i + 0, j + 0, k + 14, GameData.blockRegistry.getObjectById(3));
		world.setBlock(i + 0, j + 0, k + 15, GameData.blockRegistry.getObjectById(3));
		world.setBlock(i + 0, j + 0, k + 16, GameData.blockRegistry.getObjectById(3));
		world.setBlock(i + 0, j + 0, k + 17, GameData.blockRegistry.getObjectById(3));
		world.setBlock(i + 0, j + 0, k + 18, GameData.blockRegistry.getObjectById(3));
		world.setBlock(i + 0, j + 0, k + 19, GameData.blockRegistry.getObjectById(2));
		world.setBlock(i + 0, j + 0, k + 20, GameData.blockRegistry.getObjectById(2));
		world.setBlock(i + 0, j + 1, k + 0, Blocks.air);
		world.setBlock(i + 0, j + 1, k + 1, Blocks.air);
		world.setBlock(i + 0, j + 1, k + 2, Blocks.air);
		world.setBlock(i + 0, j + 1, k + 3, GameData.blockRegistry.getObjectById(35));
		world.setBlock(i + 0, j + 1, k + 4, GameData.blockRegistry.getObjectById(35));
		world.setBlock(i + 0, j + 1, k + 5, GameData.blockRegistry.getObjectById(35));
		world.setBlock(i + 0, j + 1, k + 6, GameData.blockRegistry.getObjectById(35));
		world.setBlock(i + 0, j + 1, k + 7, GameData.blockRegistry.getObjectById(35));
		world.setBlock(i + 0, j + 1, k + 8, GameData.blockRegistry.getObjectById(35));
		world.setBlock(i + 0, j + 1, k + 9, GameData.blockRegistry.getObjectById(35));
		world.setBlock(i + 0, j + 1, k + 10, GameData.blockRegistry.getObjectById(35));
		world.setBlock(i + 0, j + 1, k + 11, GameData.blockRegistry.getObjectById(35));
		world.setBlock(i + 0, j + 1, k + 12, GameData.blockRegistry.getObjectById(35));
		world.setBlock(i + 0, j + 1, k + 13, GameData.blockRegistry.getObjectById(35));
		world.setBlock(i + 0, j + 1, k + 14, GameData.blockRegistry.getObjectById(35));
		world.setBlock(i + 0, j + 1, k + 15, GameData.blockRegistry.getObjectById(35));
		world.setBlock(i + 0, j + 1, k + 16, GameData.blockRegistry.getObjectById(35));
		world.setBlock(i + 0, j + 1, k + 17, GameData.blockRegistry.getObjectById(35));
		world.setBlock(i + 0, j + 1, k + 18, GameData.blockRegistry.getObjectById(35));
		world.setBlock(i + 0, j + 1, k + 19, Blocks.air);
		world.setBlock(i + 0, j + 1, k + 20, Blocks.air);
		world.setBlock(i + 0, j + 2, k + 0, Blocks.air);
		world.setBlock(i + 0, j + 2, k + 1, Blocks.air);
		world.setBlock(i + 0, j + 2, k + 2, Blocks.air);
		world.setBlock(i + 0, j + 2, k + 3, GameData.blockRegistry.getObjectById(35));
		world.setBlock(i + 0, j + 2, k + 4, GameData.blockRegistry.getObjectById(35));
		world.setBlock(i + 0, j + 2, k + 5, GameData.blockRegistry.getObjectById(35));
		world.setBlock(i + 0, j + 2, k + 6, GameData.blockRegistry.getObjectById(35));
		world.setBlock(i + 0, j + 2, k + 7, GameData.blockRegistry.getObjectById(35));
		world.setBlock(i + 0, j + 2, k + 8, GameData.blockRegistry.getObjectById(35));
		world.setBlock(i + 0, j + 2, k + 9, GameData.blockRegistry.getObjectById(35));
		world.setBlock(i + 0, j + 2, k + 10, GameData.blockRegistry.getObjectById(35));
		world.setBlock(i + 0, j + 2, k + 11, GameData.blockRegistry.getObjectById(35));
		world.setBlock(i + 0, j + 2, k + 12, GameData.blockRegistry.getObjectById(35));
		world.setBlock(i + 0, j + 2, k + 13, GameData.blockRegistry.getObjectById(35));
		world.setBlock(i + 0, j + 2, k + 14, GameData.blockRegistry.getObjectById(35));
		world.setBlock(i + 0, j + 2, k + 15, GameData.blockRegistry.getObjectById(35));
		world.setBlock(i + 0, j + 2, k + 16, GameData.blockRegistry.getObjectById(35));
		world.setBlock(i + 0, j + 2, k + 17, GameData.blockRegistry.getObjectById(35));
		world.setBlock(i + 0, j + 2, k + 18, GameData.blockRegistry.getObjectById(35));
		world.setBlock(i + 0, j + 2, k + 19, Blocks.air);
		world.setBlock(i + 0, j + 2, k + 20, Blocks.air);
		world.setBlock(i + 0, j + 3, k + 0, Blocks.air);
		world.setBlock(i + 0, j + 3, k + 1, Blocks.air);
		world.setBlock(i + 0, j + 3, k + 2, Blocks.air);
		world.setBlock(i + 0, j + 3, k + 3, GameData.blockRegistry.getObjectById(35));
		world.setBlock(i + 0, j + 3, k + 4, GameData.blockRegistry.getObjectById(35));
		world.setBlock(i + 0, j + 3, k + 5, GameData.blockRegistry.getObjectById(35));
		world.setBlock(i + 0, j + 3, k + 6, GameData.blockRegistry.getObjectById(35));
		world.setBlock(i + 0, j + 3, k + 7, GameData.blockRegistry.getObjectById(35));
		world.setBlock(i + 0, j + 3, k + 8, GameData.blockRegistry.getObjectById(35));
		world.setBlock(i + 0, j + 3, k + 9, GameData.blockRegistry.getObjectById(35));
		world.setBlock(i + 0, j + 3, k + 10, GameData.blockRegistry.getObjectById(35));
		world.setBlock(i + 0, j + 3, k + 11, GameData.blockRegistry.getObjectById(35));
		world.setBlock(i + 0, j + 3, k + 12, GameData.blockRegistry.getObjectById(35));
		world.setBlock(i + 0, j + 3, k + 13, GameData.blockRegistry.getObjectById(35));
		world.setBlock(i + 0, j + 3, k + 14, GameData.blockRegistry.getObjectById(35));
		world.setBlock(i + 0, j + 3, k + 15, GameData.blockRegistry.getObjectById(35));
		world.setBlock(i + 0, j + 3, k + 16, GameData.blockRegistry.getObjectById(35));
		world.setBlock(i + 0, j + 3, k + 17, GameData.blockRegistry.getObjectById(35));
		world.setBlock(i + 0, j + 3, k + 18, GameData.blockRegistry.getObjectById(35));
		world.setBlock(i + 0, j + 3, k + 19, Blocks.air);
		world.setBlock(i + 0, j + 3, k + 20, Blocks.air);
		world.setBlock(i + 0, j + 4, k + 0, Blocks.air);
		world.setBlock(i + 0, j + 4, k + 1, Blocks.air);
		world.setBlock(i + 0, j + 4, k + 2, Blocks.air);
		world.setBlock(i + 0, j + 4, k + 3, GameData.blockRegistry.getObjectById(35));
		world.setBlock(i + 0, j + 4, k + 4, GameData.blockRegistry.getObjectById(35));
		world.setBlock(i + 0, j + 4, k + 5, GameData.blockRegistry.getObjectById(35));
		world.setBlock(i + 0, j + 4, k + 6, GameData.blockRegistry.getObjectById(35));
		world.setBlock(i + 0, j + 4, k + 7, GameData.blockRegistry.getObjectById(35));
		world.setBlock(i + 0, j + 4, k + 8, GameData.blockRegistry.getObjectById(35));
		world.setBlock(i + 0, j + 4, k + 9, GameData.blockRegistry.getObjectById(35));
		world.setBlock(i + 0, j + 4, k + 10, GameData.blockRegistry.getObjectById(35));
		world.setBlock(i + 0, j + 4, k + 11, GameData.blockRegistry.getObjectById(35));
		world.setBlock(i + 0, j + 4, k + 12, GameData.blockRegistry.getObjectById(35));
		world.setBlock(i + 0, j + 4, k + 13, GameData.blockRegistry.getObjectById(35));
		world.setBlock(i + 0, j + 4, k + 14, GameData.blockRegistry.getObjectById(35));
		world.setBlock(i + 0, j + 4, k + 15, GameData.blockRegistry.getObjectById(35));
		world.setBlock(i + 0, j + 4, k + 16, GameData.blockRegistry.getObjectById(35));
		world.setBlock(i + 0, j + 4, k + 17, GameData.blockRegistry.getObjectById(35));
		world.setBlock(i + 0, j + 4, k + 18, GameData.blockRegistry.getObjectById(35));
		world.setBlock(i + 0, j + 4, k + 19, Blocks.air);
		world.setBlock(i + 0, j + 4, k + 20, Blocks.air);
		world.setBlock(i + 0, j + 5, k + 0, Blocks.air);
		world.setBlock(i + 0, j + 5, k + 1, Blocks.air);
		world.setBlock(i + 0, j + 5, k + 2, Blocks.air);
		world.setBlock(i + 0, j + 5, k + 3, GameData.blockRegistry.getObjectById(35));
		world.setBlock(i + 0, j + 5, k + 4, GameData.blockRegistry.getObjectById(35));
		world.setBlock(i + 0, j + 5, k + 5, GameData.blockRegistry.getObjectById(35));
		world.setBlock(i + 0, j + 5, k + 6, GameData.blockRegistry.getObjectById(35));
		world.setBlock(i + 0, j + 5, k + 7, GameData.blockRegistry.getObjectById(35));
		world.setBlock(i + 0, j + 5, k + 8, GameData.blockRegistry.getObjectById(35));
		world.setBlock(i + 0, j + 5, k + 9, GameData.blockRegistry.getObjectById(35));
		world.setBlock(i + 0, j + 5, k + 10, GameData.blockRegistry.getObjectById(35));
		world.setBlock(i + 0, j + 5, k + 11, GameData.blockRegistry.getObjectById(35));
		world.setBlock(i + 0, j + 5, k + 12, GameData.blockRegistry.getObjectById(35));
		world.setBlock(i + 0, j + 5, k + 13, GameData.blockRegistry.getObjectById(35));
		world.setBlock(i + 0, j + 5, k + 14, GameData.blockRegistry.getObjectById(35));
		world.setBlock(i + 0, j + 5, k + 15, GameData.blockRegistry.getObjectById(35));
		world.setBlock(i + 0, j + 5, k + 16, GameData.blockRegistry.getObjectById(35));
		world.setBlock(i + 0, j + 5, k + 17, GameData.blockRegistry.getObjectById(35));
		world.setBlock(i + 0, j + 5, k + 18, GameData.blockRegistry.getObjectById(35));
		world.setBlock(i + 0, j + 5, k + 19, Blocks.air);
		world.setBlock(i + 0, j + 5, k + 20, Blocks.air);
		world.setBlock(i + 0, j + 6, k + 0, Blocks.air);
		world.setBlock(i + 0, j + 6, k + 1, Blocks.air);
		world.setBlock(i + 0, j + 6, k + 2, Blocks.air);
		world.setBlock(i + 0, j + 6, k + 3, GameData.blockRegistry.getObjectById(35));
		world.setBlock(i + 0, j + 6, k + 4, GameData.blockRegistry.getObjectById(35));
		world.setBlock(i + 0, j + 6, k + 5, GameData.blockRegistry.getObjectById(35));
		world.setBlock(i + 0, j + 6, k + 6, GameData.blockRegistry.getObjectById(35));
		world.setBlock(i + 0, j + 6, k + 7, GameData.blockRegistry.getObjectById(35));
		world.setBlock(i + 0, j + 6, k + 8, GameData.blockRegistry.getObjectById(35));
		world.setBlock(i + 0, j + 6, k + 9, GameData.blockRegistry.getObjectById(35));
		world.setBlock(i + 0, j + 6, k + 10, GameData.blockRegistry.getObjectById(35));
		world.setBlock(i + 0, j + 6, k + 11, GameData.blockRegistry.getObjectById(35));
		world.setBlock(i + 0, j + 6, k + 12, GameData.blockRegistry.getObjectById(35));
		world.setBlock(i + 0, j + 6, k + 13, GameData.blockRegistry.getObjectById(35));
		world.setBlock(i + 0, j + 6, k + 14, GameData.blockRegistry.getObjectById(35));
		world.setBlock(i + 0, j + 6, k + 15, GameData.blockRegistry.getObjectById(35));
		world.setBlock(i + 0, j + 6, k + 16, GameData.blockRegistry.getObjectById(35));
		world.setBlock(i + 0, j + 6, k + 17, GameData.blockRegistry.getObjectById(35));
		world.setBlock(i + 0, j + 6, k + 18, GameData.blockRegistry.getObjectById(35));
		world.setBlock(i + 0, j + 6, k + 19, Blocks.air);
		world.setBlock(i + 0, j + 6, k + 20, Blocks.air);
		world.setBlock(i + 0, j + 7, k + 0, Blocks.air);
		world.setBlock(i + 0, j + 7, k + 1, Blocks.air);
		world.setBlock(i + 0, j + 7, k + 2, Blocks.air);
		world.setBlock(i + 0, j + 7, k + 3, GameData.blockRegistry.getObjectById(35));
		world.setBlock(i + 0, j + 7, k + 4, GameData.blockRegistry.getObjectById(102));
		world.setBlock(i + 0, j + 7, k + 5, GameData.blockRegistry.getObjectById(102));
		world.setBlock(i + 0, j + 7, k + 6, GameData.blockRegistry.getObjectById(35));
		world.setBlock(i + 0, j + 7, k + 7, GameData.blockRegistry.getObjectById(102));
		world.setBlock(i + 0, j + 7, k + 8, GameData.blockRegistry.getObjectById(102));
		world.setBlock(i + 0, j + 7, k + 9, GameData.blockRegistry.getObjectById(35));
		world.setBlock(i + 0, j + 7, k + 10, GameData.blockRegistry.getObjectById(102));
		world.setBlock(i + 0, j + 7, k + 11, GameData.blockRegistry.getObjectById(102));
		world.setBlock(i + 0, j + 7, k + 12, GameData.blockRegistry.getObjectById(35));
		world.setBlock(i + 0, j + 7, k + 13, GameData.blockRegistry.getObjectById(102));
		world.setBlock(i + 0, j + 7, k + 14, GameData.blockRegistry.getObjectById(102));
		world.setBlock(i + 0, j + 7, k + 15, GameData.blockRegistry.getObjectById(35));
		world.setBlock(i + 0, j + 7, k + 16, GameData.blockRegistry.getObjectById(102));
		world.setBlock(i + 0, j + 7, k + 17, GameData.blockRegistry.getObjectById(102));
		world.setBlock(i + 0, j + 7, k + 18, GameData.blockRegistry.getObjectById(35));
		world.setBlock(i + 0, j + 7, k + 19, Blocks.air);
		world.setBlock(i + 0, j + 7, k + 20, Blocks.air);
		world.setBlock(i + 0, j + 8, k + 0, Blocks.air);
		world.setBlock(i + 0, j + 8, k + 1, Blocks.air);
		world.setBlock(i + 0, j + 8, k + 2, Blocks.air);
		world.setBlock(i + 0, j + 8, k + 3, GameData.blockRegistry.getObjectById(35));
		world.setBlock(i + 0, j + 8, k + 4, GameData.blockRegistry.getObjectById(102));
		world.setBlock(i + 0, j + 8, k + 5, GameData.blockRegistry.getObjectById(102));
		world.setBlock(i + 0, j + 8, k + 6, GameData.blockRegistry.getObjectById(35));
		world.setBlock(i + 0, j + 8, k + 7, GameData.blockRegistry.getObjectById(102));
		world.setBlock(i + 0, j + 8, k + 8, GameData.blockRegistry.getObjectById(102));
		world.setBlock(i + 0, j + 8, k + 9, GameData.blockRegistry.getObjectById(35));
		world.setBlock(i + 0, j + 8, k + 10, GameData.blockRegistry.getObjectById(102));
		world.setBlock(i + 0, j + 8, k + 11, GameData.blockRegistry.getObjectById(102));
		world.setBlock(i + 0, j + 8, k + 12, GameData.blockRegistry.getObjectById(35));
		world.setBlock(i + 0, j + 8, k + 13, GameData.blockRegistry.getObjectById(102));
		world.setBlock(i + 0, j + 8, k + 14, GameData.blockRegistry.getObjectById(102));
		world.setBlock(i + 0, j + 8, k + 15, GameData.blockRegistry.getObjectById(35));
		world.setBlock(i + 0, j + 8, k + 16, GameData.blockRegistry.getObjectById(102));
		world.setBlock(i + 0, j + 8, k + 17, GameData.blockRegistry.getObjectById(102));
		world.setBlock(i + 0, j + 8, k + 18, GameData.blockRegistry.getObjectById(35));
		world.setBlock(i + 0, j + 8, k + 19, Blocks.air);
		world.setBlock(i + 0, j + 8, k + 20, Blocks.air);
		world.setBlock(i + 0, j + 9, k + 0, Blocks.air);
		world.setBlock(i + 0, j + 9, k + 1, Blocks.air);
		world.setBlock(i + 0, j + 9, k + 2, Blocks.air);
		world.setBlock(i + 0, j + 9, k + 3, GameData.blockRegistry.getObjectById(35));
		world.setBlock(i + 0, j + 9, k + 4, GameData.blockRegistry.getObjectById(102));
		world.setBlock(i + 0, j + 9, k + 5, GameData.blockRegistry.getObjectById(102));
		world.setBlock(i + 0, j + 9, k + 6, GameData.blockRegistry.getObjectById(35));
		world.setBlock(i + 0, j + 9, k + 7, GameData.blockRegistry.getObjectById(102));
		world.setBlock(i + 0, j + 9, k + 8, GameData.blockRegistry.getObjectById(102));
		world.setBlock(i + 0, j + 9, k + 9, GameData.blockRegistry.getObjectById(35));
		world.setBlock(i + 0, j + 9, k + 10, GameData.blockRegistry.getObjectById(102));
		world.setBlock(i + 0, j + 9, k + 11, GameData.blockRegistry.getObjectById(102));
		world.setBlock(i + 0, j + 9, k + 12, GameData.blockRegistry.getObjectById(35));
		world.setBlock(i + 0, j + 9, k + 13, GameData.blockRegistry.getObjectById(102));
		world.setBlock(i + 0, j + 9, k + 14, GameData.blockRegistry.getObjectById(102));
		world.setBlock(i + 0, j + 9, k + 15, GameData.blockRegistry.getObjectById(35));
		world.setBlock(i + 0, j + 9, k + 16, GameData.blockRegistry.getObjectById(102));
		world.setBlock(i + 0, j + 9, k + 17, GameData.blockRegistry.getObjectById(102));
		world.setBlock(i + 0, j + 9, k + 18, GameData.blockRegistry.getObjectById(35));
		world.setBlock(i + 0, j + 9, k + 19, Blocks.air);
		world.setBlock(i + 0, j + 9, k + 20, Blocks.air);
		world.setBlock(i + 0, j + 10, k + 0, Blocks.air);
		world.setBlock(i + 0, j + 10, k + 1, Blocks.air);
		world.setBlock(i + 0, j + 10, k + 2, Blocks.air);
		world.setBlock(i + 0, j + 10, k + 3, GameData.blockRegistry.getObjectById(35));
		world.setBlock(i + 0, j + 10, k + 4, GameData.blockRegistry.getObjectById(102));
		world.setBlock(i + 0, j + 10, k + 5, GameData.blockRegistry.getObjectById(102));
		world.setBlock(i + 0, j + 10, k + 6, GameData.blockRegistry.getObjectById(35));
		world.setBlock(i + 0, j + 10, k + 7, GameData.blockRegistry.getObjectById(102));
		world.setBlock(i + 0, j + 10, k + 8, GameData.blockRegistry.getObjectById(102));
		world.setBlock(i + 0, j + 10, k + 9, GameData.blockRegistry.getObjectById(35));
		world.setBlock(i + 0, j + 10, k + 10, GameData.blockRegistry.getObjectById(102));
		world.setBlock(i + 0, j + 10, k + 11, GameData.blockRegistry.getObjectById(102));
		world.setBlock(i + 0, j + 10, k + 12, GameData.blockRegistry.getObjectById(35));
		world.setBlock(i + 0, j + 10, k + 13, GameData.blockRegistry.getObjectById(102));
		world.setBlock(i + 0, j + 10, k + 14, GameData.blockRegistry.getObjectById(102));
		world.setBlock(i + 0, j + 10, k + 15, GameData.blockRegistry.getObjectById(35));
		world.setBlock(i + 0, j + 10, k + 16, GameData.blockRegistry.getObjectById(102));
		world.setBlock(i + 0, j + 10, k + 17, GameData.blockRegistry.getObjectById(102));
		world.setBlock(i + 0, j + 10, k + 18, GameData.blockRegistry.getObjectById(35));
		world.setBlock(i + 0, j + 10, k + 19, Blocks.air);
		world.setBlock(i + 0, j + 10, k + 20, Blocks.air);
		world.setBlock(i + 0, j + 11, k + 0, Blocks.air);
		world.setBlock(i + 0, j + 11, k + 1, Blocks.air);
		world.setBlock(i + 0, j + 11, k + 2, Blocks.air);
		world.setBlock(i + 0, j + 11, k + 3, GameData.blockRegistry.getObjectById(35));
		world.setBlock(i + 0, j + 11, k + 4, GameData.blockRegistry.getObjectById(102));
		world.setBlock(i + 0, j + 11, k + 5, GameData.blockRegistry.getObjectById(102));
		world.setBlock(i + 0, j + 11, k + 6, GameData.blockRegistry.getObjectById(35));
		world.setBlock(i + 0, j + 11, k + 7, GameData.blockRegistry.getObjectById(102));
		world.setBlock(i + 0, j + 11, k + 8, GameData.blockRegistry.getObjectById(102));
		world.setBlock(i + 0, j + 11, k + 9, GameData.blockRegistry.getObjectById(35));
		world.setBlock(i + 0, j + 11, k + 10, GameData.blockRegistry.getObjectById(102));
		world.setBlock(i + 0, j + 11, k + 11, GameData.blockRegistry.getObjectById(102));
		world.setBlock(i + 0, j + 11, k + 12, GameData.blockRegistry.getObjectById(35));
		world.setBlock(i + 0, j + 11, k + 13, GameData.blockRegistry.getObjectById(102));
		world.setBlock(i + 0, j + 11, k + 14, GameData.blockRegistry.getObjectById(102));
		world.setBlock(i + 0, j + 11, k + 15, GameData.blockRegistry.getObjectById(35));
		world.setBlock(i + 0, j + 11, k + 16, GameData.blockRegistry.getObjectById(102));
		world.setBlock(i + 0, j + 11, k + 17, GameData.blockRegistry.getObjectById(102));
		world.setBlock(i + 0, j + 11, k + 18, GameData.blockRegistry.getObjectById(35));
		world.setBlock(i + 0, j + 11, k + 19, Blocks.air);
		world.setBlock(i + 0, j + 11, k + 20, Blocks.air);
		world.setBlock(i + 0, j + 12, k + 0, Blocks.air);
		world.setBlock(i + 0, j + 12, k + 1, Blocks.air);
		world.setBlock(i + 0, j + 12, k + 2, Blocks.air);
		world.setBlock(i + 0, j + 12, k + 3, GameData.blockRegistry.getObjectById(35), 14, 0);
		world.setBlock(i + 0, j + 12, k + 4, GameData.blockRegistry.getObjectById(35), 14, 0);
		world.setBlock(i + 0, j + 12, k + 5, GameData.blockRegistry.getObjectById(35), 14, 0);
		world.setBlock(i + 0, j + 12, k + 6, GameData.blockRegistry.getObjectById(35), 14, 0);
		world.setBlock(i + 0, j + 12, k + 7, GameData.blockRegistry.getObjectById(35), 14, 0);
		world.setBlock(i + 0, j + 12, k + 8, GameData.blockRegistry.getObjectById(35), 14, 0);
		world.setBlock(i + 0, j + 12, k + 9, GameData.blockRegistry.getObjectById(35), 14, 0);
		world.setBlock(i + 0, j + 12, k + 10, GameData.blockRegistry.getObjectById(35), 14, 0);
		world.setBlock(i + 0, j + 12, k + 11, GameData.blockRegistry.getObjectById(35), 14, 0);
		world.setBlock(i + 0, j + 12, k + 12, GameData.blockRegistry.getObjectById(35), 14, 0);
		world.setBlock(i + 0, j + 12, k + 13, GameData.blockRegistry.getObjectById(35), 14, 0);
		world.setBlock(i + 0, j + 12, k + 14, GameData.blockRegistry.getObjectById(35), 14, 0);
		world.setBlock(i + 0, j + 12, k + 15, GameData.blockRegistry.getObjectById(35), 14, 0);
		world.setBlock(i + 0, j + 12, k + 16, GameData.blockRegistry.getObjectById(35), 14, 0);
		world.setBlock(i + 0, j + 12, k + 17, GameData.blockRegistry.getObjectById(35), 14, 0);
		world.setBlock(i + 0, j + 12, k + 18, GameData.blockRegistry.getObjectById(35), 14, 0);
		world.setBlock(i + 0, j + 12, k + 19, Blocks.air);
		world.setBlock(i + 0, j + 12, k + 20, Blocks.air);
		world.setBlock(i + 0, j + 13, k + 0, Blocks.air);
		world.setBlock(i + 0, j + 13, k + 1, Blocks.air);
		world.setBlock(i + 0, j + 13, k + 2, Blocks.air);
		world.setBlock(i + 0, j + 13, k + 3, Blocks.air);
		world.setBlock(i + 0, j + 13, k + 4, Blocks.air);
		world.setBlock(i + 0, j + 13, k + 5, Blocks.air);
		world.setBlock(i + 0, j + 13, k + 6, Blocks.air);
		world.setBlock(i + 0, j + 13, k + 7, Blocks.air);
		world.setBlock(i + 0, j + 13, k + 8, Blocks.air);
		world.setBlock(i + 0, j + 13, k + 9, Blocks.air);
		world.setBlock(i + 0, j + 13, k + 10, Blocks.air);
		world.setBlock(i + 0, j + 13, k + 11, Blocks.air);
		world.setBlock(i + 0, j + 13, k + 12, Blocks.air);
		world.setBlock(i + 0, j + 13, k + 13, Blocks.air);
		world.setBlock(i + 0, j + 13, k + 14, Blocks.air);
		world.setBlock(i + 0, j + 13, k + 15, Blocks.air);
		world.setBlock(i + 0, j + 13, k + 16, Blocks.air);
		world.setBlock(i + 0, j + 13, k + 17, Blocks.air);
		world.setBlock(i + 0, j + 13, k + 18, Blocks.air);
		world.setBlock(i + 0, j + 13, k + 19, Blocks.air);
		world.setBlock(i + 0, j + 13, k + 20, Blocks.air);
		world.setBlock(i + 1, j + 0, k + 0, GameData.blockRegistry.getObjectById(2));
		world.setBlock(i + 1, j + 0, k + 1, GameData.blockRegistry.getObjectById(2));
		world.setBlock(i + 1, j + 0, k + 2, GameData.blockRegistry.getObjectById(2));
		world.setBlock(i + 1, j + 0, k + 3, GameData.blockRegistry.getObjectById(3));
		world.setBlock(i + 1, j + 0, k + 4, GameData.blockRegistry.getObjectById(3));
		world.setBlock(i + 1, j + 0, k + 5, GameData.blockRegistry.getObjectById(3));
		world.setBlock(i + 1, j + 0, k + 6, GameData.blockRegistry.getObjectById(35), 4, 0);
		world.setBlock(i + 1, j + 0, k + 7, GameData.blockRegistry.getObjectById(35), 4, 0);
		world.setBlock(i + 1, j + 0, k + 8, GameData.blockRegistry.getObjectById(35), 4, 0);
		world.setBlock(i + 1, j + 0, k + 9, GameData.blockRegistry.getObjectById(35), 4, 0);
		world.setBlock(i + 1, j + 0, k + 10, GameData.blockRegistry.getObjectById(35), 4, 0);
		world.setBlock(i + 1, j + 0, k + 11, GameData.blockRegistry.getObjectById(35), 4, 0);
		world.setBlock(i + 1, j + 0, k + 12, GameData.blockRegistry.getObjectById(35), 4, 0);
		world.setBlock(i + 1, j + 0, k + 13, GameData.blockRegistry.getObjectById(35), 4, 0);
		world.setBlock(i + 1, j + 0, k + 14, GameData.blockRegistry.getObjectById(35), 4, 0);
		world.setBlock(i + 1, j + 0, k + 15, GameData.blockRegistry.getObjectById(35), 4, 0);
		world.setBlock(i + 1, j + 0, k + 16, GameData.blockRegistry.getObjectById(35), 4, 0);
		world.setBlock(i + 1, j + 0, k + 17, GameData.blockRegistry.getObjectById(3));
		world.setBlock(i + 1, j + 0, k + 18, GameData.blockRegistry.getObjectById(3));
		world.setBlock(i + 1, j + 0, k + 19,GameData.blockRegistry.getObjectById(2));
		world.setBlock(i + 1, j + 0, k + 20,GameData.blockRegistry.getObjectById(2));
		world.setBlock(i + 1, j + 1, k + 0, Blocks.air);
		world.setBlock(i + 1, j + 1, k + 1, Blocks.air);
		world.setBlock(i + 1, j + 1, k + 2, Blocks.air);
		world.setBlock(i + 1, j + 1, k + 3, GameData.blockRegistry.getObjectById(35));
		world.setBlock(i + 1, j + 1, k + 4, GameData.blockRegistry.getObjectById(35));
		world.setBlock(i + 1, j + 1, k + 5, GameData.blockRegistry.getObjectById(35), 14, 0);
		world.setBlock(i + 1, j + 1, k + 6, GameData.blockRegistry.getObjectById(35), 14, 0);
		world.setBlock(i + 1, j + 1, k + 7, GameData.blockRegistry.getObjectById(35), 14, 0);
		world.setBlock(i + 1, j + 1, k + 8, GameData.blockRegistry.getObjectById(35), 14, 0);
		world.setBlock(i + 1, j + 1, k + 9, GameData.blockRegistry.getObjectById(35), 14, 0);
		world.setBlock(i + 1, j + 1, k + 10, GameData.blockRegistry.getObjectById(35), 14, 0);
		world.setBlock(i + 1, j + 1, k + 11, GameData.blockRegistry.getObjectById(35), 14, 0);
		world.setBlock(i + 1, j + 1, k + 12, GameData.blockRegistry.getObjectById(35), 14, 0);
		world.setBlock(i + 1, j + 1, k + 13, GameData.blockRegistry.getObjectById(35), 14, 0);
		world.setBlock(i + 1, j + 1, k + 14, GameData.blockRegistry.getObjectById(35), 14, 0);
		world.setBlock(i + 1, j + 1, k + 15, GameData.blockRegistry.getObjectById(35), 14, 0);
		world.setBlock(i + 1, j + 1, k + 16, GameData.blockRegistry.getObjectById(35), 14, 0);
		world.setBlock(i + 1, j + 1, k + 17, GameData.blockRegistry.getObjectById(35), 14, 0);
		world.setBlock(i + 1, j + 1, k + 18, GameData.blockRegistry.getObjectById(35));
		world.setBlock(i + 1, j + 1, k + 19, Blocks.air);
		world.setBlock(i + 1, j + 1, k + 20, Blocks.air);
		world.setBlock(i + 1, j + 2, k + 0, Blocks.air);
		world.setBlock(i + 1, j + 2, k + 1, Blocks.air);
		world.setBlock(i + 1, j + 2, k + 2, Blocks.air);
		world.setBlock(i + 1, j + 2, k + 3, Blocks.air);
		world.setBlock(i + 1, j + 2, k + 4, GameData.blockRegistry.getObjectById(35));
		world.setBlock(i + 1, j + 2, k + 5, GameData.blockRegistry.getObjectById(35), 14, 0);
		world.setBlock(i + 1, j + 2, k + 6, GameData.blockRegistry.getObjectById(35), 14, 0);
		world.setBlock(i + 1, j + 2, k + 7, GameData.blockRegistry.getObjectById(35), 14, 0);
		world.setBlock(i + 1, j + 2, k + 8, GameData.blockRegistry.getObjectById(35), 14, 0);
		world.setBlock(i + 1, j + 2, k + 9, GameData.blockRegistry.getObjectById(35), 14, 0);
		world.setBlock(i + 1, j + 2, k + 10, GameData.blockRegistry.getObjectById(35), 14, 0);
		world.setBlock(i + 1, j + 2, k + 11, GameData.blockRegistry.getObjectById(35), 14, 0);
		world.setBlock(i + 1, j + 2, k + 12, GameData.blockRegistry.getObjectById(35), 14, 0);
		world.setBlock(i + 1, j + 2, k + 13, GameData.blockRegistry.getObjectById(35), 14, 0);
		world.setBlock(i + 1, j + 2, k + 14, GameData.blockRegistry.getObjectById(35), 14, 0);
		world.setBlock(i + 1, j + 2, k + 15, GameData.blockRegistry.getObjectById(35), 14, 0);
		world.setBlock(i + 1, j + 2, k + 16, GameData.blockRegistry.getObjectById(35), 14, 0);
		world.setBlock(i + 1, j + 2, k + 17, GameData.blockRegistry.getObjectById(35), 14, 0);
		world.setBlock(i + 1, j + 2, k + 18, GameData.blockRegistry.getObjectById(35));
		world.setBlock(i + 1, j + 2, k + 19, Blocks.air);
		world.setBlock(i + 1, j + 2, k + 20, Blocks.air);
		world.setBlock(i + 1, j + 3, k + 0, Blocks.air);
		world.setBlock(i + 1, j + 3, k + 1, Blocks.air);
		world.setBlock(i + 1, j + 3, k + 2, Blocks.air);
		world.setBlock(i + 1, j + 3, k + 3, Blocks.air);
		world.setBlock(i + 1, j + 3, k + 4, GameData.blockRegistry.getObjectById(35));
		world.setBlock(i + 1, j + 3, k + 5, GameData.blockRegistry.getObjectById(35), 14, 0);
		world.setBlock(i + 1, j + 3, k + 6, GameData.blockRegistry.getObjectById(35), 14, 0);
		world.setBlock(i + 1, j + 3, k + 7, GameData.blockRegistry.getObjectById(35), 14, 0);
		world.setBlock(i + 1, j + 3, k + 8, GameData.blockRegistry.getObjectById(35), 14, 0);
		world.setBlock(i + 1, j + 3, k + 9, GameData.blockRegistry.getObjectById(35), 14, 0);
		world.setBlock(i + 1, j + 3, k + 10, GameData.blockRegistry.getObjectById(35), 14, 0);
		world.setBlock(i + 1, j + 3, k + 11, GameData.blockRegistry.getObjectById(35), 14, 0);
		world.setBlock(i + 1, j + 3, k + 12, GameData.blockRegistry.getObjectById(35), 14, 0);
		world.setBlock(i + 1, j + 3, k + 13, GameData.blockRegistry.getObjectById(35), 14, 0);
		world.setBlock(i + 1, j + 3, k + 14, GameData.blockRegistry.getObjectById(35), 14, 0);
		world.setBlock(i + 1, j + 3, k + 15, GameData.blockRegistry.getObjectById(35), 14, 0);
		world.setBlock(i + 1, j + 3, k + 16, GameData.blockRegistry.getObjectById(35), 14, 0);
		world.setBlock(i + 1, j + 3, k + 17, GameData.blockRegistry.getObjectById(35), 14, 0);
		world.setBlock(i + 1, j + 3, k + 18, GameData.blockRegistry.getObjectById(35));
		world.setBlock(i + 1, j + 3, k + 19, Blocks.air);
		world.setBlock(i + 1, j + 3, k + 20, Blocks.air);
		world.setBlock(i + 1, j + 4, k + 0, Blocks.air);
		world.setBlock(i + 1, j + 4, k + 1, Blocks.air);
		world.setBlock(i + 1, j + 4, k + 2, Blocks.air);
		world.setBlock(i + 1, j + 4, k + 3, Blocks.air);
		world.setBlock(i + 1, j + 4, k + 4, GameData.blockRegistry.getObjectById(35));
		world.setBlock(i + 1, j + 4, k + 5, GameData.blockRegistry.getObjectById(35), 14, 0);
		world.setBlock(i + 1, j + 4, k + 6, GameData.blockRegistry.getObjectById(35), 14, 0);
		world.setBlock(i + 1, j + 4, k + 7, GameData.blockRegistry.getObjectById(35), 14, 0);
		world.setBlock(i + 1, j + 4, k + 8, GameData.blockRegistry.getObjectById(35), 14, 0);
		world.setBlock(i + 1, j + 4, k + 9, GameData.blockRegistry.getObjectById(35), 14, 0);
		world.setBlock(i + 1, j + 4, k + 10, GameData.blockRegistry.getObjectById(35), 14, 0);
		world.setBlock(i + 1, j + 4, k + 11, GameData.blockRegistry.getObjectById(35), 14, 0);
		world.setBlock(i + 1, j + 4, k + 12, GameData.blockRegistry.getObjectById(35), 14, 0);
		world.setBlock(i + 1, j + 4, k + 13, GameData.blockRegistry.getObjectById(35), 14, 0);
		world.setBlock(i + 1, j + 4, k + 14, GameData.blockRegistry.getObjectById(35), 14, 0);
		world.setBlock(i + 1, j + 4, k + 15, GameData.blockRegistry.getObjectById(35), 14, 0);
		world.setBlock(i + 1, j + 4, k + 16, GameData.blockRegistry.getObjectById(35), 14, 0);
		world.setBlock(i + 1, j + 4, k + 17, GameData.blockRegistry.getObjectById(35), 14, 0);
		world.setBlock(i + 1, j + 4, k + 18, GameData.blockRegistry.getObjectById(35));
		world.setBlock(i + 1, j + 4, k + 19, Blocks.air);
		world.setBlock(i + 1, j + 4, k + 20, Blocks.air);
		world.setBlock(i + 1, j + 5, k + 0, Blocks.air);
		world.setBlock(i + 1, j + 5, k + 1, Blocks.air);
		world.setBlock(i + 1, j + 5, k + 2, Blocks.air);
		world.setBlock(i + 1, j + 5, k + 3, Blocks.air);
		world.setBlock(i + 1, j + 5, k + 4, GameData.blockRegistry.getObjectById(35));
		world.setBlock(i + 1, j + 5, k + 5, GameData.blockRegistry.getObjectById(35), 14, 0);
		world.setBlock(i + 1, j + 5, k + 6, GameData.blockRegistry.getObjectById(35));
		world.setBlock(i + 1, j + 5, k + 7, GameData.blockRegistry.getObjectById(35));
		world.setBlock(i + 1, j + 5, k + 8, GameData.blockRegistry.getObjectById(35));
		world.setBlock(i + 1, j + 5, k + 9, GameData.blockRegistry.getObjectById(35));
		world.setBlock(i + 1, j + 5, k + 10, GameData.blockRegistry.getObjectById(35));
		world.setBlock(i + 1, j + 5, k + 11, GameData.blockRegistry.getObjectById(35));
		world.setBlock(i + 1, j + 5, k + 12, GameData.blockRegistry.getObjectById(35));
		world.setBlock(i + 1, j + 5, k + 13, GameData.blockRegistry.getObjectById(35));
		world.setBlock(i + 1, j + 5, k + 14, GameData.blockRegistry.getObjectById(35));
		world.setBlock(i + 1, j + 5, k + 15, GameData.blockRegistry.getObjectById(35));
		world.setBlock(i + 1, j + 5, k + 16, GameData.blockRegistry.getObjectById(35));
		world.setBlock(i + 1, j + 5, k + 17, GameData.blockRegistry.getObjectById(35));
		world.setBlock(i + 1, j + 5, k + 18, GameData.blockRegistry.getObjectById(35));
		world.setBlock(i + 1, j + 5, k + 19, Blocks.air);
		world.setBlock(i + 1, j + 5, k + 20, Blocks.air);
		world.setBlock(i + 1, j + 6, k + 0, Blocks.air);
		world.setBlock(i + 1, j + 6, k + 1, Blocks.air);
		world.setBlock(i + 1, j + 6, k + 2, Blocks.air);
		world.setBlock(i + 1, j + 6, k + 3, GameData.blockRegistry.getObjectById(35));
		world.setBlock(i + 1, j + 6, k + 4, GameData.blockRegistry.getObjectById(35), 4, 0);
		world.setBlock(i + 1, j + 6, k + 5, GameData.blockRegistry.getObjectById(35), 4, 0);
		world.setBlock(i + 1, j + 6, k + 6, GameData.blockRegistry.getObjectById(35), 4, 0);
		world.setBlock(i + 1, j + 6, k + 7, GameData.blockRegistry.getObjectById(35), 4, 0);
		world.setBlock(i + 1, j + 6, k + 8, GameData.blockRegistry.getObjectById(35), 4, 0);
		world.setBlock(i + 1, j + 6, k + 9, GameData.blockRegistry.getObjectById(35), 4, 0);
		world.setBlock(i + 1, j + 6, k + 10, GameData.blockRegistry.getObjectById(35), 4, 0);
		world.setBlock(i + 1, j + 6, k + 11, GameData.blockRegistry.getObjectById(35), 4, 0);
		world.setBlock(i + 1, j + 6, k + 12, GameData.blockRegistry.getObjectById(35), 4, 0);
		world.setBlock(i + 1, j + 6, k + 13, GameData.blockRegistry.getObjectById(35), 4, 0);
		world.setBlock(i + 1, j + 6, k + 14, GameData.blockRegistry.getObjectById(35), 4, 0);
		world.setBlock(i + 1, j + 6, k + 15, GameData.blockRegistry.getObjectById(35), 4, 0);
		world.setBlock(i + 1, j + 6, k + 16, GameData.blockRegistry.getObjectById(35), 4, 0);
		world.setBlock(i + 1, j + 6, k + 17, GameData.blockRegistry.getObjectById(35), 4, 0);
		world.setBlock(i + 1, j + 6, k + 18, GameData.blockRegistry.getObjectById(35));
		world.setBlock(i + 1, j + 6, k + 19, Blocks.air);
		world.setBlock(i + 1, j + 6, k + 20, Blocks.air);
		world.setBlock(i + 1, j + 7, k + 0, Blocks.air);
		world.setBlock(i + 1, j + 7, k + 1, Blocks.air);
		world.setBlock(i + 1, j + 7, k + 2, Blocks.air);
		world.setBlock(i + 1, j + 7, k + 3, GameData.blockRegistry.getObjectById(102));
		world.setBlock(i + 1, j + 7, k + 4, Blocks.air);
		world.setBlock(i + 1, j + 7, k + 5, Blocks.air);
		world.setBlock(i + 1, j + 7, k + 6, Blocks.air);
		world.setBlock(i + 1, j + 7, k + 7, Blocks.air);
		world.setBlock(i + 1, j + 7, k + 8, Blocks.air);
		world.setBlock(i + 1, j + 7, k + 9, Blocks.air);
		world.setBlock(i + 1, j + 7, k + 10, Blocks.air);
		world.setBlock(i + 1, j + 7, k + 11, Blocks.air);
		world.setBlock(i + 1, j + 7, k + 12, Blocks.air);
		world.setBlock(i + 1, j + 7, k + 13, Blocks.air);
		world.setBlock(i + 1, j + 7, k + 14, Blocks.air);
		world.setBlock(i + 1, j + 7, k + 15, Blocks.air);
		world.setBlock(i + 1, j + 7, k + 16, Blocks.air);
		world.setBlock(i + 1, j + 7, k + 17, Blocks.air);
		world.setBlock(i + 1, j + 7, k + 18, GameData.blockRegistry.getObjectById(102));
		world.setBlock(i + 1, j + 7, k + 19, Blocks.air);
		world.setBlock(i + 1, j + 7, k + 20, Blocks.air);
		world.setBlock(i + 1, j + 8, k + 0, Blocks.air);
		world.setBlock(i + 1, j + 8, k + 1, Blocks.air);
		world.setBlock(i + 1, j + 8, k + 2, Blocks.air);
		world.setBlock(i + 1, j + 8, k + 3, GameData.blockRegistry.getObjectById(102));
		world.setBlock(i + 1, j + 8, k + 4, Blocks.air);
		world.setBlock(i + 1, j + 8, k + 5, Blocks.air);
		world.setBlock(i + 1, j + 8, k + 6, Blocks.air);
		world.setBlock(i + 1, j + 8, k + 7, Blocks.air);
		world.setBlock(i + 1, j + 8, k + 8, Blocks.air);
		world.setBlock(i + 1, j + 8, k + 9, Blocks.air);
		world.setBlock(i + 1, j + 8, k + 10, Blocks.air);
		world.setBlock(i + 1, j + 8, k + 11, Blocks.air);
		world.setBlock(i + 1, j + 8, k + 12, Blocks.air);
		world.setBlock(i + 1, j + 8, k + 13, Blocks.air);
		world.setBlock(i + 1, j + 8, k + 14, Blocks.air);
		world.setBlock(i + 1, j + 8, k + 15, Blocks.air);
		world.setBlock(i + 1, j + 8, k + 16, Blocks.air);
		world.setBlock(i + 1, j + 8, k + 17, Blocks.air);
		world.setBlock(i + 1, j + 8, k + 18, GameData.blockRegistry.getObjectById(102));
		world.setBlock(i + 1, j + 8, k + 19, Blocks.air);
		world.setBlock(i + 1, j + 8, k + 20, Blocks.air);
		world.setBlock(i + 1, j + 9, k + 0, Blocks.air);
		world.setBlock(i + 1, j + 9, k + 1, Blocks.air);
		world.setBlock(i + 1, j + 9, k + 2, Blocks.air);
		world.setBlock(i + 1, j + 9, k + 3, GameData.blockRegistry.getObjectById(102));
		world.setBlock(i + 1, j + 9, k + 4, Blocks.air);
		world.setBlock(i + 1, j + 9, k + 5, Blocks.air);
		world.setBlock(i + 1, j + 9, k + 6, Blocks.air);
		world.setBlock(i + 1, j + 9, k + 7, Blocks.air);
		world.setBlock(i + 1, j + 9, k + 8, Blocks.air);
		world.setBlock(i + 1, j + 9, k + 9, Blocks.air);
		world.setBlock(i + 1, j + 9, k + 10, Blocks.air);
		world.setBlock(i + 1, j + 9, k + 11, Blocks.air);
		world.setBlock(i + 1, j + 9, k + 12, Blocks.air);
		world.setBlock(i + 1, j + 9, k + 13, Blocks.air);
		world.setBlock(i + 1, j + 9, k + 14, Blocks.air);
		world.setBlock(i + 1, j + 9, k + 15, Blocks.air);
		world.setBlock(i + 1, j + 9, k + 16, Blocks.air);
		world.setBlock(i + 1, j + 9, k + 17, Blocks.air);
		world.setBlock(i + 1, j + 9, k + 18, GameData.blockRegistry.getObjectById(102));
		world.setBlock(i + 1, j + 9, k + 19, Blocks.air);
		world.setBlock(i + 1, j + 9, k + 20, Blocks.air);
		world.setBlock(i + 1, j + 10, k + 0, Blocks.air);
		world.setBlock(i + 1, j + 10, k + 1, Blocks.air);
		world.setBlock(i + 1, j + 10, k + 2, Blocks.air);
		world.setBlock(i + 1, j + 10, k + 3, GameData.blockRegistry.getObjectById(102));
		world.setBlock(i + 1, j + 10, k + 4, Blocks.air);
		world.setBlock(i + 1, j + 10, k + 5, Blocks.air);
		world.setBlock(i + 1, j + 10, k + 6, Blocks.air);
		world.setBlock(i + 1, j + 10, k + 7, Blocks.air);
		world.setBlock(i + 1, j + 10, k + 8, Blocks.air);
		world.setBlock(i + 1, j + 10, k + 9, Blocks.air);
		world.setBlock(i + 1, j + 10, k + 10, Blocks.air);
		world.setBlock(i + 1, j + 10, k + 11, Blocks.air);
		world.setBlock(i + 1, j + 10, k + 12, Blocks.air);
		world.setBlock(i + 1, j + 10, k + 13, Blocks.air);
		world.setBlock(i + 1, j + 10, k + 14, Blocks.air);
		world.setBlock(i + 1, j + 10, k + 15, Blocks.air);
		world.setBlock(i + 1, j + 10, k + 16, Blocks.air);
		world.setBlock(i + 1, j + 10, k + 17, Blocks.air);
		world.setBlock(i + 1, j + 10, k + 18, GameData.blockRegistry.getObjectById(102));
		world.setBlock(i + 1, j + 10, k + 19, Blocks.air);
		world.setBlock(i + 1, j + 10, k + 20, Blocks.air);
		world.setBlock(i + 1, j + 11, k + 0, Blocks.air);
		world.setBlock(i + 1, j + 11, k + 1, Blocks.air);
		world.setBlock(i + 1, j + 11, k + 2, Blocks.air);
		world.setBlock(i + 1, j + 11, k + 3, GameData.blockRegistry.getObjectById(102));
		world.setBlock(i + 1, j + 11, k + 4, Blocks.air);
		world.setBlock(i + 1, j + 11, k + 5, Blocks.air);
		world.setBlock(i + 1, j + 11, k + 6, Blocks.air);
		world.setBlock(i + 1, j + 11, k + 7, Blocks.air);
		world.setBlock(i + 1, j + 11, k + 8, Blocks.air);
		world.setBlock(i + 1, j + 11, k + 9, Blocks.air);
		world.setBlock(i + 1, j + 11, k + 10, Blocks.air);
		world.setBlock(i + 1, j + 11, k + 11, Blocks.air);
		world.setBlock(i + 1, j + 11, k + 12, Blocks.air);
		world.setBlock(i + 1, j + 11, k + 13, Blocks.air);
		world.setBlock(i + 1, j + 11, k + 14, Blocks.air);
		world.setBlock(i + 1, j + 11, k + 15, Blocks.air);
		world.setBlock(i + 1, j + 11, k + 16, Blocks.air);
		world.setBlock(i + 1, j + 11, k + 17, Blocks.air);
		world.setBlock(i + 1, j + 11, k + 18, GameData.blockRegistry.getObjectById(102));
		world.setBlock(i + 1, j + 11, k + 19, Blocks.air);
		world.setBlock(i + 1, j + 11, k + 20, Blocks.air);
		world.setBlock(i + 1, j + 12, k + 0, Blocks.air);
		world.setBlock(i + 1, j + 12, k + 1, Blocks.air);
		world.setBlock(i + 1, j + 12, k + 2, Blocks.air);
		world.setBlock(i + 1, j + 12, k + 3, GameData.blockRegistry.getObjectById(35), 14, 0);
		world.setBlock(i + 1, j + 12, k + 4, Blocks.air);
		world.setBlock(i + 1, j + 12, k + 5, Blocks.air);
		world.setBlock(i + 1, j + 12, k + 6, Blocks.air);
		world.setBlock(i + 1, j + 12, k + 7, Blocks.air);
		world.setBlock(i + 1, j + 12, k + 8, Blocks.air);
		world.setBlock(i + 1, j + 12, k + 9, Blocks.air);
		world.setBlock(i + 1, j + 12, k + 10, Blocks.air);
		world.setBlock(i + 1, j + 12, k + 11, Blocks.air);
		world.setBlock(i + 1, j + 12, k + 12, Blocks.air);
		world.setBlock(i + 1, j + 12, k + 13, Blocks.air);
		world.setBlock(i + 1, j + 12, k + 14, Blocks.air);
		world.setBlock(i + 1, j + 12, k + 15, Blocks.air);
		world.setBlock(i + 1, j + 12, k + 16, Blocks.air);
		world.setBlock(i + 1, j + 12, k + 17, Blocks.air);
		world.setBlock(i + 1, j + 12, k + 18, GameData.blockRegistry.getObjectById(35), 14, 0);
		world.setBlock(i + 1, j + 12, k + 19, Blocks.air);
		world.setBlock(i + 1, j + 12, k + 20, Blocks.air);
		world.setBlock(i + 1, j + 13, k + 0, Blocks.air);
		world.setBlock(i + 1, j + 13, k + 1, Blocks.air);
		world.setBlock(i + 1, j + 13, k + 2, Blocks.air);
		world.setBlock(i + 1, j + 13, k + 3, Blocks.air);
		world.setBlock(i + 1, j + 13, k + 4, GameData.blockRegistry.getObjectById(35), 14, 0);
		world.setBlock(i + 1, j + 13, k + 5, GameData.blockRegistry.getObjectById(35), 14, 0);
		world.setBlock(i + 1, j + 13, k + 6, GameData.blockRegistry.getObjectById(35), 14, 0);
		world.setBlock(i + 1, j + 13, k + 7, GameData.blockRegistry.getObjectById(35), 14, 0);
		world.setBlock(i + 1, j + 13, k + 8, GameData.blockRegistry.getObjectById(35), 14, 0);
		world.setBlock(i + 1, j + 13, k + 9, GameData.blockRegistry.getObjectById(35), 14, 0);
		world.setBlock(i + 1, j + 13, k + 10, GameData.blockRegistry.getObjectById(35), 14, 0);
		world.setBlock(i + 1, j + 13, k + 11, GameData.blockRegistry.getObjectById(35), 14, 0);
		world.setBlock(i + 1, j + 13, k + 12, GameData.blockRegistry.getObjectById(35), 14, 0);
		world.setBlock(i + 1, j + 13, k + 13, GameData.blockRegistry.getObjectById(35), 14, 0);
		world.setBlock(i + 1, j + 13, k + 14, GameData.blockRegistry.getObjectById(35), 14, 0);
		world.setBlock(i + 1, j + 13, k + 15, GameData.blockRegistry.getObjectById(35), 14, 0);
		world.setBlock(i + 1, j + 13, k + 16, GameData.blockRegistry.getObjectById(35), 14, 0);
		world.setBlock(i + 1, j + 13, k + 17, GameData.blockRegistry.getObjectById(35), 14, 0);
		world.setBlock(i + 1, j + 13, k + 18, Blocks.air);
		world.setBlock(i + 1, j + 13, k + 19, Blocks.air);
		world.setBlock(i + 1, j + 13, k + 20, Blocks.air);
		world.setBlock(i + 2, j + 0, k + 0,GameData.blockRegistry.getObjectById(2));
		world.setBlock(i + 2, j + 0, k + 1,GameData.blockRegistry.getObjectById(2));
		world.setBlock(i + 2, j + 0, k + 2,GameData.blockRegistry.getObjectById(2));
		world.setBlock(i + 2, j + 0, k + 3, GameData.blockRegistry.getObjectById(3));
		world.setBlock(i + 2, j + 0, k + 4, GameData.blockRegistry.getObjectById(3));
		world.setBlock(i + 2, j + 0, k + 5, GameData.blockRegistry.getObjectById(3));
		world.setBlock(i + 2, j + 0, k + 6, GameData.blockRegistry.getObjectById(35), 4, 0);
		world.setBlock(i + 2, j + 0, k + 7, GameData.blockRegistry.getObjectById(35), 4, 0);
		world.setBlock(i + 2, j + 0, k + 8, GameData.blockRegistry.getObjectById(35), 4, 0);
		world.setBlock(i + 2, j + 0, k + 9, GameData.blockRegistry.getObjectById(35), 4, 0);
		world.setBlock(i + 2, j + 0, k + 10, GameData.blockRegistry.getObjectById(35), 4, 0);
		world.setBlock(i + 2, j + 0, k + 11, GameData.blockRegistry.getObjectById(35), 4, 0);
		world.setBlock(i + 2, j + 0, k + 12, GameData.blockRegistry.getObjectById(35), 4, 0);
		world.setBlock(i + 2, j + 0, k + 13, GameData.blockRegistry.getObjectById(35), 4, 0);
		world.setBlock(i + 2, j + 0, k + 14, GameData.blockRegistry.getObjectById(35), 4, 0);
		world.setBlock(i + 2, j + 0, k + 15, GameData.blockRegistry.getObjectById(35), 4, 0);
		world.setBlock(i + 2, j + 0, k + 16, GameData.blockRegistry.getObjectById(35), 4, 0);
		world.setBlock(i + 2, j + 0, k + 17, GameData.blockRegistry.getObjectById(3));
		world.setBlock(i + 2, j + 0, k + 18, GameData.blockRegistry.getObjectById(3));
		world.setBlock(i + 2, j + 0, k + 19,GameData.blockRegistry.getObjectById(2));
		world.setBlock(i + 2, j + 0, k + 20,GameData.blockRegistry.getObjectById(2));
		world.setBlock(i + 2, j + 1, k + 0, Blocks.air);
		world.setBlock(i + 2, j + 1, k + 1, Blocks.air);
		world.setBlock(i + 2, j + 1, k + 2, Blocks.air);
		world.setBlock(i + 2, j + 1, k + 3, GameData.blockRegistry.getObjectById(35));
		world.setBlock(i + 2, j + 1, k + 4, GameData.blockRegistry.getObjectById(35));
		world.setBlock(i + 2, j + 1, k + 5, GameData.blockRegistry.getObjectById(35), 14, 0);
		world.setBlock(i + 2, j + 1, k + 6, Blocks.air);
		world.setBlock(i + 2, j + 1, k + 8, Blocks.air);
		world.setBlock(i + 2, j + 1, k + 9, Blocks.air);
		world.setBlock(i + 2, j + 1, k + 10, Blocks.air);
		world.setBlock(i + 2, j + 1, k + 11, Blocks.air);
		world.setBlock(i + 2, j + 1, k + 12, Blocks.air);
		world.setBlock(i + 2, j + 1, k + 13, Blocks.air);
		world.setBlock(i + 2, j + 1, k + 14, Blocks.air);
		world.setBlock(i + 2, j + 1, k + 15, Blocks.air);
		world.setBlock(i + 2, j + 1, k + 16, Blocks.air);
		world.setBlock(i + 2, j + 1, k + 17, GameData.blockRegistry.getObjectById(35), 14, 0);
		world.setBlock(i + 2, j + 1, k + 18, GameData.blockRegistry.getObjectById(35));
		world.setBlock(i + 2, j + 1, k + 19, Blocks.air);
		world.setBlock(i + 2, j + 1, k + 20, Blocks.air);
		world.setBlock(i + 2, j + 2, k + 0, Blocks.air);
		world.setBlock(i + 2, j + 2, k + 1, Blocks.air);
		world.setBlock(i + 2, j + 2, k + 2, Blocks.air);
		world.setBlock(i + 2, j + 2, k + 3, Blocks.air);
		world.setBlock(i + 2, j + 2, k + 4, GameData.blockRegistry.getObjectById(35));
		world.setBlock(i + 2, j + 2, k + 5, GameData.blockRegistry.getObjectById(35), 14, 0);
		world.setBlock(i + 2, j + 2, k + 6, Blocks.air);
		world.setBlock(i + 2, j + 2, k + 7, Blocks.air);
		world.setBlock(i + 2, j + 2, k + 8, Blocks.air);
		world.setBlock(i + 2, j + 2, k + 9, Blocks.air);
		world.setBlock(i + 2, j + 2, k + 10, Blocks.air);
		world.setBlock(i + 2, j + 2, k + 11, Blocks.air);
		world.setBlock(i + 2, j + 2, k + 12, Blocks.air);
		world.setBlock(i + 2, j + 2, k + 13, Blocks.air);
		world.setBlock(i + 2, j + 2, k + 14, Blocks.air);
		world.setBlock(i + 2, j + 2, k + 15, Blocks.air);
		world.setBlock(i + 2, j + 2, k + 16, Blocks.air);
		world.setBlock(i + 2, j + 2, k + 17, GameData.blockRegistry.getObjectById(35), 14, 0);
		world.setBlock(i + 2, j + 2, k + 18, GameData.blockRegistry.getObjectById(35));
		world.setBlock(i + 2, j + 2, k + 19, Blocks.air);
		world.setBlock(i + 2, j + 2, k + 20, Blocks.air);
		world.setBlock(i + 2, j + 3, k + 0, Blocks.air);
		world.setBlock(i + 2, j + 3, k + 1, Blocks.air);
		world.setBlock(i + 2, j + 3, k + 2, Blocks.air);
		world.setBlock(i + 2, j + 3, k + 3, Blocks.air);
		world.setBlock(i + 2, j + 3, k + 4, GameData.blockRegistry.getObjectById(35));
		world.setBlock(i + 2, j + 3, k + 5, GameData.blockRegistry.getObjectById(35), 14, 0);
		world.setBlock(i + 2, j + 3, k + 17, GameData.blockRegistry.getObjectById(35), 14, 0);
		world.setBlock(i + 2, j + 3, k + 18, GameData.blockRegistry.getObjectById(35));
		world.setBlock(i + 2, j + 3, k + 19, Blocks.air);
		world.setBlock(i + 2, j + 3, k + 20, Blocks.air);
		world.setBlock(i + 2, j + 4, k + 0, Blocks.air);
		world.setBlock(i + 2, j + 4, k + 1, Blocks.air);
		world.setBlock(i + 2, j + 4, k + 2, Blocks.air);
		world.setBlock(i + 2, j + 4, k + 3, Blocks.air);
		world.setBlock(i + 2, j + 4, k + 4, GameData.blockRegistry.getObjectById(35));
		world.setBlock(i + 2, j + 4, k + 5, GameData.blockRegistry.getObjectById(35), 14, 0);
		world.setBlock(i + 2, j + 4, k + 6, Blocks.air);
		world.setBlock(i + 2, j + 4, k + 7, Blocks.air);
		world.setBlock(i + 2, j + 4, k + 8, Blocks.air);
		world.setBlock(i + 2, j + 4, k + 9, Blocks.air);
		world.setBlock(i + 2, j + 4, k + 10, Blocks.air);
		world.setBlock(i + 2, j + 4, k + 11, Blocks.air);
		world.setBlock(i + 2, j + 4, k + 12, Blocks.air);
		world.setBlock(i + 2, j + 4, k + 13, Blocks.air);
		world.setBlock(i + 2, j + 4, k + 14, Blocks.air);
		world.setBlock(i + 2, j + 4, k + 15, Blocks.air);
		world.setBlock(i + 2, j + 4, k + 16, Blocks.air);
		world.setBlock(i + 2, j + 4, k + 17, GameData.blockRegistry.getObjectById(35), 14, 0);
		world.setBlock(i + 2, j + 4, k + 18, GameData.blockRegistry.getObjectById(35));
		world.setBlock(i + 2, j + 4, k + 19, Blocks.air);
		world.setBlock(i + 2, j + 4, k + 20, Blocks.air);
		world.setBlock(i + 2, j + 5, k + 0, Blocks.air);
		world.setBlock(i + 2, j + 5, k + 1, Blocks.air);
		world.setBlock(i + 2, j + 5, k + 2, Blocks.air);
		world.setBlock(i + 2, j + 5, k + 3, Blocks.air);
		world.setBlock(i + 2, j + 5, k + 4, GameData.blockRegistry.getObjectById(35));
		world.setBlock(i + 2, j + 5, k + 5, GameData.blockRegistry.getObjectById(35), 14, 0);
		world.setBlock(i + 2, j + 5, k + 6, GameData.blockRegistry.getObjectById(35));
		world.setBlock(i + 2, j + 5, k + 7, GameData.blockRegistry.getObjectById(35));
		world.setBlock(i + 2, j + 5, k + 8, GameData.blockRegistry.getObjectById(35));
		world.setBlock(i + 2, j + 5, k + 9, GameData.blockRegistry.getObjectById(35));
		world.setBlock(i + 2, j + 5, k + 10, GameData.blockRegistry.getObjectById(35));
		world.setBlock(i + 2, j + 5, k + 11, GameData.blockRegistry.getObjectById(35));
		world.setBlock(i + 2, j + 5, k + 12, GameData.blockRegistry.getObjectById(35));
		world.setBlock(i + 2, j + 5, k + 13, GameData.blockRegistry.getObjectById(35));
		world.setBlock(i + 2, j + 5, k + 14, GameData.blockRegistry.getObjectById(35));
		world.setBlock(i + 2, j + 5, k + 15, GameData.blockRegistry.getObjectById(35));
		world.setBlock(i + 2, j + 5, k + 16, GameData.blockRegistry.getObjectById(35));
		world.setBlock(i + 2, j + 5, k + 17, GameData.blockRegistry.getObjectById(35));
		world.setBlock(i + 2, j + 5, k + 18, GameData.blockRegistry.getObjectById(35));
		world.setBlock(i + 2, j + 5, k + 19, Blocks.air);
		world.setBlock(i + 2, j + 5, k + 20, Blocks.air);
		world.setBlock(i + 2, j + 6, k + 0, Blocks.air);
		world.setBlock(i + 2, j + 6, k + 1, Blocks.air);
		world.setBlock(i + 2, j + 6, k + 2, Blocks.air);
		world.setBlock(i + 2, j + 6, k + 3, GameData.blockRegistry.getObjectById(35));
		world.setBlock(i + 2, j + 6, k + 4, GameData.blockRegistry.getObjectById(35), 4, 0);
		world.setBlock(i + 2, j + 6, k + 5, GameData.blockRegistry.getObjectById(35), 4, 0);
		world.setBlock(i + 2, j + 6, k + 6, GameData.blockRegistry.getObjectById(35), 4, 0);
		world.setBlock(i + 2, j + 6, k + 7, GameData.blockRegistry.getObjectById(35), 4, 0);
		world.setBlock(i + 2, j + 6, k + 8, GameData.blockRegistry.getObjectById(35), 4, 0);
		world.setBlock(i + 2, j + 6, k + 9, GameData.blockRegistry.getObjectById(35), 4, 0);
		world.setBlock(i + 2, j + 6, k + 10, GameData.blockRegistry.getObjectById(35), 4, 0);
		world.setBlock(i + 2, j + 6, k + 11, GameData.blockRegistry.getObjectById(35), 4, 0);
		world.setBlock(i + 2, j + 6, k + 12, GameData.blockRegistry.getObjectById(35), 4, 0);
		world.setBlock(i + 2, j + 6, k + 13, GameData.blockRegistry.getObjectById(35), 4, 0);
		world.setBlock(i + 2, j + 6, k + 14, GameData.blockRegistry.getObjectById(35), 4, 0);
		world.setBlock(i + 2, j + 6, k + 15, GameData.blockRegistry.getObjectById(35), 4, 0);
		world.setBlock(i + 2, j + 6, k + 16, GameData.blockRegistry.getObjectById(35), 4, 0);
		world.setBlock(i + 2, j + 6, k + 17, GameData.blockRegistry.getObjectById(35), 4, 0);
		world.setBlock(i + 2, j + 6, k + 18, GameData.blockRegistry.getObjectById(35));
		world.setBlock(i + 2, j + 6, k + 19, Blocks.air);
		world.setBlock(i + 2, j + 6, k + 20, Blocks.air);
		world.setBlock(i + 2, j + 7, k + 0, Blocks.air);
		world.setBlock(i + 2, j + 7, k + 1, Blocks.air);
		world.setBlock(i + 2, j + 7, k + 2, Blocks.air);
		world.setBlock(i + 2, j + 7, k + 3, GameData.blockRegistry.getObjectById(102));
		world.setBlock(i + 2, j + 7, k + 4, Blocks.air);
		world.setBlock(i + 2, j + 7, k + 5, Blocks.air);
		world.setBlock(i + 2, j + 7, k + 6, Blocks.air);
		world.setBlock(i + 2, j + 7, k + 7,GameData.blockRegistry.getObjectById(102));
		world.setBlock(i + 2, j + 7, k + 8, GameData.blockRegistry.getObjectById(114), 1, 0);
		world.setBlock(i + 2, j + 7, k + 9, GameData.blockRegistry.getObjectById(114), 1, 0);
		world.setBlock(i + 2, j + 7, k + 10, GameData.blockRegistry.getObjectById(114), 1, 0);
		world.setBlock(i + 2, j + 7, k + 11,GameData.blockRegistry.getObjectById(102));
		world.setBlock(i + 2, j + 7, k + 12, Blocks.air);
		world.setBlock(i + 2, j + 7, k + 13, Blocks.air);
		world.setBlock(i + 2, j + 7, k + 14, Blocks.air);
		world.setBlock(i + 2, j + 7, k + 15, Blocks.air);
		world.setBlock(i + 2, j + 7, k + 16, Blocks.air);
		world.setBlock(i + 2, j + 7, k + 17, Blocks.air);
		world.setBlock(i + 2, j + 7, k + 18, GameData.blockRegistry.getObjectById(102));
		world.setBlock(i + 2, j + 7, k + 19, Blocks.air);
		world.setBlock(i + 2, j + 7, k + 20, Blocks.air);
		world.setBlock(i + 2, j + 8, k + 0, Blocks.air);
		world.setBlock(i + 2, j + 8, k + 1, Blocks.air);
		world.setBlock(i + 2, j + 8, k + 2, Blocks.air);
		world.setBlock(i + 2, j + 8, k + 3, GameData.blockRegistry.getObjectById(102));
		world.setBlock(i + 2, j + 8, k + 4, Blocks.air);
		world.setBlock(i + 2, j + 8, k + 5, Blocks.air);
		world.setBlock(i + 2, j + 8, k + 6, Blocks.air);
		world.setBlock(i + 2, j + 8, k + 7, Blocks.air);
		world.setBlock(i + 2, j + 8, k + 8, Blocks.air);
		world.setBlock(i + 2, j + 8, k + 9, Blocks.air);
		world.setBlock(i + 2, j + 8, k + 10, Blocks.air);
		world.setBlock(i + 2, j + 8, k + 11, Blocks.air);
		world.setBlock(i + 2, j + 8, k + 12, Blocks.air);
		world.setBlock(i + 2, j + 8, k + 13, Blocks.air);
		world.setBlock(i + 2, j + 8, k + 14, Blocks.air);
		world.setBlock(i + 2, j + 8, k + 15, Blocks.air);
		world.setBlock(i + 2, j + 8, k + 16, Blocks.air);
		world.setBlock(i + 2, j + 8, k + 17, Blocks.air);
		world.setBlock(i + 2, j + 8, k + 18, GameData.blockRegistry.getObjectById(102));
		world.setBlock(i + 2, j + 8, k + 19, Blocks.air);
		world.setBlock(i + 2, j + 8, k + 20, Blocks.air);
		world.setBlock(i + 2, j + 9, k + 0, Blocks.air);
		world.setBlock(i + 2, j + 9, k + 1, Blocks.air);
		world.setBlock(i + 2, j + 9, k + 2, Blocks.air);
		world.setBlock(i + 2, j + 9, k + 3, GameData.blockRegistry.getObjectById(102));
		world.setBlock(i + 2, j + 9, k + 4, Blocks.air);
		world.setBlock(i + 2, j + 9, k + 5, Blocks.air);
		world.setBlock(i + 2, j + 9, k + 6, Blocks.air);
		world.setBlock(i + 2, j + 9, k + 7, Blocks.air);
		world.setBlock(i + 2, j + 9, k + 8, Blocks.air);
		world.setBlock(i + 2, j + 9, k + 9, Blocks.air);
		world.setBlock(i + 2, j + 9, k + 10, Blocks.air);
		world.setBlock(i + 2, j + 9, k + 11, Blocks.air);
		world.setBlock(i + 2, j + 9, k + 12, Blocks.air);
		world.setBlock(i + 2, j + 9, k + 13, Blocks.air);
		world.setBlock(i + 2, j + 9, k + 14, Blocks.air);
		world.setBlock(i + 2, j + 9, k + 15, Blocks.air);
		world.setBlock(i + 2, j + 9, k + 16, Blocks.air);
		world.setBlock(i + 2, j + 9, k + 17, Blocks.air);
		world.setBlock(i + 2, j + 9, k + 18, GameData.blockRegistry.getObjectById(102));
		world.setBlock(i + 2, j + 9, k + 19, Blocks.air);
		world.setBlock(i + 2, j + 9, k + 20, Blocks.air);
		world.setBlock(i + 2, j + 10, k + 0, Blocks.air);
		world.setBlock(i + 2, j + 10, k + 1, Blocks.air);
		world.setBlock(i + 2, j + 10, k + 2, Blocks.air);
		world.setBlock(i + 2, j + 10, k + 3, GameData.blockRegistry.getObjectById(102));
		world.setBlock(i + 2, j + 10, k + 4, Blocks.air);
		world.setBlock(i + 2, j + 10, k + 5, Blocks.air);
		world.setBlock(i + 2, j + 10, k + 6, Blocks.air);
		world.setBlock(i + 2, j + 10, k + 7, Blocks.air);
		world.setBlock(i + 2, j + 10, k + 8, Blocks.air);
		world.setBlock(i + 2, j + 10, k + 9, Blocks.air);
		world.setBlock(i + 2, j + 10, k + 10, Blocks.air);
		world.setBlock(i + 2, j + 10, k + 11, Blocks.air);
		world.setBlock(i + 2, j + 10, k + 12, Blocks.air);
		world.setBlock(i + 2, j + 10, k + 13, Blocks.air);
		world.setBlock(i + 2, j + 10, k + 14, Blocks.air);
		world.setBlock(i + 2, j + 10, k + 15, Blocks.air);
		world.setBlock(i + 2, j + 10, k + 16, Blocks.air);
		world.setBlock(i + 2, j + 10, k + 17, Blocks.air);
		world.setBlock(i + 2, j + 10, k + 18, GameData.blockRegistry.getObjectById(102));
		world.setBlock(i + 2, j + 10, k + 19, Blocks.air);
		world.setBlock(i + 2, j + 10, k + 20, Blocks.air);
		world.setBlock(i + 2, j + 11, k + 0, Blocks.air);
		world.setBlock(i + 2, j + 11, k + 1, Blocks.air);
		world.setBlock(i + 2, j + 11, k + 2, Blocks.air);
		world.setBlock(i + 2, j + 11, k + 3, GameData.blockRegistry.getObjectById(102));
		world.setBlock(i + 2, j + 11, k + 4, Blocks.air);
		world.setBlock(i + 2, j + 11, k + 5, Blocks.air);
		world.setBlock(i + 2, j + 11, k + 6, Blocks.air);
		world.setBlock(i + 2, j + 11, k + 7, Blocks.air);
		world.setBlock(i + 2, j + 11, k + 8, Blocks.air);
		world.setBlock(i + 2, j + 11, k + 9, Blocks.air);
		world.setBlock(i + 2, j + 11, k + 10, Blocks.air);
		world.setBlock(i + 2, j + 11, k + 11, Blocks.air);
		world.setBlock(i + 2, j + 11, k + 12, Blocks.air);
		world.setBlock(i + 2, j + 11, k + 13, Blocks.air);
		world.setBlock(i + 2, j + 11, k + 14, Blocks.air);
		world.setBlock(i + 2, j + 11, k + 15, Blocks.air);
		world.setBlock(i + 2, j + 11, k + 16, Blocks.air);
		world.setBlock(i + 2, j + 11, k + 17, Blocks.air);
		world.setBlock(i + 2, j + 11, k + 18, GameData.blockRegistry.getObjectById(102));
		world.setBlock(i + 2, j + 11, k + 19, Blocks.air);
		world.setBlock(i + 2, j + 11, k + 20, Blocks.air);
		world.setBlock(i + 2, j + 12, k + 0, Blocks.air);
		world.setBlock(i + 2, j + 12, k + 1, Blocks.air);
		world.setBlock(i + 2, j + 12, k + 2, Blocks.air);
		world.setBlock(i + 2, j + 12, k + 3, GameData.blockRegistry.getObjectById(35), 14, 0);
		world.setBlock(i + 2, j + 12, k + 4, Blocks.air);
		world.setBlock(i + 2, j + 12, k + 5, Blocks.air);
		world.setBlock(i + 2, j + 12, k + 6, Blocks.air);
		world.setBlock(i + 2, j + 12, k + 7, Blocks.air);
		world.setBlock(i + 2, j + 12, k + 8, Blocks.air);
		world.setBlock(i + 2, j + 12, k + 9, Blocks.air);
		world.setBlock(i + 2, j + 12, k + 10, Blocks.air);
		world.setBlock(i + 2, j + 12, k + 11, Blocks.air);
		world.setBlock(i + 2, j + 12, k + 12, Blocks.air);
		world.setBlock(i + 2, j + 12, k + 13, Blocks.air);
		world.setBlock(i + 2, j + 12, k + 14, Blocks.air);
		world.setBlock(i + 2, j + 12, k + 15, Blocks.air);
		world.setBlock(i + 2, j + 12, k + 16, Blocks.air);
		world.setBlock(i + 2, j + 12, k + 17, Blocks.air);
		world.setBlock(i + 2, j + 12, k + 18, GameData.blockRegistry.getObjectById(35), 14, 0);
		world.setBlock(i + 2, j + 12, k + 19, Blocks.air);
		world.setBlock(i + 2, j + 12, k + 20, Blocks.air);
		world.setBlock(i + 2, j + 13, k + 0, Blocks.air);
		world.setBlock(i + 2, j + 13, k + 1, Blocks.air);
		world.setBlock(i + 2, j + 13, k + 2, Blocks.air);
		world.setBlock(i + 2, j + 13, k + 3, Blocks.air);
		world.setBlock(i + 2, j + 13, k + 4, GameData.blockRegistry.getObjectById(35), 14, 0);
		world.setBlock(i + 2, j + 13, k + 5, GameData.blockRegistry.getObjectById(35), 14, 0);
		world.setBlock(i + 2, j + 13, k + 6, GameData.blockRegistry.getObjectById(35), 14, 0);
		world.setBlock(i + 2, j + 13, k + 7, GameData.blockRegistry.getObjectById(35), 14, 0);
		world.setBlock(i + 2, j + 13, k + 8, GameData.blockRegistry.getObjectById(35), 14, 0);
		world.setBlock(i + 2, j + 13, k + 9, GameData.blockRegistry.getObjectById(35), 14, 0);
		world.setBlock(i + 2, j + 13, k + 10, GameData.blockRegistry.getObjectById(35), 14, 0);
		world.setBlock(i + 2, j + 13, k + 11, GameData.blockRegistry.getObjectById(35), 14, 0);
		world.setBlock(i + 2, j + 13, k + 12, GameData.blockRegistry.getObjectById(35), 14, 0);
		world.setBlock(i + 2, j + 13, k + 13, GameData.blockRegistry.getObjectById(35), 14, 0);
		world.setBlock(i + 2, j + 13, k + 14, GameData.blockRegistry.getObjectById(35), 14, 0);
		world.setBlock(i + 2, j + 13, k + 15, GameData.blockRegistry.getObjectById(35), 14, 0);
		world.setBlock(i + 2, j + 13, k + 16, GameData.blockRegistry.getObjectById(35), 14, 0);
		world.setBlock(i + 2, j + 13, k + 17, GameData.blockRegistry.getObjectById(35), 14, 0);
		world.setBlock(i + 2, j + 13, k + 18, Blocks.air);
		world.setBlock(i + 2, j + 13, k + 19, Blocks.air);
		world.setBlock(i + 2, j + 13, k + 20, Blocks.air);
		world.setBlock(i + 3, j + 0, k + 0,GameData.blockRegistry.getObjectById(2));
		world.setBlock(i + 3, j + 0, k + 1,GameData.blockRegistry.getObjectById(2));
		world.setBlock(i + 3, j + 0, k + 2,GameData.blockRegistry.getObjectById(2));
		world.setBlock(i + 3, j + 0, k + 3, GameData.blockRegistry.getObjectById(3));
		world.setBlock(i + 3, j + 0, k + 4, GameData.blockRegistry.getObjectById(3));
		world.setBlock(i + 3, j + 0, k + 5, GameData.blockRegistry.getObjectById(3));
		world.setBlock(i + 3, j + 0, k + 6, GameData.blockRegistry.getObjectById(35), 4, 0);
		world.setBlock(i + 3, j + 0, k + 7, GameData.blockRegistry.getObjectById(35), 4, 0);
		world.setBlock(i + 3, j + 0, k + 8, GameData.blockRegistry.getObjectById(35), 4, 0);
		world.setBlock(i + 3, j + 0, k + 9, GameData.blockRegistry.getObjectById(35), 4, 0);
		world.setBlock(i + 3, j + 0, k + 10, GameData.blockRegistry.getObjectById(35), 4, 0);
		world.setBlock(i + 3, j + 0, k + 11, GameData.blockRegistry.getObjectById(35), 4, 0);
		world.setBlock(i + 3, j + 0, k + 12, GameData.blockRegistry.getObjectById(35), 4, 0);
		world.setBlock(i + 3, j + 0, k + 13, GameData.blockRegistry.getObjectById(35), 4, 0);
		world.setBlock(i + 3, j + 0, k + 14, GameData.blockRegistry.getObjectById(35), 4, 0);
		world.setBlock(i + 3, j + 0, k + 15, GameData.blockRegistry.getObjectById(35), 4, 0);
		world.setBlock(i + 3, j + 0, k + 16, GameData.blockRegistry.getObjectById(35), 4, 0);
		world.setBlock(i + 3, j + 0, k + 17, GameData.blockRegistry.getObjectById(3));
		world.setBlock(i + 3, j + 0, k + 18, GameData.blockRegistry.getObjectById(3));
		world.setBlock(i + 3, j + 0, k + 19,GameData.blockRegistry.getObjectById(2));
		world.setBlock(i + 3, j + 0, k + 20,GameData.blockRegistry.getObjectById(2));
		world.setBlock(i + 3, j + 1, k + 0, Blocks.air);
		world.setBlock(i + 3, j + 1, k + 1, Blocks.air);
		world.setBlock(i + 3, j + 1, k + 2, Blocks.air);
		world.setBlock(i + 3, j + 1, k + 3, GameData.blockRegistry.getObjectById(35));
		world.setBlock(i + 3, j + 1, k + 4, GameData.blockRegistry.getObjectById(35));
		world.setBlock(i + 3, j + 1, k + 5, GameData.blockRegistry.getObjectById(35), 14, 0);
		world.setBlock(i + 3, j + 1, k + 6, Blocks.air);
		world.setBlock(i + 3, j + 1, k + 7, Blocks.air);
		world.setBlock(i + 3, j + 1, k + 8, Blocks.air);
		world.setBlock(i + 3, j + 1, k + 9, Blocks.air);
		world.setBlock(i + 3, j + 1, k + 10, Blocks.air);
		world.setBlock(i + 3, j + 1, k + 11, Blocks.air);
		world.setBlock(i + 3, j + 1, k + 12, Blocks.air);
		world.setBlock(i + 3, j + 1, k + 13, Blocks.air);
		world.setBlock(i + 3, j + 1, k + 14, Blocks.air);
		world.setBlock(i + 3, j + 1, k + 15, Blocks.air);
		world.setBlock(i + 3, j + 1, k + 16, Blocks.air);
		world.setBlock(i + 3, j + 1, k + 17, GameData.blockRegistry.getObjectById(35), 14, 0);
		world.setBlock(i + 3, j + 1, k + 18, GameData.blockRegistry.getObjectById(35));
		world.setBlock(i + 3, j + 1, k + 19, Blocks.air);
		world.setBlock(i + 3, j + 1, k + 20, Blocks.air);
		world.setBlock(i + 3, j + 2, k + 0, Blocks.air);
		world.setBlock(i + 3, j + 2, k + 1, Blocks.air);
		world.setBlock(i + 3, j + 2, k + 2, Blocks.air);
		world.setBlock(i + 3, j + 2, k + 3, Blocks.air);
		world.setBlock(i + 3, j + 2, k + 4, GameData.blockRegistry.getObjectById(35));
		world.setBlock(i + 3, j + 2, k + 5, GameData.blockRegistry.getObjectById(35), 14, 0);
		world.setBlock(i + 3, j + 2, k + 6, Blocks.air);
		world.setBlock(i + 3, j + 2, k + 7, Blocks.air);
		world.setBlock(i + 3, j + 2, k + 8, Blocks.air);
		world.setBlock(i + 3, j + 2, k + 9, Blocks.air);
		world.setBlock(i + 3, j + 2, k + 10, Blocks.air);
		world.setBlock(i + 3, j + 2, k + 11, Blocks.air);
		world.setBlock(i + 3, j + 2, k + 12, Blocks.air);
		world.setBlock(i + 3, j + 2, k + 13, Blocks.air);
		world.setBlock(i + 3, j + 2, k + 14, Blocks.air);
		world.setBlock(i + 3, j + 2, k + 15, Blocks.air);
		world.setBlock(i + 3, j + 2, k + 16, Blocks.air);
		world.setBlock(i + 3, j + 2, k + 17, GameData.blockRegistry.getObjectById(35), 14, 0);
		world.setBlock(i + 3, j + 2, k + 18, GameData.blockRegistry.getObjectById(35));
		world.setBlock(i + 3, j + 2, k + 19, Blocks.air);
		world.setBlock(i + 3, j + 2, k + 20, Blocks.air);
		world.setBlock(i + 3, j + 3, k + 0, Blocks.air);
		world.setBlock(i + 3, j + 3, k + 1, Blocks.air);
		world.setBlock(i + 3, j + 3, k + 2, Blocks.air);
		world.setBlock(i + 3, j + 3, k + 3, Blocks.air);
		world.setBlock(i + 3, j + 3, k + 4, GameData.blockRegistry.getObjectById(35));
		world.setBlock(i + 3, j + 3, k + 5, GameData.blockRegistry.getObjectById(35), 14, 0);
		world.setBlock(i + 3, j + 3, k + 7, Blocks.air);
		world.setBlock(i + 3, j + 3, k + 8, Blocks.air);
		world.setBlock(i + 3, j + 3, k + 9, Blocks.air);
		world.setBlock(i + 3, j + 3, k + 10, Blocks.air);
		world.setBlock(i + 3, j + 3, k + 11, Blocks.air);
		world.setBlock(i + 3, j + 3, k + 12, Blocks.air);
		world.setBlock(i + 3, j + 3, k + 13, Blocks.air);
		world.setBlock(i + 3, j + 3, k + 14, Blocks.air);
		world.setBlock(i + 3, j + 3, k + 15, Blocks.air);
		world.setBlock(i + 3, j + 3, k + 17, GameData.blockRegistry.getObjectById(35), 14, 0);
		world.setBlock(i + 3, j + 3, k + 18, GameData.blockRegistry.getObjectById(35));
		world.setBlock(i + 3, j + 3, k + 19, Blocks.air);
		world.setBlock(i + 3, j + 3, k + 20, Blocks.air);
		world.setBlock(i + 3, j + 4, k + 0, Blocks.air);
		world.setBlock(i + 3, j + 4, k + 1, Blocks.air);
		world.setBlock(i + 3, j + 4, k + 2, Blocks.air);
		world.setBlock(i + 3, j + 4, k + 3, Blocks.air);
		world.setBlock(i + 3, j + 4, k + 4, GameData.blockRegistry.getObjectById(35));
		world.setBlock(i + 3, j + 4, k + 5, GameData.blockRegistry.getObjectById(35), 14, 0);
		world.setBlock(i + 3, j + 4, k + 6, Blocks.air);
		world.setBlock(i + 3, j + 4, k + 7, Blocks.air);
		world.setBlock(i + 3, j + 4, k + 8, Blocks.air);
		world.setBlock(i + 3, j + 4, k + 9, Blocks.air);
		world.setBlock(i + 3, j + 4, k + 10, Blocks.air);
		world.setBlock(i + 3, j + 4, k + 11, Blocks.air);
		world.setBlock(i + 3, j + 4, k + 12, Blocks.air);
		world.setBlock(i + 3, j + 4, k + 13, Blocks.air);
		world.setBlock(i + 3, j + 4, k + 14, Blocks.air);
		world.setBlock(i + 3, j + 4, k + 15, Blocks.air);
		world.setBlock(i + 3, j + 4, k + 16, Blocks.air);
		world.setBlock(i + 3, j + 4, k + 17, GameData.blockRegistry.getObjectById(35), 14, 0);
		world.setBlock(i + 3, j + 4, k + 18, GameData.blockRegistry.getObjectById(35));
		world.setBlock(i + 3, j + 4, k + 19, Blocks.air);
		world.setBlock(i + 3, j + 4, k + 20, Blocks.air);
		world.setBlock(i + 3, j + 5, k + 0, Blocks.air);
		world.setBlock(i + 3, j + 5, k + 1, Blocks.air);
		world.setBlock(i + 3, j + 5, k + 2, Blocks.air);
		world.setBlock(i + 3, j + 5, k + 3, Blocks.air);
		world.setBlock(i + 3, j + 5, k + 4, GameData.blockRegistry.getObjectById(35));
		world.setBlock(i + 3, j + 5, k + 5, GameData.blockRegistry.getObjectById(35), 14, 0);
		world.setBlock(i + 3, j + 5, k + 6, GameData.blockRegistry.getObjectById(35));
		world.setBlock(i + 3, j + 5, k + 7, GameData.blockRegistry.getObjectById(35));
		world.setBlock(i + 3, j + 5, k + 8, GameData.blockRegistry.getObjectById(35));
		world.setBlock(i + 3, j + 5, k + 9, GameData.blockRegistry.getObjectById(35));
		world.setBlock(i + 3, j + 5, k + 10, GameData.blockRegistry.getObjectById(35));
		world.setBlock(i + 3, j + 5, k + 11, GameData.blockRegistry.getObjectById(35));
		world.setBlock(i + 3, j + 5, k + 12, GameData.blockRegistry.getObjectById(35));
		world.setBlock(i + 3, j + 5, k + 13, GameData.blockRegistry.getObjectById(35));
		world.setBlock(i + 3, j + 5, k + 14, GameData.blockRegistry.getObjectById(35));
		world.setBlock(i + 3, j + 5, k + 15, GameData.blockRegistry.getObjectById(35));
		world.setBlock(i + 3, j + 5, k + 16, GameData.blockRegistry.getObjectById(35));
		world.setBlock(i + 3, j + 5, k + 17, GameData.blockRegistry.getObjectById(35));
		world.setBlock(i + 3, j + 5, k + 18, GameData.blockRegistry.getObjectById(35));
		world.setBlock(i + 3, j + 5, k + 19, Blocks.air);
		world.setBlock(i + 3, j + 5, k + 20, Blocks.air);
		world.setBlock(i + 3, j + 6, k + 0, Blocks.air);
		world.setBlock(i + 3, j + 6, k + 1, Blocks.air);
		world.setBlock(i + 3, j + 6, k + 2, Blocks.air);
		world.setBlock(i + 3, j + 6, k + 3, GameData.blockRegistry.getObjectById(35));
		world.setBlock(i + 3, j + 6, k + 4, GameData.blockRegistry.getObjectById(35), 4, 0);
		world.setBlock(i + 3, j + 6, k + 5, GameData.blockRegistry.getObjectById(35), 4, 0);
		world.setBlock(i + 3, j + 6, k + 6, GameData.blockRegistry.getObjectById(35), 4, 0);
		world.setBlock(i + 3, j + 6, k + 7, GameData.blockRegistry.getObjectById(35), 4, 0);
		world.setBlock(i + 3, j + 6, k + 8, GameData.blockRegistry.getObjectById(35), 4, 0);
		world.setBlock(i + 3, j + 6, k + 9, GameData.blockRegistry.getObjectById(35), 4, 0);
		world.setBlock(i + 3, j + 6, k + 10, GameData.blockRegistry.getObjectById(35), 4, 0);
		world.setBlock(i + 3, j + 6, k + 11, GameData.blockRegistry.getObjectById(35), 4, 0);
		world.setBlock(i + 3, j + 6, k + 12, GameData.blockRegistry.getObjectById(35), 4, 0);
		world.setBlock(i + 3, j + 6, k + 13, GameData.blockRegistry.getObjectById(35), 4, 0);
		world.setBlock(i + 3, j + 6, k + 14, GameData.blockRegistry.getObjectById(35), 4, 0);
		world.setBlock(i + 3, j + 6, k + 15, GameData.blockRegistry.getObjectById(35), 4, 0);
		world.setBlock(i + 3, j + 6, k + 16, GameData.blockRegistry.getObjectById(35), 4, 0);
		world.setBlock(i + 3, j + 6, k + 17, GameData.blockRegistry.getObjectById(35), 4, 0);
		world.setBlock(i + 3, j + 6, k + 18, GameData.blockRegistry.getObjectById(35));
		world.setBlock(i + 3, j + 6, k + 19, Blocks.air);
		world.setBlock(i + 3, j + 6, k + 20, Blocks.air);
		world.setBlock(i + 3, j + 7, k + 0, Blocks.air);
		world.setBlock(i + 3, j + 7, k + 1, Blocks.air);
		world.setBlock(i + 3, j + 7, k + 2, Blocks.air);
		world.setBlock(i + 3, j + 7, k + 3, GameData.blockRegistry.getObjectById(35));
		world.setBlock(i + 3, j + 7, k + 4, Blocks.air);
		world.setBlock(i + 3, j + 7, k + 5, Blocks.air);
		world.setBlock(i + 3, j + 7, k + 6, Blocks.air);
		world.setBlock(i + 3, j + 7, k + 7, Blocks.air);
		world.setBlock(i + 3, j + 7, k + 8, Blocks.air);
		world.setBlock(i + 3, j + 7, k + 9, Blocks.air);
		world.setBlock(i + 3, j + 7, k + 10, Blocks.air);
		world.setBlock(i + 3, j + 7, k + 11, Blocks.air);
		world.setBlock(i + 3, j + 7, k + 12, Blocks.air);
		world.setBlock(i + 3, j + 7, k + 13, Blocks.air);
		world.setBlock(i + 3, j + 7, k + 14, Blocks.air);
		world.setBlock(i + 3, j + 7, k + 15, GameData.blockRegistry.getObjectById(35));
		world.setBlock(i + 3, j + 7, k + 16, GameData.blockRegistry.getObjectById(35));
		world.setBlock(i + 3, j + 7, k + 17, GameData.blockRegistry.getObjectById(35));
		world.setBlock(i + 3, j + 7, k + 18, GameData.blockRegistry.getObjectById(35));
		world.setBlock(i + 3, j + 7, k + 19, Blocks.air);
		world.setBlock(i + 3, j + 7, k + 20, Blocks.air);
		world.setBlock(i + 3, j + 8, k + 0, Blocks.air);
		world.setBlock(i + 3, j + 8, k + 1, Blocks.air);
		world.setBlock(i + 3, j + 8, k + 2, Blocks.air);
		world.setBlock(i + 3, j + 8, k + 3, GameData.blockRegistry.getObjectById(35));
		world.setBlock(i + 3, j + 8, k + 4, Blocks.air);
		world.setBlock(i + 3, j + 8, k + 5, Blocks.air);
		world.setBlock(i + 3, j + 8, k + 6, Blocks.air);
		world.setBlock(i + 3, j + 8, k + 7, Blocks.air);
		world.setBlock(i + 3, j + 8, k + 8, Blocks.air);
		world.setBlock(i + 3, j + 8, k + 9, Blocks.air);
		world.setBlock(i + 3, j + 8, k + 10, Blocks.air);
		world.setBlock(i + 3, j + 8, k + 11, Blocks.air);
		world.setBlock(i + 3, j + 8, k + 12, Blocks.air);
		world.setBlock(i + 3, j + 8, k + 13, Blocks.air);
		world.setBlock(i + 3, j + 8, k + 14, Blocks.air);
		world.setBlock(i + 3, j + 8, k + 15, GameData.blockRegistry.getObjectById(35));
		world.setBlock(i + 3, j + 8, k + 16, GameData.blockRegistry.getObjectById(35));
		world.setBlock(i + 3, j + 8, k + 17, GameData.blockRegistry.getObjectById(35));
		world.setBlock(i + 3, j + 8, k + 18, GameData.blockRegistry.getObjectById(35));
		world.setBlock(i + 3, j + 8, k + 19, Blocks.air);
		world.setBlock(i + 3, j + 8, k + 20, Blocks.air);
		world.setBlock(i + 3, j + 9, k + 0, Blocks.air);
		world.setBlock(i + 3, j + 9, k + 1, Blocks.air);
		world.setBlock(i + 3, j + 9, k + 2, Blocks.air);
		world.setBlock(i + 3, j + 9, k + 3, GameData.blockRegistry.getObjectById(35));
		world.setBlock(i + 3, j + 9, k + 4, Blocks.air);
		world.setBlock(i + 3, j + 9, k + 5, Blocks.air);
		world.setBlock(i + 3, j + 9, k + 6, Blocks.air);
		world.setBlock(i + 3, j + 9, k + 7, Blocks.air);
		world.setBlock(i + 3, j + 9, k + 8, Blocks.air);
		world.setBlock(i + 3, j + 9, k + 9, Blocks.air);
		world.setBlock(i + 3, j + 9, k + 10, Blocks.air);
		world.setBlock(i + 3, j + 9, k + 11, Blocks.air);
		world.setBlock(i + 3, j + 9, k + 12, Blocks.air);
		world.setBlock(i + 3, j + 9, k + 13, Blocks.air);
		world.setBlock(i + 3, j + 9, k + 14, Blocks.air);
		world.setBlock(i + 3, j + 9, k + 15, GameData.blockRegistry.getObjectById(35));
		world.setBlock(i + 3, j + 9, k + 16, GameData.blockRegistry.getObjectById(35));
		world.setBlock(i + 3, j + 9, k + 17, GameData.blockRegistry.getObjectById(35));
		world.setBlock(i + 3, j + 9, k + 18, GameData.blockRegistry.getObjectById(35));
		world.setBlock(i + 3, j + 9, k + 19, Blocks.air);
		world.setBlock(i + 3, j + 9, k + 20, Blocks.air);
		world.setBlock(i + 3, j + 10, k + 0, Blocks.air);
		world.setBlock(i + 3, j + 10, k + 1, Blocks.air);
		world.setBlock(i + 3, j + 10, k + 2, Blocks.air);
		world.setBlock(i + 3, j + 10, k + 3, GameData.blockRegistry.getObjectById(35));
		world.setBlock(i + 3, j + 10, k + 4, Blocks.air);
		world.setBlock(i + 3, j + 10, k + 5, Blocks.air);
		world.setBlock(i + 3, j + 10, k + 6, Blocks.air);
		world.setBlock(i + 3, j + 10, k + 7, Blocks.air);
		world.setBlock(i + 3, j + 10, k + 8, Blocks.air);
		world.setBlock(i + 3, j + 10, k + 9, Blocks.air);
		world.setBlock(i + 3, j + 10, k + 10, Blocks.air);
		world.setBlock(i + 3, j + 10, k + 11, Blocks.air);
		world.setBlock(i + 3, j + 10, k + 12, Blocks.air);
		world.setBlock(i + 3, j + 10, k + 13, Blocks.air);
		world.setBlock(i + 3, j + 10, k + 14, Blocks.air);
		world.setBlock(i + 3, j + 10, k + 15, Blocks.air);
		world.setBlock(i + 3, j + 10, k + 16, Blocks.air);
		world.setBlock(i + 3, j + 10, k + 17, Blocks.air);
		world.setBlock(i + 3, j + 10, k + 18, GameData.blockRegistry.getObjectById(35));
		world.setBlock(i + 3, j + 10, k + 19, Blocks.air);
		world.setBlock(i + 3, j + 10, k + 20, Blocks.air);
		world.setBlock(i + 3, j + 11, k + 0, Blocks.air);
		world.setBlock(i + 3, j + 11, k + 1, Blocks.air);
		world.setBlock(i + 3, j + 11, k + 2, Blocks.air);
		world.setBlock(i + 3, j + 11, k + 3, GameData.blockRegistry.getObjectById(35));
		world.setBlock(i + 3, j + 11, k + 4, Blocks.air);
		world.setBlock(i + 3, j + 11, k + 5, Blocks.air);
		world.setBlock(i + 3, j + 11, k + 6, Blocks.air);
		world.setBlock(i + 3, j + 11, k + 7, Blocks.air);
		world.setBlock(i + 3, j + 11, k + 8, Blocks.air);
		world.setBlock(i + 3, j + 11, k + 9, Blocks.air);
		world.setBlock(i + 3, j + 11, k + 10, Blocks.air);
		world.setBlock(i + 3, j + 11, k + 11, Blocks.air);
		world.setBlock(i + 3, j + 11, k + 12, Blocks.air);
		world.setBlock(i + 3, j + 11, k + 13, Blocks.air);
		world.setBlock(i + 3, j + 11, k + 14, Blocks.air);
		world.setBlock(i + 3, j + 11, k + 15, Blocks.air);
		world.setBlock(i + 3, j + 11, k + 16, Blocks.air);
		world.setBlock(i + 3, j + 11, k + 17, Blocks.air);
		world.setBlock(i + 3, j + 11, k + 18, GameData.blockRegistry.getObjectById(35));
		world.setBlock(i + 3, j + 11, k + 19, Blocks.air);
		world.setBlock(i + 3, j + 11, k + 20, Blocks.air);
		world.setBlock(i + 3, j + 12, k + 0, Blocks.air);
		world.setBlock(i + 3, j + 12, k + 1, Blocks.air);
		world.setBlock(i + 3, j + 12, k + 2, Blocks.air);
		world.setBlock(i + 3, j + 12, k + 3, GameData.blockRegistry.getObjectById(35), 14, 0);
		world.setBlock(i + 3, j + 12, k + 4, Blocks.air);
		world.setBlock(i + 3, j + 12, k + 5, Blocks.air);
		world.setBlock(i + 3, j + 12, k + 6, Blocks.air);
		world.setBlock(i + 3, j + 12, k + 7, Blocks.air);
		world.setBlock(i + 3, j + 12, k + 8, Blocks.air);
		world.setBlock(i + 3, j + 12, k + 9, Blocks.air);
		world.setBlock(i + 3, j + 12, k + 10, Blocks.air);
		world.setBlock(i + 3, j + 12, k + 11, Blocks.air);
		world.setBlock(i + 3, j + 12, k + 12, Blocks.air);
		world.setBlock(i + 3, j + 12, k + 13, Blocks.air);
		world.setBlock(i + 3, j + 12, k + 14, Blocks.air);
		world.setBlock(i + 3, j + 12, k + 15, Blocks.air);
		world.setBlock(i + 3, j + 12, k + 16, Blocks.air);
		world.setBlock(i + 3, j + 12, k + 17, Blocks.air);
		world.setBlock(i + 3, j + 12, k + 18, GameData.blockRegistry.getObjectById(35), 14, 0);
		world.setBlock(i + 3, j + 12, k + 19, Blocks.air);
		world.setBlock(i + 3, j + 12, k + 20, Blocks.air);
		world.setBlock(i + 3, j + 13, k + 0, Blocks.air);
		world.setBlock(i + 3, j + 13, k + 1, Blocks.air);
		world.setBlock(i + 3, j + 13, k + 2, Blocks.air);
		world.setBlock(i + 3, j + 13, k + 3, Blocks.air);
		world.setBlock(i + 3, j + 13, k + 4, GameData.blockRegistry.getObjectById(35), 14, 0);
		world.setBlock(i + 3, j + 13, k + 5, GameData.blockRegistry.getObjectById(35), 14, 0);
		world.setBlock(i + 3, j + 13, k + 6, GameData.blockRegistry.getObjectById(35), 14, 0);
		world.setBlock(i + 3, j + 13, k + 7, GameData.blockRegistry.getObjectById(35), 14, 0);
		world.setBlock(i + 3, j + 13, k + 8, GameData.blockRegistry.getObjectById(35), 14, 0);
		world.setBlock(i + 3, j + 13, k + 9, GameData.blockRegistry.getObjectById(35), 14, 0);
		world.setBlock(i + 3, j + 13, k + 10, GameData.blockRegistry.getObjectById(35), 14, 0);
		world.setBlock(i + 3, j + 13, k + 11, GameData.blockRegistry.getObjectById(35), 14, 0);
		world.setBlock(i + 3, j + 13, k + 12, GameData.blockRegistry.getObjectById(35), 14, 0);
		world.setBlock(i + 3, j + 13, k + 13, GameData.blockRegistry.getObjectById(35), 14, 0);
		world.setBlock(i + 3, j + 13, k + 14, GameData.blockRegistry.getObjectById(35), 14, 0);
		world.setBlock(i + 3, j + 13, k + 15, GameData.blockRegistry.getObjectById(35), 14, 0);
		world.setBlock(i + 3, j + 13, k + 16, GameData.blockRegistry.getObjectById(35), 14, 0);
		world.setBlock(i + 3, j + 13, k + 17, GameData.blockRegistry.getObjectById(35), 14, 0);
		world.setBlock(i + 3, j + 13, k + 18, Blocks.air);
		world.setBlock(i + 3, j + 13, k + 19, Blocks.air);
		world.setBlock(i + 3, j + 13, k + 20, Blocks.air);
		world.setBlock(i + 4, j + 0, k + 0,GameData.blockRegistry.getObjectById(2));
		world.setBlock(i + 4, j + 0, k + 1,GameData.blockRegistry.getObjectById(2));
		world.setBlock(i + 4, j + 0, k + 2,GameData.blockRegistry.getObjectById(2));
		world.setBlock(i + 4, j + 0, k + 3, GameData.blockRegistry.getObjectById(3));
		world.setBlock(i + 4, j + 0, k + 4, GameData.blockRegistry.getObjectById(3));
		world.setBlock(i + 4, j + 0, k + 5, GameData.blockRegistry.getObjectById(3));
		world.setBlock(i + 4, j + 0, k + 6, GameData.blockRegistry.getObjectById(35), 4, 0);
		world.setBlock(i + 4, j + 0, k + 7, GameData.blockRegistry.getObjectById(35), 4, 0);
		world.setBlock(i + 4, j + 0, k + 8, GameData.blockRegistry.getObjectById(35), 4, 0);
		world.setBlock(i + 4, j + 0, k + 9, GameData.blockRegistry.getObjectById(35), 4, 0);
		world.setBlock(i + 4, j + 0, k + 10, GameData.blockRegistry.getObjectById(35), 4, 0);
		world.setBlock(i + 4, j + 0, k + 11, GameData.blockRegistry.getObjectById(35), 4, 0);
		world.setBlock(i + 4, j + 0, k + 12, GameData.blockRegistry.getObjectById(35), 4, 0);
		world.setBlock(i + 4, j + 0, k + 13, GameData.blockRegistry.getObjectById(35), 4, 0);
		world.setBlock(i + 4, j + 0, k + 14, GameData.blockRegistry.getObjectById(35), 4, 0);
		world.setBlock(i + 4, j + 0, k + 15, GameData.blockRegistry.getObjectById(35), 4, 0);
		world.setBlock(i + 4, j + 0, k + 16, GameData.blockRegistry.getObjectById(35), 4, 0);
		world.setBlock(i + 4, j + 0, k + 17, GameData.blockRegistry.getObjectById(3));
		world.setBlock(i + 4, j + 0, k + 18, GameData.blockRegistry.getObjectById(3));
		world.setBlock(i + 4, j + 0, k + 19,GameData.blockRegistry.getObjectById(2));
		world.setBlock(i + 4, j + 0, k + 20,GameData.blockRegistry.getObjectById(2));
		world.setBlock(i + 4, j + 1, k + 0, Blocks.air);
		world.setBlock(i + 4, j + 1, k + 1, Blocks.air);
		world.setBlock(i + 4, j + 1, k + 2, Blocks.air);
		world.setBlock(i + 4, j + 1, k + 3, GameData.blockRegistry.getObjectById(35));
		world.setBlock(i + 4, j + 1, k + 4, GameData.blockRegistry.getObjectById(35));
		world.setBlock(i + 4, j + 1, k + 5, GameData.blockRegistry.getObjectById(35), 14, 0);
		world.setBlock(i + 4, j + 1, k + 6, Blocks.air);
		world.setBlock(i + 4, j + 1, k + 7, Blocks.air);
		world.setBlock(i + 4, j + 1, k + 8, GameData.blockRegistry.getObjectById(85));
		world.setBlock(i + 4, j + 1, k + 9, GameData.blockRegistry.getObjectById(35));
		world.setBlock(i + 4, j + 1, k + 10, Blocks.air);
		world.setBlock(i + 4, j + 1, k + 11, Blocks.air);
		world.setBlock(i + 4, j + 1, k + 12, Blocks.air);
		world.setBlock(i + 4, j + 1, k + 13, Blocks.air);
		world.setBlock(i + 4, j + 1, k + 14, Blocks.air);
		world.setBlock(i + 4, j + 1, k + 15, GameData.blockRegistry.getObjectById(43), 5, 0);
		world.setBlock(i + 4, j + 1, k + 16, GameData.blockRegistry.getObjectById(35));
		world.setBlock(i + 4, j + 1, k + 17, GameData.blockRegistry.getObjectById(35), 14, 0);
		world.setBlock(i + 4, j + 1, k + 18, GameData.blockRegistry.getObjectById(35));
		world.setBlock(i + 4, j + 1, k + 19, Blocks.air);
		world.setBlock(i + 4, j + 1, k + 20, Blocks.air);
		world.setBlock(i + 4, j + 2, k + 0, Blocks.air);
		world.setBlock(i + 4, j + 2, k + 1, Blocks.air);
		world.setBlock(i + 4, j + 2, k + 2, Blocks.air);
		world.setBlock(i + 4, j + 2, k + 3, Blocks.air);
		world.setBlock(i + 4, j + 2, k + 4, GameData.blockRegistry.getObjectById(35));
		world.setBlock(i + 4, j + 2, k + 5, GameData.blockRegistry.getObjectById(35), 14, 0);
		world.setBlock(i + 4, j + 2, k + 6, Blocks.air);
		world.setBlock(i + 4, j + 2, k + 7, Blocks.air);
		world.setBlock(i + 4, j + 2, k + 10, Blocks.air);
		world.setBlock(i + 4, j + 2, k + 11, Blocks.air);
		world.setBlock(i + 4, j + 2, k + 12, Blocks.air);
		world.setBlock(i + 4, j + 2, k + 13, Blocks.air);
		world.setBlock(i + 4, j + 2, k + 14, Blocks.air);
		world.setBlock(i + 4, j + 2, k + 15, Blocks.air);
		world.setBlock(i + 4, j + 2, k + 16, GameData.blockRegistry.getObjectById(35));
		world.setBlock(i + 4, j + 2, k + 17, GameData.blockRegistry.getObjectById(35), 14, 0);
		world.setBlock(i + 4, j + 2, k + 18, GameData.blockRegistry.getObjectById(35));
		world.setBlock(i + 4, j + 2, k + 19, Blocks.air);
		world.setBlock(i + 4, j + 2, k + 20, Blocks.air);
		world.setBlock(i + 4, j + 3, k + 0, Blocks.air);
		world.setBlock(i + 4, j + 3, k + 1, Blocks.air);
		world.setBlock(i + 4, j + 3, k + 2, Blocks.air);
		world.setBlock(i + 4, j + 3, k + 3, Blocks.air);
		world.setBlock(i + 4, j + 3, k + 4, GameData.blockRegistry.getObjectById(35));
		world.setBlock(i + 4, j + 3, k + 5, GameData.blockRegistry.getObjectById(35), 14, 0);
		world.setBlock(i + 4, j + 3, k + 7, Blocks.air);
		world.setBlock(i + 4, j + 3, k + 8, Blocks.air);
		world.setBlock(i + 4, j + 3, k + 9, Blocks.air);
		world.setBlock(i + 4, j + 3, k + 10, Blocks.air);
		world.setBlock(i + 4, j + 3, k + 11, Blocks.air);
		world.setBlock(i + 4, j + 3, k + 12, Blocks.air);
		world.setBlock(i + 4, j + 3, k + 13, Blocks.air);
		world.setBlock(i + 4, j + 3, k + 14, Blocks.air);
		world.setBlock(i + 4, j + 3, k + 15, Blocks.air);
		world.setBlock(i + 4, j + 3, k + 17, GameData.blockRegistry.getObjectById(35), 14, 0);
		world.setBlock(i + 4, j + 3, k + 18, GameData.blockRegistry.getObjectById(35));
		world.setBlock(i + 4, j + 3, k + 19, Blocks.air);
		world.setBlock(i + 4, j + 3, k + 20, Blocks.air);
		world.setBlock(i + 4, j + 4, k + 0, Blocks.air);
		world.setBlock(i + 4, j + 4, k + 1, Blocks.air);
		world.setBlock(i + 4, j + 4, k + 2, Blocks.air);
		world.setBlock(i + 4, j + 4, k + 3, Blocks.air);
		world.setBlock(i + 4, j + 4, k + 4, GameData.blockRegistry.getObjectById(35));
		world.setBlock(i + 4, j + 4, k + 5, GameData.blockRegistry.getObjectById(35), 14, 0);
		world.setBlock(i + 4, j + 4, k + 6, Blocks.air);
		world.setBlock(i + 4, j + 4, k + 7, Blocks.air);
		world.setBlock(i + 4, j + 4, k + 8, Blocks.air);
		world.setBlock(i + 4, j + 4, k + 9, Blocks.air);
		world.setBlock(i + 4, j + 4, k + 10, Blocks.air);
		world.setBlock(i + 4, j + 4, k + 11, Blocks.air);
		world.setBlock(i + 4, j + 4, k + 12, Blocks.air);
		world.setBlock(i + 4, j + 4, k + 13, Blocks.air);
		world.setBlock(i + 4, j + 4, k + 14, Blocks.air);
		world.setBlock(i + 4, j + 4, k + 15, Blocks.air);
		world.setBlock(i + 4, j + 4, k + 16, Blocks.air);
		world.setBlock(i + 4, j + 4, k + 17, GameData.blockRegistry.getObjectById(35), 14, 0);
		world.setBlock(i + 4, j + 4, k + 18, GameData.blockRegistry.getObjectById(35));
		world.setBlock(i + 4, j + 4, k + 19, Blocks.air);
		world.setBlock(i + 4, j + 4, k + 20, Blocks.air);
		world.setBlock(i + 4, j + 5, k + 0, Blocks.air);
		world.setBlock(i + 4, j + 5, k + 1, Blocks.air);
		world.setBlock(i + 4, j + 5, k + 2, Blocks.air);
		world.setBlock(i + 4, j + 5, k + 3, Blocks.air);
		world.setBlock(i + 4, j + 5, k + 4, GameData.blockRegistry.getObjectById(35));
		world.setBlock(i + 4, j + 5, k + 5, GameData.blockRegistry.getObjectById(35), 14, 0);
		world.setBlock(i + 4, j + 5, k + 6, GameData.blockRegistry.getObjectById(35));
		world.setBlock(i + 4, j + 5, k + 7, GameData.blockRegistry.getObjectById(35));
		world.setBlock(i + 4, j + 5, k + 8, GameData.blockRegistry.getObjectById(35));
		world.setBlock(i + 4, j + 5, k + 9, GameData.blockRegistry.getObjectById(35));
		world.setBlock(i + 4, j + 5, k + 10, GameData.blockRegistry.getObjectById(35));
		world.setBlock(i + 4, j + 5, k + 11, GameData.blockRegistry.getObjectById(35));
		world.setBlock(i + 4, j + 5, k + 12, GameData.blockRegistry.getObjectById(35));
		world.setBlock(i + 4, j + 5, k + 13, GameData.blockRegistry.getObjectById(35));
		world.setBlock(i + 4, j + 5, k + 14, GameData.blockRegistry.getObjectById(35));
		world.setBlock(i + 4, j + 5, k + 15, GameData.blockRegistry.getObjectById(35));
		world.setBlock(i + 4, j + 5, k + 16, GameData.blockRegistry.getObjectById(35));
		world.setBlock(i + 4, j + 5, k + 17, GameData.blockRegistry.getObjectById(35));
		world.setBlock(i + 4, j + 5, k + 18, GameData.blockRegistry.getObjectById(35));
		world.setBlock(i + 4, j + 5, k + 19, Blocks.air);
		world.setBlock(i + 4, j + 5, k + 20, Blocks.air);
		world.setBlock(i + 4, j + 6, k + 0, Blocks.air);
		world.setBlock(i + 4, j + 6, k + 1, Blocks.air);
		world.setBlock(i + 4, j + 6, k + 2, Blocks.air);
		world.setBlock(i + 4, j + 6, k + 3, GameData.blockRegistry.getObjectById(35));
		world.setBlock(i + 4, j + 6, k + 4, GameData.blockRegistry.getObjectById(35), 4, 0);
		world.setBlock(i + 4, j + 6, k + 5, GameData.blockRegistry.getObjectById(35), 4, 0);
		world.setBlock(i + 4, j + 6, k + 6, GameData.blockRegistry.getObjectById(35), 4, 0);
		world.setBlock(i + 4, j + 6, k + 7, GameData.blockRegistry.getObjectById(35), 4, 0);
		world.setBlock(i + 4, j + 6, k + 8, GameData.blockRegistry.getObjectById(35), 4, 0);
		world.setBlock(i + 4, j + 6, k + 9, GameData.blockRegistry.getObjectById(35), 4, 0);
		world.setBlock(i + 4, j + 6, k + 10, GameData.blockRegistry.getObjectById(35), 4, 0);
		world.setBlock(i + 4, j + 6, k + 11, GameData.blockRegistry.getObjectById(35), 4, 0);
		world.setBlock(i + 4, j + 6, k + 12, GameData.blockRegistry.getObjectById(35), 4, 0);
		world.setBlock(i + 4, j + 6, k + 13, GameData.blockRegistry.getObjectById(35), 4, 0);
		world.setBlock(i + 4, j + 6, k + 14, GameData.blockRegistry.getObjectById(35), 4, 0);
		world.setBlock(i + 4, j + 6, k + 15, GameData.blockRegistry.getObjectById(35), 4, 0);
		world.setBlock(i + 4, j + 6, k + 16, GameData.blockRegistry.getObjectById(35), 4, 0);
		world.setBlock(i + 4, j + 6, k + 17, GameData.blockRegistry.getObjectById(35), 4, 0);
		world.setBlock(i + 4, j + 6, k + 18, GameData.blockRegistry.getObjectById(35));
		world.setBlock(i + 4, j + 6, k + 19, Blocks.air);
		world.setBlock(i + 4, j + 6, k + 20, Blocks.air);
		world.setBlock(i + 4, j + 7, k + 0, Blocks.air);
		world.setBlock(i + 4, j + 7, k + 1, Blocks.air);
		world.setBlock(i + 4, j + 7, k + 2, Blocks.air);
		world.setBlock(i + 4, j + 7, k + 3, GameData.blockRegistry.getObjectById(102));
		world.setBlock(i + 4, j + 7, k + 4, Blocks.air);
		world.setBlock(i + 4, j + 7, k + 5, Blocks.air);
		world.setBlock(i + 4, j + 7, k + 6, Blocks.air);
		world.setBlock(i + 4, j + 7, k + 7, Blocks.air);
		world.setBlock(i + 4, j + 7, k + 8, Blocks.air);
		world.setBlock(i + 4, j + 7, k + 9, Blocks.air);
		world.setBlock(i + 4, j + 7, k + 10, Blocks.air);
		world.setBlock(i + 4, j + 7, k + 11, Blocks.air);
		world.setBlock(i + 4, j + 7, k + 12, Blocks.air);
		world.setBlock(i + 4, j + 7, k + 13, Blocks.air);
		world.setBlock(i + 4, j + 7, k + 14, Blocks.air);
		world.setBlock(i + 4, j + 7, k + 15, Blocks.air);
		world.setBlock(i + 4, j + 7, k + 16, Blocks.air);
		world.setBlock(i + 4, j + 7, k + 17, Blocks.air);
		world.setBlock(i + 4, j + 7, k + 18, GameData.blockRegistry.getObjectById(102));
		world.setBlock(i + 4, j + 7, k + 19, Blocks.air);
		world.setBlock(i + 4, j + 7, k + 20, Blocks.air);
		world.setBlock(i + 4, j + 8, k + 0, Blocks.air);
		world.setBlock(i + 4, j + 8, k + 1, Blocks.air);
		world.setBlock(i + 4, j + 8, k + 2, Blocks.air);
		world.setBlock(i + 4, j + 8, k + 3, GameData.blockRegistry.getObjectById(102));
		world.setBlock(i + 4, j + 8, k + 4, Blocks.air);
		world.setBlock(i + 4, j + 8, k + 5, Blocks.air);
		world.setBlock(i + 4, j + 8, k + 6, Blocks.air);
		world.setBlock(i + 4, j + 8, k + 7, Blocks.air);
		world.setBlock(i + 4, j + 8, k + 8, Blocks.air);
		world.setBlock(i + 4, j + 8, k + 9, Blocks.air);
		world.setBlock(i + 4, j + 8, k + 10, Blocks.air);
		world.setBlock(i + 4, j + 8, k + 11, Blocks.air);
		world.setBlock(i + 4, j + 8, k + 12, Blocks.air);
		world.setBlock(i + 4, j + 8, k + 13, Blocks.air);
		world.setBlock(i + 4, j + 8, k + 14, Blocks.air);
		world.setBlock(i + 4, j + 8, k + 15, Blocks.air);
		world.setBlock(i + 4, j + 8, k + 17, Blocks.air);
		world.setBlock(i + 4, j + 8, k + 18, GameData.blockRegistry.getObjectById(102));
		world.setBlock(i + 4, j + 8, k + 19, Blocks.air);
		world.setBlock(i + 4, j + 8, k + 20, Blocks.air);
		world.setBlock(i + 4, j + 9, k + 0, Blocks.air);
		world.setBlock(i + 4, j + 9, k + 1, Blocks.air);
		world.setBlock(i + 4, j + 9, k + 2, Blocks.air);
		world.setBlock(i + 4, j + 9, k + 3, GameData.blockRegistry.getObjectById(102));
		world.setBlock(i + 4, j + 9, k + 4, Blocks.air);
		world.setBlock(i + 4, j + 9, k + 5, Blocks.air);
		world.setBlock(i + 4, j + 9, k + 6, Blocks.air);
		world.setBlock(i + 4, j + 9, k + 7, Blocks.air);
		world.setBlock(i + 4, j + 9, k + 8, Blocks.air);
		world.setBlock(i + 4, j + 9, k + 9, Blocks.air);
		world.setBlock(i + 4, j + 9, k + 10, Blocks.air);
		world.setBlock(i + 4, j + 9, k + 11, Blocks.air);
		world.setBlock(i + 4, j + 9, k + 12, Blocks.air);
		world.setBlock(i + 4, j + 9, k + 13, Blocks.air);
		world.setBlock(i + 4, j + 9, k + 14, Blocks.air);
		world.setBlock(i + 4, j + 9, k + 15, Blocks.air);
		world.setBlock(i + 4, j + 9, k + 16, Blocks.air);
		world.setBlock(i + 4, j + 9, k + 17, Blocks.air);
		world.setBlock(i + 4, j + 9, k + 18, GameData.blockRegistry.getObjectById(102));
		world.setBlock(i + 4, j + 9, k + 19, Blocks.air);
		world.setBlock(i + 4, j + 9, k + 20, Blocks.air);
		world.setBlock(i + 4, j + 10, k + 0, Blocks.air);
		world.setBlock(i + 4, j + 10, k + 1, Blocks.air);
		world.setBlock(i + 4, j + 10, k + 2, Blocks.air);
		world.setBlock(i + 4, j + 10, k + 3, GameData.blockRegistry.getObjectById(102));
		world.setBlock(i + 4, j + 10, k + 4, Blocks.air);
		world.setBlock(i + 4, j + 10, k + 5, Blocks.air);
		world.setBlock(i + 4, j + 10, k + 6, Blocks.air);
		world.setBlock(i + 4, j + 10, k + 7, Blocks.air);
		world.setBlock(i + 4, j + 10, k + 8, Blocks.air);
		world.setBlock(i + 4, j + 10, k + 9, Blocks.air);
		world.setBlock(i + 4, j + 10, k + 10, Blocks.air);
		world.setBlock(i + 4, j + 10, k + 11, Blocks.air);
		world.setBlock(i + 4, j + 10, k + 12, Blocks.air);
		world.setBlock(i + 4, j + 10, k + 13, Blocks.air);
		world.setBlock(i + 4, j + 10, k + 14, Blocks.air);
		world.setBlock(i + 4, j + 10, k + 15, Blocks.air);
		world.setBlock(i + 4, j + 10, k + 16, Blocks.air);
		world.setBlock(i + 4, j + 10, k + 17, Blocks.air);
		world.setBlock(i + 4, j + 10, k + 18, GameData.blockRegistry.getObjectById(102));
		world.setBlock(i + 4, j + 10, k + 19, Blocks.air);
		world.setBlock(i + 4, j + 10, k + 20, Blocks.air);
		world.setBlock(i + 4, j + 11, k + 0, Blocks.air);
		world.setBlock(i + 4, j + 11, k + 1, Blocks.air);
		world.setBlock(i + 4, j + 11, k + 2, Blocks.air);
		world.setBlock(i + 4, j + 11, k + 3, GameData.blockRegistry.getObjectById(102));
		world.setBlock(i + 4, j + 11, k + 4, Blocks.air);
		world.setBlock(i + 4, j + 11, k + 5, Blocks.air);
		world.setBlock(i + 4, j + 11, k + 6, Blocks.air);
		world.setBlock(i + 4, j + 11, k + 7, Blocks.air);
		world.setBlock(i + 4, j + 11, k + 8, Blocks.air);
		world.setBlock(i + 4, j + 11, k + 9, Blocks.air);
		world.setBlock(i + 4, j + 11, k + 10, Blocks.air);
		world.setBlock(i + 4, j + 11, k + 11, Blocks.air);
		world.setBlock(i + 4, j + 11, k + 12, Blocks.air);
		world.setBlock(i + 4, j + 11, k + 13, Blocks.air);
		world.setBlock(i + 4, j + 11, k + 14, Blocks.air);
		world.setBlock(i + 4, j + 11, k + 15, Blocks.air);
		world.setBlock(i + 4, j + 11, k + 16, Blocks.air);
		world.setBlock(i + 4, j + 11, k + 17, Blocks.air);
		world.setBlock(i + 4, j + 11, k + 18, GameData.blockRegistry.getObjectById(102));
		world.setBlock(i + 4, j + 11, k + 19, Blocks.air);
		world.setBlock(i + 4, j + 11, k + 20, Blocks.air);
		world.setBlock(i + 4, j + 12, k + 0, Blocks.air);
		world.setBlock(i + 4, j + 12, k + 1, Blocks.air);
		world.setBlock(i + 4, j + 12, k + 2, Blocks.air);
		world.setBlock(i + 4, j + 12, k + 3, GameData.blockRegistry.getObjectById(35), 14, 0);
		world.setBlock(i + 4, j + 12, k + 4, Blocks.air);
		world.setBlock(i + 4, j + 12, k + 5, Blocks.air);
		world.setBlock(i + 4, j + 12, k + 6, Blocks.air);
		world.setBlock(i + 4, j + 12, k + 7, Blocks.air);
		world.setBlock(i + 4, j + 12, k + 8, Blocks.air);
		world.setBlock(i + 4, j + 12, k + 9, Blocks.air);
		world.setBlock(i + 4, j + 12, k + 10, Blocks.air);
		world.setBlock(i + 4, j + 12, k + 11, Blocks.air);
		world.setBlock(i + 4, j + 12, k + 12, Blocks.air);
		world.setBlock(i + 4, j + 12, k + 13, Blocks.air);
		world.setBlock(i + 4, j + 12, k + 14, Blocks.air);
		world.setBlock(i + 4, j + 12, k + 15, Blocks.air);
		world.setBlock(i + 4, j + 12, k + 16, Blocks.air);
		world.setBlock(i + 4, j + 12, k + 17, Blocks.air);
		world.setBlock(i + 4, j + 12, k + 18, GameData.blockRegistry.getObjectById(35), 14, 0);
		world.setBlock(i + 4, j + 12, k + 19, Blocks.air);
		world.setBlock(i + 4, j + 12, k + 20, Blocks.air);
		world.setBlock(i + 4, j + 13, k + 0, Blocks.air);
		world.setBlock(i + 4, j + 13, k + 1, Blocks.air);
		world.setBlock(i + 4, j + 13, k + 2, Blocks.air);
		world.setBlock(i + 4, j + 13, k + 3, Blocks.air);
		world.setBlock(i + 4, j + 13, k + 4, GameData.blockRegistry.getObjectById(35), 14, 0);
		world.setBlock(i + 4, j + 13, k + 5, GameData.blockRegistry.getObjectById(35), 14, 0);
		world.setBlock(i + 4, j + 13, k + 6, GameData.blockRegistry.getObjectById(35), 14, 0);
		world.setBlock(i + 4, j + 13, k + 7, GameData.blockRegistry.getObjectById(35), 14, 0);
		world.setBlock(i + 4, j + 13, k + 8, GameData.blockRegistry.getObjectById(35), 14, 0);
		world.setBlock(i + 4, j + 13, k + 9, GameData.blockRegistry.getObjectById(35), 14, 0);
		world.setBlock(i + 4, j + 13, k + 10, GameData.blockRegistry.getObjectById(35), 14, 0);
		world.setBlock(i + 4, j + 13, k + 11, GameData.blockRegistry.getObjectById(35), 14, 0);
		world.setBlock(i + 4, j + 13, k + 12, GameData.blockRegistry.getObjectById(35), 14, 0);
		world.setBlock(i + 4, j + 13, k + 13, GameData.blockRegistry.getObjectById(35), 14, 0);
		world.setBlock(i + 4, j + 13, k + 14, GameData.blockRegistry.getObjectById(35), 14, 0);
		world.setBlock(i + 4, j + 13, k + 15, GameData.blockRegistry.getObjectById(35), 14, 0);
		world.setBlock(i + 4, j + 13, k + 16, GameData.blockRegistry.getObjectById(35), 14, 0);
		world.setBlock(i + 4, j + 13, k + 17, GameData.blockRegistry.getObjectById(35), 14, 0);
		world.setBlock(i + 4, j + 13, k + 18, Blocks.air);
		world.setBlock(i + 4, j + 13, k + 19, Blocks.air);
		world.setBlock(i + 4, j + 13, k + 20, Blocks.air);
		world.setBlock(i + 5, j + 0, k + 0,GameData.blockRegistry.getObjectById(2));
		world.setBlock(i + 5, j + 0, k + 1,GameData.blockRegistry.getObjectById(2));
		world.setBlock(i + 5, j + 0, k + 2,GameData.blockRegistry.getObjectById(2));
		world.setBlock(i + 5, j + 0, k + 3, GameData.blockRegistry.getObjectById(3));
		world.setBlock(i + 5, j + 0, k + 4, GameData.blockRegistry.getObjectById(3));
		world.setBlock(i + 5, j + 0, k + 5, GameData.blockRegistry.getObjectById(3));
		world.setBlock(i + 5, j + 0, k + 6, GameData.blockRegistry.getObjectById(35), 4, 0);
		world.setBlock(i + 5, j + 0, k + 7, GameData.blockRegistry.getObjectById(35), 4, 0);
		world.setBlock(i + 5, j + 0, k + 8, GameData.blockRegistry.getObjectById(35), 4, 0);
		world.setBlock(i + 5, j + 0, k + 9, GameData.blockRegistry.getObjectById(35), 4, 0);
		world.setBlock(i + 5, j + 0, k + 10, GameData.blockRegistry.getObjectById(35), 4, 0);
		world.setBlock(i + 5, j + 0, k + 11, GameData.blockRegistry.getObjectById(35), 4, 0);
		world.setBlock(i + 5, j + 0, k + 12, GameData.blockRegistry.getObjectById(35), 4, 0);
		world.setBlock(i + 5, j + 0, k + 13, GameData.blockRegistry.getObjectById(35), 4, 0);
		world.setBlock(i + 5, j + 0, k + 14, GameData.blockRegistry.getObjectById(35), 4, 0);
		world.setBlock(i + 5, j + 0, k + 15, GameData.blockRegistry.getObjectById(35), 4, 0);
		world.setBlock(i + 5, j + 0, k + 16, GameData.blockRegistry.getObjectById(35), 4, 0);
		world.setBlock(i + 5, j + 0, k + 17, GameData.blockRegistry.getObjectById(3));
		world.setBlock(i + 5, j + 0, k + 18, GameData.blockRegistry.getObjectById(3));
		world.setBlock(i + 5, j + 0, k + 19,GameData.blockRegistry.getObjectById(2));
		world.setBlock(i + 5, j + 0, k + 20,GameData.blockRegistry.getObjectById(2));
		world.setBlock(i + 5, j + 1, k + 0, Blocks.air);
		world.setBlock(i + 5, j + 1, k + 1, Blocks.air);
