package FunMod.struturas;
import java.util.Random;

import net.minecraft.block.Block;
import net.minecraft.init.Blocks;
import net.minecraft.world.World;
import net.minecraft.world.gen.feature.WorldGenerator;

public class WorldGenBowserCastle extends WorldGenerator
{
	protected Block[] GetValidSpawnBlockss() {
		return new Block[] {
			Blocks.stone,
			Blocks.grass,
			Blocks.dirt
		};
	}

	public boolean LocationIsValidSpawn(World world, int i, int j, int k){
		int distanceToAir = 0;
		Block checkID = world.getBlock(i, j, k);

		while (checkID != null){
			distanceToAir++;
			checkID = world.getBlock(i, j + distanceToAir, k);
		}

		if (distanceToAir > 3){
			return false;
		}
		j += distanceToAir - 1;

		Block BlocksID = world.getBlock(i, j, k);
		Block BlocksIDAbove = world.getBlock(i, j+1, k);
		Block BlocksIDBelow = world.getBlock(i, j-1, k);
		for (Block x : GetValidSpawnBlockss()){
			if (BlocksIDAbove != null){
				return false;
			}
			if (BlocksID == x){
				return true;
			}else if (BlocksID == Blocks.snow && BlocksIDBelow == x){
				return true;
			}
		}
		return false;
	}

	public WorldGenBowserCastle() { }

	public boolean generate(World world, Random rand, int i, int j, int k) {
		if(!LocationIsValidSpawn(world, i, j, k) || !LocationIsValidSpawn(world, i + 54, j, k) || !LocationIsValidSpawn(world, i + 54, j, k + 44) || !LocationIsValidSpawn(world, i, j, k + 44))
		{
			return false;
		}
	world.setBlock(i + 0, j + 0, k + 0, Blocks.bedrock);
		world.setBlock(i + 0, j + 0, k + 1, Blocks.bedrock);
		world.setBlock(i + 0, j + 0, k + 2, Blocks.bedrock);
		world.setBlock(i + 0, j + 0, k + 3, Blocks.bedrock);
		world.setBlock(i + 0, j + 0, k + 4, Blocks.bedrock);
		world.setBlock(i + 0, j + 0, k + 5, Blocks.bedrock);
		world.setBlock(i + 0, j + 0, k + 6, Blocks.bedrock);
		world.setBlock(i + 0, j + 0, k + 7, Blocks.bedrock);
		world.setBlock(i + 0, j + 0, k + 8, Blocks.bedrock);
		world.setBlock(i + 0, j + 0, k + 9, Blocks.bedrock);
		world.setBlock(i + 0, j + 0, k + 10, Blocks.bedrock);
		world.setBlock(i + 0, j + 0, k + 11, Blocks.bedrock);
		world.setBlock(i + 0, j + 0, k + 12, Blocks.bedrock);
		world.setBlock(i + 0, j + 0, k + 13, Blocks.bedrock);
		world.setBlock(i + 0, j + 0, k + 14, Blocks.bedrock);
		world.setBlock(i + 0, j + 0, k + 15, Blocks.bedrock);
		world.setBlock(i + 0, j + 0, k + 16, Blocks.bedrock);
		world.setBlock(i + 0, j + 0, k + 17, Blocks.bedrock);
		world.setBlock(i + 0, j + 0, k + 18, Blocks.bedrock);
		world.setBlock(i + 0, j + 0, k + 19, Blocks.bedrock);
		world.setBlock(i + 0, j + 0, k + 20, Blocks.bedrock);
		world.setBlock(i + 0, j + 0, k + 21, Blocks.bedrock);
		world.setBlock(i + 0, j + 0, k + 22, Blocks.bedrock);
		world.setBlock(i + 0, j + 0, k + 23, Blocks.bedrock);
		world.setBlock(i + 0, j + 0, k + 24, Blocks.bedrock);
		world.setBlock(i + 0, j + 0, k + 25, Blocks.bedrock);
		world.setBlock(i + 0, j + 0, k + 26, Blocks.bedrock);
		world.setBlock(i + 0, j + 0, k + 27, Blocks.bedrock);
		world.setBlock(i + 0, j + 0, k + 28, Blocks.bedrock);
		world.setBlock(i + 0, j + 0, k + 29, Blocks.bedrock);
		world.setBlock(i + 0, j + 0, k + 30, Blocks.bedrock);
		world.setBlock(i + 0, j + 0, k + 31, Blocks.bedrock);
		world.setBlock(i + 0, j + 0, k + 32, Blocks.bedrock);
		world.setBlock(i + 0, j + 0, k + 33, Blocks.bedrock);
		world.setBlock(i + 0, j + 0, k + 34, Blocks.bedrock);
		world.setBlock(i + 0, j + 0, k + 35, Blocks.bedrock);
		world.setBlock(i + 0, j + 0, k + 36, Blocks.bedrock);
		world.setBlock(i + 0, j + 0, k + 37, Blocks.bedrock);
		world.setBlock(i + 0, j + 0, k + 38, Blocks.bedrock);
		world.setBlock(i + 0, j + 0, k + 39, Blocks.bedrock);
		world.setBlock(i + 0, j + 0, k + 40, Blocks.bedrock);
		world.setBlock(i + 0, j + 0, k + 41, Blocks.bedrock);
		world.setBlock(i + 0, j + 0, k + 42, Blocks.bedrock);
		world.setBlock(i + 0, j + 0, k + 43, Blocks.bedrock);
		world.setBlock(i + 0, j + 0, k + 44, Blocks.bedrock);
		world.setBlock(i + 0, j + 1, k + 0, Blocks.dirt);
		world.setBlock(i + 0, j + 1, k + 1, Blocks.dirt);
		world.setBlock(i + 0, j + 1, k + 2, Blocks.dirt);
		world.setBlock(i + 0, j + 1, k + 3, Blocks.dirt);
		world.setBlock(i + 0, j + 1, k + 4, Blocks.dirt);
		world.setBlock(i + 0, j + 1, k + 5, Blocks.dirt);
		world.setBlock(i + 0, j + 1, k + 6, Blocks.dirt);
		world.setBlock(i + 0, j + 1, k + 7, Blocks.dirt);
		world.setBlock(i + 0, j + 1, k + 8, Blocks.dirt);
		world.setBlock(i + 0, j + 1, k + 9, Blocks.dirt);
		world.setBlock(i + 0, j + 1, k + 10, Blocks.dirt);
		world.setBlock(i + 0, j + 1, k + 11, Blocks.dirt);
		world.setBlock(i + 0, j + 1, k + 12, Blocks.dirt);
		world.setBlock(i + 0, j + 1, k + 13, Blocks.dirt);
		world.setBlock(i + 0, j + 1, k + 14, Blocks.dirt);
		world.setBlock(i + 0, j + 1, k + 15, Blocks.dirt);
		world.setBlock(i + 0, j + 1, k + 16, Blocks.dirt);
		world.setBlock(i + 0, j + 1, k + 17, Blocks.dirt);
		world.setBlock(i + 0, j + 1, k + 18, Blocks.dirt);
		world.setBlock(i + 0, j + 1, k + 19, Blocks.dirt);
		world.setBlock(i + 0, j + 1, k + 20, Blocks.dirt);
		world.setBlock(i + 0, j + 1, k + 21, Blocks.dirt);
		world.setBlock(i + 0, j + 1, k + 22, Blocks.dirt);
		world.setBlock(i + 0, j + 1, k + 23, Blocks.dirt);
		world.setBlock(i + 0, j + 1, k + 24, Blocks.dirt);
		world.setBlock(i + 0, j + 1, k + 25, Blocks.dirt);
		world.setBlock(i + 0, j + 1, k + 26, Blocks.dirt);
		world.setBlock(i + 0, j + 1, k + 27, Blocks.dirt);
		world.setBlock(i + 0, j + 1, k + 28, Blocks.dirt);
		world.setBlock(i + 0, j + 1, k + 29, Blocks.dirt);
		world.setBlock(i + 0, j + 1, k + 30, Blocks.dirt);
		world.setBlock(i + 0, j + 1, k + 31, Blocks.dirt);
		world.setBlock(i + 0, j + 1, k + 32, Blocks.dirt);
		world.setBlock(i + 0, j + 1, k + 33, Blocks.dirt);
		world.setBlock(i + 0, j + 1, k + 34, Blocks.dirt);
		world.setBlock(i + 0, j + 1, k + 35, Blocks.dirt);
		world.setBlock(i + 0, j + 1, k + 36, Blocks.dirt);
		world.setBlock(i + 0, j + 1, k + 37, Blocks.dirt);
		world.setBlock(i + 0, j + 1, k + 38, Blocks.dirt);
		world.setBlock(i + 0, j + 1, k + 39, Blocks.dirt);
		world.setBlock(i + 0, j + 1, k + 40, Blocks.dirt);
		world.setBlock(i + 0, j + 1, k + 41, Blocks.dirt);
		world.setBlock(i + 0, j + 1, k + 42, Blocks.dirt);
		world.setBlock(i + 0, j + 1, k + 43, Blocks.dirt);
		world.setBlock(i + 0, j + 1, k + 44, Blocks.dirt);
		world.setBlock(i + 0, j + 2, k + 0, Blocks.dirt);
		world.setBlock(i + 0, j + 2, k + 1, Blocks.dirt);
		world.setBlock(i + 0, j + 2, k + 2, Blocks.dirt);
		world.setBlock(i + 0, j + 2, k + 3, Blocks.dirt);
		world.setBlock(i + 0, j + 2, k + 4, Blocks.dirt);
		world.setBlock(i + 0, j + 2, k + 5, Blocks.dirt);
		world.setBlock(i + 0, j + 2, k + 6, Blocks.dirt);
		world.setBlock(i + 0, j + 2, k + 7, Blocks.dirt);
		world.setBlock(i + 0, j + 2, k + 8, Blocks.dirt);
		world.setBlock(i + 0, j + 2, k + 9, Blocks.dirt);
		world.setBlock(i + 0, j + 2, k + 10, Blocks.dirt);
		world.setBlock(i + 0, j + 2, k + 11, Blocks.dirt);
		world.setBlock(i + 0, j + 2, k + 12, Blocks.dirt);
		world.setBlock(i + 0, j + 2, k + 13, Blocks.dirt);
		world.setBlock(i + 0, j + 2, k + 14, Blocks.dirt);
		world.setBlock(i + 0, j + 2, k + 15, Blocks.dirt);
		world.setBlock(i + 0, j + 2, k + 16, Blocks.dirt);
		world.setBlock(i + 0, j + 2, k + 17, Blocks.dirt);
		world.setBlock(i + 0, j + 2, k + 18, Blocks.dirt);
		world.setBlock(i + 0, j + 2, k + 19, Blocks.dirt);
		world.setBlock(i + 0, j + 2, k + 20, Blocks.dirt);
		world.setBlock(i + 0, j + 2, k + 21, Blocks.dirt);
		world.setBlock(i + 0, j + 2, k + 22, Blocks.dirt);
		world.setBlock(i + 0, j + 2, k + 23, Blocks.dirt);
		world.setBlock(i + 0, j + 2, k + 24, Blocks.dirt);
		world.setBlock(i + 0, j + 2, k + 25, Blocks.dirt);
		world.setBlock(i + 0, j + 2, k + 26, Blocks.dirt);
		world.setBlock(i + 0, j + 2, k + 27, Blocks.dirt);
		world.setBlock(i + 0, j + 2, k + 28, Blocks.dirt);
		world.setBlock(i + 0, j + 2, k + 29, Blocks.dirt);
		world.setBlock(i + 0, j + 2, k + 30, Blocks.dirt);
		world.setBlock(i + 0, j + 2, k + 31, Blocks.dirt);
		world.setBlock(i + 0, j + 2, k + 32, Blocks.dirt);
		world.setBlock(i + 0, j + 2, k + 33, Blocks.dirt);
		world.setBlock(i + 0, j + 2, k + 34, Blocks.dirt);
		world.setBlock(i + 0, j + 2, k + 35, Blocks.dirt);
		world.setBlock(i + 0, j + 2, k + 36, Blocks.dirt);
		world.setBlock(i + 0, j + 2, k + 37, Blocks.dirt);
		world.setBlock(i + 0, j + 2, k + 38, Blocks.dirt);
		world.setBlock(i + 0, j + 2, k + 39, Blocks.dirt);
		world.setBlock(i + 0, j + 2, k + 40, Blocks.dirt);
		world.setBlock(i + 0, j + 2, k + 41, Blocks.dirt);
		world.setBlock(i + 0, j + 2, k + 42, Blocks.dirt);
		world.setBlock(i + 0, j + 2, k + 43, Blocks.dirt);
		world.setBlock(i + 0, j + 2, k + 44, Blocks.dirt);
		world.setBlock(i + 0, j + 3, k + 0, Blocks.grass);
		world.setBlock(i + 0, j + 3, k + 1, Blocks.grass);
		world.setBlock(i + 0, j + 3, k + 2, Blocks.grass);
		world.setBlock(i + 0, j + 3, k + 3, Blocks.grass);
		world.setBlock(i + 0, j + 3, k + 4, Blocks.grass);
		world.setBlock(i + 0, j + 3, k + 5, Blocks.grass);
		world.setBlock(i + 0, j + 3, k + 6, Blocks.grass);
		world.setBlock(i + 0, j + 3, k + 7, Blocks.grass);
		world.setBlock(i + 0, j + 3, k + 8, Blocks.grass);
		world.setBlock(i + 0, j + 3, k + 9, Blocks.grass);
		world.setBlock(i + 0, j + 3, k + 10, Blocks.grass);
		world.setBlock(i + 0, j + 3, k + 11, Blocks.grass);
		world.setBlock(i + 0, j + 3, k + 12, Blocks.grass);
		world.setBlock(i + 0, j + 3, k + 13, Blocks.grass);
		world.setBlock(i + 0, j + 3, k + 14, Blocks.grass);
		world.setBlock(i + 0, j + 3, k + 15, Blocks.grass);
		world.setBlock(i + 0, j + 3, k + 16, Blocks.grass);
		world.setBlock(i + 0, j + 3, k + 17, Blocks.grass);
		world.setBlock(i + 0, j + 3, k + 18, Blocks.grass);
		world.setBlock(i + 0, j + 3, k + 19, Blocks.grass);
		world.setBlock(i + 0, j + 3, k + 20, Blocks.grass);
		world.setBlock(i + 0, j + 3, k + 21, Blocks.grass);
		world.setBlock(i + 0, j + 3, k + 22, Blocks.grass);
		world.setBlock(i + 0, j + 3, k + 23, Blocks.grass);
		world.setBlock(i + 0, j + 3, k + 24, Blocks.grass);
		world.setBlock(i + 0, j + 3, k + 25, Blocks.grass);
		world.setBlock(i + 0, j + 3, k + 26, Blocks.grass);
		world.setBlock(i + 0, j + 3, k + 27, Blocks.grass);
		world.setBlock(i + 0, j + 3, k + 28, Blocks.grass);
		world.setBlock(i + 0, j + 3, k + 29, Blocks.grass);
		world.setBlock(i + 0, j + 3, k + 30, Blocks.grass);
		world.setBlock(i + 0, j + 3, k + 31, Blocks.grass);
		world.setBlock(i + 0, j + 3, k + 32, Blocks.grass);
		world.setBlock(i + 0, j + 3, k + 33, Blocks.grass);
		world.setBlock(i + 0, j + 3, k + 34, Blocks.grass);
		world.setBlock(i + 0, j + 3, k + 35, Blocks.grass);
		world.setBlock(i + 0, j + 3, k + 36, Blocks.grass);
		world.setBlock(i + 0, j + 3, k + 37, Blocks.grass);
		world.setBlock(i + 0, j + 3, k + 38, Blocks.grass);
		world.setBlock(i + 0, j + 3, k + 39, Blocks.grass);
		world.setBlock(i + 0, j + 3, k + 40, Blocks.grass);
		world.setBlock(i + 0, j + 3, k + 41, Blocks.grass);
		world.setBlock(i + 0, j + 3, k + 42, Blocks.grass);
		world.setBlock(i + 0, j + 3, k + 43, Blocks.grass);
		world.setBlock(i + 0, j + 3, k + 44, Blocks.grass);
		world.setBlock(i + 1, j + 0, k + 0, Blocks.bedrock);
		world.setBlock(i + 1, j + 0, k + 1, Blocks.bedrock);
		world.setBlock(i + 1, j + 0, k + 2, Blocks.bedrock);
		world.setBlock(i + 1, j + 0, k + 3, Blocks.bedrock);
		world.setBlock(i + 1, j + 0, k + 4, Blocks.bedrock);
		world.setBlock(i + 1, j + 0, k + 5, Blocks.bedrock);
		world.setBlock(i + 1, j + 0, k + 6, Blocks.bedrock);
		world.setBlock(i + 1, j + 0, k + 7, Blocks.bedrock);
		world.setBlock(i + 1, j + 0, k + 8, Blocks.bedrock);
		world.setBlock(i + 1, j + 0, k + 9, Blocks.bedrock);
		world.setBlock(i + 1, j + 0, k + 10, Blocks.bedrock);
		world.setBlock(i + 1, j + 0, k + 11, Blocks.bedrock);
		world.setBlock(i + 1, j + 0, k + 12, Blocks.bedrock);
		world.setBlock(i + 1, j + 0, k + 13, Blocks.bedrock);
		world.setBlock(i + 1, j + 0, k + 14, Blocks.bedrock);
		world.setBlock(i + 1, j + 0, k + 15, Blocks.bedrock);
		world.setBlock(i + 1, j + 0, k + 16, Blocks.bedrock);
		world.setBlock(i + 1, j + 0, k + 17, Blocks.bedrock);
		world.setBlock(i + 1, j + 0, k + 18, Blocks.bedrock);
		world.setBlock(i + 1, j + 0, k + 19, Blocks.bedrock);
		world.setBlock(i + 1, j + 0, k + 20, Blocks.bedrock);
		world.setBlock(i + 1, j + 0, k + 21, Blocks.bedrock);
		world.setBlock(i + 1, j + 0, k + 22, Blocks.bedrock);
		world.setBlock(i + 1, j + 0, k + 23, Blocks.bedrock);
		world.setBlock(i + 1, j + 0, k + 24, Blocks.bedrock);
		world.setBlock(i + 1, j + 0, k + 25, Blocks.bedrock);
		world.setBlock(i + 1, j + 0, k + 26, Blocks.bedrock);
		world.setBlock(i + 1, j + 0, k + 27, Blocks.bedrock);
		world.setBlock(i + 1, j + 0, k + 28, Blocks.bedrock);
		world.setBlock(i + 1, j + 0, k + 29, Blocks.bedrock);
		world.setBlock(i + 1, j + 0, k + 30, Blocks.bedrock);
		world.setBlock(i + 1, j + 0, k + 31, Blocks.bedrock);
		world.setBlock(i + 1, j + 0, k + 32, Blocks.bedrock);
		world.setBlock(i + 1, j + 0, k + 33, Blocks.bedrock);
		world.setBlock(i + 1, j + 0, k + 34, Blocks.bedrock);
		world.setBlock(i + 1, j + 0, k + 35, Blocks.bedrock);
		world.setBlock(i + 1, j + 0, k + 36, Blocks.bedrock);
		world.setBlock(i + 1, j + 0, k + 37, Blocks.bedrock);
		world.setBlock(i + 1, j + 0, k + 38, Blocks.bedrock);
		world.setBlock(i + 1, j + 0, k + 39, Blocks.bedrock);
		world.setBlock(i + 1, j + 0, k + 40, Blocks.bedrock);
		world.setBlock(i + 1, j + 0, k + 41, Blocks.bedrock);
		world.setBlock(i + 1, j + 0, k + 42, Blocks.bedrock);
		world.setBlock(i + 1, j + 0, k + 43, Blocks.bedrock);
		world.setBlock(i + 1, j + 0, k + 44, Blocks.bedrock);
		world.setBlock(i + 1, j + 1, k + 0, Blocks.dirt);
		world.setBlock(i + 1, j + 1, k + 1, Blocks.dirt);
		world.setBlock(i + 1, j + 1, k + 2, Blocks.dirt);
		world.setBlock(i + 1, j + 1, k + 3, Blocks.dirt);
		world.setBlock(i + 1, j + 1, k + 4, Blocks.dirt);
		world.setBlock(i + 1, j + 1, k + 5, Blocks.dirt);
		world.setBlock(i + 1, j + 1, k + 6, Blocks.dirt);
		world.setBlock(i + 1, j + 1, k + 7, Blocks.dirt);
		world.setBlock(i + 1, j + 1, k + 8, Blocks.dirt);
		world.setBlock(i + 1, j + 1, k + 9, Blocks.dirt);
		world.setBlock(i + 1, j + 1, k + 10, Blocks.dirt);
		world.setBlock(i + 1, j + 1, k + 11, Blocks.dirt);
		world.setBlock(i + 1, j + 1, k + 12, Blocks.dirt);
		world.setBlock(i + 1, j + 1, k + 13, Blocks.dirt);
		world.setBlock(i + 1, j + 1, k + 14, Blocks.dirt);
		world.setBlock(i + 1, j + 1, k + 15, Blocks.dirt);
		world.setBlock(i + 1, j + 1, k + 16, Blocks.dirt);
		world.setBlock(i + 1, j + 1, k + 17, Blocks.dirt);
		world.setBlock(i + 1, j + 1, k + 18, Blocks.dirt);
		world.setBlock(i + 1, j + 1, k + 19, Blocks.dirt);
		world.setBlock(i + 1, j + 1, k + 20, Blocks.dirt);
		world.setBlock(i + 1, j + 1, k + 21, Blocks.dirt);
		world.setBlock(i + 1, j + 1, k + 22, Blocks.dirt);
		world.setBlock(i + 1, j + 1, k + 23, Blocks.dirt);
		world.setBlock(i + 1, j + 1, k + 24, Blocks.dirt);
		world.setBlock(i + 1, j + 1, k + 25, Blocks.dirt);
		world.setBlock(i + 1, j + 1, k + 26, Blocks.dirt);
		world.setBlock(i + 1, j + 1, k + 27, Blocks.dirt);
		world.setBlock(i + 1, j + 1, k + 28, Blocks.dirt);
		world.setBlock(i + 1, j + 1, k + 29, Blocks.dirt);
		world.setBlock(i + 1, j + 1, k + 30, Blocks.dirt);
		world.setBlock(i + 1, j + 1, k + 31, Blocks.dirt);
		world.setBlock(i + 1, j + 1, k + 32, Blocks.dirt);
		world.setBlock(i + 1, j + 1, k + 33, Blocks.dirt);
		world.setBlock(i + 1, j + 1, k + 34, Blocks.dirt);
		world.setBlock(i + 1, j + 1, k + 35, Blocks.dirt);
		world.setBlock(i + 1, j + 1, k + 36, Blocks.dirt);
		world.setBlock(i + 1, j + 1, k + 37, Blocks.dirt);
		world.setBlock(i + 1, j + 1, k + 38, Blocks.dirt);
		world.setBlock(i + 1, j + 1, k + 39, Blocks.dirt);
		world.setBlock(i + 1, j + 1, k + 40, Blocks.dirt);
		world.setBlock(i + 1, j + 1, k + 41, Blocks.dirt);
		world.setBlock(i + 1, j + 1, k + 42, Blocks.dirt);
		world.setBlock(i + 1, j + 1, k + 43, Blocks.dirt);
		world.setBlock(i + 1, j + 1, k + 44, Blocks.dirt);
		world.setBlock(i + 1, j + 2, k + 0, Blocks.dirt);
		world.setBlock(i + 1, j + 2, k + 1, Blocks.dirt);
		world.setBlock(i + 1, j + 2, k + 2, Blocks.dirt);
		world.setBlock(i + 1, j + 2, k + 3, Blocks.dirt);
		world.setBlock(i + 1, j + 2, k + 4, Blocks.dirt);
		world.setBlock(i + 1, j + 2, k + 5, Blocks.dirt);
		world.setBlock(i + 1, j + 2, k + 6, Blocks.dirt);
		world.setBlock(i + 1, j + 2, k + 7, Blocks.dirt);
		world.setBlock(i + 1, j + 2, k + 8, Blocks.dirt);
		world.setBlock(i + 1, j + 2, k + 9, Blocks.dirt);
		world.setBlock(i + 1, j + 2, k + 10, Blocks.dirt);
		world.setBlock(i + 1, j + 2, k + 11, Blocks.dirt);
		world.setBlock(i + 1, j + 2, k + 12, Blocks.dirt);
		world.setBlock(i + 1, j + 2, k + 13, Blocks.dirt);
		world.setBlock(i + 1, j + 2, k + 14, Blocks.dirt);
		world.setBlock(i + 1, j + 2, k + 15, Blocks.dirt);
		world.setBlock(i + 1, j + 2, k + 16, Blocks.dirt);
		world.setBlock(i + 1, j + 2, k + 17, Blocks.dirt);
		world.setBlock(i + 1, j + 2, k + 18, Blocks.dirt);
		world.setBlock(i + 1, j + 2, k + 19, Blocks.dirt);
		world.setBlock(i + 1, j + 2, k + 20, Blocks.dirt);
		world.setBlock(i + 1, j + 2, k + 21, Blocks.dirt);
		world.setBlock(i + 1, j + 2, k + 22, Blocks.dirt);
		world.setBlock(i + 1, j + 2, k + 23, Blocks.dirt);
		world.setBlock(i + 1, j + 2, k + 24, Blocks.dirt);
		world.setBlock(i + 1, j + 2, k + 25, Blocks.dirt);
		world.setBlock(i + 1, j + 2, k + 26, Blocks.dirt);
		world.setBlock(i + 1, j + 2, k + 27, Blocks.dirt);
		world.setBlock(i + 1, j + 2, k + 28, Blocks.dirt);
		world.setBlock(i + 1, j + 2, k + 29, Blocks.dirt);
		world.setBlock(i + 1, j + 2, k + 30, Blocks.dirt);
		world.setBlock(i + 1, j + 2, k + 31, Blocks.dirt);
		world.setBlock(i + 1, j + 2, k + 32, Blocks.dirt);
		world.setBlock(i + 1, j + 2, k + 33, Blocks.dirt);
		world.setBlock(i + 1, j + 2, k + 34, Blocks.dirt);
		world.setBlock(i + 1, j + 2, k + 35, Blocks.dirt);
		world.setBlock(i + 1, j + 2, k + 36, Blocks.dirt);
		world.setBlock(i + 1, j + 2, k + 37, Blocks.dirt);
		world.setBlock(i + 1, j + 2, k + 38, Blocks.dirt);
		world.setBlock(i + 1, j + 2, k + 39, Blocks.dirt);
		world.setBlock(i + 1, j + 2, k + 40, Blocks.dirt);
		world.setBlock(i + 1, j + 2, k + 41, Blocks.dirt);
		world.setBlock(i + 1, j + 2, k + 42, Blocks.dirt);
		world.setBlock(i + 1, j + 2, k + 43, Blocks.dirt);
		world.setBlock(i + 1, j + 2, k + 44, Blocks.dirt);
		world.setBlock(i + 1, j + 3, k + 0, Blocks.grass);
		world.setBlock(i + 1, j + 3, k + 1, Blocks.grass);
		world.setBlock(i + 1, j + 3, k + 2, Blocks.grass);
		world.setBlock(i + 1, j + 3, k + 3, Blocks.grass);
		world.setBlock(i + 1, j + 3, k + 4, Blocks.grass);
		world.setBlock(i + 1, j + 3, k + 5, Blocks.grass);
		world.setBlock(i + 1, j + 3, k + 6, Blocks.grass);
		world.setBlock(i + 1, j + 3, k + 7, Blocks.grass);
		world.setBlock(i + 1, j + 3, k + 8, Blocks.grass);
		world.setBlock(i + 1, j + 3, k + 9, Blocks.grass);
		world.setBlock(i + 1, j + 3, k + 10, Blocks.grass);
		world.setBlock(i + 1, j + 3, k + 11, Blocks.grass);
		world.setBlock(i + 1, j + 3, k + 12, Blocks.grass);
		world.setBlock(i + 1, j + 3, k + 13, Blocks.grass);
		world.setBlock(i + 1, j + 3, k + 14, Blocks.grass);
		world.setBlock(i + 1, j + 3, k + 15, Blocks.grass);
		world.setBlock(i + 1, j + 3, k + 16, Blocks.grass);
		world.setBlock(i + 1, j + 3, k + 17, Blocks.grass);
		world.setBlock(i + 1, j + 3, k + 18, Blocks.grass);
		world.setBlock(i + 1, j + 3, k + 19, Blocks.grass);
		world.setBlock(i + 1, j + 3, k + 20, Blocks.grass);
		world.setBlock(i + 1, j + 3, k + 21, Blocks.grass);
		world.setBlock(i + 1, j + 3, k + 22, Blocks.grass);
		world.setBlock(i + 1, j + 3, k + 23, Blocks.grass);
		world.setBlock(i + 1, j + 3, k + 24, Blocks.grass);
		world.setBlock(i + 1, j + 3, k + 25, Blocks.grass);
		world.setBlock(i + 1, j + 3, k + 26, Blocks.grass);
		world.setBlock(i + 1, j + 3, k + 27, Blocks.grass);
		world.setBlock(i + 1, j + 3, k + 28, Blocks.grass);
		world.setBlock(i + 1, j + 3, k + 29, Blocks.grass);
		world.setBlock(i + 1, j + 3, k + 30, Blocks.grass);
		world.setBlock(i + 1, j + 3, k + 31, Blocks.grass);
		world.setBlock(i + 1, j + 3, k + 32, Blocks.grass);
		world.setBlock(i + 1, j + 3, k + 33, Blocks.grass);
		world.setBlock(i + 1, j + 3, k + 34, Blocks.grass);
		world.setBlock(i + 1, j + 3, k + 35, Blocks.grass);
		world.setBlock(i + 1, j + 3, k + 36, Blocks.grass);
		world.setBlock(i + 1, j + 3, k + 37, Blocks.grass);
		world.setBlock(i + 1, j + 3, k + 38, Blocks.grass);
		world.setBlock(i + 1, j + 3, k + 39, Blocks.grass);
		world.setBlock(i + 1, j + 3, k + 40, Blocks.grass);
		world.setBlock(i + 1, j + 3, k + 41, Blocks.grass);
		world.setBlock(i + 1, j + 3, k + 42, Blocks.grass);
		world.setBlock(i + 1, j + 3, k + 43, Blocks.grass);
		world.setBlock(i + 1, j + 3, k + 44, Blocks.grass);
		world.setBlock(i + 2, j + 0, k + 0, Blocks.bedrock);
		world.setBlock(i + 2, j + 0, k + 1, Blocks.bedrock);
		world.setBlock(i + 2, j + 0, k + 2, Blocks.bedrock);
		world.setBlock(i + 2, j + 0, k + 3, Blocks.bedrock);
		world.setBlock(i + 2, j + 0, k + 4, Blocks.bedrock);
		world.setBlock(i + 2, j + 0, k + 5, Blocks.bedrock);
		world.setBlock(i + 2, j + 0, k + 6, Blocks.bedrock);
		world.setBlock(i + 2, j + 0, k + 7, Blocks.bedrock);
		world.setBlock(i + 2, j + 0, k + 8, Blocks.bedrock);
		world.setBlock(i + 2, j + 0, k + 9, Blocks.bedrock);
		world.setBlock(i + 2, j + 0, k + 10, Blocks.bedrock);
		world.setBlock(i + 2, j + 0, k + 11, Blocks.bedrock);
		world.setBlock(i + 2, j + 0, k + 12, Blocks.bedrock);
		world.setBlock(i + 2, j + 0, k + 13, Blocks.bedrock);
		world.setBlock(i + 2, j + 0, k + 14, Blocks.bedrock);
		world.setBlock(i + 2, j + 0, k + 15, Blocks.bedrock);
		world.setBlock(i + 2, j + 0, k + 16, Blocks.bedrock);
		world.setBlock(i + 2, j + 0, k + 17, Blocks.bedrock);
		world.setBlock(i + 2, j + 0, k + 18, Blocks.bedrock);
		world.setBlock(i + 2, j + 0, k + 19, Blocks.bedrock);
		world.setBlock(i + 2, j + 0, k + 20, Blocks.bedrock);
		world.setBlock(i + 2, j + 0, k + 21, Blocks.bedrock);
		world.setBlock(i + 2, j + 0, k + 22, Blocks.bedrock);
		world.setBlock(i + 2, j + 0, k + 23, Blocks.bedrock);
		world.setBlock(i + 2, j + 0, k + 24, Blocks.bedrock);
		world.setBlock(i + 2, j + 0, k + 25, Blocks.bedrock);
		world.setBlock(i + 2, j + 0, k + 26, Blocks.bedrock);
		world.setBlock(i + 2, j + 0, k + 27, Blocks.bedrock);
		world.setBlock(i + 2, j + 0, k + 28, Blocks.bedrock);
		world.setBlock(i + 2, j + 0, k + 29, Blocks.bedrock);
		world.setBlock(i + 2, j + 0, k + 30, Blocks.bedrock);
		world.setBlock(i + 2, j + 0, k + 31, Blocks.bedrock);
		world.setBlock(i + 2, j + 0, k + 32, Blocks.bedrock);
		world.setBlock(i + 2, j + 0, k + 33, Blocks.bedrock);
		world.setBlock(i + 2, j + 0, k + 34, Blocks.bedrock);
		world.setBlock(i + 2, j + 0, k + 35, Blocks.bedrock);
		world.setBlock(i + 2, j + 0, k + 36, Blocks.bedrock);
		world.setBlock(i + 2, j + 0, k + 37, Blocks.bedrock);
		world.setBlock(i + 2, j + 0, k + 38, Blocks.bedrock);
		world.setBlock(i + 2, j + 0, k + 39, Blocks.bedrock);
		world.setBlock(i + 2, j + 0, k + 40, Blocks.bedrock);
		world.setBlock(i + 2, j + 0, k + 41, Blocks.bedrock);
		world.setBlock(i + 2, j + 0, k + 42, Blocks.bedrock);
		world.setBlock(i + 2, j + 0, k + 43, Blocks.bedrock);
		world.setBlock(i + 2, j + 0, k + 44, Blocks.bedrock);
		world.setBlock(i + 2, j + 1, k + 0, Blocks.dirt);
		world.setBlock(i + 2, j + 1, k + 1, Blocks.dirt);
		world.setBlock(i + 2, j + 1, k + 2, Blocks.dirt);
		world.setBlock(i + 2, j + 1, k + 3, Blocks.dirt);
		world.setBlock(i + 2, j + 1, k + 4, Blocks.dirt);
		world.setBlock(i + 2, j + 1, k + 5, Blocks.dirt);
		world.setBlock(i + 2, j + 1, k + 6, Blocks.dirt);
		world.setBlock(i + 2, j + 1, k + 7, Blocks.dirt);
		world.setBlock(i + 2, j + 1, k + 8, Blocks.dirt);
		world.setBlock(i + 2, j + 1, k + 9, Blocks.dirt);
		world.setBlock(i + 2, j + 1, k + 10, Blocks.dirt);
		world.setBlock(i + 2, j + 1, k + 11, Blocks.dirt);
		world.setBlock(i + 2, j + 1, k + 12, Blocks.dirt);
		world.setBlock(i + 2, j + 1, k + 13, Blocks.dirt);
		world.setBlock(i + 2, j + 1, k + 14, Blocks.dirt);
		world.setBlock(i + 2, j + 1, k + 15, Blocks.dirt);
		world.setBlock(i + 2, j + 1, k + 16, Blocks.dirt);
		world.setBlock(i + 2, j + 1, k + 17, Blocks.dirt);
		world.setBlock(i + 2, j + 1, k + 18, Blocks.dirt);
		world.setBlock(i + 2, j + 1, k + 19, Blocks.dirt);
		world.setBlock(i + 2, j + 1, k + 20, Blocks.dirt);
		world.setBlock(i + 2, j + 1, k + 21, Blocks.dirt);
		world.setBlock(i + 2, j + 1, k + 22, Blocks.dirt);
		world.setBlock(i + 2, j + 1, k + 23, Blocks.dirt);
		world.setBlock(i + 2, j + 1, k + 24, Blocks.dirt);
		world.setBlock(i + 2, j + 1, k + 25, Blocks.dirt);
		world.setBlock(i + 2, j + 1, k + 26, Blocks.dirt);
		world.setBlock(i + 2, j + 1, k + 27, Blocks.dirt);
		world.setBlock(i + 2, j + 1, k + 28, Blocks.dirt);
		world.setBlock(i + 2, j + 1, k + 29, Blocks.dirt);
		world.setBlock(i + 2, j + 1, k + 30, Blocks.dirt);
		world.setBlock(i + 2, j + 1, k + 31, Blocks.dirt);
		world.setBlock(i + 2, j + 1, k + 32, Blocks.dirt);
		world.setBlock(i + 2, j + 1, k + 33, Blocks.dirt);
		world.setBlock(i + 2, j + 1, k + 34, Blocks.dirt);
		world.setBlock(i + 2, j + 1, k + 35, Blocks.dirt);
		world.setBlock(i + 2, j + 1, k + 36, Blocks.dirt);
		world.setBlock(i + 2, j + 1, k + 37, Blocks.dirt);
		world.setBlock(i + 2, j + 1, k + 38, Blocks.dirt);
		world.setBlock(i + 2, j + 1, k + 39, Blocks.dirt);
		world.setBlock(i + 2, j + 1, k + 40, Blocks.dirt);
		world.setBlock(i + 2, j + 1, k + 41, Blocks.dirt);
		world.setBlock(i + 2, j + 1, k + 42, Blocks.dirt);
		world.setBlock(i + 2, j + 1, k + 43, Blocks.dirt);
		world.setBlock(i + 2, j + 1, k + 44, Blocks.dirt);
		world.setBlock(i + 2, j + 2, k + 0, Blocks.dirt);
		world.setBlock(i + 2, j + 2, k + 1, Blocks.dirt);
		world.setBlock(i + 2, j + 2, k + 2, Blocks.dirt);
		world.setBlock(i + 2, j + 2, k + 3, Blocks.dirt);
		world.setBlock(i + 2, j + 2, k + 4, Blocks.dirt);
		world.setBlock(i + 2, j + 2, k + 5, Blocks.dirt);
		world.setBlock(i + 2, j + 2, k + 6, Blocks.dirt);
		world.setBlock(i + 2, j + 2, k + 7, Blocks.dirt);
		world.setBlock(i + 2, j + 2, k + 8, Blocks.dirt);
		world.setBlock(i + 2, j + 2, k + 9, Blocks.dirt);
		world.setBlock(i + 2, j + 2, k + 10, Blocks.dirt);
		world.setBlock(i + 2, j + 2, k + 11, Blocks.dirt);
		world.setBlock(i + 2, j + 2, k + 12, Blocks.dirt);
		world.setBlock(i + 2, j + 2, k + 13, Blocks.dirt);
		world.setBlock(i + 2, j + 2, k + 14, Blocks.dirt);
		world.setBlock(i + 2, j + 2, k + 15, Blocks.dirt);
		world.setBlock(i + 2, j + 2, k + 16, Blocks.dirt);
		world.setBlock(i + 2, j + 2, k + 17, Blocks.dirt);
		world.setBlock(i + 2, j + 2, k + 18, Blocks.dirt);
		world.setBlock(i + 2, j + 2, k + 19, Blocks.dirt);
		world.setBlock(i + 2, j + 2, k + 20, Blocks.dirt);
		world.setBlock(i + 2, j + 2, k + 21, Blocks.dirt);
		world.setBlock(i + 2, j + 2, k + 22, Blocks.dirt);
		world.setBlock(i + 2, j + 2, k + 23, Blocks.dirt);
		world.setBlock(i + 2, j + 2, k + 24, Blocks.dirt);
		world.setBlock(i + 2, j + 2, k + 25, Blocks.dirt);
		world.setBlock(i + 2, j + 2, k + 26, Blocks.dirt);
		world.setBlock(i + 2, j + 2, k + 27, Blocks.dirt);
		world.setBlock(i + 2, j + 2, k + 28, Blocks.dirt);
		world.setBlock(i + 2, j + 2, k + 29, Blocks.dirt);
		world.setBlock(i + 2, j + 2, k + 30, Blocks.dirt);
		world.setBlock(i + 2, j + 2, k + 31, Blocks.dirt);
		world.setBlock(i + 2, j + 2, k + 32, Blocks.dirt);
		world.setBlock(i + 2, j + 2, k + 33, Blocks.dirt);
		world.setBlock(i + 2, j + 2, k + 34, Blocks.dirt);
		world.setBlock(i + 2, j + 2, k + 35, Blocks.dirt);
		world.setBlock(i + 2, j + 2, k + 36, Blocks.dirt);
		world.setBlock(i + 2, j + 2, k + 37, Blocks.dirt);
		world.setBlock(i + 2, j + 2, k + 38, Blocks.dirt);
		world.setBlock(i + 2, j + 2, k + 39, Blocks.dirt);
		world.setBlock(i + 2, j + 2, k + 40, Blocks.dirt);
		world.setBlock(i + 2, j + 2, k + 41, Blocks.dirt);
		world.setBlock(i + 2, j + 2, k + 42, Blocks.dirt);
		world.setBlock(i + 2, j + 2, k + 43, Blocks.dirt);
		world.setBlock(i + 2, j + 2, k + 44, Blocks.dirt);
		world.setBlock(i + 2, j + 3, k + 0, Blocks.grass);
		world.setBlock(i + 2, j + 3, k + 1, Blocks.grass);
		world.setBlock(i + 2, j + 3, k + 2, Blocks.grass);
		world.setBlock(i + 2, j + 3, k + 3, Blocks.grass);
		world.setBlock(i + 2, j + 3, k + 4, Blocks.grass);
		world.setBlock(i + 2, j + 3, k + 5, Blocks.grass);
		world.setBlock(i + 2, j + 3, k + 6, Blocks.grass);
		world.setBlock(i + 2, j + 3, k + 7, Blocks.grass);
		world.setBlock(i + 2, j + 3, k + 8, Blocks.grass);
		world.setBlock(i + 2, j + 3, k + 9, Blocks.grass);
		world.setBlock(i + 2, j + 3, k + 10, Blocks.grass);
		world.setBlock(i + 2, j + 3, k + 11, Blocks.grass);
		world.setBlock(i + 2, j + 3, k + 12, Blocks.grass);
		world.setBlock(i + 2, j + 3, k + 13, Blocks.grass);
		world.setBlock(i + 2, j + 3, k + 14, Blocks.grass);
		world.setBlock(i + 2, j + 3, k + 15, Blocks.grass);
		world.setBlock(i + 2, j + 3, k + 16, Blocks.grass);
		world.setBlock(i + 2, j + 3, k + 17, Blocks.grass);
		world.setBlock(i + 2, j + 3, k + 18, Blocks.grass);
		world.setBlock(i + 2, j + 3, k + 19, Blocks.grass);
		world.setBlock(i + 2, j + 3, k + 20, Blocks.grass);
		world.setBlock(i + 2, j + 3, k + 21, Blocks.grass);
		world.setBlock(i + 2, j + 3, k + 22, Blocks.grass);
		world.setBlock(i + 2, j + 3, k + 23, Blocks.grass);
		world.setBlock(i + 2, j + 3, k + 24, Blocks.grass);
		world.setBlock(i + 2, j + 3, k + 25, Blocks.grass);
		world.setBlock(i + 2, j + 3, k + 26, Blocks.grass);
		world.setBlock(i + 2, j + 3, k + 27, Blocks.grass);
		world.setBlock(i + 2, j + 3, k + 28, Blocks.grass);
		world.setBlock(i + 2, j + 3, k + 29, Blocks.grass);
		world.setBlock(i + 2, j + 3, k + 30, Blocks.grass);
		world.setBlock(i + 2, j + 3, k + 31, Blocks.grass);
		world.setBlock(i + 2, j + 3, k + 32, Blocks.grass);
		world.setBlock(i + 2, j + 3, k + 33, Blocks.grass);
		world.setBlock(i + 2, j + 3, k + 34, Blocks.grass);
		world.setBlock(i + 2, j + 3, k + 35, Blocks.grass);
		world.setBlock(i + 2, j + 3, k + 36, Blocks.grass);
		world.setBlock(i + 2, j + 3, k + 37, Blocks.grass);
		world.setBlock(i + 2, j + 3, k + 38, Blocks.grass);
		world.setBlock(i + 2, j + 3, k + 39, Blocks.grass);
		world.setBlock(i + 2, j + 3, k + 40, Blocks.grass);
		world.setBlock(i + 2, j + 3, k + 41, Blocks.grass);
		world.setBlock(i + 2, j + 3, k + 42, Blocks.grass);
		world.setBlock(i + 2, j + 3, k + 43, Blocks.grass);
		world.setBlock(i + 2, j + 3, k + 44, Blocks.grass);
		world.setBlock(i + 3, j + 0, k + 0, Blocks.bedrock);
		world.setBlock(i + 3, j + 0, k + 1, Blocks.bedrock);
		world.setBlock(i + 3, j + 0, k + 2, Blocks.bedrock);
		world.setBlock(i + 3, j + 0, k + 3, Blocks.bedrock);
		world.setBlock(i + 3, j + 0, k + 4, Blocks.bedrock);
		world.setBlock(i + 3, j + 0, k + 5, Blocks.bedrock);
		world.setBlock(i + 3, j + 0, k + 6, Blocks.bedrock);
		world.setBlock(i + 3, j + 0, k + 7, Blocks.bedrock);
		world.setBlock(i + 3, j + 0, k + 8, Blocks.bedrock);
		world.setBlock(i + 3, j + 0, k + 9, Blocks.bedrock);
		world.setBlock(i + 3, j + 0, k + 10, Blocks.bedrock);
		world.setBlock(i + 3, j + 0, k + 11, Blocks.bedrock);
		world.setBlock(i + 3, j + 0, k + 12, Blocks.bedrock);
		world.setBlock(i + 3, j + 0, k + 13, Blocks.bedrock);
		world.setBlock(i + 3, j + 0, k + 14, Blocks.bedrock);
		world.setBlock(i + 3, j + 0, k + 15, Blocks.bedrock);
		world.setBlock(i + 3, j + 0, k + 16, Blocks.bedrock);
		world.setBlock(i + 3, j + 0, k + 17, Blocks.bedrock);
		world.setBlock(i + 3, j + 0, k + 18, Blocks.bedrock);
		world.setBlock(i + 3, j + 0, k + 19, Blocks.bedrock);
		world.setBlock(i + 3, j + 0, k + 20, Blocks.bedrock);
		world.setBlock(i + 3, j + 0, k + 21, Blocks.bedrock);
		world.setBlock(i + 3, j + 0, k + 22, Blocks.bedrock);
		world.setBlock(i + 3, j + 0, k + 23, Blocks.bedrock);
		world.setBlock(i + 3, j + 0, k + 24, Blocks.bedrock);
		world.setBlock(i + 3, j + 0, k + 25, Blocks.bedrock);
		world.setBlock(i + 3, j + 0, k + 26, Blocks.bedrock);
		world.setBlock(i + 3, j + 0, k + 27, Blocks.bedrock);
		world.setBlock(i + 3, j + 0, k + 28, Blocks.bedrock);
		world.setBlock(i + 3, j + 0, k + 29, Blocks.bedrock);
		world.setBlock(i + 3, j + 0, k + 30, Blocks.bedrock);
		world.setBlock(i + 3, j + 0, k + 31, Blocks.bedrock);
		world.setBlock(i + 3, j + 0, k + 32, Blocks.bedrock);
		world.setBlock(i + 3, j + 0, k + 33, Blocks.bedrock);
		world.setBlock(i + 3, j + 0, k + 34, Blocks.bedrock);
		world.setBlock(i + 3, j + 0, k + 35, Blocks.bedrock);
		world.setBlock(i + 3, j + 0, k + 36, Blocks.bedrock);
		world.setBlock(i + 3, j + 0, k + 37, Blocks.bedrock);
		world.setBlock(i + 3, j + 0, k + 38, Blocks.bedrock);
		world.setBlock(i + 3, j + 0, k + 39, Blocks.bedrock);
		world.setBlock(i + 3, j + 0, k + 40, Blocks.bedrock);
		world.setBlock(i + 3, j + 0, k + 41, Blocks.bedrock);
		world.setBlock(i + 3, j + 0, k + 42, Blocks.bedrock);
		world.setBlock(i + 3, j + 0, k + 43, Blocks.bedrock);
		world.setBlock(i + 3, j + 0, k + 44, Blocks.bedrock);
		world.setBlock(i + 3, j + 1, k + 0, Blocks.dirt);
		world.setBlock(i + 3, j + 1, k + 1, Blocks.dirt);
		world.setBlock(i + 3, j + 1, k + 2, Blocks.dirt);
		world.setBlock(i + 3, j + 1, k + 3, Blocks.dirt);
		world.setBlock(i + 3, j + 1, k + 4, Blocks.dirt);
		world.setBlock(i + 3, j + 1, k + 5, Blocks.dirt);
		world.setBlock(i + 3, j + 1, k + 6, Blocks.dirt);
		world.setBlock(i + 3, j + 1, k + 7, Blocks.dirt);
		world.setBlock(i + 3, j + 1, k + 8, Blocks.dirt);
		world.setBlock(i + 3, j + 1, k + 9, Blocks.dirt);
		world.setBlock(i + 3, j + 1, k + 10, Blocks.dirt);
		world.setBlock(i + 3, j + 1, k + 11, Blocks.dirt);
		world.setBlock(i + 3, j + 1, k + 12, Blocks.dirt);
		world.setBlock(i + 3, j + 1, k + 13, Blocks.dirt);
		world.setBlock(i + 3, j + 1, k + 14, Blocks.dirt);
		world.setBlock(i + 3, j + 1, k + 15, Blocks.dirt);
		world.setBlock(i + 3, j + 1, k + 16, Blocks.dirt);
		world.setBlock(i + 3, j + 1, k + 17, Blocks.dirt);
		world.setBlock(i + 3, j + 1, k + 18, Blocks.dirt);
		world.setBlock(i + 3, j + 1, k + 19, Blocks.dirt);
		world.setBlock(i + 3, j + 1, k + 20, Blocks.dirt);
		world.setBlock(i + 3, j + 1, k + 21, Blocks.dirt);
		world.setBlock(i + 3, j + 1, k + 22, Blocks.dirt);
		world.setBlock(i + 3, j + 1, k + 23, Blocks.dirt);
		world.setBlock(i + 3, j + 1, k + 24, Blocks.dirt);
		world.setBlock(i + 3, j + 1, k + 25, Blocks.dirt);
		world.setBlock(i + 3, j + 1, k + 26, Blocks.dirt);
		world.setBlock(i + 3, j + 1, k + 27, Blocks.dirt);
		world.setBlock(i + 3, j + 1, k + 28, Blocks.dirt);
		world.setBlock(i + 3, j + 1, k + 29, Blocks.dirt);
		world.setBlock(i + 3, j + 1, k + 30, Blocks.dirt);
		world.setBlock(i + 3, j + 1, k + 31, Blocks.dirt);
		world.setBlock(i + 3, j + 1, k + 32, Blocks.dirt);
		world.setBlock(i + 3, j + 1, k + 33, Blocks.dirt);
		world.setBlock(i + 3, j + 1, k + 34, Blocks.dirt);
		world.setBlock(i + 3, j + 1, k + 35, Blocks.dirt);
		world.setBlock(i + 3, j + 1, k + 36, Blocks.dirt);
		world.setBlock(i + 3, j + 1, k + 37, Blocks.dirt);
		world.setBlock(i + 3, j + 1, k + 38, Blocks.dirt);
		world.setBlock(i + 3, j + 1, k + 39, Blocks.dirt);
		world.setBlock(i + 3, j + 1, k + 40, Blocks.dirt);
		world.setBlock(i + 3, j + 1, k + 41, Blocks.dirt);
		world.setBlock(i + 3, j + 1, k + 42, Blocks.dirt);
		world.setBlock(i + 3, j + 1, k + 43, Blocks.dirt);
		world.setBlock(i + 3, j + 1, k + 44, Blocks.dirt);
		world.setBlock(i + 3, j + 2, k + 0, Blocks.dirt);
		world.setBlock(i + 3, j + 2, k + 1, Blocks.dirt);
		world.setBlock(i + 3, j + 2, k + 2, Blocks.dirt);
		world.setBlock(i + 3, j + 2, k + 3, Blocks.dirt);
		world.setBlock(i + 3, j + 2, k + 4, Blocks.dirt);
		world.setBlock(i + 3, j + 2, k + 5, Blocks.dirt);
		world.setBlock(i + 3, j + 2, k + 6, Blocks.dirt);
		world.setBlock(i + 3, j + 2, k + 7, Blocks.dirt);
		world.setBlock(i + 3, j + 2, k + 8, Blocks.dirt);
		world.setBlock(i + 3, j + 2, k + 9, Blocks.dirt);
		world.setBlock(i + 3, j + 2, k + 10, Blocks.dirt);
		world.setBlock(i + 3, j + 2, k + 11, Blocks.dirt);
		world.setBlock(i + 3, j + 2, k + 12, Blocks.dirt);
		world.setBlock(i + 3, j + 2, k + 13, Blocks.dirt);
		world.setBlock(i + 3, j + 2, k + 14, Blocks.dirt);
		world.setBlock(i + 3, j + 2, k + 15, Blocks.dirt);
		world.setBlock(i + 3, j + 2, k + 16, Blocks.dirt);
		world.setBlock(i + 3, j + 2, k + 17, Blocks.dirt);
		world.setBlock(i + 3, j + 2, k + 18, Blocks.dirt);
		world.setBlock(i + 3, j + 2, k + 19, Blocks.dirt);
		world.setBlock(i + 3, j + 2, k + 20, Blocks.dirt);
		world.setBlock(i + 3, j + 2, k + 21, Blocks.dirt);
		world.setBlock(i + 3, j + 2, k + 22, Blocks.dirt);
		world.setBlock(i + 3, j + 2, k + 23, Blocks.dirt);
		world.setBlock(i + 3, j + 2, k + 24, Blocks.dirt);
		world.setBlock(i + 3, j + 2, k + 25, Blocks.dirt);
		world.setBlock(i + 3, j + 2, k + 26, Blocks.dirt);
		world.setBlock(i + 3, j + 2, k + 27, Blocks.dirt);
		world.setBlock(i + 3, j + 2, k + 28, Blocks.dirt);
		world.setBlock(i + 3, j + 2, k + 29, Blocks.dirt);
		world.setBlock(i + 3, j + 2, k + 30, Blocks.dirt);
		world.setBlock(i + 3, j + 2, k + 31, Blocks.dirt);
		world.setBlock(i + 3, j + 2, k + 32, Blocks.dirt);
		world.setBlock(i + 3, j + 2, k + 33, Blocks.dirt);
		world.setBlock(i + 3, j + 2, k + 34, Blocks.dirt);
		world.setBlock(i + 3, j + 2, k + 35, Blocks.dirt);
		world.setBlock(i + 3, j + 2, k + 36, Blocks.dirt);
		world.setBlock(i + 3, j + 2, k + 37, Blocks.dirt);
		world.setBlock(i + 3, j + 2, k + 38, Blocks.dirt);
		world.setBlock(i + 3, j + 2, k + 39, Blocks.dirt);
		world.setBlock(i + 3, j + 2, k + 40, Blocks.dirt);
		world.setBlock(i + 3, j + 2, k + 41, Blocks.dirt);
		world.setBlock(i + 3, j + 2, k + 42, Blocks.dirt);
		world.setBlock(i + 3, j + 2, k + 43, Blocks.dirt);
		world.setBlock(i + 3, j + 2, k + 44, Blocks.dirt);
		world.setBlock(i + 3, j + 3, k + 0, Blocks.grass);
		world.setBlock(i + 3, j + 3, k + 1, Blocks.grass);
		world.setBlock(i + 3, j + 3, k + 2, Blocks.grass);
		world.setBlock(i + 3, j + 3, k + 3, Blocks.grass);
		world.setBlock(i + 3, j + 3, k + 4, Blocks.grass);
		world.setBlock(i + 3, j + 3, k + 5, Blocks.grass);
		world.setBlock(i + 3, j + 3, k + 6, Blocks.grass);
		world.setBlock(i + 3, j + 3, k + 7, Blocks.grass);
		world.setBlock(i + 3, j + 3, k + 8, Blocks.grass);
		world.setBlock(i + 3, j + 3, k + 9, Blocks.grass);
		world.setBlock(i + 3, j + 3, k + 10, Blocks.grass);
		world.setBlock(i + 3, j + 3, k + 11, Blocks.grass);
		world.setBlock(i + 3, j + 3, k + 12, Blocks.grass);
		world.setBlock(i + 3, j + 3, k + 13, Blocks.grass);
		world.setBlock(i + 3, j + 3, k + 14, Blocks.grass);
		world.setBlock(i + 3, j + 3, k + 15, Blocks.grass);
		world.setBlock(i + 3, j + 3, k + 16, Blocks.grass);
		world.setBlock(i + 3, j + 3, k + 17, Blocks.grass);
		world.setBlock(i + 3, j + 3, k + 18, Blocks.grass);
		world.setBlock(i + 3, j + 3, k + 19, Blocks.grass);
		world.setBlock(i + 3, j + 3, k + 20, Blocks.grass);
		world.setBlock(i + 3, j + 3, k + 21, Blocks.grass);
		world.setBlock(i + 3, j + 3, k + 22, Blocks.grass);
		world.setBlock(i + 3, j + 3, k + 23, Blocks.grass);
		world.setBlock(i + 3, j + 3, k + 24, Blocks.grass);
		world.setBlock(i + 3, j + 3, k + 25, Blocks.grass);
		world.setBlock(i + 3, j + 3, k + 26, Blocks.grass);
		world.setBlock(i + 3, j + 3, k + 27, Blocks.grass);
		world.setBlock(i + 3, j + 3, k + 28, Blocks.grass);
		world.setBlock(i + 3, j + 3, k + 29, Blocks.grass);
		world.setBlock(i + 3, j + 3, k + 30, Blocks.grass);
		world.setBlock(i + 3, j + 3, k + 31, Blocks.grass);
		world.setBlock(i + 3, j + 3, k + 32, Blocks.grass);
		world.setBlock(i + 3, j + 3, k + 33, Blocks.grass);
		world.setBlock(i + 3, j + 3, k + 34, Blocks.grass);
		world.setBlock(i + 3, j + 3, k + 35, Blocks.grass);
		world.setBlock(i + 3, j + 3, k + 36, Blocks.grass);
		world.setBlock(i + 3, j + 3, k + 37, Blocks.grass);
		world.setBlock(i + 3, j + 3, k + 38, Blocks.grass);
		world.setBlock(i + 3, j + 3, k + 39, Blocks.grass);
		world.setBlock(i + 3, j + 3, k + 40, Blocks.grass);
		world.setBlock(i + 3, j + 3, k + 41, Blocks.grass);
		world.setBlock(i + 3, j + 3, k + 42, Blocks.grass);
		world.setBlock(i + 3, j + 3, k + 43, Blocks.grass);
		world.setBlock(i + 3, j + 3, k + 44, Blocks.grass);
		world.setBlock(i + 4, j + 0, k + 0, Blocks.bedrock);
		world.setBlock(i + 4, j + 0, k + 1, Blocks.bedrock);
		world.setBlock(i + 4, j + 0, k + 2, Blocks.bedrock);
		world.setBlock(i + 4, j + 0, k + 3, Blocks.bedrock);
		world.setBlock(i + 4, j + 0, k + 4, Blocks.bedrock);
		world.setBlock(i + 4, j + 0, k + 5, Blocks.bedrock);
		world.setBlock(i + 4, j + 0, k + 6, Blocks.bedrock);
		world.setBlock(i + 4, j + 0, k + 7, Blocks.bedrock);
		world.setBlock(i + 4, j + 0, k + 8, Blocks.bedrock);
		world.setBlock(i + 4, j + 0, k + 9, Blocks.bedrock);
		world.setBlock(i + 4, j + 0, k + 10, Blocks.bedrock);
		world.setBlock(i + 4, j + 0, k + 11, Blocks.bedrock);
		world.setBlock(i + 4, j + 0, k + 12, Blocks.bedrock);
		world.setBlock(i + 4, j + 0, k + 13, Blocks.bedrock);
		world.setBlock(i + 4, j + 0, k + 14, Blocks.bedrock);
		world.setBlock(i + 4, j + 0, k + 15, Blocks.bedrock);
		world.setBlock(i + 4, j + 0, k + 16, Blocks.bedrock);
		world.setBlock(i + 4, j + 0, k + 17, Blocks.bedrock);
		world.setBlock(i + 4, j + 0, k + 18, Blocks.bedrock);
		world.setBlock(i + 4, j + 0, k + 19, Blocks.bedrock);
		world.setBlock(i + 4, j + 0, k + 20, Blocks.bedrock);
		world.setBlock(i + 4, j + 0, k + 21, Blocks.bedrock);
		world.setBlock(i + 4, j + 0, k + 22, Blocks.bedrock);
		world.setBlock(i + 4, j + 0, k + 23, Blocks.bedrock);
		world.setBlock(i + 4, j + 0, k + 24, Blocks.bedrock);
		world.setBlock(i + 4, j + 0, k + 25, Blocks.bedrock);
		world.setBlock(i + 4, j + 0, k + 26, Blocks.bedrock);
		world.setBlock(i + 4, j + 0, k + 27, Blocks.bedrock);
		world.setBlock(i + 4, j + 0, k + 28, Blocks.bedrock);
		world.setBlock(i + 4, j + 0, k + 29, Blocks.bedrock);
		world.setBlock(i + 4, j + 0, k + 30, Blocks.bedrock);
		world.setBlock(i + 4, j + 0, k + 31, Blocks.bedrock);
		world.setBlock(i + 4, j + 0, k + 32, Blocks.bedrock);
		world.setBlock(i + 4, j + 0, k + 33, Blocks.bedrock);
		world.setBlock(i + 4, j + 0, k + 34, Blocks.bedrock);
		world.setBlock(i + 4, j + 0, k + 35, Blocks.bedrock);
		world.setBlock(i + 4, j + 0, k + 36, Blocks.bedrock);
		world.setBlock(i + 4, j + 0, k + 37, Blocks.bedrock);
		world.setBlock(i + 4, j + 0, k + 38, Blocks.bedrock);
		world.setBlock(i + 4, j + 0, k + 39, Blocks.bedrock);
		world.setBlock(i + 4, j + 0, k + 40, Blocks.bedrock);
		world.setBlock(i + 4, j + 0, k + 41, Blocks.bedrock);
		world.setBlock(i + 4, j + 0, k + 42, Blocks.bedrock);
		world.setBlock(i + 4, j + 0, k + 43, Blocks.bedrock);
		world.setBlock(i + 4, j + 0, k + 44, Blocks.bedrock);
		world.setBlock(i + 4, j + 1, k + 0, Blocks.dirt);
		world.setBlock(i + 4, j + 1, k + 1, Blocks.dirt);
		world.setBlock(i + 4, j + 1, k + 2, Blocks.dirt);
		world.setBlock(i + 4, j + 1, k + 3, Blocks.dirt);
		world.setBlock(i + 4, j + 1, k + 4, Blocks.dirt);
		world.setBlock(i + 4, j + 1, k + 5, Blocks.dirt);
		world.setBlock(i + 4, j + 1, k + 6, Blocks.dirt);
		world.setBlock(i + 4, j + 1, k + 7, Blocks.dirt);
		world.setBlock(i + 4, j + 1, k + 8, Blocks.dirt);
		world.setBlock(i + 4, j + 1, k + 9, Blocks.dirt);
		world.setBlock(i + 4, j + 1, k + 10, Blocks.dirt);
		world.setBlock(i + 4, j + 1, k + 11, Blocks.dirt);
		world.setBlock(i + 4, j + 1, k + 12, Blocks.dirt);
		world.setBlock(i + 4, j + 1, k + 13, Blocks.dirt);
		world.setBlock(i + 4, j + 1, k + 14, Blocks.dirt);
		world.setBlock(i + 4, j + 1, k + 15, Blocks.dirt);
		world.setBlock(i + 4, j + 1, k + 16, Blocks.dirt);
		world.setBlock(i + 4, j + 1, k + 17, Blocks.dirt);
		world.setBlock(i + 4, j + 1, k + 18, Blocks.dirt);
		world.setBlock(i + 4, j + 1, k + 19, Blocks.dirt);
		world.setBlock(i + 4, j + 1, k + 20, Blocks.dirt);
		world.setBlock(i + 4, j + 1, k + 21, Blocks.dirt);
		world.setBlock(i + 4, j + 1, k + 22, Blocks.dirt);
		world.setBlock(i + 4, j + 1, k + 23, Blocks.dirt);
		world.setBlock(i + 4, j + 1, k + 24, Blocks.dirt);
		world.setBlock(i + 4, j + 1, k + 25, Blocks.dirt);
		world.setBlock(i + 4, j + 1, k + 26, Blocks.dirt);
		world.setBlock(i + 4, j + 1, k + 27, Blocks.dirt);
		world.setBlock(i + 4, j + 1, k + 28, Blocks.dirt);
		world.setBlock(i + 4, j + 1, k + 29, Blocks.dirt);
		world.setBlock(i + 4, j + 1, k + 30, Blocks.dirt);
		world.setBlock(i + 4, j + 1, k + 31, Blocks.dirt);
		world.setBlock(i + 4, j + 1, k + 32, Blocks.dirt);
		world.setBlock(i + 4, j + 1, k + 33, Blocks.dirt);
		world.setBlock(i + 4, j + 1, k + 34, Blocks.dirt);
		world.setBlock(i + 4, j + 1, k + 35, Blocks.dirt);
		world.setBlock(i + 4, j + 1, k + 36, Blocks.dirt);
		world.setBlock(i + 4, j + 1, k + 37, Blocks.dirt);
		world.setBlock(i + 4, j + 1, k + 38, Blocks.dirt);
		world.setBlock(i + 4, j + 1, k + 39, Blocks.dirt);
		world.setBlock(i + 4, j + 1, k + 40, Blocks.dirt);
		world.setBlock(i + 4, j + 1, k + 41, Blocks.dirt);
		world.setBlock(i + 4, j + 1, k + 42, Blocks.dirt);
		world.setBlock(i + 4, j + 1, k + 43, Blocks.dirt);
		world.setBlock(i + 4, j + 1, k + 44, Blocks.dirt);
		world.setBlock(i + 4, j + 2, k + 0, Blocks.dirt);
		world.setBlock(i + 4, j + 2, k + 1, Blocks.dirt);
		world.setBlock(i + 4, j + 2, k + 2, Blocks.dirt);
		world.setBlock(i + 4, j + 2, k + 3, Blocks.dirt);
		world.setBlock(i + 4, j + 2, k + 4, Blocks.dirt);
		world.setBlock(i + 4, j + 2, k + 5, Blocks.dirt);
		world.setBlock(i + 4, j + 2, k + 6, Blocks.dirt);
		world.setBlock(i + 4, j + 2, k + 7, Blocks.dirt);
		world.setBlock(i + 4, j + 2, k + 8, Blocks.dirt);
		world.setBlock(i + 4, j + 2, k + 9, Blocks.dirt);
		world.setBlock(i + 4, j + 2, k + 10, Blocks.dirt);
		world.setBlock(i + 4, j + 2, k + 11, Blocks.dirt);
		world.setBlock(i + 4, j + 2, k + 12, Blocks.dirt);
		world.setBlock(i + 4, j + 2, k + 13, Blocks.dirt);
		world.setBlock(i + 4, j + 2, k + 14, Blocks.dirt);
		world.setBlock(i + 4, j + 2, k + 15, Blocks.dirt);
		world.setBlock(i + 4, j + 2, k + 16, Blocks.dirt);
		world.setBlock(i + 4, j + 2, k + 17, Blocks.dirt);
		world.setBlock(i + 4, j + 2, k + 18, Blocks.dirt);
		world.setBlock(i + 4, j + 2, k + 19, Blocks.dirt);
		world.setBlock(i + 4, j + 2, k + 20, Blocks.dirt);
		world.setBlock(i + 4, j + 2, k + 21, Blocks.dirt);
		world.setBlock(i + 4, j + 2, k + 22, Blocks.dirt);
		world.setBlock(i + 4, j + 2, k + 23, Blocks.dirt);
		world.setBlock(i + 4, j + 2, k + 24, Blocks.dirt);
		world.setBlock(i + 4, j + 2, k + 25, Blocks.dirt);
		world.setBlock(i + 4, j + 2, k + 26, Blocks.dirt);
		world.setBlock(i + 4, j + 2, k + 27, Blocks.dirt);
		world.setBlock(i + 4, j + 2, k + 28, Blocks.dirt);
		world.setBlock(i + 4, j + 2, k + 29, Blocks.dirt);
		world.setBlock(i + 4, j + 2, k + 30, Blocks.dirt);
		world.setBlock(i + 4, j + 2, k + 31, Blocks.dirt);
		world.setBlock(i + 4, j + 2, k + 32, Blocks.dirt);
		world.setBlock(i + 4, j + 2, k + 33, Blocks.dirt);
		world.setBlock(i + 4, j + 2, k + 34, Blocks.dirt);
		world.setBlock(i + 4, j + 2, k + 35, Blocks.dirt);
		world.setBlock(i + 4, j + 2, k + 36, Blocks.dirt);
		world.setBlock(i + 4, j + 2, k + 37, Blocks.dirt);
		world.setBlock(i + 4, j + 2, k + 38, Blocks.dirt);
		world.setBlock(i + 4, j + 2, k + 39, Blocks.dirt);
		world.setBlock(i + 4, j + 2, k + 40, Blocks.dirt);
		world.setBlock(i + 4, j + 2, k + 41, Blocks.dirt);
		world.setBlock(i + 4, j + 2, k + 42, Blocks.dirt);
		world.setBlock(i + 4, j + 2, k + 43, Blocks.dirt);
		world.setBlock(i + 4, j + 2, k + 44, Blocks.dirt);
		world.setBlock(i + 4, j + 3, k + 0, Blocks.grass);
		world.setBlock(i + 4, j + 3, k + 1, Blocks.grass);
		world.setBlock(i + 4, j + 3, k + 2, Blocks.grass);
		world.setBlock(i + 4, j + 3, k + 3, Blocks.grass);
		world.setBlock(i + 4, j + 3, k + 4, Blocks.grass);
		world.setBlock(i + 4, j + 3, k + 5, Blocks.grass);
		world.setBlock(i + 4, j + 3, k + 6, Blocks.grass);
		world.setBlock(i + 4, j + 3, k + 7, Blocks.grass);
		world.setBlock(i + 4, j + 3, k + 8, Blocks.grass);
		world.setBlock(i + 4, j + 3, k + 9, Blocks.grass);
		world.setBlock(i + 4, j + 3, k + 10, Blocks.grass);
		world.setBlock(i + 4, j + 3, k + 11, Blocks.grass);
		world.setBlock(i + 4, j + 3, k + 12, Blocks.grass);
		world.setBlock(i + 4, j + 3, k + 13, Blocks.grass);
		world.setBlock(i + 4, j + 3, k + 14, Blocks.grass);
		world.setBlock(i + 4, j + 3, k + 15, Blocks.grass);
		world.setBlock(i + 4, j + 3, k + 16, Blocks.grass);
		world.setBlock(i + 4, j + 3, k + 17, Blocks.grass);
		world.setBlock(i + 4, j + 3, k + 18, Blocks.grass);
		world.setBlock(i + 4, j + 3, k + 19, Blocks.grass);
		world.setBlock(i + 4, j + 3, k + 20, Blocks.grass);
		world.setBlock(i + 4, j + 3, k + 21, Blocks.grass);
		world.setBlock(i + 4, j + 3, k + 22, Blocks.grass);
		world.setBlock(i + 4, j + 3, k + 23, Blocks.grass);
		world.setBlock(i + 4, j + 3, k + 24, Blocks.grass);
		world.setBlock(i + 4, j + 3, k + 25, Blocks.grass);
		world.setBlock(i + 4, j + 3, k + 26, Blocks.grass);
		world.setBlock(i + 4, j + 3, k + 27, Blocks.grass);
		world.setBlock(i + 4, j + 3, k + 28, Blocks.grass);
		world.setBlock(i + 4, j + 3, k + 29, Blocks.grass);
		world.setBlock(i + 4, j + 3, k + 30, Blocks.grass);
		world.setBlock(i + 4, j + 3, k + 31, Blocks.grass);
		world.setBlock(i + 4, j + 3, k + 32, Blocks.grass);
		world.setBlock(i + 4, j + 3, k + 33, Blocks.grass);
		world.setBlock(i + 4, j + 3, k + 34, Blocks.grass);
		world.setBlock(i + 4, j + 3, k + 35, Blocks.grass);
		world.setBlock(i + 4, j + 3, k + 36, Blocks.grass);
		world.setBlock(i + 4, j + 3, k + 37, Blocks.grass);
		world.setBlock(i + 4, j + 3, k + 38, Blocks.grass);
		world.setBlock(i + 4, j + 3, k + 39, Blocks.grass);
		world.setBlock(i + 4, j + 3, k + 40, Blocks.grass);
		world.setBlock(i + 4, j + 3, k + 41, Blocks.grass);
		world.setBlock(i + 4, j + 3, k + 42, Blocks.grass);
		world.setBlock(i + 4, j + 3, k + 43, Blocks.grass);
		world.setBlock(i + 4, j + 3, k + 44, Blocks.grass);
		world.setBlock(i + 5, j + 0, k + 0, Blocks.bedrock);
		world.setBlock(i + 5, j + 0, k + 1, Blocks.bedrock);
		world.setBlock(i + 5, j + 0, k + 2, Blocks.bedrock);
		world.setBlock(i + 5, j + 0, k + 3, Blocks.bedrock);
		world.setBlock(i + 5, j + 0, k + 4, Blocks.bedrock);
		world.setBlock(i + 5, j + 0, k + 5, Blocks.bedrock);
		world.setBlock(i + 5, j + 0, k + 6, Blocks.bedrock);
		world.setBlock(i + 5, j + 0, k + 7, Blocks.bedrock);
		world.setBlock(i + 5, j + 0, k + 8, Blocks.bedrock);
		world.setBlock(i + 5, j + 0, k + 9, Blocks.bedrock);
		world.setBlock(i + 5, j + 0, k + 10, Blocks.bedrock);
		world.setBlock(i + 5, j + 0, k + 11, Blocks.bedrock);
		world.setBlock(i + 5, j + 0, k + 12, Blocks.bedrock);
		world.setBlock(i + 5, j + 0, k + 13, Blocks.bedrock);
		world.setBlock(i + 5, j + 0, k + 14, Blocks.bedrock);
		world.setBlock(i + 5, j + 0, k + 15, Blocks.bedrock);
		world.setBlock(i + 5, j + 0, k + 16, Blocks.bedrock);
		world.setBlock(i + 5, j + 0, k + 17, Blocks.bedrock);
		world.setBlock(i + 5, j + 0, k + 18, Blocks.bedrock);
		world.setBlock(i + 5, j + 0, k + 19, Blocks.bedrock);
		world.setBlock(i + 5, j + 0, k + 20, Blocks.bedrock);
		world.setBlock(i + 5, j + 0, k + 21, Blocks.bedrock);
		world.setBlock(i + 5, j + 0, k + 22, Blocks.bedrock);
		world.setBlock(i + 5, j + 0, k + 23, Blocks.bedrock);
		world.setBlock(i + 5, j + 0, k + 24, Blocks.bedrock);
		world.setBlock(i + 5, j + 0, k + 25, Blocks.bedrock);
		world.setBlock(i + 5, j + 0, k + 26, Blocks.bedrock);
		world.setBlock(i + 5, j + 0, k + 27, Blocks.bedrock);
		world.setBlock(i + 5, j + 0, k + 28, Blocks.bedrock);
		world.setBlock(i + 5, j + 0, k + 29, Blocks.bedrock);
		world.setBlock(i + 5, j + 0, k + 30, Blocks.bedrock);
		world.setBlock(i + 5, j + 0, k + 31, Blocks.bedrock);
		world.setBlock(i + 5, j + 0, k + 32, Blocks.bedrock);
		world.setBlock(i + 5, j + 0, k + 33, Blocks.bedrock);
		world.setBlock(i + 5, j + 0, k + 34, Blocks.bedrock);
		world.setBlock(i + 5, j + 0, k + 35, Blocks.bedrock);
		world.setBlock(i + 5, j + 0, k + 36, Blocks.bedrock);
		world.setBlock(i + 5, j + 0, k + 37, Blocks.bedrock);
		world.setBlock(i + 5, j + 0, k + 38, Blocks.bedrock);
		world.setBlock(i + 5, j + 0, k + 39, Blocks.bedrock);
		world.setBlock(i + 5, j + 0, k + 40, Blocks.bedrock);
		world.setBlock(i + 5, j + 0, k + 41, Blocks.bedrock);
		world.setBlock(i + 5, j + 0, k + 42, Blocks.bedrock);
		world.setBlock(i + 5, j + 0, k + 43, Blocks.bedrock);
		world.setBlock(i + 5, j + 0, k + 44, Blocks.bedrock);
		world.setBlock(i + 5, j + 1, k + 0, Blocks.dirt);
		world.setBlock(i + 5, j + 1, k + 1, Blocks.dirt);
		world.setBlock(i + 5, j + 1, k + 2, Blocks.dirt);
		world.setBlock(i + 5, j + 1, k + 3, Blocks.dirt);
		world.setBlock(i + 5, j + 1, k + 4, Blocks.dirt);
		world.setBlock(i + 5, j + 1, k + 5, Blocks.dirt);
		world.setBlock(i + 5, j + 1, k + 6, Blocks.dirt);
		world.setBlock(i + 5, j + 1, k + 7, Blocks.dirt);
		world.setBlock(i + 5, j + 1, k + 8, Blocks.dirt);
		world.setBlock(i + 5, j + 1, k + 9, Blocks.dirt);
		world.setBlock(i + 5, j + 1, k + 10, Blocks.dirt);
		world.setBlock(i + 5, j + 1, k + 11, Blocks.dirt);
		world.setBlock(i + 5, j + 1, k + 12, Blocks.dirt);
		world.setBlock(i + 5, j + 1, k + 13, Blocks.dirt);
		world.setBlock(i + 5, j + 1, k + 14, Blocks.dirt);
		world.setBlock(i + 5, j + 1, k + 15, Blocks.dirt);
		world.setBlock(i + 5, j + 1, k + 16, Blocks.dirt);
		world.setBlock(i + 5, j + 1, k + 17, Blocks.dirt);
		world.setBlock(i + 5, j + 1, k + 18, Blocks.dirt);
		world.setBlock(i + 5, j + 1, k + 19, Blocks.dirt);
		world.setBlock(i + 5, j + 1, k + 20, Blocks.dirt);
		world.setBlock(i + 5, j + 1, k + 21, Blocks.dirt);
		world.setBlock(i + 5, j + 1, k + 22, Blocks.dirt);
		world.setBlock(i + 5, j + 1, k + 23, Blocks.dirt);
		world.setBlock(i + 5, j + 1, k + 24, Blocks.dirt);
		world.setBlock(i + 5, j + 1, k + 25, Blocks.dirt);
		world.setBlock(i + 5, j + 1, k + 26, Blocks.dirt);
		world.setBlock(i + 5, j + 1, k + 27, Blocks.dirt);
		world.setBlock(i + 5, j + 1, k + 28, Blocks.dirt);
		world.setBlock(i + 5, j + 1, k + 29, Blocks.dirt);
		world.setBlock(i + 5, j + 1, k + 30, Blocks.dirt);
		world.setBlock(i + 5, j + 1, k + 31, Blocks.dirt);
		world.setBlock(i + 5, j + 1, k + 32, Blocks.dirt);
		world.setBlock(i + 5, j + 1, k + 33, Blocks.dirt);
		world.setBlock(i + 5, j + 1, k + 34, Blocks.dirt);
		world.setBlock(i + 5, j + 1, k + 35, Blocks.dirt);
		world.setBlock(i + 5, j + 1, k + 36, Blocks.dirt);
		world.setBlock(i + 5, j + 1, k + 37, Blocks.dirt);
		world.setBlock(i + 5, j + 1, k + 38, Blocks.dirt);
		world.setBlock(i + 5, j + 1, k + 39, Blocks.dirt);
		world.setBlock(i + 5, j + 1, k + 40, Blocks.dirt);
		world.setBlock(i + 5, j + 1, k + 41, Blocks.dirt);
		world.setBlock(i + 5, j + 1, k + 42, Blocks.dirt);
		world.setBlock(i + 5, j + 1, k + 43, Blocks.dirt);
		world.setBlock(i + 5, j + 1, k + 44, Blocks.dirt);
		world.setBlock(i + 5, j + 2, k + 0, Blocks.dirt);
		world.setBlock(i + 5, j + 2, k + 1, Blocks.dirt);
		world.setBlock(i + 5, j + 2, k + 2, Blocks.dirt);
		world.setBlock(i + 5, j + 2, k + 3, Blocks.dirt);
		world.setBlock(i + 5, j + 2, k + 4, Blocks.dirt);
		world.setBlock(i + 5, j + 2, k + 5, Blocks.dirt);
		world.setBlock(i + 5, j + 2, k + 6, Blocks.dirt);
		world.setBlock(i + 5, j + 2, k + 7, Blocks.dirt);
		world.setBlock(i + 5, j + 2, k + 8, Blocks.dirt);
		world.setBlock(i + 5, j + 2, k + 9, Blocks.dirt);
		world.setBlock(i + 5, j + 2, k + 10, Blocks.dirt);
		world.setBlock(i + 5, j + 2, k + 11, Blocks.dirt);
		world.setBlock(i + 5, j + 2, k + 12, Blocks.dirt);
		world.setBlock(i + 5, j + 2, k + 13, Blocks.dirt);
		world.setBlock(i + 5, j + 2, k + 14, Blocks.dirt);
		world.setBlock(i + 5, j + 2, k + 15, Blocks.dirt);
		world.setBlock(i + 5, j + 2, k + 16, Blocks.dirt);
		world.setBlock(i + 5, j + 2, k + 17, Blocks.dirt);
		world.setBlock(i + 5, j + 2, k + 18, Blocks.dirt);
		world.setBlock(i + 5, j + 2, k + 19, Blocks.dirt);
		world.setBlock(i + 5, j + 2, k + 20, Blocks.dirt);
		world.setBlock(i + 5, j + 2, k + 21, Blocks.dirt);
		world.setBlock(i + 5, j + 2, k + 22, Blocks.dirt);
		world.setBlock(i + 5, j + 2, k + 23, Blocks.dirt);
		world.setBlock(i + 5, j + 2, k + 24, Blocks.dirt);
		world.setBlock(i + 5, j + 2, k + 25, Blocks.dirt);
		world.setBlock(i + 5, j + 2, k + 26, Blocks.dirt);
		world.setBlock(i + 5, j + 2, k + 27, Blocks.dirt);
		world.setBlock(i + 5, j + 2, k + 28, Blocks.dirt);
		world.setBlock(i + 5, j + 2, k + 29, Blocks.dirt);
		world.setBlock(i + 5, j + 2, k + 30, Blocks.dirt);
		world.setBlock(i + 5, j + 2, k + 31, Blocks.dirt);
		world.setBlock(i + 5, j + 2, k + 32, Blocks.dirt);
		world.setBlock(i + 5, j + 2, k + 33, Blocks.dirt);
		world.setBlock(i + 5, j + 2, k + 34, Blocks.dirt);
		world.setBlock(i + 5, j + 2, k + 35, Blocks.dirt);
		world.setBlock(i + 5, j + 2, k + 36, Blocks.dirt);
		world.setBlock(i + 5, j + 2, k + 37, Blocks.dirt);
		world.setBlock(i + 5, j + 2, k + 38, Blocks.dirt);
		world.setBlock(i + 5, j + 2, k + 39, Blocks.dirt);
		world.setBlock(i + 5, j + 2, k + 40, Blocks.dirt);
		world.setBlock(i + 5, j + 2, k + 41, Blocks.dirt);
		world.setBlock(i + 5, j + 2, k + 42, Blocks.dirt);
		world.setBlock(i + 5, j + 2, k + 43, Blocks.dirt);
		world.setBlock(i + 5, j + 2, k + 44, Blocks.dirt);
		world.setBlock(i + 5, j + 3, k + 0, Blocks.grass);
		world.setBlock(i + 5, j + 3, k + 1, Blocks.grass);
		world.setBlock(i + 5, j + 3, k + 2, Blocks.grass);
		world.setBlock(i + 5, j + 3, k + 3, Blocks.grass);
		world.setBlock(i + 5, j + 3, k + 4, Blocks.grass);
		world.setBlock(i + 5, j + 3, k + 5, Blocks.grass);
		world.setBlock(i + 5, j + 3, k + 6, Blocks.grass);
		world.setBlock(i + 5, j + 3, k + 7, Blocks.grass);
		world.setBlock(i + 5, j + 3, k + 8, Blocks.grass);
		world.setBlock(i + 5, j + 3, k + 9, Blocks.grass);
		world.setBlock(i + 5, j + 3, k + 10, Blocks.grass);
		world.setBlock(i + 5, j + 3, k + 11, Blocks.grass);
		world.setBlock(i + 5, j + 3, k + 12, Blocks.grass);
		world.setBlock(i + 5, j + 3, k + 13, Blocks.grass);
		world.setBlock(i + 5, j + 3, k + 14, Blocks.grass);
		world.setBlock(i + 5, j + 3, k + 15, Blocks.grass);
		world.setBlock(i + 5, j + 3, k + 16, Blocks.grass);
		world.setBlock(i + 5, j + 3, k + 17, Blocks.grass);
		world.setBlock(i + 5, j + 3, k + 18, Blocks.grass);
		world.setBlock(i + 5, j + 3, k + 19, Blocks.grass);
		world.setBlock(i + 5, j + 3, k + 20, Blocks.grass);
		world.setBlock(i + 5, j + 3, k + 21, Blocks.grass);
		world.setBlock(i + 5, j + 3, k + 22, Blocks.grass);
		world.setBlock(i + 5, j + 3, k + 23, Blocks.grass);
		world.setBlock(i + 5, j + 3, k + 24, Blocks.grass);
		world.setBlock(i + 5, j + 3, k + 25, Blocks.grass);
		world.setBlock(i + 5, j + 3, k + 26, Blocks.grass);
		world.setBlock(i + 5, j + 3, k + 27, Blocks.grass);
		world.setBlock(i + 5, j + 3, k + 28, Blocks.grass);
		world.setBlock(i + 5, j + 3, k + 29, Blocks.grass);
		world.setBlock(i + 5, j + 3, k + 30, Blocks.grass);
		world.setBlock(i + 5, j + 3, k + 31, Blocks.grass);
		world.setBlock(i + 5, j + 3, k + 32, Blocks.grass);
		world.setBlock(i + 5, j + 3, k + 33, Blocks.grass);
		world.setBlock(i + 5, j + 3, k + 34, Blocks.grass);
		world.setBlock(i + 5, j + 3, k + 35, Blocks.grass);
		world.setBlock(i + 5, j + 3, k + 36, Blocks.grass);
		world.setBlock(i + 5, j + 3, k + 37, Blocks.grass);
		world.setBlock(i + 5, j + 3, k + 38, Blocks.grass);
		world.setBlock(i + 5, j + 3, k + 39, Blocks.grass);
		world.setBlock(i + 5, j + 3, k + 40, Blocks.grass);
		world.setBlock(i + 5, j + 3, k + 41, Blocks.grass);
		world.setBlock(i + 5, j + 3, k + 42, Blocks.grass);
		world.setBlock(i + 5, j + 3, k + 43, Blocks.grass);
		world.setBlock(i + 5, j + 3, k + 44, Blocks.grass);
		world.setBlock(i + 6, j + 0, k + 0, Blocks.bedrock);
		world.setBlock(i + 6, j + 0, k + 1, Blocks.bedrock);
		world.setBlock(i + 6, j + 0, k + 2, Blocks.bedrock);
		world.setBlock(i + 6, j + 0, k + 3, Blocks.bedrock);
		world.setBlock(i + 6, j + 0, k + 4, Blocks.bedrock);
		world.setBlock(i + 6, j + 0, k + 5, Blocks.bedrock);
		world.setBlock(i + 6, j + 0, k + 6, Blocks.bedrock);
		world.setBlock(i + 6, j + 0, k + 7, Blocks.bedrock);
		world.setBlock(i + 6, j + 0, k + 8, Blocks.bedrock);
		world.setBlock(i + 6, j + 0, k + 9, Blocks.bedrock);
		world.setBlock(i + 6, j + 0, k + 10, Blocks.bedrock);
		world.setBlock(i + 6, j + 0, k + 11, Blocks.bedrock);
		world.setBlock(i + 6, j + 0, k + 12, Blocks.bedrock);
		world.setBlock(i + 6, j + 0, k + 13, Blocks.bedrock);
		world.setBlock(i + 6, j + 0, k + 14, Blocks.bedrock);
		world.setBlock(i + 6, j + 0, k + 15, Blocks.bedrock);
		world.setBlock(i + 6, j + 0, k + 16, Blocks.bedrock);
		world.setBlock(i + 6, j + 0, k + 17, Blocks.bedrock);
		world.setBlock(i + 6, j + 0, k + 18, Blocks.bedrock);
		world.setBlock(i + 6, j + 0, k + 19, Blocks.bedrock);
		world.setBlock(i + 6, j + 0, k + 20, Blocks.bedrock);
		world.setBlock(i + 6, j + 0, k + 21, Blocks.bedrock);
		world.setBlock(i + 6, j + 0, k + 22, Blocks.bedrock);
		world.setBlock(i + 6, j + 0, k + 23, Blocks.bedrock);
		world.setBlock(i + 6, j + 0, k + 24, Blocks.bedrock);
		world.setBlock(i + 6, j + 0, k + 25, Blocks.bedrock);
		world.setBlock(i + 6, j + 0, k + 26, Blocks.bedrock);
		world.setBlock(i + 6, j + 0, k + 27, Blocks.bedrock);
		world.setBlock(i + 6, j + 0, k + 28, Blocks.bedrock);
		world.setBlock(i + 6, j + 0, k + 29, Blocks.bedrock);
		world.setBlock(i + 6, j + 0, k + 30, Blocks.bedrock);
		world.setBlock(i + 6, j + 0, k + 31, Blocks.bedrock);
		world.setBlock(i + 6, j + 0, k + 32, Blocks.bedrock);
		world.setBlock(i + 6, j + 0, k + 33, Blocks.bedrock);
		world.setBlock(i + 6, j + 0, k + 34, Blocks.bedrock);
		world.setBlock(i + 6, j + 0, k + 35, Blocks.bedrock);
		world.setBlock(i + 6, j + 0, k + 36, Blocks.bedrock);
		world.setBlock(i + 6, j + 0, k + 37, Blocks.bedrock);
		world.setBlock(i + 6, j + 0, k + 38, Blocks.bedrock);
		world.setBlock(i + 6, j + 0, k + 39, Blocks.bedrock);
		world.setBlock(i + 6, j + 0, k + 40, Blocks.bedrock);
		world.setBlock(i + 6, j + 0, k + 41, Blocks.bedrock);
		world.setBlock(i + 6, j + 0, k + 42, Blocks.bedrock);
		world.setBlock(i + 6, j + 0, k + 43, Blocks.bedrock);
		world.setBlock(i + 6, j + 0, k + 44, Blocks.bedrock);
		world.setBlock(i + 6, j + 1, k + 0, Blocks.dirt);
		world.setBlock(i + 6, j + 1, k + 1, Blocks.dirt);
		world.setBlock(i + 6, j + 1, k + 2, Blocks.dirt);
		world.setBlock(i + 6, j + 1, k + 3, Blocks.dirt);
		world.setBlock(i + 6, j + 1, k + 4, Blocks.dirt);
		world.setBlock(i + 6, j + 1, k + 5, Blocks.dirt);
		world.setBlock(i + 6, j + 1, k + 6, Blocks.dirt);
		world.setBlock(i + 6, j + 1, k + 7, Blocks.dirt);
		world.setBlock(i + 6, j + 1, k + 8, Blocks.dirt);
		world.setBlock(i + 6, j + 1, k + 9, Blocks.dirt);
		world.setBlock(i + 6, j + 1, k + 10, Blocks.dirt);
		world.setBlock(i + 6, j + 1, k + 11, Blocks.dirt);
		world.setBlock(i + 6, j + 1, k + 12, Blocks.dirt);
		world.setBlock(i + 6, j + 1, k + 13, Blocks.dirt);
		world.setBlock(i + 6, j + 1, k + 14, Blocks.dirt);
		world.setBlock(i + 6, j + 1, k + 15, Blocks.dirt);
		world.setBlock(i + 6, j + 1, k + 16, Blocks.dirt);
		world.setBlock(i + 6, j + 1, k + 17, Blocks.dirt);
		world.setBlock(i + 6, j + 1, k + 18, Blocks.dirt);
		world.setBlock(i + 6, j + 1, k + 19, Blocks.dirt);
		world.setBlock(i + 6, j + 1, k + 20, Blocks.dirt);
		world.setBlock(i + 6, j + 1, k + 21, Blocks.dirt);
		world.setBlock(i + 6, j + 1, k + 22, Blocks.dirt);
		world.setBlock(i + 6, j + 1, k + 23, Blocks.dirt);
		world.setBlock(i + 6, j + 1, k + 24, Blocks.dirt);
		world.setBlock(i + 6, j + 1, k + 25, Blocks.dirt);
		world.setBlock(i + 6, j + 1, k + 26, Blocks.dirt);
		world.setBlock(i + 6, j + 1, k + 27, Blocks.dirt);
		world.setBlock(i + 6, j + 1, k + 28, Blocks.dirt);
		world.setBlock(i + 6, j + 1, k + 29, Blocks.dirt);
		world.setBlock(i + 6, j + 1, k + 30, Blocks.dirt);
		world.setBlock(i + 6, j + 1, k + 31, Blocks.dirt);
		world.setBlock(i + 6, j + 1, k + 32, Blocks.dirt);
		world.setBlock(i + 6, j + 1, k + 33, Blocks.dirt);
		world.setBlock(i + 6, j + 1, k + 34, Blocks.dirt);
		world.setBlock(i + 6, j + 1, k + 35, Blocks.dirt);
		world.setBlock(i + 6, j + 1, k + 36, Blocks.dirt);
		world.setBlock(i + 6, j + 1, k + 37, Blocks.dirt);
		world.setBlock(i + 6, j + 1, k + 38, Blocks.dirt);
		world.setBlock(i + 6, j + 1, k + 39, Blocks.dirt);
		world.setBlock(i + 6, j + 1, k + 40, Blocks.dirt);
		world.setBlock(i + 6, j + 1, k + 41, Blocks.dirt);
		world.setBlock(i + 6, j + 1, k + 42, Blocks.dirt);
		world.setBlock(i + 6, j + 1, k + 43, Blocks.dirt);
		world.setBlock(i + 6, j + 1, k + 44, Blocks.dirt);
		world.setBlock(i + 6, j + 2, k + 0, Blocks.dirt);
		world.setBlock(i + 6, j + 2, k + 1, Blocks.dirt);
		world.setBlock(i + 6, j + 2, k + 2, Blocks.dirt);
		world.setBlock(i + 6, j + 2, k + 3, Blocks.dirt);
		world.setBlock(i + 6, j + 2, k + 4, Blocks.dirt);
		world.setBlock(i + 6, j + 2, k + 5, Blocks.dirt);
		world.setBlock(i + 6, j + 2, k + 6, Blocks.dirt);
		world.setBlock(i + 6, j + 2, k + 7, Blocks.dirt);
		world.setBlock(i + 6, j + 2, k + 8, Blocks.dirt);
		world.setBlock(i + 6, j + 2, k + 9, Blocks.dirt);
		world.setBlock(i + 6, j + 2, k + 10, Blocks.dirt);
		world.setBlock(i + 6, j + 2, k + 11, Blocks.dirt);
		world.setBlock(i + 6, j + 2, k + 12, Blocks.dirt);
		world.setBlock(i + 6, j + 2, k + 13, Blocks.dirt);
		world.setBlock(i + 6, j + 2, k + 14, Blocks.dirt);
		world.setBlock(i + 6, j + 2, k + 15, Blocks.dirt);
		world.setBlock(i + 6, j + 2, k + 16, Blocks.dirt);
		world.setBlock(i + 6, j + 2, k + 17, Blocks.dirt);
		world.setBlock(i + 6, j + 2, k + 18, Blocks.dirt);
		world.setBlock(i + 6, j + 2, k + 19, Blocks.dirt);
		world.setBlock(i + 6, j + 2, k + 20, Blocks.dirt);
		world.setBlock(i + 6, j + 2, k + 21, Blocks.dirt);
		world.setBlock(i + 6, j + 2, k + 22, Blocks.dirt);
		world.setBlock(i + 6, j + 2, k + 23, Blocks.dirt);
		world.setBlock(i + 6, j + 2, k + 24, Blocks.dirt);
		world.setBlock(i + 6, j + 2, k + 25, Blocks.dirt);
		world.setBlock(i + 6, j + 2, k + 26, Blocks.dirt);
		world.setBlock(i + 6, j + 2, k + 27, Blocks.dirt);
		world.setBlock(i + 6, j + 2, k + 28, Blocks.dirt);
		world.setBlock(i + 6, j + 2, k + 29, Blocks.dirt);
		world.setBlock(i + 6, j + 2, k + 30, Blocks.dirt);
		world.setBlock(i + 6, j + 2, k + 31, Blocks.dirt);
		world.setBlock(i + 6, j + 2, k + 32, Blocks.dirt);
		world.setBlock(i + 6, j + 2, k + 33, Blocks.dirt);
		world.setBlock(i + 6, j + 2, k + 34, Blocks.dirt);
		world.setBlock(i + 6, j + 2, k + 35, Blocks.dirt);
		world.setBlock(i + 6, j + 2, k + 36, Blocks.dirt);
		world.setBlock(i + 6, j + 2, k + 37, Blocks.dirt);
		world.setBlock(i + 6, j + 2, k + 38, Blocks.dirt);
		world.setBlock(i + 6, j + 2, k + 39, Blocks.dirt);
		world.setBlock(i + 6, j + 2, k + 40, Blocks.dirt);
		world.setBlock(i + 6, j + 2, k + 41, Blocks.dirt);
		world.setBlock(i + 6, j + 2, k + 42, Blocks.dirt);
		world.setBlock(i + 6, j + 2, k + 43, Blocks.dirt);
		world.setBlock(i + 6, j + 2, k + 44, Blocks.dirt);
		world.setBlock(i + 6, j + 3, k + 0, Blocks.grass);
		world.setBlock(i + 6, j + 3, k + 1, Blocks.grass);
		world.setBlock(i + 6, j + 3, k + 2, Blocks.grass);
		world.setBlock(i + 6, j + 3, k + 3, Blocks.grass);
		world.setBlock(i + 6, j + 3, k + 4, Blocks.grass);
		world.setBlock(i + 6, j + 3, k + 5, Blocks.grass);
		world.setBlock(i + 6, j + 3, k + 6, Blocks.grass);
		world.setBlock(i + 6, j + 3, k + 7, Blocks.grass);
		world.setBlock(i + 6, j + 3, k + 8, Blocks.grass);
		world.setBlock(i + 6, j + 3, k + 9, Blocks.grass);
		world.setBlock(i + 6, j + 3, k + 10, Blocks.grass);
		world.setBlock(i + 6, j + 3, k + 11, Blocks.grass);
		world.setBlock(i + 6, j + 3, k + 12, Blocks.grass);
		world.setBlock(i + 6, j + 3, k + 13, Blocks.grass);
		world.setBlock(i + 6, j + 3, k + 14, Blocks.grass);
		world.setBlock(i + 6, j + 3, k + 15, Blocks.grass);
		world.setBlock(i + 6, j + 3, k + 16, Blocks.grass);
		world.setBlock(i + 6, j + 3, k + 17, Blocks.grass);
		world.setBlock(i + 6, j + 3, k + 18, Blocks.grass);
		world.setBlock(i + 6, j + 3, k + 19, Blocks.grass);
		world.setBlock(i + 6, j + 3, k + 20, Blocks.grass);
		world.setBlock(i + 6, j + 3, k + 21, Blocks.grass);
		world.setBlock(i + 6, j + 3, k + 22, Blocks.grass);
		world.setBlock(i + 6, j + 3, k + 23, Blocks.grass);
		world.setBlock(i + 6, j + 3, k + 24, Blocks.grass);
		world.setBlock(i + 6, j + 3, k + 25, Blocks.grass);
		world.setBlock(i + 6, j + 3, k + 26, Blocks.grass);
		world.setBlock(i + 6, j + 3, k + 27, Blocks.grass);
		world.setBlock(i + 6, j + 3, k + 28, Blocks.grass);
		world.setBlock(i + 6, j + 3, k + 29, Blocks.grass);
		world.setBlock(i + 6, j + 3, k + 30, Blocks.grass);
		world.setBlock(i + 6, j + 3, k + 31, Blocks.grass);
		world.setBlock(i + 6, j + 3, k + 32, Blocks.grass);
		world.setBlock(i + 6, j + 3, k + 33, Blocks.grass);
		world.setBlock(i + 6, j + 3, k + 34, Blocks.grass);
		world.setBlock(i + 6, j + 3, k + 35, Blocks.grass);
		world.setBlock(i + 6, j + 3, k + 36, Blocks.grass);
		world.setBlock(i + 6, j + 3, k + 37, Blocks.grass);
		world.setBlock(i + 6, j + 3, k + 38, Blocks.grass);
		world.setBlock(i + 6, j + 3, k + 39, Blocks.grass);
		world.setBlock(i + 6, j + 3, k + 40, Blocks.grass);
		world.setBlock(i + 6, j + 3, k + 41, Blocks.grass);
		world.setBlock(i + 6, j + 3, k + 42, Blocks.grass);
		world.setBlock(i + 6, j + 3, k + 43, Blocks.grass);
		world.setBlock(i + 6, j + 3, k + 44, Blocks.grass);
		world.setBlock(i + 7, j + 0, k + 0, Blocks.bedrock);
		world.setBlock(i + 7, j + 0, k + 1, Blocks.bedrock);
		world.setBlock(i + 7, j + 0, k + 2, Blocks.bedrock);
		world.setBlock(i + 7, j + 0, k + 3, Blocks.bedrock);
		world.setBlock(i + 7, j + 0, k + 4, Blocks.bedrock);
		world.setBlock(i + 7, j + 0, k + 5, Blocks.bedrock);
		world.setBlock(i + 7, j + 0, k + 6, Blocks.bedrock);
		world.setBlock(i + 7, j + 0, k + 7, Blocks.bedrock);
		world.setBlock(i + 7, j + 0, k + 8, Blocks.bedrock);
		world.setBlock(i + 7, j + 0, k + 9, Blocks.bedrock);
		world.setBlock(i + 7, j + 0, k + 10, Blocks.bedrock);
		world.setBlock(i + 7, j + 0, k + 11, Blocks.bedrock);
		world.setBlock(i + 7, j + 0, k + 12, Blocks.bedrock);
		world.setBlock(i + 7, j + 0, k + 13, Blocks.bedrock);
		world.setBlock(i + 7, j + 0, k + 14, Blocks.bedrock);
		world.setBlock(i + 7, j + 0, k + 15, Blocks.bedrock);
		world.setBlock(i + 7, j + 0, k + 16, Blocks.bedrock);
		world.setBlock(i + 7, j + 0, k + 17, Blocks.bedrock);
		world.setBlock(i + 7, j + 0, k + 18, Blocks.bedrock);
		world.setBlock(i + 7, j + 0, k + 19, Blocks.bedrock);
		world.setBlock(i + 7, j + 0, k + 20, Blocks.bedrock);
		world.setBlock(i + 7, j + 0, k + 21, Blocks.bedrock);
		world.setBlock(i + 7, j + 0, k + 22, Blocks.bedrock);
		world.setBlock(i + 7, j + 0, k + 23, Blocks.bedrock);
		world.setBlock(i + 7, j + 0, k + 24, Blocks.bedrock);
		world.setBlock(i + 7, j + 0, k + 25, Blocks.bedrock);
		world.setBlock(i + 7, j + 0, k + 26, Blocks.bedrock);
		world.setBlock(i + 7, j + 0, k + 27, Blocks.bedrock);
		world.setBlock(i + 7, j + 0, k + 28, Blocks.bedrock);
		world.setBlock(i + 7, j + 0, k + 29, Blocks.bedrock);
		world.setBlock(i + 7, j + 0, k + 30, Blocks.bedrock);
		world.setBlock(i + 7, j + 0, k + 31, Blocks.bedrock);
		world.setBlock(i + 7, j + 0, k + 32, Blocks.bedrock);
		world.setBlock(i + 7, j + 0, k + 33, Blocks.bedrock);
		world.setBlock(i + 7, j + 0, k + 34, Blocks.bedrock);
		world.setBlock(i + 7, j + 0, k + 35, Blocks.bedrock);
		world.setBlock(i + 7, j + 0, k + 36, Blocks.bedrock);
		world.setBlock(i + 7, j + 0, k + 37, Blocks.bedrock);
		world.setBlock(i + 7, j + 0, k + 38, Blocks.bedrock);
		world.setBlock(i + 7, j + 0, k + 39, Blocks.bedrock);
		world.setBlock(i + 7, j + 0, k + 40, Blocks.bedrock);
		world.setBlock(i + 7, j + 0, k + 41, Blocks.bedrock);
		world.setBlock(i + 7, j + 0, k + 42, Blocks.bedrock);
		world.setBlock(i + 7, j + 0, k + 43, Blocks.bedrock);
		world.setBlock(i + 7, j + 0, k + 44, Blocks.bedrock);
		world.setBlock(i + 7, j + 1, k + 0, Blocks.dirt);
		world.setBlock(i + 7, j + 1, k + 1, Blocks.dirt);
		world.setBlock(i + 7, j + 1, k + 2, Blocks.dirt);
		world.setBlock(i + 7, j + 1, k + 3, Blocks.dirt);
		world.setBlock(i + 7, j + 1, k + 4, Blocks.dirt);
		world.setBlock(i + 7, j + 1, k + 5, Blocks.dirt);
		world.setBlock(i + 7, j + 1, k + 6, Blocks.dirt);
		world.setBlock(i + 7, j + 1, k + 7, Blocks.dirt);
		world.setBlock(i + 7, j + 1, k + 8, Blocks.dirt);
		world.setBlock(i + 7, j + 1, k + 9, Blocks.dirt);
		world.setBlock(i + 7, j + 1, k + 10, Blocks.dirt);
		world.setBlock(i + 7, j + 1, k + 11, Blocks.dirt);
		world.setBlock(i + 7, j + 1, k + 12, Blocks.dirt);
		world.setBlock(i + 7, j + 1, k + 13, Blocks.dirt);
		world.setBlock(i + 7, j + 1, k + 14, Blocks.dirt);
		world.setBlock(i + 7, j + 1, k + 15, Blocks.dirt);
		world.setBlock(i + 7, j + 1, k + 16, Blocks.dirt);
		world.setBlock(i + 7, j + 1, k + 17, Blocks.dirt);
		world.setBlock(i + 7, j + 1, k + 18, Blocks.dirt);
		world.setBlock(i + 7, j + 1, k + 19, Blocks.dirt);
		world.setBlock(i + 7, j + 1, k + 20, Blocks.dirt);
		world.setBlock(i + 7, j + 1, k + 21, Blocks.dirt);
		world.setBlock(i + 7, j + 1, k + 22, Blocks.dirt);
		world.setBlock(i + 7, j + 1, k + 23, Blocks.dirt);
		world.setBlock(i + 7, j + 1, k + 24, Blocks.dirt);
		world.setBlock(i + 7, j + 1, k + 25, Blocks.dirt);
		world.setBlock(i + 7, j + 1, k + 26, Blocks.dirt);
		world.setBlock(i + 7, j + 1, k + 27, Blocks.dirt);
		world.setBlock(i + 7, j + 1, k + 28, Blocks.dirt);
		world.setBlock(i + 7, j + 1, k + 29, Blocks.dirt);
		world.setBlock(i + 7, j + 1, k + 30, Blocks.dirt);
		world.setBlock(i + 7, j + 1, k + 31, Blocks.dirt);
		world.setBlock(i + 7, j + 1, k + 32, Blocks.dirt);
		world.setBlock(i + 7, j + 1, k + 33, Blocks.dirt);
		world.setBlock(i + 7, j + 1, k + 34, Blocks.dirt);
		world.setBlock(i + 7, j + 1, k + 35, Blocks.dirt);
		world.setBlock(i + 7, j + 1, k + 36, Blocks.dirt);
		world.setBlock(i + 7, j + 1, k + 37, Blocks.dirt);
		world.setBlock(i + 7, j + 1, k + 38, Blocks.dirt);
		world.setBlock(i + 7, j + 1, k + 39, Blocks.dirt);
		world.setBlock(i + 7, j + 1, k + 40, Blocks.dirt);
		world.setBlock(i + 7, j + 1, k + 41, Blocks.dirt);
		world.setBlock(i + 7, j + 1, k + 42, Blocks.dirt);
		world.setBlock(i + 7, j + 1, k + 43, Blocks.dirt);
		world.setBlock(i + 7, j + 1, k + 44, Blocks.dirt);
		world.setBlock(i + 7, j + 2, k + 0, Blocks.dirt);
		world.setBlock(i + 7, j + 2, k + 1, Blocks.dirt);
		world.setBlock(i + 7, j + 2, k + 2, Blocks.dirt);
		world.setBlock(i + 7, j + 2, k + 3, Blocks.dirt);
		world.setBlock(i + 7, j + 2, k + 4, Blocks.dirt);
		world.setBlock(i + 7, j + 2, k + 5, Blocks.dirt);
		world.setBlock(i + 7, j + 2, k + 6, Blocks.dirt);
		world.setBlock(i + 7, j + 2, k + 7, Blocks.dirt);
		world.setBlock(i + 7, j + 2, k + 8, Blocks.dirt);
		world.setBlock(i + 7, j + 2, k + 9, Blocks.dirt);
		world.setBlock(i + 7, j + 2, k + 10, Blocks.dirt);
		world.setBlock(i + 7, j + 2, k + 11, Blocks.dirt);
		world.setBlock(i + 7, j + 2, k + 12, Blocks.dirt);
		world.setBlock(i + 7, j + 2, k + 13, Blocks.dirt);
		world.setBlock(i + 7, j + 2, k + 14, Blocks.dirt);
		world.setBlock(i + 7, j + 2, k + 15, Blocks.dirt);
		world.setBlock(i + 7, j + 2, k + 16, Blocks.dirt);
		world.setBlock(i + 7, j + 2, k + 17, Blocks.dirt);
		world.setBlock(i + 7, j + 2, k + 18, Blocks.dirt);
		world.setBlock(i + 7, j + 2, k + 19, Blocks.dirt);
		world.setBlock(i + 7, j + 2, k + 20, Blocks.dirt);
		world.setBlock(i + 7, j + 2, k + 21, Blocks.dirt);
		world.setBlock(i + 7, j + 2, k + 22, Blocks.dirt);
		world.setBlock(i + 7, j + 2, k + 23, Blocks.dirt);
		world.setBlock(i + 7, j + 2, k + 24, Blocks.dirt);
		world.setBlock(i + 7, j + 2, k + 25, Blocks.dirt);
		world.setBlock(i + 7, j + 2, k + 26, Blocks.dirt);
		world.setBlock(i + 7, j + 2, k + 27, Blocks.dirt);
		world.setBlock(i + 7, j + 2, k + 28, Blocks.dirt);
		world.setBlock(i + 7, j + 2, k + 29, Blocks.dirt);
		world.setBlock(i + 7, j + 2, k + 30, Blocks.dirt);
		world.setBlock(i + 7, j + 2, k + 31, Blocks.dirt);
		world.setBlock(i + 7, j + 2, k + 32, Blocks.dirt);
		world.setBlock(i + 7, j + 2, k + 33, Blocks.dirt);
		world.setBlock(i + 7, j + 2, k + 34, Blocks.dirt);
		world.setBlock(i + 7, j + 2, k + 35, Blocks.dirt);
		world.setBlock(i + 7, j + 2, k + 36, Blocks.dirt);
		world.setBlock(i + 7, j + 2, k + 37, Blocks.dirt);
		world.setBlock(i + 7, j + 2, k + 38, Blocks.dirt);
		world.setBlock(i + 7, j + 2, k + 39, Blocks.dirt);
		world.setBlock(i + 7, j + 2, k + 40, Blocks.dirt);
		world.setBlock(i + 7, j + 2, k + 41, Blocks.dirt);
		world.setBlock(i + 7, j + 2, k + 42, Blocks.dirt);
		world.setBlock(i + 7, j + 2, k + 43, Blocks.dirt);
		world.setBlock(i + 7, j + 2, k + 44, Blocks.dirt);
		world.setBlock(i + 7, j + 3, k + 0, Blocks.grass);
		world.setBlock(i + 7, j + 3, k + 1, Blocks.grass);
		world.setBlock(i + 7, j + 3, k + 2, Blocks.grass);
		world.setBlock(i + 7, j + 3, k + 3, Blocks.grass);
		world.setBlock(i + 7, j + 3, k + 4, Blocks.grass);
		world.setBlock(i + 7, j + 3, k + 5, Blocks.grass);
		world.setBlock(i + 7, j + 3, k + 6, Blocks.grass);
		world.setBlock(i + 7, j + 3, k + 7, Blocks.grass);
		world.setBlock(i + 7, j + 3, k + 8, Blocks.grass);
		world.setBlock(i + 7, j + 3, k + 9, Blocks.grass);
		world.setBlock(i + 7, j + 3, k + 10, Blocks.grass);
		world.setBlock(i + 7, j + 3, k + 11, Blocks.grass);
		world.setBlock(i + 7, j + 3, k + 12, Blocks.grass);
		world.setBlock(i + 7, j + 3, k + 13, Blocks.grass);
		world.setBlock(i + 7, j + 3, k + 14, Blocks.grass);
		world.setBlock(i + 7, j + 3, k + 15, Blocks.grass);
		world.setBlock(i + 7, j + 3, k + 16, Blocks.grass);
		world.setBlock(i + 7, j + 3, k + 17, Blocks.grass);
		world.setBlock(i + 7, j + 3, k + 18, Blocks.grass);
		world.setBlock(i + 7, j + 3, k + 19, Blocks.grass);
		world.setBlock(i + 7, j + 3, k + 20, Blocks.grass);
		world.setBlock(i + 7, j + 3, k + 21, Blocks.grass);
		world.setBlock(i + 7, j + 3, k + 22, Blocks.grass);
		world.setBlock(i + 7, j + 3, k + 23, Blocks.grass);
		world.setBlock(i + 7, j + 3, k + 24, Blocks.grass);
		world.setBlock(i + 7, j + 3, k + 25, Blocks.grass);
		world.setBlock(i + 7, j + 3, k + 26, Blocks.grass);
		world.setBlock(i + 7, j + 3, k + 27, Blocks.grass);
		world.setBlock(i + 7, j + 3, k + 28, Blocks.grass);
		world.setBlock(i + 7, j + 3, k + 29, Blocks.grass);
		world.setBlock(i + 7, j + 3, k + 30, Blocks.grass);
		world.setBlock(i + 7, j + 3, k + 31, Blocks.grass);
		world.setBlock(i + 7, j + 3, k + 32, Blocks.grass);
		world.setBlock(i + 7, j + 3, k + 33, Blocks.grass);
		world.setBlock(i + 7, j + 3, k + 34, Blocks.grass);
		world.setBlock(i + 7, j + 3, k + 35, Blocks.grass);
		world.setBlock(i + 7, j + 3, k + 36, Blocks.grass);
		world.setBlock(i + 7, j + 3, k + 37, Blocks.grass);
		world.setBlock(i + 7, j + 3, k + 38, Blocks.grass);
		world.setBlock(i + 7, j + 3, k + 39, Blocks.grass);
		world.setBlock(i + 7, j + 3, k + 40, Blocks.grass);
		world.setBlock(i + 7, j + 3, k + 41, Blocks.grass);
		world.setBlock(i + 7, j + 3, k + 42, Blocks.grass);
		world.setBlock(i + 7, j + 3, k + 43, Blocks.grass);
		world.setBlock(i + 7, j + 3, k + 44, Blocks.grass);
		world.setBlock(i + 8, j + 0, k + 0, Blocks.bedrock);
		world.setBlock(i + 8, j + 0, k + 1, Blocks.bedrock);
		world.setBlock(i + 8, j + 0, k + 2, Blocks.bedrock);
		world.setBlock(i + 8, j + 0, k + 3, Blocks.bedrock);
		world.setBlock(i + 8, j + 0, k + 4, Blocks.bedrock);
		world.setBlock(i + 8, j + 0, k + 5, Blocks.bedrock);
		world.setBlock(i + 8, j + 0, k + 6, Blocks.bedrock);
		world.setBlock(i + 8, j + 0, k + 7, Blocks.bedrock);
		world.setBlock(i + 8, j + 0, k + 8, Blocks.bedrock);
		world.setBlock(i + 8, j + 0, k + 9, Blocks.bedrock);
		world.setBlock(i + 8, j + 0, k + 10, Blocks.bedrock);
		world.setBlock(i + 8, j + 0, k + 11, Blocks.bedrock);
		world.setBlock(i + 8, j + 0, k + 12, Blocks.bedrock);
		world.setBlock(i + 8, j + 0, k + 13, Blocks.bedrock);
		world.setBlock(i + 8, j + 0, k + 14, Blocks.bedrock);
		world.setBlock(i + 8, j + 0, k + 15, Blocks.bedrock);
		world.setBlock(i + 8, j + 0, k + 16, Blocks.bedrock);
		world.setBlock(i + 8, j + 0, k + 17, Blocks.bedrock);
		world.setBlock(i + 8, j + 0, k + 18, Blocks.bedrock);
		world.setBlock(i + 8, j + 0, k + 19, Blocks.bedrock);
		world.setBlock(i + 8, j + 0, k + 20, Blocks.bedrock);
		world.setBlock(i + 8, j + 0, k + 21, Blocks.bedrock);
		world.setBlock(i + 8, j + 0, k + 22, Blocks.bedrock);
		world.setBlock(i + 8, j + 0, k + 23, Blocks.bedrock);
		world.setBlock(i + 8, j + 0, k + 24, Blocks.bedrock);
		world.setBlock(i + 8, j + 0, k + 25, Blocks.bedrock);
		world.setBlock(i + 8, j + 0, k + 26, Blocks.bedrock);
		world.setBlock(i + 8, j + 0, k + 27, Blocks.bedrock);
		world.setBlock(i + 8, j + 0, k + 28, Blocks.bedrock);
		world.setBlock(i + 8, j + 0, k + 29, Blocks.bedrock);
		world.setBlock(i + 8, j + 0, k + 30, Blocks.bedrock);
		world.setBlock(i + 8, j + 0, k + 31, Blocks.bedrock);
		world.setBlock(i + 8, j + 0, k + 32, Blocks.bedrock);
		world.setBlock(i + 8, j + 0, k + 33, Blocks.bedrock);
		world.setBlock(i + 8, j + 0, k + 34, Blocks.bedrock);
		world.setBlock(i + 8, j + 0, k + 35, Blocks.bedrock);
		world.setBlock(i + 8, j + 0, k + 36, Blocks.bedrock);
		world.setBlock(i + 8, j + 0, k + 37, Blocks.bedrock);
		world.setBlock(i + 8, j + 0, k + 38, Blocks.bedrock);
		world.setBlock(i + 8, j + 0, k + 39, Blocks.bedrock);
		world.setBlock(i + 8, j + 0, k + 40, Blocks.bedrock);
		world.setBlock(i + 8, j + 0, k + 41, Blocks.bedrock);
		world.setBlock(i + 8, j + 0, k + 42, Blocks.bedrock);
		world.setBlock(i + 8, j + 0, k + 43, Blocks.bedrock);
		world.setBlock(i + 8, j + 0, k + 44, Blocks.bedrock);
		world.setBlock(i + 8, j + 1, k + 0, Blocks.dirt);
		world.setBlock(i + 8, j + 1, k + 1, Blocks.dirt);
		world.setBlock(i + 8, j + 1, k + 2, Blocks.dirt);
		world.setBlock(i + 8, j + 1, k + 3, Blocks.dirt);
		world.setBlock(i + 8, j + 1, k + 4, Blocks.dirt);
		world.setBlock(i + 8, j + 1, k + 5, Blocks.dirt);
		world.setBlock(i + 8, j + 1, k + 6, Blocks.dirt);
		world.setBlock(i + 8, j + 1, k + 7, Blocks.dirt);
		world.setBlock(i + 8, j + 1, k + 8, Blocks.dirt);
		world.setBlock(i + 8, j + 1, k + 9, Blocks.dirt);
		world.setBlock(i + 8, j + 1, k + 10, Blocks.dirt);
		world.setBlock(i + 8, j + 1, k + 11, Blocks.dirt);
		world.setBlock(i + 8, j + 1, k + 12, Blocks.dirt);
		world.setBlock(i + 8, j + 1, k + 13, Blocks.dirt);
		world.setBlock(i + 8, j + 1, k + 14, Blocks.dirt);

		generate2(world, rand, i, j, k);
		return true;
	}

	public boolean generate2(World world, Random rand, int i, int j, int k) {
		world.setBlock(i + 8, j + 1, k + 15, Blocks.dirt);
		world.setBlock(i + 8, j + 1, k + 16, Blocks.dirt);
		world.setBlock(i + 8, j + 1, k + 17, Blocks.dirt);
		world.setBlock(i + 8, j + 1, k + 18, Blocks.dirt);
		world.setBlock(i + 8, j + 1, k + 19, Blocks.dirt);
		world.setBlock(i + 8, j + 1, k + 20, Blocks.dirt);
		world.setBlock(i + 8, j + 1, k + 21, Blocks.dirt);
		world.setBlock(i + 8, j + 1, k + 22, Blocks.dirt);
		world.setBlock(i + 8, j + 1, k + 23, Blocks.dirt);
		world.setBlock(i + 8, j + 1, k + 24, Blocks.dirt);
		world.setBlock(i + 8, j + 1, k + 25, Blocks.dirt);
		world.setBlock(i + 8, j + 1, k + 26, Blocks.dirt);
		world.setBlock(i + 8, j + 1, k + 27, Blocks.dirt);
		world.setBlock(i + 8, j + 1, k + 28, Blocks.dirt);
		world.setBlock(i + 8, j + 1, k + 29, Blocks.dirt);
		world.setBlock(i + 8, j + 1, k + 30, Blocks.dirt);
		world.setBlock(i + 8, j + 1, k + 31, Blocks.dirt);
		world.setBlock(i + 8, j + 1, k + 32, Blocks.dirt);
		world.setBlock(i + 8, j + 1, k + 33, Blocks.dirt);
		world.setBlock(i + 8, j + 1, k + 34, Blocks.dirt);
		world.setBlock(i + 8, j + 1, k + 35, Blocks.dirt);
		world.setBlock(i + 8, j + 1, k + 36, Blocks.dirt);
		world.setBlock(i + 8, j + 1, k + 37, Blocks.dirt);
		world.setBlock(i + 8, j + 1, k + 38, Blocks.dirt);
		world.setBlock(i + 8, j + 1, k + 39, Blocks.dirt);
		world.setBlock(i + 8, j + 1, k + 40, Blocks.dirt);
		world.setBlock(i + 8, j + 1, k + 41, Blocks.dirt);
		world.setBlock(i + 8, j + 1, k + 42, Blocks.dirt);
		world.setBlock(i + 8, j + 1, k + 43, Blocks.dirt);
		world.setBlock(i + 8, j + 1, k + 44, Blocks.dirt);
		world.setBlock(i + 8, j + 2, k + 0, Blocks.dirt);
		world.setBlock(i + 8, j + 2, k + 1, Blocks.dirt);
		world.setBlock(i + 8, j + 2, k + 2, Blocks.dirt);
		world.setBlock(i + 8, j + 2, k + 3, Blocks.dirt);
		world.setBlock(i + 8, j + 2, k + 4, Blocks.dirt);
		world.setBlock(i + 8, j + 2, k + 5, Blocks.dirt);
		world.setBlock(i + 8, j + 2, k + 6, Blocks.dirt);
		world.setBlock(i + 8, j + 2, k + 7, Blocks.dirt);
		world.setBlock(i + 8, j + 2, k + 8, Blocks.dirt);
		world.setBlock(i + 8, j + 2, k + 9, Blocks.dirt);
		world.setBlock(i + 8, j + 2, k + 10, Blocks.dirt);
		world.setBlock(i + 8, j + 2, k + 11, Blocks.dirt);
		world.setBlock(i + 8, j + 2, k + 12, Blocks.dirt);
		world.setBlock(i + 8, j + 2, k + 13, Blocks.dirt);
		world.setBlock(i + 8, j + 2, k + 14, Blocks.dirt);
		world.setBlock(i + 8, j + 2, k + 15, Blocks.dirt);
		world.setBlock(i + 8, j + 2, k + 16, Blocks.dirt);
		world.setBlock(i + 8, j + 2, k + 17, Blocks.dirt);
		world.setBlock(i + 8, j + 2, k + 18, Blocks.dirt);
		world.setBlock(i + 8, j + 2, k + 19, Blocks.dirt);
		world.setBlock(i + 8, j + 2, k + 20, Blocks.dirt);
		world.setBlock(i + 8, j + 2, k + 21, Blocks.dirt);
		world.setBlock(i + 8, j + 2, k + 22, Blocks.dirt);
		world.setBlock(i + 8, j + 2, k + 23, Blocks.dirt);
		world.setBlock(i + 8, j + 2, k + 24, Blocks.dirt);
		world.setBlock(i + 8, j + 2, k + 25, Blocks.dirt);
		world.setBlock(i + 8, j + 2, k + 26, Blocks.dirt);
		world.setBlock(i + 8, j + 2, k + 27, Blocks.dirt);
		world.setBlock(i + 8, j + 2, k + 28, Blocks.dirt);
		world.setBlock(i + 8, j + 2, k + 29, Blocks.dirt);
		world.setBlock(i + 8, j + 2, k + 30, Blocks.dirt);
		world.setBlock(i + 8, j + 2, k + 31, Blocks.dirt);
		world.setBlock(i + 8, j + 2, k + 32, Blocks.dirt);
		world.setBlock(i + 8, j + 2, k + 33, Blocks.dirt);
		world.setBlock(i + 8, j + 2, k + 34, Blocks.dirt);
		world.setBlock(i + 8, j + 2, k + 35, Blocks.dirt);
		world.setBlock(i + 8, j + 2, k + 36, Blocks.dirt);
		world.setBlock(i + 8, j + 2, k + 37, Blocks.dirt);
		world.setBlock(i + 8, j + 2, k + 38, Blocks.dirt);
		world.setBlock(i + 8, j + 2, k + 39, Blocks.dirt);
		world.setBlock(i + 8, j + 2, k + 40, Blocks.dirt);
		world.setBlock(i + 8, j + 2, k + 41, Blocks.dirt);
		world.setBlock(i + 8, j + 2, k + 42, Blocks.dirt);
		world.setBlock(i + 8, j + 2, k + 43, Blocks.dirt);
		world.setBlock(i + 8, j + 2, k + 44, Blocks.dirt);
		world.setBlock(i + 8, j + 3, k + 0, Blocks.grass);
		world.setBlock(i + 8, j + 3, k + 1, Blocks.grass);
		world.setBlock(i + 8, j + 3, k + 2, Blocks.grass);
		world.setBlock(i + 8, j + 3, k + 3, Blocks.grass);
		world.setBlock(i + 8, j + 3, k + 4, Blocks.grass);
		world.setBlock(i + 8, j + 3, k + 5, Blocks.grass);
		world.setBlock(i + 8, j + 3, k + 6, Blocks.grass);
		world.setBlock(i + 8, j + 3, k + 7, Blocks.grass);
		world.setBlock(i + 8, j + 3, k + 8, Blocks.grass);
		world.setBlock(i + 8, j + 3, k + 9, Blocks.grass);
		world.setBlock(i + 8, j + 3, k + 10, Blocks.grass);
		world.setBlock(i + 8, j + 3, k + 11, Blocks.grass);
		world.setBlock(i + 8, j + 3, k + 12, Blocks.grass);
		world.setBlock(i + 8, j + 3, k + 13, Blocks.grass);
		world.setBlock(i + 8, j + 3, k + 14, Blocks.grass);
		world.setBlock(i + 8, j + 3, k + 15, Blocks.grass);
		world.setBlock(i + 8, j + 3, k + 16, Blocks.grass);
		world.setBlock(i + 8, j + 3, k + 17, Blocks.grass);
		world.setBlock(i + 8, j + 3, k + 18, Blocks.grass);
		world.setBlock(i + 8, j + 3, k + 19, Blocks.grass);
		world.setBlock(i + 8, j + 3, k + 20, Blocks.grass);
		world.setBlock(i + 8, j + 3, k + 21, Blocks.grass);
		world.setBlock(i + 8, j + 3, k + 22, Blocks.grass);
		world.setBlock(i + 8, j + 3, k + 23, Blocks.grass);
		world.setBlock(i + 8, j + 3, k + 24, Blocks.grass);
		world.setBlock(i + 8, j + 3, k + 25, Blocks.grass);
		world.setBlock(i + 8, j + 3, k + 26, Blocks.grass);
		world.setBlock(i + 8, j + 3, k + 27, Blocks.grass);
		world.setBlock(i + 8, j + 3, k + 28, Blocks.grass);
		world.setBlock(i + 8, j + 3, k + 29, Blocks.grass);
		world.setBlock(i + 8, j + 3, k + 30, Blocks.grass);
		world.setBlock(i + 8, j + 3, k + 31, Blocks.grass);
		world.setBlock(i + 8, j + 3, k + 32, Blocks.grass);
		world.setBlock(i + 8, j + 3, k + 33, Blocks.grass);
		world.setBlock(i + 8, j + 3, k + 34, Blocks.grass);
		world.setBlock(i + 8, j + 3, k + 35, Blocks.grass);
		world.setBlock(i + 8, j + 3, k + 36, Blocks.grass);
		world.setBlock(i + 8, j + 3, k + 37, Blocks.grass);
		world.setBlock(i + 8, j + 3, k + 38, Blocks.grass);
		world.setBlock(i + 8, j + 3, k + 39, Blocks.grass);
		world.setBlock(i + 8, j + 3, k + 40, Blocks.grass);
		world.setBlock(i + 8, j + 3, k + 41, Blocks.grass);
		world.setBlock(i + 8, j + 3, k + 42, Blocks.grass);
		world.setBlock(i + 8, j + 3, k + 43, Blocks.grass);
		world.setBlock(i + 8, j + 3, k + 44, Blocks.grass);
		world.setBlock(i + 9, j + 0, k + 0, Blocks.bedrock);
		world.setBlock(i + 9, j + 0, k + 1, Blocks.bedrock);
		world.setBlock(i + 9, j + 0, k + 2, Blocks.bedrock);
		world.setBlock(i + 9, j + 0, k + 3, Blocks.bedrock);
		world.setBlock(i + 9, j + 0, k + 4, Blocks.bedrock);
		world.setBlock(i + 9, j + 0, k + 5, Blocks.bedrock);
		world.setBlock(i + 9, j + 0, k + 6, Blocks.bedrock);
		world.setBlock(i + 9, j + 0, k + 7, Blocks.bedrock);
		world.setBlock(i + 9, j + 0, k + 8, Blocks.bedrock);
		world.setBlock(i + 9, j + 0, k + 9, Blocks.bedrock);
		world.setBlock(i + 9, j + 0, k + 10, Blocks.bedrock);
		world.setBlock(i + 9, j + 0, k + 11, Blocks.bedrock);
		world.setBlock(i + 9, j + 0, k + 12, Blocks.bedrock);
		world.setBlock(i + 9, j + 0, k + 13, Blocks.bedrock);
		world.setBlock(i + 9, j + 0, k + 14, Blocks.bedrock);
		world.setBlock(i + 9, j + 0, k + 15, Blocks.bedrock);
		world.setBlock(i + 9, j + 0, k + 16, Blocks.bedrock);
		world.setBlock(i + 9, j + 0, k + 17, Blocks.bedrock);
		world.setBlock(i + 9, j + 0, k + 18, Blocks.bedrock);
		world.setBlock(i + 9, j + 0, k + 19, Blocks.bedrock);
		world.setBlock(i + 9, j + 0, k + 20, Blocks.bedrock);
		world.setBlock(i + 9, j + 0, k + 21, Blocks.bedrock);
		world.setBlock(i + 9, j + 0, k + 22, Blocks.bedrock);
		world.setBlock(i + 9, j + 0, k + 23, Blocks.bedrock);
		world.setBlock(i + 9, j + 0, k + 24, Blocks.bedrock);
		world.setBlock(i + 9, j + 0, k + 25, Blocks.bedrock);
		world.setBlock(i + 9, j + 0, k + 26, Blocks.bedrock);
		world.setBlock(i + 9, j + 0, k + 27, Blocks.bedrock);
		world.setBlock(i + 9, j + 0, k + 28, Blocks.bedrock);
		world.setBlock(i + 9, j + 0, k + 29, Blocks.bedrock);
		world.setBlock(i + 9, j + 0, k + 30, Blocks.bedrock);
		world.setBlock(i + 9, j + 0, k + 31, Blocks.bedrock);
		world.setBlock(i + 9, j + 0, k + 32, Blocks.bedrock);
		world.setBlock(i + 9, j + 0, k + 33, Blocks.bedrock);
		world.setBlock(i + 9, j + 0, k + 34, Blocks.bedrock);
		world.setBlock(i + 9, j + 0, k + 35, Blocks.bedrock);
		world.setBlock(i + 9, j + 0, k + 36, Blocks.bedrock);
		world.setBlock(i + 9, j + 0, k + 37, Blocks.bedrock);
		world.setBlock(i + 9, j + 0, k + 38, Blocks.bedrock);
		world.setBlock(i + 9, j + 0, k + 39, Blocks.bedrock);
		world.setBlock(i + 9, j + 0, k + 40, Blocks.bedrock);
		world.setBlock(i + 9, j + 0, k + 41, Blocks.bedrock);
		world.setBlock(i + 9, j + 0, k + 42, Blocks.bedrock);
		world.setBlock(i + 9, j + 0, k + 43, Blocks.bedrock);
		world.setBlock(i + 9, j + 0, k + 44, Blocks.bedrock);
		world.setBlock(i + 9, j + 1, k + 0, Blocks.dirt);
		world.setBlock(i + 9, j + 1, k + 1, Blocks.dirt);
		world.setBlock(i + 9, j + 1, k + 2, Blocks.dirt);
		world.setBlock(i + 9, j + 1, k + 3, Blocks.dirt);
		world.setBlock(i + 9, j + 1, k + 4, Blocks.dirt);
		world.setBlock(i + 9, j + 1, k + 5, Blocks.dirt);
		world.setBlock(i + 9, j + 1, k + 6, Blocks.dirt);
		world.setBlock(i + 9, j + 1, k + 7, Blocks.dirt);
		world.setBlock(i + 9, j + 1, k + 8, Blocks.dirt);
		world.setBlock(i + 9, j + 1, k + 9, Blocks.dirt);
		world.setBlock(i + 9, j + 1, k + 10, Blocks.dirt);
		world.setBlock(i + 9, j + 1, k + 11, Blocks.dirt);
		world.setBlock(i + 9, j + 1, k + 12, Blocks.dirt);
		world.setBlock(i + 9, j + 1, k + 13, Blocks.dirt);
		world.setBlock(i + 9, j + 1, k + 14, Blocks.dirt);
		world.setBlock(i + 9, j + 1, k + 15, Blocks.dirt);
		world.setBlock(i + 9, j + 1, k + 16, Blocks.dirt);
		world.setBlock(i + 9, j + 1, k + 17, Blocks.dirt);
		world.setBlock(i + 9, j + 1, k + 18, Blocks.dirt);
		world.setBlock(i + 9, j + 1, k + 19, Blocks.dirt);
		world.setBlock(i + 9, j + 1, k + 20, Blocks.dirt);
		world.setBlock(i + 9, j + 1, k + 21, Blocks.dirt);
		world.setBlock(i + 9, j + 1, k + 22, Blocks.dirt);
		world.setBlock(i + 9, j + 1, k + 23, Blocks.dirt);
		world.setBlock(i + 9, j + 1, k + 24, Blocks.dirt);
		world.setBlock(i + 9, j + 1, k + 25, Blocks.dirt);
		world.setBlock(i + 9, j + 1, k + 26, Blocks.dirt);
		world.setBlock(i + 9, j + 1, k + 27, Blocks.dirt);
		world.setBlock(i + 9, j + 1, k + 28, Blocks.dirt);
		world.setBlock(i + 9, j + 1, k + 29, Blocks.dirt);
		world.setBlock(i + 9, j + 1, k + 30, Blocks.dirt);
		world.setBlock(i + 9, j + 1, k + 31, Blocks.dirt);
		world.setBlock(i + 9, j + 1, k + 32, Blocks.dirt);
		world.setBlock(i + 9, j + 1, k + 33, Blocks.dirt);
		world.setBlock(i + 9, j + 1, k + 34, Blocks.dirt);
		world.setBlock(i + 9, j + 1, k + 35, Blocks.dirt);
		world.setBlock(i + 9, j + 1, k + 36, Blocks.dirt);
		world.setBlock(i + 9, j + 1, k + 37, Blocks.dirt);
		world.setBlock(i + 9, j + 1, k + 38, Blocks.dirt);
		world.setBlock(i + 9, j + 1, k + 39, Blocks.dirt);
		world.setBlock(i + 9, j + 1, k + 40, Blocks.dirt);
		world.setBlock(i + 9, j + 1, k + 41, Blocks.dirt);
		world.setBlock(i + 9, j + 1, k + 42, Blocks.dirt);
		world.setBlock(i + 9, j + 1, k + 43, Blocks.dirt);
		world.setBlock(i + 9, j + 1, k + 44, Blocks.dirt);
		world.setBlock(i + 9, j + 2, k + 0, Blocks.dirt);
		world.setBlock(i + 9, j + 2, k + 1, Blocks.dirt);
		world.setBlock(i + 9, j + 2, k + 2, Blocks.dirt);
		world.setBlock(i + 9, j + 2, k + 3, Blocks.dirt);
		world.setBlock(i + 9, j + 2, k + 4, Blocks.dirt);
		world.setBlock(i + 9, j + 2, k + 5, Blocks.dirt);
		world.setBlock(i + 9, j + 2, k + 6, Blocks.dirt);
		world.setBlock(i + 9, j + 2, k + 7, Blocks.dirt);
		world.setBlock(i + 9, j + 2, k + 8, Blocks.dirt);
		world.setBlock(i + 9, j + 2, k + 9, Blocks.dirt);
		world.setBlock(i + 9, j + 2, k + 10, Blocks.dirt);
		world.setBlock(i + 9, j + 2, k + 11, Blocks.dirt);
		world.setBlock(i + 9, j + 2, k + 12, Blocks.dirt);
		world.setBlock(i + 9, j + 2, k + 13, Blocks.dirt);
		world.setBlock(i + 9, j + 2, k + 14, Blocks.dirt);
		world.setBlock(i + 9, j + 2, k + 15, Blocks.dirt);
		world.setBlock(i + 9, j + 2, k + 16, Blocks.dirt);
		world.setBlock(i + 9, j + 2, k + 17, Blocks.dirt);
		world.setBlock(i + 9, j + 2, k + 18, Blocks.dirt);
		world.setBlock(i + 9, j + 2, k + 19, Blocks.dirt);
		world.setBlock(i + 9, j + 2, k + 20, Blocks.dirt);
		world.setBlock(i + 9, j + 2, k + 21, Blocks.dirt);
		world.setBlock(i + 9, j + 2, k + 22, Blocks.dirt);
		world.setBlock(i + 9, j + 2, k + 23, Blocks.dirt);
		world.setBlock(i + 9, j + 2, k + 24, Blocks.dirt);
		world.setBlock(i + 9, j + 2, k + 25, Blocks.dirt);
		world.setBlock(i + 9, j + 2, k + 26, Blocks.dirt);
		world.setBlock(i + 9, j + 2, k + 27, Blocks.dirt);
		world.setBlock(i + 9, j + 2, k + 28, Blocks.dirt);
		world.setBlock(i + 9, j + 2, k + 29, Blocks.dirt);
		world.setBlock(i + 9, j + 2, k + 30, Blocks.dirt);
		world.setBlock(i + 9, j + 2, k + 31, Blocks.dirt);
		world.setBlock(i + 9, j + 2, k + 32, Blocks.dirt);
		world.setBlock(i + 9, j + 2, k + 33, Blocks.dirt);
		world.setBlock(i + 9, j + 2, k + 34, Blocks.dirt);
		world.setBlock(i + 9, j + 2, k + 35, Blocks.dirt);
		world.setBlock(i + 9, j + 2, k + 36, Blocks.dirt);
		world.setBlock(i + 9, j + 2, k + 37, Blocks.dirt);
		world.setBlock(i + 9, j + 2, k + 38, Blocks.dirt);
		world.setBlock(i + 9, j + 2, k + 39, Blocks.dirt);
		world.setBlock(i + 9, j + 2, k + 40, Blocks.dirt);
		world.setBlock(i + 9, j + 2, k + 41, Blocks.dirt);
		world.setBlock(i + 9, j + 2, k + 42, Blocks.dirt);
		world.setBlock(i + 9, j + 2, k + 43, Blocks.dirt);
		world.setBlock(i + 9, j + 2, k + 44, Blocks.dirt);
		world.setBlock(i + 9, j + 3, k + 0, Blocks.grass);
		world.setBlock(i + 9, j + 3, k + 1, Blocks.grass);
		world.setBlock(i + 9, j + 3, k + 2, Blocks.grass);
		world.setBlock(i + 9, j + 3, k + 3, Blocks.grass);
		world.setBlock(i + 9, j + 3, k + 4, Blocks.grass);
		world.setBlock(i + 9, j + 3, k + 5, Blocks.grass);
		world.setBlock(i + 9, j + 3, k + 6, Blocks.grass);
		world.setBlock(i + 9, j + 3, k + 7, Blocks.grass);
		world.setBlock(i + 9, j + 3, k + 8, Blocks.dirt);
		world.setBlock(i + 9, j + 3, k + 9, Blocks.dirt);
		world.setBlock(i + 9, j + 3, k + 10, Blocks.dirt);
		world.setBlock(i + 9, j + 3, k + 11, Blocks.grass);
		world.setBlock(i + 9, j + 3, k + 12, Blocks.grass);
		world.setBlock(i + 9, j + 3, k + 13, Blocks.grass);
		world.setBlock(i + 9, j + 3, k + 14, Blocks.grass);
		world.setBlock(i + 9, j + 3, k + 15, Blocks.grass);
		world.setBlock(i + 9, j + 3, k + 16, Blocks.grass);
		world.setBlock(i + 9, j + 3, k + 17, Blocks.grass);
		world.setBlock(i + 9, j + 3, k + 18, Blocks.grass);
		world.setBlock(i + 9, j + 3, k + 19, Blocks.grass);
		world.setBlock(i + 9, j + 3, k + 20, Blocks.grass);
		world.setBlock(i + 9, j + 3, k + 21, Blocks.grass);
		world.setBlock(i + 9, j + 3, k + 22, Blocks.grass);
		world.setBlock(i + 9, j + 3, k + 23, Blocks.grass);
		world.setBlock(i + 9, j + 3, k + 24, Blocks.grass);
		world.setBlock(i + 9, j + 3, k + 25, Blocks.grass);
		world.setBlock(i + 9, j + 3, k + 26, Blocks.grass);
		world.setBlock(i + 9, j + 3, k + 27, Blocks.grass);
		world.setBlock(i + 9, j + 3, k + 28, Blocks.grass);
		world.setBlock(i + 9, j + 3, k + 29, Blocks.grass);
		world.setBlock(i + 9, j + 3, k + 30, Blocks.grass);
		world.setBlock(i + 9, j + 3, k + 31, Blocks.grass);
		world.setBlock(i + 9, j + 3, k + 32, Blocks.grass);
		world.setBlock(i + 9, j + 3, k + 33, Blocks.grass);
		world.setBlock(i + 9, j + 3, k + 34, Blocks.grass);
		world.setBlock(i + 9, j + 3, k + 35, Blocks.grass);
		world.setBlock(i + 9, j + 3, k + 36, Blocks.dirt);
		world.setBlock(i + 9, j + 3, k + 37, Blocks.dirt);
		world.setBlock(i + 9, j + 3, k + 38, Blocks.dirt);
		world.setBlock(i + 9, j + 3, k + 39, Blocks.grass);
		world.setBlock(i + 9, j + 3, k + 40, Blocks.grass);
		world.setBlock(i + 9, j + 3, k + 41, Blocks.grass);
		world.setBlock(i + 9, j + 3, k + 42, Blocks.grass);
		world.setBlock(i + 9, j + 3, k + 43, Blocks.grass);
		world.setBlock(i + 9, j + 3, k + 44, Blocks.grass);
		world.setBlock(i + 9, j + 4, k + 8, Blocks.brick_block);
		world.setBlock(i + 9, j + 4, k + 9, Blocks.brick_block);
		world.setBlock(i + 9, j + 4, k + 10, Blocks.brick_block);
		world.setBlock(i + 9, j + 4, k + 36, Blocks.brick_block);
		world.setBlock(i + 9, j + 4, k + 37, Blocks.brick_block);
		world.setBlock(i + 9, j + 4, k + 38, Blocks.brick_block);
		world.setBlock(i + 9, j + 5, k + 8, Blocks.brick_block);
		world.setBlock(i + 9, j + 5, k + 9, Blocks.brick_block);
		world.setBlock(i + 9, j + 5, k + 10, Blocks.brick_block);
		world.setBlock(i + 9, j + 5, k + 36, Blocks.brick_block);
		world.setBlock(i + 9, j + 5, k + 37, Blocks.brick_block);
		world.setBlock(i + 9, j + 5, k + 38, Blocks.brick_block);
		world.setBlock(i + 9, j + 6, k + 8, Blocks.brick_block);
		world.setBlock(i + 9, j + 6, k + 9, Blocks.brick_block);
		world.setBlock(i + 9, j + 6, k + 10, Blocks.brick_block);
		world.setBlock(i + 9, j + 6, k + 36, Blocks.brick_block);
		world.setBlock(i + 9, j + 6, k + 37, Blocks.brick_block);
		world.setBlock(i + 9, j + 6, k + 38, Blocks.brick_block);
		world.setBlock(i + 9, j + 7, k + 8, Blocks.brick_block);
		world.setBlock(i + 9, j + 7, k + 9, Blocks.brick_block);
		world.setBlock(i + 9, j + 7, k + 10, Blocks.brick_block);
		world.setBlock(i + 9, j + 7, k + 36, Blocks.brick_block);
		world.setBlock(i + 9, j + 7, k + 37, Blocks.brick_block);
		world.setBlock(i + 9, j + 7, k + 38, Blocks.brick_block);
		world.setBlock(i + 9, j + 8, k + 8, Blocks.brick_block);
		world.setBlock(i + 9, j + 8, k + 9, Blocks.brick_block);
		world.setBlock(i + 9, j + 8, k + 10, Blocks.brick_block);
