/*
*** MADE BY MITHION'S .SCHEMATIC TO JAVA CONVERTING TOOL v1.6 ***
*/

package FunMod.struturas;
import java.util.Random;

import net.minecraft.block.Block;
import net.minecraft.world.World;
import net.minecraft.world.gen.feature.WorldGenerator;

public class WorldGenCasaDoPokemon extends WorldGenerator
{
	public WorldGenCasaDoPokemon() { }
	protected int[] GetValidSpawnBlocks() {
		  return new int[] {
		   Block.stone.blockID,
		   Block.grass.blockID,
		   Block.dirt.blockID
		  };
		 }

		  public boolean LocationIsValidSpawn(World world, int i, int j, int k){
		  int distanceToAir = 0;
		  int checkID = world.getBlockId(i, j, k);

		   while (checkID != 0){
		   distanceToAir++;
		   checkID = world.getBlockId(i, j + distanceToAir, k);
		  }

		   if (distanceToAir > 0){
		   return false;
		  }
		  j += distanceToAir - 1;

		   int blockID = world.getBlockId(i, j, k);
		  int blockIDAbove = world.getBlockId(i, j+1, k);
		  int blockIDBelow = world.getBlockId(i, j-1, k);
		  for (int x : GetValidSpawnBlocks()){
		   if (blockIDAbove != 0){
		    return false;
		   }
		   if (blockID == x){
		    return true;
		   }else if (blockID == Block.snow.blockID && blockIDBelow == x){
		    return true;
		   }
		  }
		  return false;
		 }

		

		
	public boolean generate(World world, Random rand, int i, int j, int k) {
		if(!LocationIsValidSpawn(world, i, j, k) || !LocationIsValidSpawn(world, i + 4, j, k) || !LocationIsValidSpawn(world, i + 4, j, k + 4) || !LocationIsValidSpawn(world, i, j, k + 4))
		  {
		   return false;
		  }
		world.setBlock(i + 0, j + 0, k + 0, 2);
		world.setBlock(i + 0, j + 0, k + 1, 2);
		world.setBlock(i + 0, j + 0, k + 2, 2);
		world.setBlock(i + 0, j + 0, k + 3, 3);
		world.setBlock(i + 0, j + 0, k + 4, 3);
		world.setBlock(i + 0, j + 0, k + 5, 3);
		world.setBlock(i + 0, j + 0, k + 6, 3);
		world.setBlock(i + 0, j + 0, k + 7, 3);
		world.setBlock(i + 0, j + 0, k + 8, 3);
		world.setBlock(i + 0, j + 0, k + 9, 3);
		world.setBlock(i + 0, j + 0, k + 10, 3);
		world.setBlock(i + 0, j + 0, k + 11, 3);
		world.setBlock(i + 0, j + 0, k + 12, 3);
		world.setBlock(i + 0, j + 0, k + 13, 3);
		world.setBlock(i + 0, j + 0, k + 14, 3);
		world.setBlock(i + 0, j + 0, k + 15, 3);
		world.setBlock(i + 0, j + 0, k + 16, 3);
		world.setBlock(i + 0, j + 0, k + 17, 3);
		world.setBlock(i + 0, j + 0, k + 18, 3);
		world.setBlock(i + 0, j + 0, k + 19, 2);
		world.setBlock(i + 0, j + 0, k + 20, 2);
		world.setBlock(i + 0, j + 1, k + 0, 0);
		world.setBlock(i + 0, j + 1, k + 1, 0);
		world.setBlock(i + 0, j + 1, k + 2, 0);
		world.setBlock(i + 0, j + 1, k + 3, 35);
		world.setBlock(i + 0, j + 1, k + 4, 35);
		world.setBlock(i + 0, j + 1, k + 5, 35);
		world.setBlock(i + 0, j + 1, k + 6, 35);
		world.setBlock(i + 0, j + 1, k + 7, 35);
		world.setBlock(i + 0, j + 1, k + 8, 35);
		world.setBlock(i + 0, j + 1, k + 9, 35);
		world.setBlock(i + 0, j + 1, k + 10, 35);
		world.setBlock(i + 0, j + 1, k + 11, 35);
		world.setBlock(i + 0, j + 1, k + 12, 35);
		world.setBlock(i + 0, j + 1, k + 13, 35);
		world.setBlock(i + 0, j + 1, k + 14, 35);
		world.setBlock(i + 0, j + 1, k + 15, 35);
		world.setBlock(i + 0, j + 1, k + 16, 35);
		world.setBlock(i + 0, j + 1, k + 17, 35);
		world.setBlock(i + 0, j + 1, k + 18, 35);
		world.setBlock(i + 0, j + 1, k + 19, 0);
		world.setBlock(i + 0, j + 1, k + 20, 0);
		world.setBlock(i + 0, j + 2, k + 0, 0);
		world.setBlock(i + 0, j + 2, k + 1, 0);
		world.setBlock(i + 0, j + 2, k + 2, 0);
		world.setBlock(i + 0, j + 2, k + 3, 35);
		world.setBlock(i + 0, j + 2, k + 4, 35);
		world.setBlock(i + 0, j + 2, k + 5, 35);
		world.setBlock(i + 0, j + 2, k + 6, 35);
		world.setBlock(i + 0, j + 2, k + 7, 35);
		world.setBlock(i + 0, j + 2, k + 8, 35);
		world.setBlock(i + 0, j + 2, k + 9, 35);
		world.setBlock(i + 0, j + 2, k + 10, 35);
		world.setBlock(i + 0, j + 2, k + 11, 35);
		world.setBlock(i + 0, j + 2, k + 12, 35);
		world.setBlock(i + 0, j + 2, k + 13, 35);
		world.setBlock(i + 0, j + 2, k + 14, 35);
		world.setBlock(i + 0, j + 2, k + 15, 35);
		world.setBlock(i + 0, j + 2, k + 16, 35);
		world.setBlock(i + 0, j + 2, k + 17, 35);
		world.setBlock(i + 0, j + 2, k + 18, 35);
		world.setBlock(i + 0, j + 2, k + 19, 0);
		world.setBlock(i + 0, j + 2, k + 20, 0);
		world.setBlock(i + 0, j + 3, k + 0, 0);
		world.setBlock(i + 0, j + 3, k + 1, 0);
		world.setBlock(i + 0, j + 3, k + 2, 0);
		world.setBlock(i + 0, j + 3, k + 3, 35);
		world.setBlock(i + 0, j + 3, k + 4, 35);
		world.setBlock(i + 0, j + 3, k + 5, 35);
		world.setBlock(i + 0, j + 3, k + 6, 35);
		world.setBlock(i + 0, j + 3, k + 7, 35);
		world.setBlock(i + 0, j + 3, k + 8, 35);
		world.setBlock(i + 0, j + 3, k + 9, 35);
		world.setBlock(i + 0, j + 3, k + 10, 35);
		world.setBlock(i + 0, j + 3, k + 11, 35);
		world.setBlock(i + 0, j + 3, k + 12, 35);
		world.setBlock(i + 0, j + 3, k + 13, 35);
		world.setBlock(i + 0, j + 3, k + 14, 35);
		world.setBlock(i + 0, j + 3, k + 15, 35);
		world.setBlock(i + 0, j + 3, k + 16, 35);
		world.setBlock(i + 0, j + 3, k + 17, 35);
		world.setBlock(i + 0, j + 3, k + 18, 35);
		world.setBlock(i + 0, j + 3, k + 19, 0);
		world.setBlock(i + 0, j + 3, k + 20, 0);
		world.setBlock(i + 0, j + 4, k + 0, 0);
		world.setBlock(i + 0, j + 4, k + 1, 0);
		world.setBlock(i + 0, j + 4, k + 2, 0);
		world.setBlock(i + 0, j + 4, k + 3, 35);
		world.setBlock(i + 0, j + 4, k + 4, 35);
		world.setBlock(i + 0, j + 4, k + 5, 35);
		world.setBlock(i + 0, j + 4, k + 6, 35);
		world.setBlock(i + 0, j + 4, k + 7, 35);
		world.setBlock(i + 0, j + 4, k + 8, 35);
		world.setBlock(i + 0, j + 4, k + 9, 35);
		world.setBlock(i + 0, j + 4, k + 10, 35);
		world.setBlock(i + 0, j + 4, k + 11, 35);
		world.setBlock(i + 0, j + 4, k + 12, 35);
		world.setBlock(i + 0, j + 4, k + 13, 35);
		world.setBlock(i + 0, j + 4, k + 14, 35);
		world.setBlock(i + 0, j + 4, k + 15, 35);
		world.setBlock(i + 0, j + 4, k + 16, 35);
		world.setBlock(i + 0, j + 4, k + 17, 35);
		world.setBlock(i + 0, j + 4, k + 18, 35);
		world.setBlock(i + 0, j + 4, k + 19, 0);
		world.setBlock(i + 0, j + 4, k + 20, 0);
		world.setBlock(i + 0, j + 5, k + 0, 0);
		world.setBlock(i + 0, j + 5, k + 1, 0);
		world.setBlock(i + 0, j + 5, k + 2, 0);
		world.setBlock(i + 0, j + 5, k + 3, 35);
		world.setBlock(i + 0, j + 5, k + 4, 35);
		world.setBlock(i + 0, j + 5, k + 5, 35);
		world.setBlock(i + 0, j + 5, k + 6, 35);
		world.setBlock(i + 0, j + 5, k + 7, 35);
		world.setBlock(i + 0, j + 5, k + 8, 35);
		world.setBlock(i + 0, j + 5, k + 9, 35);
		world.setBlock(i + 0, j + 5, k + 10, 35);
		world.setBlock(i + 0, j + 5, k + 11, 35);
		world.setBlock(i + 0, j + 5, k + 12, 35);
		world.setBlock(i + 0, j + 5, k + 13, 35);
		world.setBlock(i + 0, j + 5, k + 14, 35);
		world.setBlock(i + 0, j + 5, k + 15, 35);
		world.setBlock(i + 0, j + 5, k + 16, 35);
		world.setBlock(i + 0, j + 5, k + 17, 35);
		world.setBlock(i + 0, j + 5, k + 18, 35);
		world.setBlock(i + 0, j + 5, k + 19, 0);
		world.setBlock(i + 0, j + 5, k + 20, 0);
		world.setBlock(i + 0, j + 6, k + 0, 0);
		world.setBlock(i + 0, j + 6, k + 1, 0);
		world.setBlock(i + 0, j + 6, k + 2, 0);
		world.setBlock(i + 0, j + 6, k + 3, 35);
		world.setBlock(i + 0, j + 6, k + 4, 35);
		world.setBlock(i + 0, j + 6, k + 5, 35);
		world.setBlock(i + 0, j + 6, k + 6, 35);
		world.setBlock(i + 0, j + 6, k + 7, 35);
		world.setBlock(i + 0, j + 6, k + 8, 35);
		world.setBlock(i + 0, j + 6, k + 9, 35);
		world.setBlock(i + 0, j + 6, k + 10, 35);
		world.setBlock(i + 0, j + 6, k + 11, 35);
		world.setBlock(i + 0, j + 6, k + 12, 35);
		world.setBlock(i + 0, j + 6, k + 13, 35);
		world.setBlock(i + 0, j + 6, k + 14, 35);
		world.setBlock(i + 0, j + 6, k + 15, 35);
		world.setBlock(i + 0, j + 6, k + 16, 35);
		world.setBlock(i + 0, j + 6, k + 17, 35);
		world.setBlock(i + 0, j + 6, k + 18, 35);
		world.setBlock(i + 0, j + 6, k + 19, 0);
		world.setBlock(i + 0, j + 6, k + 20, 0);
		world.setBlock(i + 0, j + 7, k + 0, 0);
		world.setBlock(i + 0, j + 7, k + 1, 0);
		world.setBlock(i + 0, j + 7, k + 2, 0);
		world.setBlock(i + 0, j + 7, k + 3, 35);
		world.setBlock(i + 0, j + 7, k + 4, 102);
		world.setBlock(i + 0, j + 7, k + 5, 102);
		world.setBlock(i + 0, j + 7, k + 6, 35);
		world.setBlock(i + 0, j + 7, k + 7, 102);
		world.setBlock(i + 0, j + 7, k + 8, 102);
		world.setBlock(i + 0, j + 7, k + 9, 35);
		world.setBlock(i + 0, j + 7, k + 10, 102);
		world.setBlock(i + 0, j + 7, k + 11, 102);
		world.setBlock(i + 0, j + 7, k + 12, 35);
		world.setBlock(i + 0, j + 7, k + 13, 102);
		world.setBlock(i + 0, j + 7, k + 14, 102);
		world.setBlock(i + 0, j + 7, k + 15, 35);
		world.setBlock(i + 0, j + 7, k + 16, 102);
		world.setBlock(i + 0, j + 7, k + 17, 102);
		world.setBlock(i + 0, j + 7, k + 18, 35);
		world.setBlock(i + 0, j + 7, k + 19, 0);
		world.setBlock(i + 0, j + 7, k + 20, 0);
		world.setBlock(i + 0, j + 8, k + 0, 0);
		world.setBlock(i + 0, j + 8, k + 1, 0);
		world.setBlock(i + 0, j + 8, k + 2, 0);
		world.setBlock(i + 0, j + 8, k + 3, 35);
		world.setBlock(i + 0, j + 8, k + 4, 102);
		world.setBlock(i + 0, j + 8, k + 5, 102);
		world.setBlock(i + 0, j + 8, k + 6, 35);
		world.setBlock(i + 0, j + 8, k + 7, 102);
		world.setBlock(i + 0, j + 8, k + 8, 102);
		world.setBlock(i + 0, j + 8, k + 9, 35);
		world.setBlock(i + 0, j + 8, k + 10, 102);
		world.setBlock(i + 0, j + 8, k + 11, 102);
		world.setBlock(i + 0, j + 8, k + 12, 35);
		world.setBlock(i + 0, j + 8, k + 13, 102);
		world.setBlock(i + 0, j + 8, k + 14, 102);
		world.setBlock(i + 0, j + 8, k + 15, 35);
		world.setBlock(i + 0, j + 8, k + 16, 102);
		world.setBlock(i + 0, j + 8, k + 17, 102);
		world.setBlock(i + 0, j + 8, k + 18, 35);
		world.setBlock(i + 0, j + 8, k + 19, 0);
		world.setBlock(i + 0, j + 8, k + 20, 0);
		world.setBlock(i + 0, j + 9, k + 0, 0);
		world.setBlock(i + 0, j + 9, k + 1, 0);
		world.setBlock(i + 0, j + 9, k + 2, 0);
		world.setBlock(i + 0, j + 9, k + 3, 35);
		world.setBlock(i + 0, j + 9, k + 4, 102);
		world.setBlock(i + 0, j + 9, k + 5, 102);
		world.setBlock(i + 0, j + 9, k + 6, 35);
		world.setBlock(i + 0, j + 9, k + 7, 102);
		world.setBlock(i + 0, j + 9, k + 8, 102);
		world.setBlock(i + 0, j + 9, k + 9, 35);
		world.setBlock(i + 0, j + 9, k + 10, 102);
		world.setBlock(i + 0, j + 9, k + 11, 102);
		world.setBlock(i + 0, j + 9, k + 12, 35);
		world.setBlock(i + 0, j + 9, k + 13, 102);
		world.setBlock(i + 0, j + 9, k + 14, 102);
		world.setBlock(i + 0, j + 9, k + 15, 35);
		world.setBlock(i + 0, j + 9, k + 16, 102);
		world.setBlock(i + 0, j + 9, k + 17, 102);
		world.setBlock(i + 0, j + 9, k + 18, 35);
		world.setBlock(i + 0, j + 9, k + 19, 0);
		world.setBlock(i + 0, j + 9, k + 20, 0);
		world.setBlock(i + 0, j + 10, k + 0, 0);
		world.setBlock(i + 0, j + 10, k + 1, 0);
		world.setBlock(i + 0, j + 10, k + 2, 0);
		world.setBlock(i + 0, j + 10, k + 3, 35);
		world.setBlock(i + 0, j + 10, k + 4, 102);
		world.setBlock(i + 0, j + 10, k + 5, 102);
		world.setBlock(i + 0, j + 10, k + 6, 35);
		world.setBlock(i + 0, j + 10, k + 7, 102);
		world.setBlock(i + 0, j + 10, k + 8, 102);
		world.setBlock(i + 0, j + 10, k + 9, 35);
		world.setBlock(i + 0, j + 10, k + 10, 102);
		world.setBlock(i + 0, j + 10, k + 11, 102);
		world.setBlock(i + 0, j + 10, k + 12, 35);
		world.setBlock(i + 0, j + 10, k + 13, 102);
		world.setBlock(i + 0, j + 10, k + 14, 102);
		world.setBlock(i + 0, j + 10, k + 15, 35);
		world.setBlock(i + 0, j + 10, k + 16, 102);
		world.setBlock(i + 0, j + 10, k + 17, 102);
		world.setBlock(i + 0, j + 10, k + 18, 35);
		world.setBlock(i + 0, j + 10, k + 19, 0);
		world.setBlock(i + 0, j + 10, k + 20, 0);
		world.setBlock(i + 0, j + 11, k + 0, 0);
		world.setBlock(i + 0, j + 11, k + 1, 0);
		world.setBlock(i + 0, j + 11, k + 2, 0);
		world.setBlock(i + 0, j + 11, k + 3, 35);
		world.setBlock(i + 0, j + 11, k + 4, 102);
		world.setBlock(i + 0, j + 11, k + 5, 102);
		world.setBlock(i + 0, j + 11, k + 6, 35);
		world.setBlock(i + 0, j + 11, k + 7, 102);
		world.setBlock(i + 0, j + 11, k + 8, 102);
		world.setBlock(i + 0, j + 11, k + 9, 35);
		world.setBlock(i + 0, j + 11, k + 10, 102);
		world.setBlock(i + 0, j + 11, k + 11, 102);
		world.setBlock(i + 0, j + 11, k + 12, 35);
		world.setBlock(i + 0, j + 11, k + 13, 102);
		world.setBlock(i + 0, j + 11, k + 14, 102);
		world.setBlock(i + 0, j + 11, k + 15, 35);
		world.setBlock(i + 0, j + 11, k + 16, 102);
		world.setBlock(i + 0, j + 11, k + 17, 102);
		world.setBlock(i + 0, j + 11, k + 18, 35);
		world.setBlock(i + 0, j + 11, k + 19, 0);
		world.setBlock(i + 0, j + 11, k + 20, 0);
		world.setBlock(i + 0, j + 12, k + 0, 0);
		world.setBlock(i + 0, j + 12, k + 1, 0);
		world.setBlock(i + 0, j + 12, k + 2, 0);
		world.setBlockAndMetadata(i + 0, j + 12, k + 3, 35, 14);
		world.setBlockAndMetadata(i + 0, j + 12, k + 4, 35, 14);
		world.setBlockAndMetadata(i + 0, j + 12, k + 5, 35, 14);
		world.setBlockAndMetadata(i + 0, j + 12, k + 6, 35, 14);
		world.setBlockAndMetadata(i + 0, j + 12, k + 7, 35, 14);
		world.setBlockAndMetadata(i + 0, j + 12, k + 8, 35, 14);
		world.setBlockAndMetadata(i + 0, j + 12, k + 9, 35, 14);
		world.setBlockAndMetadata(i + 0, j + 12, k + 10, 35, 14);
		world.setBlockAndMetadata(i + 0, j + 12, k + 11, 35, 14);
		world.setBlockAndMetadata(i + 0, j + 12, k + 12, 35, 14);
		world.setBlockAndMetadata(i + 0, j + 12, k + 13, 35, 14);
		world.setBlockAndMetadata(i + 0, j + 12, k + 14, 35, 14);
		world.setBlockAndMetadata(i + 0, j + 12, k + 15, 35, 14);
		world.setBlockAndMetadata(i + 0, j + 12, k + 16, 35, 14);
		world.setBlockAndMetadata(i + 0, j + 12, k + 17, 35, 14);
		world.setBlockAndMetadata(i + 0, j + 12, k + 18, 35, 14);
		world.setBlock(i + 0, j + 12, k + 19, 0);
		world.setBlock(i + 0, j + 12, k + 20, 0);
		world.setBlock(i + 0, j + 13, k + 0, 0);
		world.setBlock(i + 0, j + 13, k + 1, 0);
		world.setBlock(i + 0, j + 13, k + 2, 0);
		world.setBlock(i + 0, j + 13, k + 3, 0);
		world.setBlock(i + 0, j + 13, k + 4, 0);
		world.setBlock(i + 0, j + 13, k + 5, 0);
		world.setBlock(i + 0, j + 13, k + 6, 0);
		world.setBlock(i + 0, j + 13, k + 7, 0);
		world.setBlock(i + 0, j + 13, k + 8, 0);
		world.setBlock(i + 0, j + 13, k + 9, 0);
		world.setBlock(i + 0, j + 13, k + 10, 0);
		world.setBlock(i + 0, j + 13, k + 11, 0);
		world.setBlock(i + 0, j + 13, k + 12, 0);
		world.setBlock(i + 0, j + 13, k + 13, 0);
		world.setBlock(i + 0, j + 13, k + 14, 0);
		world.setBlock(i + 0, j + 13, k + 15, 0);
		world.setBlock(i + 0, j + 13, k + 16, 0);
		world.setBlock(i + 0, j + 13, k + 17, 0);
		world.setBlock(i + 0, j + 13, k + 18, 0);
		world.setBlock(i + 0, j + 13, k + 19, 0);
		world.setBlock(i + 0, j + 13, k + 20, 0);
		world.setBlock(i + 1, j + 0, k + 0, 2);
		world.setBlock(i + 1, j + 0, k + 1, 2);
		world.setBlock(i + 1, j + 0, k + 2, 2);
		world.setBlock(i + 1, j + 0, k + 3, 3);
		world.setBlock(i + 1, j + 0, k + 4, 3);
		world.setBlock(i + 1, j + 0, k + 5, 3);
		world.setBlockAndMetadata(i + 1, j + 0, k + 6, 35, 4);
		world.setBlockAndMetadata(i + 1, j + 0, k + 7, 35, 4);
		world.setBlockAndMetadata(i + 1, j + 0, k + 8, 35, 4);
		world.setBlockAndMetadata(i + 1, j + 0, k + 9, 35, 4);
		world.setBlockAndMetadata(i + 1, j + 0, k + 10, 35, 4);
		world.setBlockAndMetadata(i + 1, j + 0, k + 11, 35, 4);
		world.setBlockAndMetadata(i + 1, j + 0, k + 12, 35, 4);
		world.setBlockAndMetadata(i + 1, j + 0, k + 13, 35, 4);
		world.setBlockAndMetadata(i + 1, j + 0, k + 14, 35, 4);
		world.setBlockAndMetadata(i + 1, j + 0, k + 15, 35, 4);
		world.setBlockAndMetadata(i + 1, j + 0, k + 16, 35, 4);
		world.setBlock(i + 1, j + 0, k + 17, 3);
		world.setBlock(i + 1, j + 0, k + 18, 3);
		world.setBlock(i + 1, j + 0, k + 19, 2);
		world.setBlock(i + 1, j + 0, k + 20, 2);
		world.setBlock(i + 1, j + 1, k + 0, 0);
		world.setBlock(i + 1, j + 1, k + 1, 0);
		world.setBlock(i + 1, j + 1, k + 2, 0);
		world.setBlock(i + 1, j + 1, k + 3, 35);
		world.setBlock(i + 1, j + 1, k + 4, 35);
		world.setBlockAndMetadata(i + 1, j + 1, k + 5, 35, 14);
		world.setBlockAndMetadata(i + 1, j + 1, k + 6, 35, 14);
		world.setBlockAndMetadata(i + 1, j + 1, k + 7, 35, 14);
		world.setBlockAndMetadata(i + 1, j + 1, k + 8, 35, 14);
		world.setBlockAndMetadata(i + 1, j + 1, k + 9, 35, 14);
		world.setBlockAndMetadata(i + 1, j + 1, k + 10, 35, 14);
		world.setBlockAndMetadata(i + 1, j + 1, k + 11, 35, 14);
		world.setBlockAndMetadata(i + 1, j + 1, k + 12, 35, 14);
		world.setBlockAndMetadata(i + 1, j + 1, k + 13, 35, 14);
		world.setBlockAndMetadata(i + 1, j + 1, k + 14, 35, 14);
		world.setBlockAndMetadata(i + 1, j + 1, k + 15, 35, 14);
		world.setBlockAndMetadata(i + 1, j + 1, k + 16, 35, 14);
		world.setBlockAndMetadata(i + 1, j + 1, k + 17, 35, 14);
		world.setBlock(i + 1, j + 1, k + 18, 35);
		world.setBlock(i + 1, j + 1, k + 19, 0);
		world.setBlock(i + 1, j + 1, k + 20, 0);
		world.setBlock(i + 1, j + 2, k + 0, 0);
		world.setBlock(i + 1, j + 2, k + 1, 0);
		world.setBlock(i + 1, j + 2, k + 2, 0);
		world.setBlock(i + 1, j + 2, k + 3, 0);
		world.setBlock(i + 1, j + 2, k + 4, 35);
		world.setBlockAndMetadata(i + 1, j + 2, k + 5, 35, 14);
		world.setBlockAndMetadata(i + 1, j + 2, k + 6, 35, 14);
		world.setBlockAndMetadata(i + 1, j + 2, k + 7, 35, 14);
		world.setBlockAndMetadata(i + 1, j + 2, k + 8, 35, 14);
		world.setBlockAndMetadata(i + 1, j + 2, k + 9, 35, 14);
		world.setBlockAndMetadata(i + 1, j + 2, k + 10, 35, 14);
		world.setBlockAndMetadata(i + 1, j + 2, k + 11, 35, 14);
		world.setBlockAndMetadata(i + 1, j + 2, k + 12, 35, 14);
		world.setBlockAndMetadata(i + 1, j + 2, k + 13, 35, 14);
		world.setBlockAndMetadata(i + 1, j + 2, k + 14, 35, 14);
		world.setBlockAndMetadata(i + 1, j + 2, k + 15, 35, 14);
		world.setBlockAndMetadata(i + 1, j + 2, k + 16, 35, 14);
		world.setBlockAndMetadata(i + 1, j + 2, k + 17, 35, 14);
		world.setBlock(i + 1, j + 2, k + 18, 35);
		world.setBlock(i + 1, j + 2, k + 19, 0);
		world.setBlock(i + 1, j + 2, k + 20, 0);
		world.setBlock(i + 1, j + 3, k + 0, 0);
		world.setBlock(i + 1, j + 3, k + 1, 0);
		world.setBlock(i + 1, j + 3, k + 2, 0);
		world.setBlock(i + 1, j + 3, k + 3, 0);
		world.setBlock(i + 1, j + 3, k + 4, 35);
		world.setBlockAndMetadata(i + 1, j + 3, k + 5, 35, 14);
		world.setBlockAndMetadata(i + 1, j + 3, k + 6, 35, 14);
		world.setBlockAndMetadata(i + 1, j + 3, k + 7, 35, 14);
		world.setBlockAndMetadata(i + 1, j + 3, k + 8, 35, 14);
		world.setBlockAndMetadata(i + 1, j + 3, k + 9, 35, 14);
		world.setBlockAndMetadata(i + 1, j + 3, k + 10, 35, 14);
		world.setBlockAndMetadata(i + 1, j + 3, k + 11, 35, 14);
		world.setBlockAndMetadata(i + 1, j + 3, k + 12, 35, 14);
		world.setBlockAndMetadata(i + 1, j + 3, k + 13, 35, 14);
		world.setBlockAndMetadata(i + 1, j + 3, k + 14, 35, 14);
		world.setBlockAndMetadata(i + 1, j + 3, k + 15, 35, 14);
		world.setBlockAndMetadata(i + 1, j + 3, k + 16, 35, 14);
		world.setBlockAndMetadata(i + 1, j + 3, k + 17, 35, 14);
		world.setBlock(i + 1, j + 3, k + 18, 35);
		world.setBlock(i + 1, j + 3, k + 19, 0);
		world.setBlock(i + 1, j + 3, k + 20, 0);
		world.setBlock(i + 1, j + 4, k + 0, 0);
		world.setBlock(i + 1, j + 4, k + 1, 0);
		world.setBlock(i + 1, j + 4, k + 2, 0);
		world.setBlock(i + 1, j + 4, k + 3, 0);
		world.setBlock(i + 1, j + 4, k + 4, 35);
		world.setBlockAndMetadata(i + 1, j + 4, k + 5, 35, 14);
		world.setBlockAndMetadata(i + 1, j + 4, k + 6, 35, 14);
		world.setBlockAndMetadata(i + 1, j + 4, k + 7, 35, 14);
		world.setBlockAndMetadata(i + 1, j + 4, k + 8, 35, 14);
		world.setBlockAndMetadata(i + 1, j + 4, k + 9, 35, 14);
		world.setBlockAndMetadata(i + 1, j + 4, k + 10, 35, 14);
		world.setBlockAndMetadata(i + 1, j + 4, k + 11, 35, 14);
		world.setBlockAndMetadata(i + 1, j + 4, k + 12, 35, 14);
		world.setBlockAndMetadata(i + 1, j + 4, k + 13, 35, 14);
		world.setBlockAndMetadata(i + 1, j + 4, k + 14, 35, 14);
		world.setBlockAndMetadata(i + 1, j + 4, k + 15, 35, 14);
		world.setBlockAndMetadata(i + 1, j + 4, k + 16, 35, 14);
		world.setBlockAndMetadata(i + 1, j + 4, k + 17, 35, 14);
		world.setBlock(i + 1, j + 4, k + 18, 35);
		world.setBlock(i + 1, j + 4, k + 19, 0);
		world.setBlock(i + 1, j + 4, k + 20, 0);
		world.setBlock(i + 1, j + 5, k + 0, 0);
		world.setBlock(i + 1, j + 5, k + 1, 0);
		world.setBlock(i + 1, j + 5, k + 2, 0);
		world.setBlock(i + 1, j + 5, k + 3, 0);
		world.setBlock(i + 1, j + 5, k + 4, 35);
		world.setBlockAndMetadata(i + 1, j + 5, k + 5, 35, 14);
		world.setBlock(i + 1, j + 5, k + 6, 35);
		world.setBlock(i + 1, j + 5, k + 7, 35);
		world.setBlock(i + 1, j + 5, k + 8, 35);
		world.setBlock(i + 1, j + 5, k + 9, 35);
		world.setBlock(i + 1, j + 5, k + 10, 35);
		world.setBlock(i + 1, j + 5, k + 11, 35);
		world.setBlock(i + 1, j + 5, k + 12, 35);
		world.setBlock(i + 1, j + 5, k + 13, 35);
		world.setBlock(i + 1, j + 5, k + 14, 35);
		world.setBlock(i + 1, j + 5, k + 15, 35);
		world.setBlock(i + 1, j + 5, k + 16, 35);
		world.setBlock(i + 1, j + 5, k + 17, 35);
		world.setBlock(i + 1, j + 5, k + 18, 35);
		world.setBlock(i + 1, j + 5, k + 19, 0);
		world.setBlock(i + 1, j + 5, k + 20, 0);
		world.setBlock(i + 1, j + 6, k + 0, 0);
		world.setBlock(i + 1, j + 6, k + 1, 0);
		world.setBlock(i + 1, j + 6, k + 2, 0);
		world.setBlock(i + 1, j + 6, k + 3, 35);
		world.setBlockAndMetadata(i + 1, j + 6, k + 4, 35, 4);
		world.setBlockAndMetadata(i + 1, j + 6, k + 5, 35, 4);
		world.setBlockAndMetadata(i + 1, j + 6, k + 6, 35, 4);
		world.setBlockAndMetadata(i + 1, j + 6, k + 7, 35, 4);
		world.setBlockAndMetadata(i + 1, j + 6, k + 8, 35, 4);
		world.setBlockAndMetadata(i + 1, j + 6, k + 9, 35, 4);
		world.setBlockAndMetadata(i + 1, j + 6, k + 10, 35, 4);
		world.setBlockAndMetadata(i + 1, j + 6, k + 11, 35, 4);
		world.setBlockAndMetadata(i + 1, j + 6, k + 12, 35, 4);
		world.setBlockAndMetadata(i + 1, j + 6, k + 13, 35, 4);
		world.setBlockAndMetadata(i + 1, j + 6, k + 14, 35, 4);
		world.setBlockAndMetadata(i + 1, j + 6, k + 15, 35, 4);
		world.setBlockAndMetadata(i + 1, j + 6, k + 16, 35, 4);
		world.setBlockAndMetadata(i + 1, j + 6, k + 17, 35, 4);
		world.setBlock(i + 1, j + 6, k + 18, 35);
		world.setBlock(i + 1, j + 6, k + 19, 0);
		world.setBlock(i + 1, j + 6, k + 20, 0);
		world.setBlock(i + 1, j + 7, k + 0, 0);
		world.setBlock(i + 1, j + 7, k + 1, 0);
		world.setBlock(i + 1, j + 7, k + 2, 0);
		world.setBlock(i + 1, j + 7, k + 3, 102);
		world.setBlock(i + 1, j + 7, k + 4, 0);
		world.setBlock(i + 1, j + 7, k + 5, 0);
		world.setBlock(i + 1, j + 7, k + 6, 0);
		world.setBlock(i + 1, j + 7, k + 7, 0);
		world.setBlock(i + 1, j + 7, k + 8, 0);
		world.setBlock(i + 1, j + 7, k + 9, 0);
		world.setBlock(i + 1, j + 7, k + 10, 0);
		world.setBlock(i + 1, j + 7, k + 11, 0);
		world.setBlock(i + 1, j + 7, k + 12, 0);
		world.setBlock(i + 1, j + 7, k + 13, 0);
		world.setBlock(i + 1, j + 7, k + 14, 0);
		world.setBlock(i + 1, j + 7, k + 15, 0);
		world.setBlock(i + 1, j + 7, k + 16, 0);
		world.setBlock(i + 1, j + 7, k + 17, 0);
		world.setBlock(i + 1, j + 7, k + 18, 102);
		world.setBlock(i + 1, j + 7, k + 19, 0);
		world.setBlock(i + 1, j + 7, k + 20, 0);
		world.setBlock(i + 1, j + 8, k + 0, 0);
		world.setBlock(i + 1, j + 8, k + 1, 0);
		world.setBlock(i + 1, j + 8, k + 2, 0);
		world.setBlock(i + 1, j + 8, k + 3, 102);
		world.setBlock(i + 1, j + 8, k + 4, 0);
		world.setBlock(i + 1, j + 8, k + 5, 0);
		world.setBlock(i + 1, j + 8, k + 6, 0);
		world.setBlock(i + 1, j + 8, k + 7, 0);
		world.setBlock(i + 1, j + 8, k + 8, 0);
		world.setBlock(i + 1, j + 8, k + 9, 0);
		world.setBlock(i + 1, j + 8, k + 10, 0);
		world.setBlock(i + 1, j + 8, k + 11, 0);
		world.setBlock(i + 1, j + 8, k + 12, 0);
		world.setBlock(i + 1, j + 8, k + 13, 0);
		world.setBlock(i + 1, j + 8, k + 14, 0);
		world.setBlock(i + 1, j + 8, k + 15, 0);
		world.setBlock(i + 1, j + 8, k + 16, 0);
		world.setBlock(i + 1, j + 8, k + 17, 0);
		world.setBlock(i + 1, j + 8, k + 18, 102);
		world.setBlock(i + 1, j + 8, k + 19, 0);
		world.setBlock(i + 1, j + 8, k + 20, 0);
		world.setBlock(i + 1, j + 9, k + 0, 0);
		world.setBlock(i + 1, j + 9, k + 1, 0);
		world.setBlock(i + 1, j + 9, k + 2, 0);
		world.setBlock(i + 1, j + 9, k + 3, 102);
		world.setBlock(i + 1, j + 9, k + 4, 0);
		world.setBlock(i + 1, j + 9, k + 5, 0);
		world.setBlock(i + 1, j + 9, k + 6, 0);
		world.setBlock(i + 1, j + 9, k + 7, 0);
		world.setBlock(i + 1, j + 9, k + 8, 0);
		world.setBlock(i + 1, j + 9, k + 9, 0);
		world.setBlock(i + 1, j + 9, k + 10, 0);
		world.setBlock(i + 1, j + 9, k + 11, 0);
		world.setBlock(i + 1, j + 9, k + 12, 0);
		world.setBlock(i + 1, j + 9, k + 13, 0);
		world.setBlock(i + 1, j + 9, k + 14, 0);
		world.setBlock(i + 1, j + 9, k + 15, 0);
		world.setBlock(i + 1, j + 9, k + 16, 0);
		world.setBlock(i + 1, j + 9, k + 17, 0);
		world.setBlock(i + 1, j + 9, k + 18, 102);
		world.setBlock(i + 1, j + 9, k + 19, 0);
		world.setBlock(i + 1, j + 9, k + 20, 0);
		world.setBlock(i + 1, j + 10, k + 0, 0);
		world.setBlock(i + 1, j + 10, k + 1, 0);
		world.setBlock(i + 1, j + 10, k + 2, 0);
		world.setBlock(i + 1, j + 10, k + 3, 102);
		world.setBlock(i + 1, j + 10, k + 4, 0);
		world.setBlock(i + 1, j + 10, k + 5, 0);
		world.setBlock(i + 1, j + 10, k + 6, 0);
		world.setBlock(i + 1, j + 10, k + 7, 0);
		world.setBlock(i + 1, j + 10, k + 8, 0);
		world.setBlock(i + 1, j + 10, k + 9, 0);
		world.setBlock(i + 1, j + 10, k + 10, 0);
		world.setBlock(i + 1, j + 10, k + 11, 0);
		world.setBlock(i + 1, j + 10, k + 12, 0);
		world.setBlock(i + 1, j + 10, k + 13, 0);
		world.setBlock(i + 1, j + 10, k + 14, 0);
		world.setBlock(i + 1, j + 10, k + 15, 0);
		world.setBlock(i + 1, j + 10, k + 16, 0);
		world.setBlock(i + 1, j + 10, k + 17, 0);
		world.setBlock(i + 1, j + 10, k + 18, 102);
		world.setBlock(i + 1, j + 10, k + 19, 0);
		world.setBlock(i + 1, j + 10, k + 20, 0);
		world.setBlock(i + 1, j + 11, k + 0, 0);
		world.setBlock(i + 1, j + 11, k + 1, 0);
		world.setBlock(i + 1, j + 11, k + 2, 0);
		world.setBlock(i + 1, j + 11, k + 3, 102);
		world.setBlock(i + 1, j + 11, k + 4, 0);
		world.setBlock(i + 1, j + 11, k + 5, 0);
		world.setBlock(i + 1, j + 11, k + 6, 0);
		world.setBlock(i + 1, j + 11, k + 7, 0);
		world.setBlock(i + 1, j + 11, k + 8, 0);
		world.setBlock(i + 1, j + 11, k + 9, 0);
		world.setBlock(i + 1, j + 11, k + 10, 0);
		world.setBlock(i + 1, j + 11, k + 11, 0);
		world.setBlock(i + 1, j + 11, k + 12, 0);
		world.setBlock(i + 1, j + 11, k + 13, 0);
		world.setBlock(i + 1, j + 11, k + 14, 0);
		world.setBlock(i + 1, j + 11, k + 15, 0);
		world.setBlock(i + 1, j + 11, k + 16, 0);
		world.setBlock(i + 1, j + 11, k + 17, 0);
		world.setBlock(i + 1, j + 11, k + 18, 102);
		world.setBlock(i + 1, j + 11, k + 19, 0);
		world.setBlock(i + 1, j + 11, k + 20, 0);
		world.setBlock(i + 1, j + 12, k + 0, 0);
		world.setBlock(i + 1, j + 12, k + 1, 0);
		world.setBlock(i + 1, j + 12, k + 2, 0);
		world.setBlockAndMetadata(i + 1, j + 12, k + 3, 35, 14);
		world.setBlock(i + 1, j + 12, k + 4, 0);
		world.setBlock(i + 1, j + 12, k + 5, 0);
		world.setBlock(i + 1, j + 12, k + 6, 0);
		world.setBlock(i + 1, j + 12, k + 7, 0);
		world.setBlock(i + 1, j + 12, k + 8, 0);
		world.setBlock(i + 1, j + 12, k + 9, 0);
		world.setBlock(i + 1, j + 12, k + 10, 0);
		world.setBlock(i + 1, j + 12, k + 11, 0);
		world.setBlock(i + 1, j + 12, k + 12, 0);
		world.setBlock(i + 1, j + 12, k + 13, 0);
		world.setBlock(i + 1, j + 12, k + 14, 0);
		world.setBlock(i + 1, j + 12, k + 15, 0);
		world.setBlock(i + 1, j + 12, k + 16, 0);
		world.setBlock(i + 1, j + 12, k + 17, 0);
		world.setBlockAndMetadata(i + 1, j + 12, k + 18, 35, 14);
		world.setBlock(i + 1, j + 12, k + 19, 0);
		world.setBlock(i + 1, j + 12, k + 20, 0);
		world.setBlock(i + 1, j + 13, k + 0, 0);
		world.setBlock(i + 1, j + 13, k + 1, 0);
		world.setBlock(i + 1, j + 13, k + 2, 0);
		world.setBlock(i + 1, j + 13, k + 3, 0);
		world.setBlockAndMetadata(i + 1, j + 13, k + 4, 35, 14);
		world.setBlockAndMetadata(i + 1, j + 13, k + 5, 35, 14);
		world.setBlockAndMetadata(i + 1, j + 13, k + 6, 35, 14);
		world.setBlockAndMetadata(i + 1, j + 13, k + 7, 35, 14);
		world.setBlockAndMetadata(i + 1, j + 13, k + 8, 35, 14);
		world.setBlockAndMetadata(i + 1, j + 13, k + 9, 35, 14);
		world.setBlockAndMetadata(i + 1, j + 13, k + 10, 35, 14);
		world.setBlockAndMetadata(i + 1, j + 13, k + 11, 35, 14);
		world.setBlockAndMetadata(i + 1, j + 13, k + 12, 35, 14);
		world.setBlockAndMetadata(i + 1, j + 13, k + 13, 35, 14);
		world.setBlockAndMetadata(i + 1, j + 13, k + 14, 35, 14);
		world.setBlockAndMetadata(i + 1, j + 13, k + 15, 35, 14);
		world.setBlockAndMetadata(i + 1, j + 13, k + 16, 35, 14);
		world.setBlockAndMetadata(i + 1, j + 13, k + 17, 35, 14);
		world.setBlock(i + 1, j + 13, k + 18, 0);
		world.setBlock(i + 1, j + 13, k + 19, 0);
		world.setBlock(i + 1, j + 13, k + 20, 0);
		world.setBlock(i + 2, j + 0, k + 0, 2);
		world.setBlock(i + 2, j + 0, k + 1, 2);
		world.setBlock(i + 2, j + 0, k + 2, 2);
		world.setBlock(i + 2, j + 0, k + 3, 3);
		world.setBlock(i + 2, j + 0, k + 4, 3);
		world.setBlock(i + 2, j + 0, k + 5, 3);
		world.setBlockAndMetadata(i + 2, j + 0, k + 6, 35, 4);
		world.setBlockAndMetadata(i + 2, j + 0, k + 7, 35, 4);
		world.setBlockAndMetadata(i + 2, j + 0, k + 8, 35, 4);
		world.setBlockAndMetadata(i + 2, j + 0, k + 9, 35, 4);
		world.setBlockAndMetadata(i + 2, j + 0, k + 10, 35, 4);
		world.setBlockAndMetadata(i + 2, j + 0, k + 11, 35, 4);
		world.setBlockAndMetadata(i + 2, j + 0, k + 12, 35, 4);
		world.setBlockAndMetadata(i + 2, j + 0, k + 13, 35, 4);
		world.setBlockAndMetadata(i + 2, j + 0, k + 14, 35, 4);
		world.setBlockAndMetadata(i + 2, j + 0, k + 15, 35, 4);
		world.setBlockAndMetadata(i + 2, j + 0, k + 16, 35, 4);
		world.setBlock(i + 2, j + 0, k + 17, 3);
		world.setBlock(i + 2, j + 0, k + 18, 3);
		world.setBlock(i + 2, j + 0, k + 19, 2);
		world.setBlock(i + 2, j + 0, k + 20, 2);
		world.setBlock(i + 2, j + 1, k + 0, 0);
		world.setBlock(i + 2, j + 1, k + 1, 0);
		world.setBlock(i + 2, j + 1, k + 2, 0);
		world.setBlock(i + 2, j + 1, k + 3, 35);
		world.setBlock(i + 2, j + 1, k + 4, 35);
		world.setBlockAndMetadata(i + 2, j + 1, k + 5, 35, 14);
		world.setBlock(i + 2, j + 1, k + 6, 0);
		world.setBlock(i + 2, j + 1, k + 8, 0);
		world.setBlock(i + 2, j + 1, k + 9, 0);
		world.setBlock(i + 2, j + 1, k + 10, 0);
		world.setBlock(i + 2, j + 1, k + 11, 0);
		world.setBlock(i + 2, j + 1, k + 12, 0);
		world.setBlock(i + 2, j + 1, k + 13, 0);
		world.setBlock(i + 2, j + 1, k + 14, 0);
		world.setBlock(i + 2, j + 1, k + 15, 0);
		world.setBlock(i + 2, j + 1, k + 16, 0);
		world.setBlockAndMetadata(i + 2, j + 1, k + 17, 35, 14);
		world.setBlock(i + 2, j + 1, k + 18, 35);
		world.setBlock(i + 2, j + 1, k + 19, 0);
		world.setBlock(i + 2, j + 1, k + 20, 0);
		world.setBlock(i + 2, j + 2, k + 0, 0);
		world.setBlock(i + 2, j + 2, k + 1, 0);
		world.setBlock(i + 2, j + 2, k + 2, 0);
		world.setBlock(i + 2, j + 2, k + 3, 0);
		world.setBlock(i + 2, j + 2, k + 4, 35);
		world.setBlockAndMetadata(i + 2, j + 2, k + 5, 35, 14);
		world.setBlock(i + 2, j + 2, k + 6, 0);
		world.setBlock(i + 2, j + 2, k + 7, 0);
		world.setBlock(i + 2, j + 2, k + 8, 0);
		world.setBlock(i + 2, j + 2, k + 9, 0);
		world.setBlock(i + 2, j + 2, k + 10, 0);
		world.setBlock(i + 2, j + 2, k + 11, 0);
		world.setBlock(i + 2, j + 2, k + 12, 0);
		world.setBlock(i + 2, j + 2, k + 13, 0);
		world.setBlock(i + 2, j + 2, k + 14, 0);
		world.setBlock(i + 2, j + 2, k + 15, 0);
		world.setBlock(i + 2, j + 2, k + 16, 0);
		world.setBlockAndMetadata(i + 2, j + 2, k + 17, 35, 14);
		world.setBlock(i + 2, j + 2, k + 18, 35);
		world.setBlock(i + 2, j + 2, k + 19, 0);
		world.setBlock(i + 2, j + 2, k + 20, 0);
		world.setBlock(i + 2, j + 3, k + 0, 0);
		world.setBlock(i + 2, j + 3, k + 1, 0);
		world.setBlock(i + 2, j + 3, k + 2, 0);
		world.setBlock(i + 2, j + 3, k + 3, 0);
		world.setBlock(i + 2, j + 3, k + 4, 35);
		world.setBlockAndMetadata(i + 2, j + 3, k + 5, 35, 14);
		world.setBlockAndMetadata(i + 2, j + 3, k + 17, 35, 14);
		world.setBlock(i + 2, j + 3, k + 18, 35);
		world.setBlock(i + 2, j + 3, k + 19, 0);
		world.setBlock(i + 2, j + 3, k + 20, 0);
		world.setBlock(i + 2, j + 4, k + 0, 0);
		world.setBlock(i + 2, j + 4, k + 1, 0);
		world.setBlock(i + 2, j + 4, k + 2, 0);
		world.setBlock(i + 2, j + 4, k + 3, 0);
		world.setBlock(i + 2, j + 4, k + 4, 35);
		world.setBlockAndMetadata(i + 2, j + 4, k + 5, 35, 14);
		world.setBlock(i + 2, j + 4, k + 6, 0);
		world.setBlock(i + 2, j + 4, k + 7, 0);
		world.setBlock(i + 2, j + 4, k + 8, 0);
		world.setBlock(i + 2, j + 4, k + 9, 0);
		world.setBlock(i + 2, j + 4, k + 10, 0);
		world.setBlock(i + 2, j + 4, k + 11, 0);
		world.setBlock(i + 2, j + 4, k + 12, 0);
		world.setBlock(i + 2, j + 4, k + 13, 0);
		world.setBlock(i + 2, j + 4, k + 14, 0);
		world.setBlock(i + 2, j + 4, k + 15, 0);
		world.setBlock(i + 2, j + 4, k + 16, 0);
		world.setBlockAndMetadata(i + 2, j + 4, k + 17, 35, 14);
		world.setBlock(i + 2, j + 4, k + 18, 35);
		world.setBlock(i + 2, j + 4, k + 19, 0);
		world.setBlock(i + 2, j + 4, k + 20, 0);
		world.setBlock(i + 2, j + 5, k + 0, 0);
		world.setBlock(i + 2, j + 5, k + 1, 0);
		world.setBlock(i + 2, j + 5, k + 2, 0);
		world.setBlock(i + 2, j + 5, k + 3, 0);
		world.setBlock(i + 2, j + 5, k + 4, 35);
		world.setBlockAndMetadata(i + 2, j + 5, k + 5, 35, 14);
		world.setBlock(i + 2, j + 5, k + 6, 35);
		world.setBlock(i + 2, j + 5, k + 7, 35);
		world.setBlock(i + 2, j + 5, k + 8, 35);
		world.setBlock(i + 2, j + 5, k + 9, 35);
		world.setBlock(i + 2, j + 5, k + 10, 35);
		world.setBlock(i + 2, j + 5, k + 11, 35);
		world.setBlock(i + 2, j + 5, k + 12, 35);
		world.setBlock(i + 2, j + 5, k + 13, 35);
		world.setBlock(i + 2, j + 5, k + 14, 35);
		world.setBlock(i + 2, j + 5, k + 15, 35);
		world.setBlock(i + 2, j + 5, k + 16, 35);
		world.setBlock(i + 2, j + 5, k + 17, 35);
		world.setBlock(i + 2, j + 5, k + 18, 35);
		world.setBlock(i + 2, j + 5, k + 19, 0);
		world.setBlock(i + 2, j + 5, k + 20, 0);
		world.setBlock(i + 2, j + 6, k + 0, 0);
		world.setBlock(i + 2, j + 6, k + 1, 0);
		world.setBlock(i + 2, j + 6, k + 2, 0);
		world.setBlock(i + 2, j + 6, k + 3, 35);
		world.setBlockAndMetadata(i + 2, j + 6, k + 4, 35, 4);
		world.setBlockAndMetadata(i + 2, j + 6, k + 5, 35, 4);
		world.setBlockAndMetadata(i + 2, j + 6, k + 6, 35, 4);
		world.setBlockAndMetadata(i + 2, j + 6, k + 7, 35, 4);
		world.setBlockAndMetadata(i + 2, j + 6, k + 8, 35, 4);
		world.setBlockAndMetadata(i + 2, j + 6, k + 9, 35, 4);
		world.setBlockAndMetadata(i + 2, j + 6, k + 10, 35, 4);
		world.setBlockAndMetadata(i + 2, j + 6, k + 11, 35, 4);
		world.setBlockAndMetadata(i + 2, j + 6, k + 12, 35, 4);
		world.setBlockAndMetadata(i + 2, j + 6, k + 13, 35, 4);
		world.setBlockAndMetadata(i + 2, j + 6, k + 14, 35, 4);
		world.setBlockAndMetadata(i + 2, j + 6, k + 15, 35, 4);
		world.setBlockAndMetadata(i + 2, j + 6, k + 16, 35, 4);
		world.setBlockAndMetadata(i + 2, j + 6, k + 17, 35, 4);
		world.setBlock(i + 2, j + 6, k + 18, 35);
		world.setBlock(i + 2, j + 6, k + 19, 0);
		world.setBlock(i + 2, j + 6, k + 20, 0);
		world.setBlock(i + 2, j + 7, k + 0, 0);
		world.setBlock(i + 2, j + 7, k + 1, 0);
		world.setBlock(i + 2, j + 7, k + 2, 0);
		world.setBlock(i + 2, j + 7, k + 3, 102);
		world.setBlock(i + 2, j + 7, k + 4, 0);
		world.setBlock(i + 2, j + 7, k + 5, 0);
		world.setBlock(i + 2, j + 7, k + 6, 0);
		world.setBlock(i + 2, j + 7, k + 7, 112);
		world.setBlockAndMetadata(i + 2, j + 7, k + 8, 114, 1);
		world.setBlockAndMetadata(i + 2, j + 7, k + 9, 114, 1);
		world.setBlockAndMetadata(i + 2, j + 7, k + 10, 114, 1);
		world.setBlock(i + 2, j + 7, k + 11, 112);
		world.setBlock(i + 2, j + 7, k + 12, 0);
		world.setBlock(i + 2, j + 7, k + 13, 0);
		world.setBlock(i + 2, j + 7, k + 14, 0);
		world.setBlock(i + 2, j + 7, k + 15, 0);
		world.setBlock(i + 2, j + 7, k + 16, 0);
		world.setBlock(i + 2, j + 7, k + 17, 0);
		world.setBlock(i + 2, j + 7, k + 18, 102);
		world.setBlock(i + 2, j + 7, k + 19, 0);
		world.setBlock(i + 2, j + 7, k + 20, 0);
		world.setBlock(i + 2, j + 8, k + 0, 0);
		world.setBlock(i + 2, j + 8, k + 1, 0);
		world.setBlock(i + 2, j + 8, k + 2, 0);
		world.setBlock(i + 2, j + 8, k + 3, 102);
		world.setBlock(i + 2, j + 8, k + 4, 0);
		world.setBlock(i + 2, j + 8, k + 5, 0);
		world.setBlock(i + 2, j + 8, k + 6, 0);
		world.setBlock(i + 2, j + 8, k + 7, 0);
		world.setBlock(i + 2, j + 8, k + 8, 0);
		world.setBlock(i + 2, j + 8, k + 9, 0);
		world.setBlock(i + 2, j + 8, k + 10, 0);
		world.setBlock(i + 2, j + 8, k + 11, 0);
		world.setBlock(i + 2, j + 8, k + 12, 0);
		world.setBlock(i + 2, j + 8, k + 13, 0);
		world.setBlock(i + 2, j + 8, k + 14, 0);
		world.setBlock(i + 2, j + 8, k + 15, 0);
		world.setBlock(i + 2, j + 8, k + 16, 0);
		world.setBlock(i + 2, j + 8, k + 17, 0);
		world.setBlock(i + 2, j + 8, k + 18, 102);
		world.setBlock(i + 2, j + 8, k + 19, 0);
		world.setBlock(i + 2, j + 8, k + 20, 0);
		world.setBlock(i + 2, j + 9, k + 0, 0);
		world.setBlock(i + 2, j + 9, k + 1, 0);
		world.setBlock(i + 2, j + 9, k + 2, 0);
		world.setBlock(i + 2, j + 9, k + 3, 102);
		world.setBlock(i + 2, j + 9, k + 4, 0);
		world.setBlock(i + 2, j + 9, k + 5, 0);
		world.setBlock(i + 2, j + 9, k + 6, 0);
		world.setBlock(i + 2, j + 9, k + 7, 0);
		world.setBlock(i + 2, j + 9, k + 8, 0);
		world.setBlock(i + 2, j + 9, k + 9, 0);
		world.setBlock(i + 2, j + 9, k + 10, 0);
		world.setBlock(i + 2, j + 9, k + 11, 0);
		world.setBlock(i + 2, j + 9, k + 12, 0);
		world.setBlock(i + 2, j + 9, k + 13, 0);
		world.setBlock(i + 2, j + 9, k + 14, 0);
		world.setBlock(i + 2, j + 9, k + 15, 0);
		world.setBlock(i + 2, j + 9, k + 16, 0);
		world.setBlock(i + 2, j + 9, k + 17, 0);
		world.setBlock(i + 2, j + 9, k + 18, 102);
		world.setBlock(i + 2, j + 9, k + 19, 0);
		world.setBlock(i + 2, j + 9, k + 20, 0);
		world.setBlock(i + 2, j + 10, k + 0, 0);
		world.setBlock(i + 2, j + 10, k + 1, 0);
		world.setBlock(i + 2, j + 10, k + 2, 0);
		world.setBlock(i + 2, j + 10, k + 3, 102);
		world.setBlock(i + 2, j + 10, k + 4, 0);
		world.setBlock(i + 2, j + 10, k + 5, 0);
		world.setBlock(i + 2, j + 10, k + 6, 0);
		world.setBlock(i + 2, j + 10, k + 7, 0);
		world.setBlock(i + 2, j + 10, k + 8, 0);
		world.setBlock(i + 2, j + 10, k + 9, 0);
		world.setBlock(i + 2, j + 10, k + 10, 0);
		world.setBlock(i + 2, j + 10, k + 11, 0);
		world.setBlock(i + 2, j + 10, k + 12, 0);
		world.setBlock(i + 2, j + 10, k + 13, 0);
		world.setBlock(i + 2, j + 10, k + 14, 0);
		world.setBlock(i + 2, j + 10, k + 15, 0);
		world.setBlock(i + 2, j + 10, k + 16, 0);
		world.setBlock(i + 2, j + 10, k + 17, 0);
		world.setBlock(i + 2, j + 10, k + 18, 102);
		world.setBlock(i + 2, j + 10, k + 19, 0);
		world.setBlock(i + 2, j + 10, k + 20, 0);
		world.setBlock(i + 2, j + 11, k + 0, 0);
		world.setBlock(i + 2, j + 11, k + 1, 0);
		world.setBlock(i + 2, j + 11, k + 2, 0);
		world.setBlock(i + 2, j + 11, k + 3, 102);
		world.setBlock(i + 2, j + 11, k + 4, 0);
		world.setBlock(i + 2, j + 11, k + 5, 0);
		world.setBlock(i + 2, j + 11, k + 6, 0);
		world.setBlock(i + 2, j + 11, k + 7, 0);
		world.setBlock(i + 2, j + 11, k + 8, 0);
		world.setBlock(i + 2, j + 11, k + 9, 0);
		world.setBlock(i + 2, j + 11, k + 10, 0);
		world.setBlock(i + 2, j + 11, k + 11, 0);
		world.setBlock(i + 2, j + 11, k + 12, 0);
		world.setBlock(i + 2, j + 11, k + 13, 0);
		world.setBlock(i + 2, j + 11, k + 14, 0);
		world.setBlock(i + 2, j + 11, k + 15, 0);
		world.setBlock(i + 2, j + 11, k + 16, 0);
		world.setBlock(i + 2, j + 11, k + 17, 0);
		world.setBlock(i + 2, j + 11, k + 18, 102);
		world.setBlock(i + 2, j + 11, k + 19, 0);
		world.setBlock(i + 2, j + 11, k + 20, 0);
		world.setBlock(i + 2, j + 12, k + 0, 0);
		world.setBlock(i + 2, j + 12, k + 1, 0);
		world.setBlock(i + 2, j + 12, k + 2, 0);
		world.setBlockAndMetadata(i + 2, j + 12, k + 3, 35, 14);
		world.setBlock(i + 2, j + 12, k + 4, 0);
		world.setBlock(i + 2, j + 12, k + 5, 0);
		world.setBlock(i + 2, j + 12, k + 6, 0);
		world.setBlock(i + 2, j + 12, k + 7, 0);
		world.setBlock(i + 2, j + 12, k + 8, 0);
		world.setBlock(i + 2, j + 12, k + 9, 0);
		world.setBlock(i + 2, j + 12, k + 10, 0);
		world.setBlock(i + 2, j + 12, k + 11, 0);
		world.setBlock(i + 2, j + 12, k + 12, 0);
		world.setBlock(i + 2, j + 12, k + 13, 0);
		world.setBlock(i + 2, j + 12, k + 14, 0);
		world.setBlock(i + 2, j + 12, k + 15, 0);
		world.setBlock(i + 2, j + 12, k + 16, 0);
		world.setBlock(i + 2, j + 12, k + 17, 0);
		world.setBlockAndMetadata(i + 2, j + 12, k + 18, 35, 14);
		world.setBlock(i + 2, j + 12, k + 19, 0);
		world.setBlock(i + 2, j + 12, k + 20, 0);
		world.setBlock(i + 2, j + 13, k + 0, 0);
		world.setBlock(i + 2, j + 13, k + 1, 0);
		world.setBlock(i + 2, j + 13, k + 2, 0);
		world.setBlock(i + 2, j + 13, k + 3, 0);
		world.setBlockAndMetadata(i + 2, j + 13, k + 4, 35, 14);
		world.setBlockAndMetadata(i + 2, j + 13, k + 5, 35, 14);
		world.setBlockAndMetadata(i + 2, j + 13, k + 6, 35, 14);
		world.setBlockAndMetadata(i + 2, j + 13, k + 7, 35, 14);
		world.setBlockAndMetadata(i + 2, j + 13, k + 8, 35, 14);
		world.setBlockAndMetadata(i + 2, j + 13, k + 9, 35, 14);
		world.setBlockAndMetadata(i + 2, j + 13, k + 10, 35, 14);
		world.setBlockAndMetadata(i + 2, j + 13, k + 11, 35, 14);
		world.setBlockAndMetadata(i + 2, j + 13, k + 12, 35, 14);
		world.setBlockAndMetadata(i + 2, j + 13, k + 13, 35, 14);
		world.setBlockAndMetadata(i + 2, j + 13, k + 14, 35, 14);
		world.setBlockAndMetadata(i + 2, j + 13, k + 15, 35, 14);
		world.setBlockAndMetadata(i + 2, j + 13, k + 16, 35, 14);
		world.setBlockAndMetadata(i + 2, j + 13, k + 17, 35, 14);
		world.setBlock(i + 2, j + 13, k + 18, 0);
		world.setBlock(i + 2, j + 13, k + 19, 0);
		world.setBlock(i + 2, j + 13, k + 20, 0);
		world.setBlock(i + 3, j + 0, k + 0, 2);
		world.setBlock(i + 3, j + 0, k + 1, 2);
		world.setBlock(i + 3, j + 0, k + 2, 2);
		world.setBlock(i + 3, j + 0, k + 3, 3);
		world.setBlock(i + 3, j + 0, k + 4, 3);
		world.setBlock(i + 3, j + 0, k + 5, 3);
		world.setBlockAndMetadata(i + 3, j + 0, k + 6, 35, 4);
		world.setBlockAndMetadata(i + 3, j + 0, k + 7, 35, 4);
		world.setBlockAndMetadata(i + 3, j + 0, k + 8, 35, 4);
		world.setBlockAndMetadata(i + 3, j + 0, k + 9, 35, 4);
		world.setBlockAndMetadata(i + 3, j + 0, k + 10, 35, 4);
		world.setBlockAndMetadata(i + 3, j + 0, k + 11, 35, 4);
		world.setBlockAndMetadata(i + 3, j + 0, k + 12, 35, 4);
		world.setBlockAndMetadata(i + 3, j + 0, k + 13, 35, 4);
		world.setBlockAndMetadata(i + 3, j + 0, k + 14, 35, 4);
		world.setBlockAndMetadata(i + 3, j + 0, k + 15, 35, 4);
		world.setBlockAndMetadata(i + 3, j + 0, k + 16, 35, 4);
		world.setBlock(i + 3, j + 0, k + 17, 3);
		world.setBlock(i + 3, j + 0, k + 18, 3);
		world.setBlock(i + 3, j + 0, k + 19, 2);
		world.setBlock(i + 3, j + 0, k + 20, 2);
		world.setBlock(i + 3, j + 1, k + 0, 0);
		world.setBlock(i + 3, j + 1, k + 1, 0);
		world.setBlock(i + 3, j + 1, k + 2, 0);
		world.setBlock(i + 3, j + 1, k + 3, 35);
		world.setBlock(i + 3, j + 1, k + 4, 35);
		world.setBlockAndMetadata(i + 3, j + 1, k + 5, 35, 14);
		world.setBlock(i + 3, j + 1, k + 6, 0);
		world.setBlock(i + 3, j + 1, k + 7, 0);
		world.setBlock(i + 3, j + 1, k + 8, 0);
		world.setBlock(i + 3, j + 1, k + 9, 0);
		world.setBlock(i + 3, j + 1, k + 10, 0);
		world.setBlock(i + 3, j + 1, k + 11, 0);
		world.setBlock(i + 3, j + 1, k + 12, 0);
		world.setBlock(i + 3, j + 1, k + 13, 0);
		world.setBlock(i + 3, j + 1, k + 14, 0);
		world.setBlock(i + 3, j + 1, k + 15, 0);
		world.setBlock(i + 3, j + 1, k + 16, 0);
		world.setBlockAndMetadata(i + 3, j + 1, k + 17, 35, 14);
		world.setBlock(i + 3, j + 1, k + 18, 35);
		world.setBlock(i + 3, j + 1, k + 19, 0);
		world.setBlock(i + 3, j + 1, k + 20, 0);
		world.setBlock(i + 3, j + 2, k + 0, 0);
		world.setBlock(i + 3, j + 2, k + 1, 0);
		world.setBlock(i + 3, j + 2, k + 2, 0);
		world.setBlock(i + 3, j + 2, k + 3, 0);
		world.setBlock(i + 3, j + 2, k + 4, 35);
		world.setBlockAndMetadata(i + 3, j + 2, k + 5, 35, 14);
		world.setBlock(i + 3, j + 2, k + 6, 0);
		world.setBlock(i + 3, j + 2, k + 7, 0);
		world.setBlock(i + 3, j + 2, k + 8, 0);
		world.setBlock(i + 3, j + 2, k + 9, 0);
		world.setBlock(i + 3, j + 2, k + 10, 0);
		world.setBlock(i + 3, j + 2, k + 11, 0);
		world.setBlock(i + 3, j + 2, k + 12, 0);
		world.setBlock(i + 3, j + 2, k + 13, 0);
		world.setBlock(i + 3, j + 2, k + 14, 0);
		world.setBlock(i + 3, j + 2, k + 15, 0);
		world.setBlock(i + 3, j + 2, k + 16, 0);
		world.setBlockAndMetadata(i + 3, j + 2, k + 17, 35, 14);
		world.setBlock(i + 3, j + 2, k + 18, 35);
		world.setBlock(i + 3, j + 2, k + 19, 0);
		world.setBlock(i + 3, j + 2, k + 20, 0);
		world.setBlock(i + 3, j + 3, k + 0, 0);
		world.setBlock(i + 3, j + 3, k + 1, 0);
		world.setBlock(i + 3, j + 3, k + 2, 0);
		world.setBlock(i + 3, j + 3, k + 3, 0);
		world.setBlock(i + 3, j + 3, k + 4, 35);
		world.setBlockAndMetadata(i + 3, j + 3, k + 5, 35, 14);
		world.setBlock(i + 3, j + 3, k + 7, 0);
		world.setBlock(i + 3, j + 3, k + 8, 0);
		world.setBlock(i + 3, j + 3, k + 9, 0);
		world.setBlock(i + 3, j + 3, k + 10, 0);
		world.setBlock(i + 3, j + 3, k + 11, 0);
		world.setBlock(i + 3, j + 3, k + 12, 0);
		world.setBlock(i + 3, j + 3, k + 13, 0);
		world.setBlock(i + 3, j + 3, k + 14, 0);
		world.setBlock(i + 3, j + 3, k + 15, 0);
		world.setBlockAndMetadata(i + 3, j + 3, k + 17, 35, 14);
		world.setBlock(i + 3, j + 3, k + 18, 35);
		world.setBlock(i + 3, j + 3, k + 19, 0);
		world.setBlock(i + 3, j + 3, k + 20, 0);
		world.setBlock(i + 3, j + 4, k + 0, 0);
		world.setBlock(i + 3, j + 4, k + 1, 0);
		world.setBlock(i + 3, j + 4, k + 2, 0);
		world.setBlock(i + 3, j + 4, k + 3, 0);
		world.setBlock(i + 3, j + 4, k + 4, 35);
		world.setBlockAndMetadata(i + 3, j + 4, k + 5, 35, 14);
		world.setBlock(i + 3, j + 4, k + 6, 0);
		world.setBlock(i + 3, j + 4, k + 7, 0);
		world.setBlock(i + 3, j + 4, k + 8, 0);
		world.setBlock(i + 3, j + 4, k + 9, 0);
		world.setBlock(i + 3, j + 4, k + 10, 0);
		world.setBlock(i + 3, j + 4, k + 11, 0);
		world.setBlock(i + 3, j + 4, k + 12, 0);
		world.setBlock(i + 3, j + 4, k + 13, 0);
		world.setBlock(i + 3, j + 4, k + 14, 0);
		world.setBlock(i + 3, j + 4, k + 15, 0);
		world.setBlock(i + 3, j + 4, k + 16, 0);
		world.setBlockAndMetadata(i + 3, j + 4, k + 17, 35, 14);
		world.setBlock(i + 3, j + 4, k + 18, 35);
		world.setBlock(i + 3, j + 4, k + 19, 0);
		world.setBlock(i + 3, j + 4, k + 20, 0);
		world.setBlock(i + 3, j + 5, k + 0, 0);
		world.setBlock(i + 3, j + 5, k + 1, 0);
		world.setBlock(i + 3, j + 5, k + 2, 0);
		world.setBlock(i + 3, j + 5, k + 3, 0);
		world.setBlock(i + 3, j + 5, k + 4, 35);
		world.setBlockAndMetadata(i + 3, j + 5, k + 5, 35, 14);
		world.setBlock(i + 3, j + 5, k + 6, 35);
		world.setBlock(i + 3, j + 5, k + 7, 35);
		world.setBlock(i + 3, j + 5, k + 8, 35);
		world.setBlock(i + 3, j + 5, k + 9, 35);
		world.setBlock(i + 3, j + 5, k + 10, 35);
		world.setBlock(i + 3, j + 5, k + 11, 35);
		world.setBlock(i + 3, j + 5, k + 12, 35);
		world.setBlock(i + 3, j + 5, k + 13, 35);
		world.setBlock(i + 3, j + 5, k + 14, 35);
		world.setBlock(i + 3, j + 5, k + 15, 35);
		world.setBlock(i + 3, j + 5, k + 16, 35);
		world.setBlock(i + 3, j + 5, k + 17, 35);
		world.setBlock(i + 3, j + 5, k + 18, 35);
		world.setBlock(i + 3, j + 5, k + 19, 0);
		world.setBlock(i + 3, j + 5, k + 20, 0);
		world.setBlock(i + 3, j + 6, k + 0, 0);
		world.setBlock(i + 3, j + 6, k + 1, 0);
		world.setBlock(i + 3, j + 6, k + 2, 0);
		world.setBlock(i + 3, j + 6, k + 3, 35);
		world.setBlockAndMetadata(i + 3, j + 6, k + 4, 35, 4);
		world.setBlockAndMetadata(i + 3, j + 6, k + 5, 35, 4);
		world.setBlockAndMetadata(i + 3, j + 6, k + 6, 35, 4);
		world.setBlockAndMetadata(i + 3, j + 6, k + 7, 35, 4);
		world.setBlockAndMetadata(i + 3, j + 6, k + 8, 35, 4);
		world.setBlockAndMetadata(i + 3, j + 6, k + 9, 35, 4);
		world.setBlockAndMetadata(i + 3, j + 6, k + 10, 35, 4);
		world.setBlockAndMetadata(i + 3, j + 6, k + 11, 35, 4);
		world.setBlockAndMetadata(i + 3, j + 6, k + 12, 35, 4);
		world.setBlockAndMetadata(i + 3, j + 6, k + 13, 35, 4);
		world.setBlockAndMetadata(i + 3, j + 6, k + 14, 35, 4);
		world.setBlockAndMetadata(i + 3, j + 6, k + 15, 35, 4);
		world.setBlockAndMetadata(i + 3, j + 6, k + 16, 35, 4);
		world.setBlockAndMetadata(i + 3, j + 6, k + 17, 35, 4);
		world.setBlock(i + 3, j + 6, k + 18, 35);
		world.setBlock(i + 3, j + 6, k + 19, 0);
		world.setBlock(i + 3, j + 6, k + 20, 0);
		world.setBlock(i + 3, j + 7, k + 0, 0);
		world.setBlock(i + 3, j + 7, k + 1, 0);
		world.setBlock(i + 3, j + 7, k + 2, 0);
		world.setBlock(i + 3, j + 7, k + 3, 35);
		world.setBlock(i + 3, j + 7, k + 4, 0);
		world.setBlock(i + 3, j + 7, k + 5, 0);
		world.setBlock(i + 3, j + 7, k + 6, 0);
		world.setBlock(i + 3, j + 7, k + 7, 0);
		world.setBlock(i + 3, j + 7, k + 8, 0);
		world.setBlock(i + 3, j + 7, k + 9, 0);
		world.setBlock(i + 3, j + 7, k + 10, 0);
		world.setBlock(i + 3, j + 7, k + 11, 0);
		world.setBlock(i + 3, j + 7, k + 12, 0);
		world.setBlock(i + 3, j + 7, k + 13, 0);
		world.setBlock(i + 3, j + 7, k + 14, 0);
		world.setBlock(i + 3, j + 7, k + 15, 35);
		world.setBlock(i + 3, j + 7, k + 16, 35);
		world.setBlock(i + 3, j + 7, k + 17, 35);
		world.setBlock(i + 3, j + 7, k + 18, 35);
		world.setBlock(i + 3, j + 7, k + 19, 0);
		world.setBlock(i + 3, j + 7, k + 20, 0);
		world.setBlock(i + 3, j + 8, k + 0, 0);
		world.setBlock(i + 3, j + 8, k + 1, 0);
		world.setBlock(i + 3, j + 8, k + 2, 0);
		world.setBlock(i + 3, j + 8, k + 3, 35);
		world.setBlock(i + 3, j + 8, k + 4, 0);
		world.setBlock(i + 3, j + 8, k + 5, 0);
		world.setBlock(i + 3, j + 8, k + 6, 0);
		world.setBlock(i + 3, j + 8, k + 7, 0);
		world.setBlock(i + 3, j + 8, k + 8, 0);
		world.setBlock(i + 3, j + 8, k + 9, 0);
		world.setBlock(i + 3, j + 8, k + 10, 0);
		world.setBlock(i + 3, j + 8, k + 11, 0);
		world.setBlock(i + 3, j + 8, k + 12, 0);
		world.setBlock(i + 3, j + 8, k + 13, 0);
		world.setBlock(i + 3, j + 8, k + 14, 0);
		world.setBlock(i + 3, j + 8, k + 15, 35);
		world.setBlock(i + 3, j + 8, k + 16, 35);
		world.setBlock(i + 3, j + 8, k + 17, 35);
		world.setBlock(i + 3, j + 8, k + 18, 35);
		world.setBlock(i + 3, j + 8, k + 19, 0);
		world.setBlock(i + 3, j + 8, k + 20, 0);
		world.setBlock(i + 3, j + 9, k + 0, 0);
		world.setBlock(i + 3, j + 9, k + 1, 0);
		world.setBlock(i + 3, j + 9, k + 2, 0);
		world.setBlock(i + 3, j + 9, k + 3, 35);
		world.setBlock(i + 3, j + 9, k + 4, 0);
		world.setBlock(i + 3, j + 9, k + 5, 0);
		world.setBlock(i + 3, j + 9, k + 6, 0);
		world.setBlock(i + 3, j + 9, k + 7, 0);
		world.setBlock(i + 3, j + 9, k + 8, 0);
		world.setBlock(i + 3, j + 9, k + 9, 0);
		world.setBlock(i + 3, j + 9, k + 10, 0);
		world.setBlock(i + 3, j + 9, k + 11, 0);
		world.setBlock(i + 3, j + 9, k + 12, 0);
		world.setBlock(i + 3, j + 9, k + 13, 0);
		world.setBlock(i + 3, j + 9, k + 14, 0);
		world.setBlock(i + 3, j + 9, k + 15, 35);
		world.setBlock(i + 3, j + 9, k + 16, 35);
		world.setBlock(i + 3, j + 9, k + 17, 35);
		world.setBlock(i + 3, j + 9, k + 18, 35);
		world.setBlock(i + 3, j + 9, k + 19, 0);
		world.setBlock(i + 3, j + 9, k + 20, 0);
		world.setBlock(i + 3, j + 10, k + 0, 0);
		world.setBlock(i + 3, j + 10, k + 1, 0);
		world.setBlock(i + 3, j + 10, k + 2, 0);
		world.setBlock(i + 3, j + 10, k + 3, 35);
		world.setBlock(i + 3, j + 10, k + 4, 0);
		world.setBlock(i + 3, j + 10, k + 5, 0);
		world.setBlock(i + 3, j + 10, k + 6, 0);
		world.setBlock(i + 3, j + 10, k + 7, 0);
		world.setBlock(i + 3, j + 10, k + 8, 0);
		world.setBlock(i + 3, j + 10, k + 9, 0);
		world.setBlock(i + 3, j + 10, k + 10, 0);
		world.setBlock(i + 3, j + 10, k + 11, 0);
		world.setBlock(i + 3, j + 10, k + 12, 0);
		world.setBlock(i + 3, j + 10, k + 13, 0);
		world.setBlock(i + 3, j + 10, k + 14, 0);
		world.setBlock(i + 3, j + 10, k + 15, 0);
		world.setBlock(i + 3, j + 10, k + 16, 0);
		world.setBlock(i + 3, j + 10, k + 17, 0);
		world.setBlock(i + 3, j + 10, k + 18, 35);
		world.setBlock(i + 3, j + 10, k + 19, 0);
		world.setBlock(i + 3, j + 10, k + 20, 0);
		world.setBlock(i + 3, j + 11, k + 0, 0);
		world.setBlock(i + 3, j + 11, k + 1, 0);
		world.setBlock(i + 3, j + 11, k + 2, 0);
		world.setBlock(i + 3, j + 11, k + 3, 35);
		world.setBlock(i + 3, j + 11, k + 4, 0);
		world.setBlock(i + 3, j + 11, k + 5, 0);
		world.setBlock(i + 3, j + 11, k + 6, 0);
		world.setBlock(i + 3, j + 11, k + 7, 0);
		world.setBlock(i + 3, j + 11, k + 8, 0);
		world.setBlock(i + 3, j + 11, k + 9, 0);
		world.setBlock(i + 3, j + 11, k + 10, 0);
		world.setBlock(i + 3, j + 11, k + 11, 0);
		world.setBlock(i + 3, j + 11, k + 12, 0);
		world.setBlock(i + 3, j + 11, k + 13, 0);
		world.setBlock(i + 3, j + 11, k + 14, 0);
		world.setBlock(i + 3, j + 11, k + 15, 0);
		world.setBlock(i + 3, j + 11, k + 16, 0);
		world.setBlock(i + 3, j + 11, k + 17, 0);
		world.setBlock(i + 3, j + 11, k + 18, 35);
		world.setBlock(i + 3, j + 11, k + 19, 0);
		world.setBlock(i + 3, j + 11, k + 20, 0);
		world.setBlock(i + 3, j + 12, k + 0, 0);
		world.setBlock(i + 3, j + 12, k + 1, 0);
		world.setBlock(i + 3, j + 12, k + 2, 0);
		world.setBlockAndMetadata(i + 3, j + 12, k + 3, 35, 14);
		world.setBlock(i + 3, j + 12, k + 4, 0);
		world.setBlock(i + 3, j + 12, k + 5, 0);
		world.setBlock(i + 3, j + 12, k + 6, 0);
		world.setBlock(i + 3, j + 12, k + 7, 0);
		world.setBlock(i + 3, j + 12, k + 8, 0);
		world.setBlock(i + 3, j + 12, k + 9, 0);
		world.setBlock(i + 3, j + 12, k + 10, 0);
		world.setBlock(i + 3, j + 12, k + 11, 0);
		world.setBlock(i + 3, j + 12, k + 12, 0);
		world.setBlock(i + 3, j + 12, k + 13, 0);
		world.setBlock(i + 3, j + 12, k + 14, 0);
		world.setBlock(i + 3, j + 12, k + 15, 0);
		world.setBlock(i + 3, j + 12, k + 16, 0);
		world.setBlock(i + 3, j + 12, k + 17, 0);
		world.setBlockAndMetadata(i + 3, j + 12, k + 18, 35, 14);
		world.setBlock(i + 3, j + 12, k + 19, 0);
		world.setBlock(i + 3, j + 12, k + 20, 0);
		world.setBlock(i + 3, j + 13, k + 0, 0);
		world.setBlock(i + 3, j + 13, k + 1, 0);
		world.setBlock(i + 3, j + 13, k + 2, 0);
		world.setBlock(i + 3, j + 13, k + 3, 0);
		world.setBlockAndMetadata(i + 3, j + 13, k + 4, 35, 14);
		world.setBlockAndMetadata(i + 3, j + 13, k + 5, 35, 14);
		world.setBlockAndMetadata(i + 3, j + 13, k + 6, 35, 14);
		world.setBlockAndMetadata(i + 3, j + 13, k + 7, 35, 14);
		world.setBlockAndMetadata(i + 3, j + 13, k + 8, 35, 14);
		world.setBlockAndMetadata(i + 3, j + 13, k + 9, 35, 14);
		world.setBlockAndMetadata(i + 3, j + 13, k + 10, 35, 14);
		world.setBlockAndMetadata(i + 3, j + 13, k + 11, 35, 14);
		world.setBlockAndMetadata(i + 3, j + 13, k + 12, 35, 14);
		world.setBlockAndMetadata(i + 3, j + 13, k + 13, 35, 14);
		world.setBlockAndMetadata(i + 3, j + 13, k + 14, 35, 14);
		world.setBlockAndMetadata(i + 3, j + 13, k + 15, 35, 14);
		world.setBlockAndMetadata(i + 3, j + 13, k + 16, 35, 14);
		world.setBlockAndMetadata(i + 3, j + 13, k + 17, 35, 14);
		world.setBlock(i + 3, j + 13, k + 18, 0);
		world.setBlock(i + 3, j + 13, k + 19, 0);
		world.setBlock(i + 3, j + 13, k + 20, 0);
		world.setBlock(i + 4, j + 0, k + 0, 2);
		world.setBlock(i + 4, j + 0, k + 1, 2);
		world.setBlock(i + 4, j + 0, k + 2, 2);
		world.setBlock(i + 4, j + 0, k + 3, 3);
		world.setBlock(i + 4, j + 0, k + 4, 3);
		world.setBlock(i + 4, j + 0, k + 5, 3);
		world.setBlockAndMetadata(i + 4, j + 0, k + 6, 35, 4);
		world.setBlockAndMetadata(i + 4, j + 0, k + 7, 35, 4);
		world.setBlockAndMetadata(i + 4, j + 0, k + 8, 35, 4);
		world.setBlockAndMetadata(i + 4, j + 0, k + 9, 35, 4);
		world.setBlockAndMetadata(i + 4, j + 0, k + 10, 35, 4);
		world.setBlockAndMetadata(i + 4, j + 0, k + 11, 35, 4);
		world.setBlockAndMetadata(i + 4, j + 0, k + 12, 35, 4);
		world.setBlockAndMetadata(i + 4, j + 0, k + 13, 35, 4);
		world.setBlockAndMetadata(i + 4, j + 0, k + 14, 35, 4);
		world.setBlockAndMetadata(i + 4, j + 0, k + 15, 35, 4);
		world.setBlockAndMetadata(i + 4, j + 0, k + 16, 35, 4);
		world.setBlock(i + 4, j + 0, k + 17, 3);
		world.setBlock(i + 4, j + 0, k + 18, 3);
		world.setBlock(i + 4, j + 0, k + 19, 2);
		world.setBlock(i + 4, j + 0, k + 20, 2);
		world.setBlock(i + 4, j + 1, k + 0, 0);
		world.setBlock(i + 4, j + 1, k + 1, 0);
		world.setBlock(i + 4, j + 1, k + 2, 0);
		world.setBlock(i + 4, j + 1, k + 3, 35);
		world.setBlock(i + 4, j + 1, k + 4, 35);
		world.setBlockAndMetadata(i + 4, j + 1, k + 5, 35, 14);
		world.setBlock(i + 4, j + 1, k + 6, 0);
		world.setBlock(i + 4, j + 1, k + 7, 0);
		world.setBlock(i + 4, j + 1, k + 8, 85);
		world.setBlock(i + 4, j + 1, k + 9, 85);
		world.setBlock(i + 4, j + 1, k + 10, 0);
		world.setBlock(i + 4, j + 1, k + 11, 0);
		world.setBlock(i + 4, j + 1, k + 12, 0);
		world.setBlock(i + 4, j + 1, k + 13, 0);
		world.setBlock(i + 4, j + 1, k + 14, 0);
		world.setBlockAndMetadata(i + 4, j + 1, k + 15, 43, 5);
		world.setBlock(i + 4, j + 1, k + 16, 35);
		world.setBlockAndMetadata(i + 4, j + 1, k + 17, 35, 14);
		world.setBlock(i + 4, j + 1, k + 18, 35);
		world.setBlock(i + 4, j + 1, k + 19, 0);
		world.setBlock(i + 4, j + 1, k + 20, 0);
		world.setBlock(i + 4, j + 2, k + 0, 0);
		world.setBlock(i + 4, j + 2, k + 1, 0);
		world.setBlock(i + 4, j + 2, k + 2, 0);
		world.setBlock(i + 4, j + 2, k + 3, 0);
		world.setBlock(i + 4, j + 2, k + 4, 35);
		world.setBlockAndMetadata(i + 4, j + 2, k + 5, 35, 14);
		world.setBlock(i + 4, j + 2, k + 6, 0);
		world.setBlock(i + 4, j + 2, k + 7, 0);
		world.setBlock(i + 4, j + 2, k + 10, 0);
		world.setBlock(i + 4, j + 2, k + 11, 0);
		world.setBlock(i + 4, j + 2, k + 12, 0);
		world.setBlock(i + 4, j + 2, k + 13, 0);
		world.setBlock(i + 4, j + 2, k + 14, 0);
		world.setBlock(i + 4, j + 2, k + 15, 0);
		world.setBlock(i + 4, j + 2, k + 16, 35);
		world.setBlockAndMetadata(i + 4, j + 2, k + 17, 35, 14);
		world.setBlock(i + 4, j + 2, k + 18, 35);
		world.setBlock(i + 4, j + 2, k + 19, 0);
		world.setBlock(i + 4, j + 2, k + 20, 0);
		world.setBlock(i + 4, j + 3, k + 0, 0);
		world.setBlock(i + 4, j + 3, k + 1, 0);
		world.setBlock(i + 4, j + 3, k + 2, 0);
		world.setBlock(i + 4, j + 3, k + 3, 0);
		world.setBlock(i + 4, j + 3, k + 4, 35);
		world.setBlockAndMetadata(i + 4, j + 3, k + 5, 35, 14);
		world.setBlock(i + 4, j + 3, k + 7, 0);
		world.setBlock(i + 4, j + 3, k + 8, 0);
		world.setBlock(i + 4, j + 3, k + 9, 0);
		world.setBlock(i + 4, j + 3, k + 10, 0);
		world.setBlock(i + 4, j + 3, k + 11, 0);
		world.setBlock(i + 4, j + 3, k + 12, 0);
		world.setBlock(i + 4, j + 3, k + 13, 0);
		world.setBlock(i + 4, j + 3, k + 14, 0);
		world.setBlock(i + 4, j + 3, k + 15, 0);
		world.setBlockAndMetadata(i + 4, j + 3, k + 17, 35, 14);
		world.setBlock(i + 4, j + 3, k + 18, 35);
		world.setBlock(i + 4, j + 3, k + 19, 0);
		world.setBlock(i + 4, j + 3, k + 20, 0);
		world.setBlock(i + 4, j + 4, k + 0, 0);
		world.setBlock(i + 4, j + 4, k + 1, 0);
		world.setBlock(i + 4, j + 4, k + 2, 0);
		world.setBlock(i + 4, j + 4, k + 3, 0);
		world.setBlock(i + 4, j + 4, k + 4, 35);
		world.setBlockAndMetadata(i + 4, j + 4, k + 5, 35, 14);
		world.setBlock(i + 4, j + 4, k + 6, 0);
		world.setBlock(i + 4, j + 4, k + 7, 0);
		world.setBlock(i + 4, j + 4, k + 8, 0);
		world.setBlock(i + 4, j + 4, k + 9, 0);
		world.setBlock(i + 4, j + 4, k + 10, 0);
		world.setBlock(i + 4, j + 4, k + 11, 0);
		world.setBlock(i + 4, j + 4, k + 12, 0);
		world.setBlock(i + 4, j + 4, k + 13, 0);
		world.setBlock(i + 4, j + 4, k + 14, 0);
		world.setBlock(i + 4, j + 4, k + 15, 0);
		world.setBlock(i + 4, j + 4, k + 16, 0);
		world.setBlockAndMetadata(i + 4, j + 4, k + 17, 35, 14);
		world.setBlock(i + 4, j + 4, k + 18, 35);
		world.setBlock(i + 4, j + 4, k + 19, 0);
		world.setBlock(i + 4, j + 4, k + 20, 0);
		world.setBlock(i + 4, j + 5, k + 0, 0);
		world.setBlock(i + 4, j + 5, k + 1, 0);
		world.setBlock(i + 4, j + 5, k + 2, 0);
		world.setBlock(i + 4, j + 5, k + 3, 0);
		world.setBlock(i + 4, j + 5, k + 4, 35);
		world.setBlockAndMetadata(i + 4, j + 5, k + 5, 35, 14);
		world.setBlock(i + 4, j + 5, k + 6, 35);
		world.setBlock(i + 4, j + 5, k + 7, 35);
		world.setBlock(i + 4, j + 5, k + 8, 35);
		world.setBlock(i + 4, j + 5, k + 9, 35);
		world.setBlock(i + 4, j + 5, k + 10, 35);
		world.setBlock(i + 4, j + 5, k + 11, 35);
		world.setBlock(i + 4, j + 5, k + 12, 35);
		world.setBlock(i + 4, j + 5, k + 13, 35);
		world.setBlock(i + 4, j + 5, k + 14, 35);
		world.setBlock(i + 4, j + 5, k + 15, 35);
		world.setBlock(i + 4, j + 5, k + 16, 35);
		world.setBlock(i + 4, j + 5, k + 17, 35);
		world.setBlock(i + 4, j + 5, k + 18, 35);
		world.setBlock(i + 4, j + 5, k + 19, 0);
		world.setBlock(i + 4, j + 5, k + 20, 0);
		world.setBlock(i + 4, j + 6, k + 0, 0);
		world.setBlock(i + 4, j + 6, k + 1, 0);
		world.setBlock(i + 4, j + 6, k + 2, 0);
		world.setBlock(i + 4, j + 6, k + 3, 35);
		world.setBlockAndMetadata(i + 4, j + 6, k + 4, 35, 4);
		world.setBlockAndMetadata(i + 4, j + 6, k + 5, 35, 4);
		world.setBlockAndMetadata(i + 4, j + 6, k + 6, 35, 4);
		world.setBlockAndMetadata(i + 4, j + 6, k + 7, 35, 4);
		world.setBlockAndMetadata(i + 4, j + 6, k + 8, 35, 4);
		world.setBlockAndMetadata(i + 4, j + 6, k + 9, 35, 4);
		world.setBlockAndMetadata(i + 4, j + 6, k + 10, 35, 4);
		world.setBlockAndMetadata(i + 4, j + 6, k + 11, 35, 4);
		world.setBlockAndMetadata(i + 4, j + 6, k + 12, 35, 4);
		world.setBlockAndMetadata(i + 4, j + 6, k + 13, 35, 4);
		world.setBlockAndMetadata(i + 4, j + 6, k + 14, 35, 4);
		world.setBlockAndMetadata(i + 4, j + 6, k + 15, 35, 4);
		world.setBlockAndMetadata(i + 4, j + 6, k + 16, 35, 4);
		world.setBlockAndMetadata(i + 4, j + 6, k + 17, 35, 4);
		world.setBlock(i + 4, j + 6, k + 18, 35);
		world.setBlock(i + 4, j + 6, k + 19, 0);
		world.setBlock(i + 4, j + 6, k + 20, 0);
		world.setBlock(i + 4, j + 7, k + 0, 0);
		world.setBlock(i + 4, j + 7, k + 1, 0);
		world.setBlock(i + 4, j + 7, k + 2, 0);
		world.setBlock(i + 4, j + 7, k + 3, 102);
		world.setBlock(i + 4, j + 7, k + 4, 0);
		world.setBlock(i + 4, j + 7, k + 5, 0);
		world.setBlock(i + 4, j + 7, k + 6, 0);
		world.setBlock(i + 4, j + 7, k + 7, 0);
		world.setBlock(i + 4, j + 7, k + 8, 0);
		world.setBlock(i + 4, j + 7, k + 9, 0);
		world.setBlock(i + 4, j + 7, k + 10, 0);
		world.setBlock(i + 4, j + 7, k + 11, 0);
		world.setBlock(i + 4, j + 7, k + 12, 0);
		world.setBlock(i + 4, j + 7, k + 13, 0);
		world.setBlock(i + 4, j + 7, k + 14, 0);
		world.setBlock(i + 4, j + 7, k + 15, 0);
		world.setBlock(i + 4, j + 7, k + 16, 0);
		world.setBlock(i + 4, j + 7, k + 17, 0);
		world.setBlock(i + 4, j + 7, k + 18, 102);
		world.setBlock(i + 4, j + 7, k + 19, 0);
		world.setBlock(i + 4, j + 7, k + 20, 0);
		world.setBlock(i + 4, j + 8, k + 0, 0);
		world.setBlock(i + 4, j + 8, k + 1, 0);
		world.setBlock(i + 4, j + 8, k + 2, 0);
		world.setBlock(i + 4, j + 8, k + 3, 102);
		world.setBlock(i + 4, j + 8, k + 4, 0);
		world.setBlock(i + 4, j + 8, k + 5, 0);
		world.setBlock(i + 4, j + 8, k + 6, 0);
		world.setBlock(i + 4, j + 8, k + 7, 0);
		world.setBlock(i + 4, j + 8, k + 8, 0);
		world.setBlock(i + 4, j + 8, k + 9, 0);
		world.setBlock(i + 4, j + 8, k + 10, 0);
		world.setBlock(i + 4, j + 8, k + 11, 0);
		world.setBlock(i + 4, j + 8, k + 12, 0);
		world.setBlock(i + 4, j + 8, k + 13, 0);
		world.setBlock(i + 4, j + 8, k + 14, 0);
		world.setBlock(i + 4, j + 8, k + 15, 0);
		world.setBlock(i + 4, j + 8, k + 17, 0);
		world.setBlock(i + 4, j + 8, k + 18, 102);
		world.setBlock(i + 4, j + 8, k + 19, 0);
		world.setBlock(i + 4, j + 8, k + 20, 0);
		world.setBlock(i + 4, j + 9, k + 0, 0);
		world.setBlock(i + 4, j + 9, k + 1, 0);
		world.setBlock(i + 4, j + 9, k + 2, 0);
		world.setBlock(i + 4, j + 9, k + 3, 102);
		world.setBlock(i + 4, j + 9, k + 4, 0);
		world.setBlock(i + 4, j + 9, k + 5, 0);
		world.setBlock(i + 4, j + 9, k + 6, 0);
		world.setBlock(i + 4, j + 9, k + 7, 0);
		world.setBlock(i + 4, j + 9, k + 8, 0);
		world.setBlock(i + 4, j + 9, k + 9, 0);
		world.setBlock(i + 4, j + 9, k + 10, 0);
		world.setBlock(i + 4, j + 9, k + 11, 0);
		world.setBlock(i + 4, j + 9, k + 12, 0);
		world.setBlock(i + 4, j + 9, k + 13, 0);
		world.setBlock(i + 4, j + 9, k + 14, 0);
		world.setBlock(i + 4, j + 9, k + 15, 0);
		world.setBlock(i + 4, j + 9, k + 16, 0);
		world.setBlock(i + 4, j + 9, k + 17, 0);
		world.setBlock(i + 4, j + 9, k + 18, 102);
		world.setBlock(i + 4, j + 9, k + 19, 0);
		world.setBlock(i + 4, j + 9, k + 20, 0);
		world.setBlock(i + 4, j + 10, k + 0, 0);
		world.setBlock(i + 4, j + 10, k + 1, 0);
		world.setBlock(i + 4, j + 10, k + 2, 0);
		world.setBlock(i + 4, j + 10, k + 3, 102);
		world.setBlock(i + 4, j + 10, k + 4, 0);
		world.setBlock(i + 4, j + 10, k + 5, 0);
		world.setBlock(i + 4, j + 10, k + 6, 0);
		world.setBlock(i + 4, j + 10, k + 7, 0);
		world.setBlock(i + 4, j + 10, k + 8, 0);
		world.setBlock(i + 4, j + 10, k + 9, 0);
		world.setBlock(i + 4, j + 10, k + 10, 0);
		world.setBlock(i + 4, j + 10, k + 11, 0);
		world.setBlock(i + 4, j + 10, k + 12, 0);
		world.setBlock(i + 4, j + 10, k + 13, 0);
		world.setBlock(i + 4, j + 10, k + 14, 0);
		world.setBlock(i + 4, j + 10, k + 15, 0);
		world.setBlock(i + 4, j + 10, k + 16, 0);
		world.setBlock(i + 4, j + 10, k + 17, 0);
		world.setBlock(i + 4, j + 10, k + 18, 102);
		world.setBlock(i + 4, j + 10, k + 19, 0);
		world.setBlock(i + 4, j + 10, k + 20, 0);
		world.setBlock(i + 4, j + 11, k + 0, 0);
		world.setBlock(i + 4, j + 11, k + 1, 0);
		world.setBlock(i + 4, j + 11, k + 2, 0);
		world.setBlock(i + 4, j + 11, k + 3, 102);
		world.setBlock(i + 4, j + 11, k + 4, 0);
		world.setBlock(i + 4, j + 11, k + 5, 0);
		world.setBlock(i + 4, j + 11, k + 6, 0);
		world.setBlock(i + 4, j + 11, k + 7, 0);
		world.setBlock(i + 4, j + 11, k + 8, 0);
		world.setBlock(i + 4, j + 11, k + 9, 0);
		world.setBlock(i + 4, j + 11, k + 10, 0);
		world.setBlock(i + 4, j + 11, k + 11, 0);
		world.setBlock(i + 4, j + 11, k + 12, 0);
		world.setBlock(i + 4, j + 11, k + 13, 0);
		world.setBlock(i + 4, j + 11, k + 14, 0);
		world.setBlock(i + 4, j + 11, k + 15, 0);
		world.setBlock(i + 4, j + 11, k + 16, 0);
		world.setBlock(i + 4, j + 11, k + 17, 0);
		world.setBlock(i + 4, j + 11, k + 18, 102);
		world.setBlock(i + 4, j + 11, k + 19, 0);
		world.setBlock(i + 4, j + 11, k + 20, 0);
		world.setBlock(i + 4, j + 12, k + 0, 0);
		world.setBlock(i + 4, j + 12, k + 1, 0);
		world.setBlock(i + 4, j + 12, k + 2, 0);
		world.setBlockAndMetadata(i + 4, j + 12, k + 3, 35, 14);
		world.setBlock(i + 4, j + 12, k + 4, 0);
		world.setBlock(i + 4, j + 12, k + 5, 0);
		world.setBlock(i + 4, j + 12, k + 6, 0);
		world.setBlock(i + 4, j + 12, k + 7, 0);
		world.setBlock(i + 4, j + 12, k + 8, 0);
		world.setBlock(i + 4, j + 12, k + 9, 0);
		world.setBlock(i + 4, j + 12, k + 10, 0);
		world.setBlock(i + 4, j + 12, k + 11, 0);
		world.setBlock(i + 4, j + 12, k + 12, 0);
		world.setBlock(i + 4, j + 12, k + 13, 0);
		world.setBlock(i + 4, j + 12, k + 14, 0);
		world.setBlock(i + 4, j + 12, k + 15, 0);
		world.setBlock(i + 4, j + 12, k + 16, 0);
		world.setBlock(i + 4, j + 12, k + 17, 0);
		world.setBlockAndMetadata(i + 4, j + 12, k + 18, 35, 14);
		world.setBlock(i + 4, j + 12, k + 19, 0);
		world.setBlock(i + 4, j + 12, k + 20, 0);
		world.setBlock(i + 4, j + 13, k + 0, 0);
		world.setBlock(i + 4, j + 13, k + 1, 0);
		world.setBlock(i + 4, j + 13, k + 2, 0);
		world.setBlock(i + 4, j + 13, k + 3, 0);
		world.setBlockAndMetadata(i + 4, j + 13, k + 4, 35, 14);
		world.setBlockAndMetadata(i + 4, j + 13, k + 5, 35, 14);
		world.setBlockAndMetadata(i + 4, j + 13, k + 6, 35, 14);
		world.setBlockAndMetadata(i + 4, j + 13, k + 7, 35, 14);
		world.setBlockAndMetadata(i + 4, j + 13, k + 8, 35, 14);
		world.setBlockAndMetadata(i + 4, j + 13, k + 9, 35, 14);
		world.setBlockAndMetadata(i + 4, j + 13, k + 10, 35, 14);
		world.setBlockAndMetadata(i + 4, j + 13, k + 11, 35, 14);
		world.setBlockAndMetadata(i + 4, j + 13, k + 12, 35, 14);
		world.setBlockAndMetadata(i + 4, j + 13, k + 13, 35, 14);
		world.setBlockAndMetadata(i + 4, j + 13, k + 14, 35, 14);
		world.setBlockAndMetadata(i + 4, j + 13, k + 15, 35, 14);
		world.setBlockAndMetadata(i + 4, j + 13, k + 16, 35, 14);
		world.setBlockAndMetadata(i + 4, j + 13, k + 17, 35, 14);
		world.setBlock(i + 4, j + 13, k + 18, 0);
		world.setBlock(i + 4, j + 13, k + 19, 0);
		world.setBlock(i + 4, j + 13, k + 20, 0);
		world.setBlock(i + 5, j + 0, k + 0, 2);
		world.setBlock(i + 5, j + 0, k + 1, 2);
		world.setBlock(i + 5, j + 0, k + 2, 2);
		world.setBlock(i + 5, j + 0, k + 3, 3);
		world.setBlock(i + 5, j + 0, k + 4, 3);
		world.setBlock(i + 5, j + 0, k + 5, 3);
		world.setBlockAndMetadata(i + 5, j + 0, k + 6, 35, 4);
		world.setBlockAndMetadata(i + 5, j + 0, k + 7, 35, 4);
		world.setBlockAndMetadata(i + 5, j + 0, k + 8, 35, 4);
		world.setBlockAndMetadata(i + 5, j + 0, k + 9, 35, 4);
		world.setBlockAndMetadata(i + 5, j + 0, k + 10, 35, 4);
		world.setBlockAndMetadata(i + 5, j + 0, k + 11, 35, 4);
		world.setBlockAndMetadata(i + 5, j + 0, k + 12, 35, 4);
		world.setBlockAndMetadata(i + 5, j + 0, k + 13, 35, 4);
		world.setBlockAndMetadata(i + 5, j + 0, k + 14, 35, 4);
		world.setBlockAndMetadata(i + 5, j + 0, k + 15, 35, 4);
		world.setBlockAndMetadata(i + 5, j + 0, k + 16, 35, 4);
		world.setBlock(i + 5, j + 0, k + 17, 3);
		world.setBlock(i + 5, j + 0, k + 18, 3);
		world.setBlock(i + 5, j + 0, k + 19, 2);
		world.setBlock(i + 5, j + 0, k + 20, 2);
		world.setBlock(i + 5, j + 1, k + 0, 0);
		world.setBlock(i + 5, j + 1, k + 1, 0);
		world.setBlock(i + 5, j + 1, k + 2, 0);
		world.setBlock(i + 5, j + 1, k + 3, 35);
		world.setBlock(i + 5, j + 1, k + 4, 35);
		world.setBlockAndMetadata(i + 5, j + 1, k + 5, 35, 14);
		world.setBlock(i + 5, j + 1, k + 6, 0);
		world.setBlock(i + 5, j + 1, k + 7, 0);
		world.setBlock(i + 5, j + 1, k + 8, 85);
		world.setBlock(i + 5, j + 1, k + 9, 85);
		world.setBlock(i + 5, j + 1, k + 11, 0);
		world.setBlock(i + 5, j + 1, k + 12, 0);
		world.setBlock(i + 5, j + 1, k + 13, 0);
		world.setBlock(i + 5, j + 1, k + 14, 0);
		world.setBlock(i + 5, j + 1, k + 15, 0);
		world.setBlock(i + 5, j + 1, k + 16, 0);
		world.setBlockAndMetadata(i + 5, j + 1, k + 17, 35, 14);
		world.setBlock(i + 5, j + 1, k + 18, 35);
		world.setBlock(i + 5, j + 1, k + 19, 0);
		world.setBlock(i + 5, j + 1, k + 20, 0);
		world.setBlock(i + 5, j + 2, k + 0, 0);
		world.setBlock(i + 5, j + 2, k + 1, 0);
		world.setBlock(i + 5, j + 2, k + 2, 0);
		world.setBlock(i + 5, j + 2, k + 3, 0);
		world.setBlock(i + 5, j + 2, k + 4, 35);
		world.setBlockAndMetadata(i + 5, j + 2, k + 5, 35, 14);
		world.setBlock(i + 5, j + 2, k + 6, 0);
		world.setBlock(i + 5, j + 2, k + 7, 0);

		generate2(world, rand, i, j, k);
		return true;
	}

	public boolean generate2(World world, Random rand, int i, int j, int k) {
		world.setBlock(i + 5, j + 2, k + 10, 0);
		world.setBlock(i + 5, j + 2, k + 11, 0);
		world.setBlock(i + 5, j + 2, k + 12, 0);
		world.setBlock(i + 5, j + 2, k + 13, 0);
		world.setBlock(i + 5, j + 2, k + 14, 0);
		world.setBlock(i + 5, j + 2, k + 15, 0);
		world.setBlock(i + 5, j + 2, k + 16, 0);
		world.setBlockAndMetadata(i + 5, j + 2, k + 17, 35, 14);
		world.setBlock(i + 5, j + 2, k + 18, 35);
		world.setBlock(i + 5, j + 2, k + 19, 0);
		world.setBlock(i + 5, j + 2, k + 20, 0);
		world.setBlock(i + 5, j + 3, k + 0, 0);
		world.setBlock(i + 5, j + 3, k + 1, 0);
		world.setBlock(i + 5, j + 3, k + 2, 0);
		world.setBlock(i + 5, j + 3, k + 3, 0);
		world.setBlock(i + 5, j + 3, k + 4, 35);
		world.setBlockAndMetadata(i + 5, j + 3, k + 5, 35, 14);
		world.setBlock(i + 5, j + 3, k + 7, 0);
		world.setBlock(i + 5, j + 3, k + 8, 0);
		world.setBlock(i + 5, j + 3, k + 9, 0);
		world.setBlock(i + 5, j + 3, k + 10, 0);
		world.setBlock(i + 5, j + 3, k + 11, 0);
		world.setBlock(i + 5, j + 3, k + 12, 0);
		world.setBlock(i + 5, j + 3, k + 13, 0);
		world.setBlock(i + 5, j + 3, k + 14, 0);
		world.setBlock(i + 5, j + 3, k + 15, 0);
		world.setBlockAndMetadata(i + 5, j + 3, k + 17, 35, 14);
		world.setBlock(i + 5, j + 3, k + 18, 35);
		world.setBlock(i + 5, j + 3, k + 19, 0);
		world.setBlock(i + 5, j + 3, k + 20, 0);
		world.setBlock(i + 5, j + 4, k + 0, 0);
		world.setBlock(i + 5, j + 4, k + 1, 0);
		world.setBlock(i + 5, j + 4, k + 2, 0);
		world.setBlock(i + 5, j + 4, k + 3, 0);
		world.setBlock(i + 5, j + 4, k + 4, 35);
		world.setBlockAndMetadata(i + 5, j + 4, k + 5, 35, 14);
		world.setBlock(i + 5, j + 4, k + 6, 0);
		world.setBlock(i + 5, j + 4, k + 7, 0);
		world.setBlock(i + 5, j + 4, k + 8, 0);
		world.setBlock(i + 5, j + 4, k + 9, 0);
		world.setBlock(i + 5, j + 4, k + 10, 0);
		world.setBlock(i + 5, j + 4, k + 11, 0);
		world.setBlock(i + 5, j + 4, k + 12, 0);
		world.setBlock(i + 5, j + 4, k + 13, 0);
		world.setBlock(i + 5, j + 4, k + 14, 0);
		world.setBlock(i + 5, j + 4, k + 15, 0);
		world.setBlock(i + 5, j + 4, k + 16, 0);
		world.setBlockAndMetadata(i + 5, j + 4, k + 17, 35, 14);
		world.setBlock(i + 5, j + 4, k + 18, 35);
		world.setBlock(i + 5, j + 4, k + 19, 0);
		world.setBlock(i + 5, j + 4, k + 20, 0);
		world.setBlock(i + 5, j + 5, k + 0, 0);
		world.setBlock(i + 5, j + 5, k + 1, 0);
		world.setBlock(i + 5, j + 5, k + 2, 0);
		world.setBlock(i + 5, j + 5, k + 3, 0);
		world.setBlock(i + 5, j + 5, k + 4, 35);
		world.setBlockAndMetadata(i + 5, j + 5, k + 5, 35, 14);
		world.setBlock(i + 5, j + 5, k + 6, 35);
		world.setBlock(i + 5, j + 5, k + 7, 35);
		world.setBlock(i + 5, j + 5, k + 8, 35);
		world.setBlock(i + 5, j + 5, k + 9, 35);
		world.setBlock(i + 5, j + 5, k + 10, 35);
		world.setBlock(i + 5, j + 5, k + 11, 35);
		world.setBlock(i + 5, j + 5, k + 12, 35);
		world.setBlock(i + 5, j + 5, k + 13, 35);
		world.setBlock(i + 5, j + 5, k + 14, 35);
		world.setBlock(i + 5, j + 5, k + 15, 35);
		world.setBlock(i + 5, j + 5, k + 16, 35);
		world.setBlock(i + 5, j + 5, k + 17, 35);
		world.setBlock(i + 5, j + 5, k + 18, 35);
		world.setBlock(i + 5, j + 5, k + 19, 0);
		world.setBlock(i + 5, j + 5, k + 20, 0);
		world.setBlock(i + 5, j + 6, k + 0, 0);
		world.setBlock(i + 5, j + 6, k + 1, 0);
		world.setBlock(i + 5, j + 6, k + 2, 0);
		world.setBlock(i + 5, j + 6, k + 3, 35);
		world.setBlockAndMetadata(i + 5, j + 6, k + 4, 35, 4);
		world.setBlockAndMetadata(i + 5, j + 6, k + 5, 35, 4);
		world.setBlockAndMetadata(i + 5, j + 6, k + 6, 35, 4);
		world.setBlockAndMetadata(i + 5, j + 6, k + 7, 35, 4);
		world.setBlockAndMetadata(i + 5, j + 6, k + 8, 35, 4);
		world.setBlockAndMetadata(i + 5, j + 6, k + 9, 35, 4);
		world.setBlockAndMetadata(i + 5, j + 6, k + 10, 35, 4);
		world.setBlockAndMetadata(i + 5, j + 6, k + 11, 35, 4);
		world.setBlockAndMetadata(i + 5, j + 6, k + 12, 35, 4);
		world.setBlockAndMetadata(i + 5, j + 6, k + 13, 35, 4);
		world.setBlockAndMetadata(i + 5, j + 6, k + 14, 35, 4);
		world.setBlockAndMetadata(i + 5, j + 6, k + 15, 35, 4);
		world.setBlockAndMetadata(i + 5, j + 6, k + 16, 35, 4);
		world.setBlockAndMetadata(i + 5, j + 6, k + 17, 35, 4);
		world.setBlock(i + 5, j + 6, k + 18, 35);
		world.setBlock(i + 5, j + 6, k + 19, 0);
		world.setBlock(i + 5, j + 6, k + 20, 0);
		world.setBlock(i + 5, j + 7, k + 0, 0);
		world.setBlock(i + 5, j + 7, k + 1, 0);
		world.setBlock(i + 5, j + 7, k + 2, 0);
		world.setBlock(i + 5, j + 7, k + 3, 102);
		world.setBlock(i + 5, j + 7, k + 4, 0);
		world.setBlock(i + 5, j + 7, k + 5, 0);
		world.setBlock(i + 5, j + 7, k + 6, 0);
		world.setBlock(i + 5, j + 7, k + 7, 0);
		world.setBlock(i + 5, j + 7, k + 8, 0);
		world.setBlock(i + 5, j + 7, k + 9, 0);
		world.setBlock(i + 5, j + 7, k + 10, 0);
		world.setBlock(i + 5, j + 7, k + 11, 0);
		world.setBlock(i + 5, j + 7, k + 12, 0);
		world.setBlock(i + 5, j + 7, k + 13, 0);
		world.setBlock(i + 5, j + 7, k + 14, 0);
		world.setBlock(i + 5, j + 7, k + 15, 0);
		world.setBlockAndMetadata(i + 5, j + 7, k + 16, 35, 14);
		world.setBlockAndMetadata(i + 5, j + 7, k + 17, 54, 2);
		world.setBlock(i + 5, j + 7, k + 18, 102);
		world.setBlock(i + 5, j + 7, k + 19, 0);
		world.setBlock(i + 5, j + 7, k + 20, 0);
		world.setBlock(i + 5, j + 8, k + 0, 0);
		world.setBlock(i + 5, j + 8, k + 1, 0);
		world.setBlock(i + 5, j + 8, k + 2, 0);
		world.setBlock(i + 5, j + 8, k + 3, 102);
		world.setBlock(i + 5, j + 8, k + 4, 0);
		world.setBlock(i + 5, j + 8, k + 5, 0);
		world.setBlock(i + 5, j + 8, k + 6, 0);
		world.setBlock(i + 5, j + 8, k + 7, 0);
		world.setBlock(i + 5, j + 8, k + 8, 0);
		world.setBlock(i + 5, j + 8, k + 9, 0);
		world.setBlock(i + 5, j + 8, k + 10, 0);
		world.setBlock(i + 5, j + 8, k + 11, 0);
		world.setBlock(i + 5, j + 8, k + 12, 0);
		world.setBlock(i + 5, j + 8, k + 13, 0);
		world.setBlock(i + 5, j + 8, k + 14, 0);
		world.setBlock(i + 5, j + 8, k + 15, 0);
		world.setBlock(i + 5, j + 8, k + 16, 0);
		world.setBlock(i + 5, j + 8, k + 17, 0);
		world.setBlock(i + 5, j + 8, k + 18, 102);
		world.setBlock(i + 5, j + 8, k + 19, 0);
		world.setBlock(i + 5, j + 8, k + 20, 0);
		world.setBlock(i + 5, j + 9, k + 0, 0);
		world.setBlock(i + 5, j + 9, k + 1, 0);
		world.setBlock(i + 5, j + 9, k + 2, 0);
		world.setBlock(i + 5, j + 9, k + 3, 102);
		world.setBlock(i + 5, j + 9, k + 4, 0);
		world.setBlock(i + 5, j + 9, k + 5, 0);
		world.setBlock(i + 5, j + 9, k + 6, 0);
		world.setBlock(i + 5, j + 9, k + 7, 0);
		world.setBlock(i + 5, j + 9, k + 8, 0);
		world.setBlock(i + 5, j + 9, k + 9, 0);
		world.setBlock(i + 5, j + 9, k + 10, 0);
		world.setBlock(i + 5, j + 9, k + 11, 0);
		world.setBlock(i + 5, j + 9, k + 12, 0);
		world.setBlock(i + 5, j + 9, k + 13, 0);
		world.setBlock(i + 5, j + 9, k + 14, 0);
		world.setBlock(i + 5, j + 9, k + 15, 0);
		world.setBlock(i + 5, j + 9, k + 16, 0);
		world.setBlock(i + 5, j + 9, k + 17, 0);
		world.setBlock(i + 5, j + 9, k + 18, 102);
		world.setBlock(i + 5, j + 9, k + 19, 0);
		world.setBlock(i + 5, j + 9, k + 20, 0);
		world.setBlock(i + 5, j + 10, k + 0, 0);
		world.setBlock(i + 5, j + 10, k + 1, 0);
		world.setBlock(i + 5, j + 10, k + 2, 0);
		world.setBlock(i + 5, j + 10, k + 3, 102);
		world.setBlock(i + 5, j + 10, k + 4, 0);
		world.setBlock(i + 5, j + 10, k + 5, 0);
		world.setBlock(i + 5, j + 10, k + 6, 0);
		world.setBlock(i + 5, j + 10, k + 7, 0);
		world.setBlock(i + 5, j + 10, k + 8, 0);
		world.setBlock(i + 5, j + 10, k + 9, 0);
		world.setBlock(i + 5, j + 10, k + 10, 0);
		world.setBlock(i + 5, j + 10, k + 11, 0);
		world.setBlock(i + 5, j + 10, k + 12, 0);
		world.setBlock(i + 5, j + 10, k + 13, 0);
		world.setBlock(i + 5, j + 10, k + 14, 0);
		world.setBlock(i + 5, j + 10, k + 15, 0);
		world.setBlock(i + 5, j + 10, k + 16, 0);
		world.setBlock(i + 5, j + 10, k + 17, 0);
		world.setBlock(i + 5, j + 10, k + 18, 102);
		world.setBlock(i + 5, j + 10, k + 19, 0);
		world.setBlock(i + 5, j + 10, k + 20, 0);
		world.setBlock(i + 5, j + 11, k + 0, 0);
		world.setBlock(i + 5, j + 11, k + 1, 0);
		world.setBlock(i + 5, j + 11, k + 2, 0);
		world.setBlock(i + 5, j + 11, k + 3, 102);
		world.setBlock(i + 5, j + 11, k + 4, 0);
		world.setBlock(i + 5, j + 11, k + 5, 0);
		world.setBlock(i + 5, j + 11, k + 6, 0);
		world.setBlock(i + 5, j + 11, k + 7, 0);
		world.setBlock(i + 5, j + 11, k + 8, 0);
		world.setBlock(i + 5, j + 11, k + 9, 0);
		world.setBlock(i + 5, j + 11, k + 10, 0);
		world.setBlock(i + 5, j + 11, k + 11, 0);
		world.setBlock(i + 5, j + 11, k + 12, 0);
		world.setBlock(i + 5, j + 11, k + 13, 0);
		world.setBlock(i + 5, j + 11, k + 14, 0);
		world.setBlock(i + 5, j + 11, k + 15, 0);
		world.setBlock(i + 5, j + 11, k + 16, 0);
		world.setBlock(i + 5, j + 11, k + 17, 0);
		world.setBlock(i + 5, j + 11, k + 18, 102);
		world.setBlock(i + 5, j + 11, k + 19, 0);
		world.setBlock(i + 5, j + 11, k + 20, 0);
		world.setBlock(i + 5, j + 12, k + 0, 0);
		world.setBlock(i + 5, j + 12, k + 1, 0);
		world.setBlock(i + 5, j + 12, k + 2, 0);
		world.setBlockAndMetadata(i + 5, j + 12, k + 3, 35, 14);
		world.setBlock(i + 5, j + 12, k + 4, 0);
		world.setBlock(i + 5, j + 12, k + 5, 0);
		world.setBlock(i + 5, j + 12, k + 6, 0);
		world.setBlock(i + 5, j + 12, k + 7, 0);
		world.setBlock(i + 5, j + 12, k + 8, 0);
		world.setBlock(i + 5, j + 12, k + 9, 0);
		world.setBlock(i + 5, j + 12, k + 10, 0);
		world.setBlock(i + 5, j + 12, k + 11, 0);
		world.setBlock(i + 5, j + 12, k + 12, 0);
		world.setBlock(i + 5, j + 12, k + 13, 0);
		world.setBlock(i + 5, j + 12, k + 14, 0);
		world.setBlock(i + 5, j + 12, k + 15, 0);
		world.setBlock(i + 5, j + 12, k + 16, 0);
		world.setBlock(i + 5, j + 12, k + 17, 0);
		world.setBlockAndMetadata(i + 5, j + 12, k + 18, 35, 14);
		world.setBlock(i + 5, j + 12, k + 19, 0);
		world.setBlock(i + 5, j + 12, k + 20, 0);
		world.setBlock(i + 5, j + 13, k + 0, 0);
		world.setBlock(i + 5, j + 13, k + 1, 0);
		world.setBlock(i + 5, j + 13, k + 2, 0);
		world.setBlock(i + 5, j + 13, k + 3, 0);
		world.setBlockAndMetadata(i + 5, j + 13, k + 4, 35, 14);
		world.setBlockAndMetadata(i + 5, j + 13, k + 5, 35, 14);
		world.setBlockAndMetadata(i + 5, j + 13, k + 6, 35, 14);
		world.setBlockAndMetadata(i + 5, j + 13, k + 7, 35, 14);
		world.setBlockAndMetadata(i + 5, j + 13, k + 8, 35, 14);
		world.setBlockAndMetadata(i + 5, j + 13, k + 9, 35, 14);
		world.setBlockAndMetadata(i + 5, j + 13, k + 10, 35, 14);
		world.setBlockAndMetadata(i + 5, j + 13, k + 11, 35, 14);
		world.setBlockAndMetadata(i + 5, j + 13, k + 12, 35, 14);
		world.setBlockAndMetadata(i + 5, j + 13, k + 13, 35, 14);
		world.setBlockAndMetadata(i + 5, j + 13, k + 14, 35, 14);
		world.setBlockAndMetadata(i + 5, j + 13, k + 15, 35, 14);
		world.setBlockAndMetadata(i + 5, j + 13, k + 16, 35, 14);
		world.setBlockAndMetadata(i + 5, j + 13, k + 17, 35, 14);
		world.setBlock(i + 5, j + 13, k + 18, 0);
		world.setBlock(i + 5, j + 13, k + 19, 0);
		world.setBlock(i + 5, j + 13, k + 20, 0);
		world.setBlock(i + 6, j + 0, k + 0, 2);
		world.setBlock(i + 6, j + 0, k + 1, 2);
		world.setBlock(i + 6, j + 0, k + 2, 2);
		world.setBlock(i + 6, j + 0, k + 3, 3);
		world.setBlock(i + 6, j + 0, k + 4, 3);
		world.setBlock(i + 6, j + 0, k + 5, 3);
		world.setBlockAndMetadata(i + 6, j + 0, k + 6, 35, 4);
		world.setBlockAndMetadata(i + 6, j + 0, k + 7, 35, 4);
		world.setBlockAndMetadata(i + 6, j + 0, k + 8, 35, 4);
		world.setBlockAndMetadata(i + 6, j + 0, k + 9, 35, 4);
		world.setBlockAndMetadata(i + 6, j + 0, k + 10, 35, 4);
		world.setBlockAndMetadata(i + 6, j + 0, k + 11, 35, 4);
		world.setBlockAndMetadata(i + 6, j + 0, k + 12, 35, 4);
		world.setBlockAndMetadata(i + 6, j + 0, k + 13, 35, 4);
		world.setBlockAndMetadata(i + 6, j + 0, k + 14, 35, 4);
		world.setBlockAndMetadata(i + 6, j + 0, k + 15, 35, 4);
		world.setBlockAndMetadata(i + 6, j + 0, k + 16, 35, 4);
		world.setBlock(i + 6, j + 0, k + 17, 3);
		world.setBlock(i + 6, j + 0, k + 18, 3);
		world.setBlock(i + 6, j + 0, k + 19, 2);
		world.setBlock(i + 6, j + 0, k + 20, 2);
		world.setBlock(i + 6, j + 1, k + 0, 0);
		world.setBlock(i + 6, j + 1, k + 1, 0);
		world.setBlock(i + 6, j + 1, k + 2, 0);
		world.setBlock(i + 6, j + 1, k + 3, 35);
		world.setBlock(i + 6, j + 1, k + 4, 35);
		world.setBlockAndMetadata(i + 6, j + 1, k + 5, 35, 14);
		world.setBlock(i + 6, j + 1, k + 6, 0);
		world.setBlock(i + 6, j + 1, k + 7, 0);
		world.setBlock(i + 6, j + 1, k + 8, 0);
		world.setBlock(i + 6, j + 1, k + 9, 0);
		world.setBlock(i + 6, j + 1, k + 10, 0);
		world.setBlock(i + 6, j + 1, k + 12, 0);
		world.setBlock(i + 6, j + 1, k + 13, 0);
		world.setBlock(i + 6, j + 1, k + 14, 0);
		world.setBlock(i + 6, j + 1, k + 15, 0);
		world.setBlock(i + 6, j + 1, k + 16, 0);
		world.setBlockAndMetadata(i + 6, j + 1, k + 17, 35, 14);
		world.setBlock(i + 6, j + 1, k + 18, 35);
		world.setBlock(i + 6, j + 1, k + 19, 0);
		world.setBlock(i + 6, j + 1, k + 20, 0);
		world.setBlock(i + 6, j + 2, k + 0, 0);
		world.setBlock(i + 6, j + 2, k + 1, 0);
		world.setBlock(i + 6, j + 2, k + 2, 0);
		world.setBlock(i + 6, j + 2, k + 3, 0);
		world.setBlock(i + 6, j + 2, k + 4, 35);
		world.setBlockAndMetadata(i + 6, j + 2, k + 5, 35, 14);
		world.setBlock(i + 6, j + 2, k + 6, 0);
		world.setBlock(i + 6, j + 2, k + 7, 0);
		world.setBlock(i + 6, j + 2, k + 8, 0);
		world.setBlock(i + 6, j + 2, k + 9, 0);
		world.setBlock(i + 6, j + 2, k + 10, 0);
		world.setBlock(i + 6, j + 2, k + 11, 0);
		world.setBlock(i + 6, j + 2, k + 12, 0);
		world.setBlock(i + 6, j + 2, k + 13, 0);
		world.setBlock(i + 6, j + 2, k + 14, 0);
		world.setBlock(i + 6, j + 2, k + 15, 0);
		world.setBlock(i + 6, j + 2, k + 16, 0);
		world.setBlockAndMetadata(i + 6, j + 2, k + 17, 35, 14);
		world.setBlock(i + 6, j + 2, k + 18, 35);
		world.setBlock(i + 6, j + 2, k + 19, 0);
		world.setBlock(i + 6, j + 2, k + 20, 0);
		world.setBlock(i + 6, j + 3, k + 0, 0);
		world.setBlock(i + 6, j + 3, k + 1, 0);
		world.setBlock(i + 6, j + 3, k + 2, 0);
		world.setBlock(i + 6, j + 3, k + 3, 0);
		world.setBlock(i + 6, j + 3, k + 4, 35);
		world.setBlockAndMetadata(i + 6, j + 3, k + 5, 35, 14);
		world.setBlock(i + 6, j + 3, k + 7, 0);
		world.setBlock(i + 6, j + 3, k + 8, 0);
		world.setBlock(i + 6, j + 3, k + 9, 0);
		world.setBlock(i + 6, j + 3, k + 10, 0);
		world.setBlock(i + 6, j + 3, k + 11, 0);
		world.setBlock(i + 6, j + 3, k + 12, 0);
		world.setBlock(i + 6, j + 3, k + 13, 0);
		world.setBlock(i + 6, j + 3, k + 14, 0);
		world.setBlock(i + 6, j + 3, k + 15, 0);
		world.setBlockAndMetadata(i + 6, j + 3, k + 17, 35, 14);
		world.setBlock(i + 6, j + 3, k + 18, 35);
		world.setBlock(i + 6, j + 3, k + 19, 0);
		world.setBlock(i + 6, j + 3, k + 20, 0);
		world.setBlock(i + 6, j + 4, k + 0, 0);
		world.setBlock(i + 6, j + 4, k + 1, 0);
		world.setBlock(i + 6, j + 4, k + 2, 0);
		world.setBlock(i + 6, j + 4, k + 3, 0);
		world.setBlock(i + 6, j + 4, k + 4, 35);
		world.setBlockAndMetadata(i + 6, j + 4, k + 5, 35, 14);
		world.setBlock(i + 6, j + 4, k + 6, 0);
		world.setBlock(i + 6, j + 4, k + 7, 0);
		world.setBlock(i + 6, j + 4, k + 8, 0);
		world.setBlock(i + 6, j + 4, k + 9, 0);
		world.setBlock(i + 6, j + 4, k + 10, 0);
		world.setBlock(i + 6, j + 4, k + 11, 0);
		world.setBlock(i + 6, j + 4, k + 12, 0);
		world.setBlock(i + 6, j + 4, k + 13, 0);
		world.setBlock(i + 6, j + 4, k + 14, 0);
		world.setBlock(i + 6, j + 4, k + 15, 0);
		world.setBlock(i + 6, j + 4, k + 16, 0);
		world.setBlockAndMetadata(i + 6, j + 4, k + 17, 35, 14);
		world.setBlock(i + 6, j + 4, k + 18, 35);
		world.setBlock(i + 6, j + 4, k + 19, 0);
		world.setBlock(i + 6, j + 4, k + 20, 0);
		world.setBlock(i + 6, j + 5, k + 0, 0);
		world.setBlock(i + 6, j + 5, k + 1, 0);
		world.setBlock(i + 6, j + 5, k + 2, 0);
		world.setBlock(i + 6, j + 5, k + 3, 0);
		world.setBlock(i + 6, j + 5, k + 4, 35);
		world.setBlockAndMetadata(i + 6, j + 5, k + 5, 35, 14);
		world.setBlock(i + 6, j + 5, k + 6, 35);
		world.setBlock(i + 6, j + 5, k + 7, 35);
		world.setBlock(i + 6, j + 5, k + 8, 35);
		world.setBlock(i + 6, j + 5, k + 9, 35);
		world.setBlock(i + 6, j + 5, k + 10, 35);
		world.setBlock(i + 6, j + 5, k + 11, 35);
		world.setBlock(i + 6, j + 5, k + 12, 35);
		world.setBlock(i + 6, j + 5, k + 13, 35);
		world.setBlock(i + 6, j + 5, k + 14, 35);
		world.setBlock(i + 6, j + 5, k + 15, 35);
		world.setBlock(i + 6, j + 5, k + 16, 35);
		world.setBlock(i + 6, j + 5, k + 17, 35);
		world.setBlock(i + 6, j + 5, k + 18, 35);
		world.setBlock(i + 6, j + 5, k + 19, 0);
		world.setBlock(i + 6, j + 5, k + 20, 0);
		world.setBlock(i + 6, j + 6, k + 0, 0);
		world.setBlock(i + 6, j + 6, k + 1, 0);
		world.setBlock(i + 6, j + 6, k + 2, 0);
		world.setBlock(i + 6, j + 6, k + 3, 35);
		world.setBlockAndMetadata(i + 6, j + 6, k + 4, 35, 4);
		world.setBlockAndMetadata(i + 6, j + 6, k + 5, 35, 4);
		world.setBlockAndMetadata(i + 6, j + 6, k + 6, 35, 4);
		world.setBlockAndMetadata(i + 6, j + 6, k + 7, 35, 4);
		world.setBlockAndMetadata(i + 6, j + 6, k + 8, 35, 4);
		world.setBlockAndMetadata(i + 6, j + 6, k + 9, 35, 4);
		world.setBlockAndMetadata(i + 6, j + 6, k + 10, 35, 4);
		world.setBlockAndMetadata(i + 6, j + 6, k + 11, 35, 4);
		world.setBlockAndMetadata(i + 6, j + 6, k + 12, 35, 4);
		world.setBlockAndMetadata(i + 6, j + 6, k + 13, 35, 4);
		world.setBlockAndMetadata(i + 6, j + 6, k + 14, 35, 4);
		world.setBlockAndMetadata(i + 6, j + 6, k + 15, 35, 4);
		world.setBlockAndMetadata(i + 6, j + 6, k + 16, 35, 4);
		world.setBlockAndMetadata(i + 6, j + 6, k + 17, 35, 4);
		world.setBlock(i + 6, j + 6, k + 18, 35);
		world.setBlock(i + 6, j + 6, k + 19, 0);
		world.setBlock(i + 6, j + 6, k + 20, 0);
		world.setBlock(i + 6, j + 7, k + 0, 0);
		world.setBlock(i + 6, j + 7, k + 1, 0);
		world.setBlock(i + 6, j + 7, k + 2, 0);
		world.setBlock(i + 6, j + 7, k + 3, 35);
		world.setBlock(i + 6, j + 7, k + 4, 0);
		world.setBlock(i + 6, j + 7, k + 5, 112);
		world.setBlock(i + 6, j + 7, k + 6, 0);
		world.setBlock(i + 6, j + 7, k + 7, 0);
		world.setBlock(i + 6, j + 7, k + 8, 0);
		world.setBlock(i + 6, j + 7, k + 9, 0);
		world.setBlock(i + 6, j + 7, k + 10, 0);
		world.setBlock(i + 6, j + 7, k + 11, 0);
		world.setBlock(i + 6, j + 7, k + 12, 0);
		world.setBlock(i + 6, j + 7, k + 13, 0);
		world.setBlock(i + 6, j + 7, k + 14, 0);
		world.setBlock(i + 6, j + 7, k + 15, 35);
		world.setBlock(i + 6, j + 7, k + 16, 35);
		world.setBlock(i + 6, j + 7, k + 17, 35);
		world.setBlock(i + 6, j + 7, k + 18, 35);
		world.setBlock(i + 6, j + 7, k + 19, 0);
		world.setBlock(i + 6, j + 7, k + 20, 0);
		world.setBlock(i + 6, j + 8, k + 0, 0);
		world.setBlock(i + 6, j + 8, k + 1, 0);
		world.setBlock(i + 6, j + 8, k + 2, 35);
		world.setBlock(i + 6, j + 8, k + 3, 35);
		world.setBlock(i + 6, j + 8, k + 4, 0);
		world.setBlock(i + 6, j + 8, k + 5, 0);
		world.setBlock(i + 6, j + 8, k + 6, 0);
		world.setBlock(i + 6, j + 8, k + 7, 0);
		world.setBlock(i + 6, j + 8, k + 8, 0);
		world.setBlock(i + 6, j + 8, k + 9, 0);
		world.setBlock(i + 6, j + 8, k + 10, 0);
		world.setBlock(i + 6, j + 8, k + 11, 0);
		world.setBlock(i + 6, j + 8, k + 12, 0);
		world.setBlock(i + 6, j + 8, k + 13, 0);
		world.setBlock(i + 6, j + 8, k + 14, 0);
		world.setBlock(i + 6, j + 8, k + 15, 35);
		world.setBlock(i + 6, j + 8, k + 16, 35);
		world.setBlock(i + 6, j + 8, k + 17, 35);
		world.setBlock(i + 6, j + 8, k + 18, 35);
		world.setBlock(i + 6, j + 8, k + 19, 0);
		world.setBlock(i + 6, j + 8, k + 20, 0);
		world.setBlock(i + 6, j + 9, k + 0, 0);
		world.setBlock(i + 6, j + 9, k + 1, 0);
		world.setBlock(i + 6, j + 9, k + 2, 35);
		world.setBlock(i + 6, j + 9, k + 3, 35);
		world.setBlock(i + 6, j + 9, k + 4, 0);
		world.setBlock(i + 6, j + 9, k + 5, 0);
		world.setBlock(i + 6, j + 9, k + 6, 0);
		world.setBlock(i + 6, j + 9, k + 7, 0);
		world.setBlock(i + 6, j + 9, k + 8, 0);
		world.setBlock(i + 6, j + 9, k + 9, 0);
		world.setBlock(i + 6, j + 9, k + 10, 0);
		world.setBlock(i + 6, j + 9, k + 11, 0);
		world.setBlock(i + 6, j + 9, k + 12, 0);
		world.setBlock(i + 6, j + 9, k + 13, 0);
		world.setBlock(i + 6, j + 9, k + 14, 0);
		world.setBlock(i + 6, j + 9, k + 15, 35);
		world.setBlock(i + 6, j + 9, k + 16, 35);
		world.setBlock(i + 6, j + 9, k + 17, 35);
		world.setBlock(i + 6, j + 9, k + 18, 35);
		world.setBlock(i + 6, j + 9, k + 19, 0);
		world.setBlock(i + 6, j + 9, k + 20, 0);
		world.setBlock(i + 6, j + 10, k + 0, 0);
		world.setBlock(i + 6, j + 10, k + 1, 0);
		world.setBlock(i + 6, j + 10, k + 2, 35);
		world.setBlock(i + 6, j + 10, k + 3, 35);
		world.setBlock(i + 6, j + 10, k + 4, 0);
		world.setBlock(i + 6, j + 10, k + 5, 0);
		world.setBlock(i + 6, j + 10, k + 6, 0);
		world.setBlock(i + 6, j + 10, k + 7, 0);
		world.setBlock(i + 6, j + 10, k + 8, 0);
		world.setBlock(i + 6, j + 10, k + 9, 0);
		world.setBlock(i + 6, j + 10, k + 10, 0);
		world.setBlock(i + 6, j + 10, k + 11, 0);
		world.setBlock(i + 6, j + 10, k + 12, 0);
		world.setBlock(i + 6, j + 10, k + 13, 0);
		world.setBlock(i + 6, j + 10, k + 14, 0);
		world.setBlock(i + 6, j + 10, k + 15, 0);
		world.setBlock(i + 6, j + 10, k + 16, 0);
		world.setBlock(i + 6, j + 10, k + 17, 0);
		world.setBlock(i + 6, j + 10, k + 18, 35);
		world.setBlock(i + 6, j + 10, k + 19, 0);
		world.setBlock(i + 6, j + 10, k + 20, 0);
		world.setBlock(i + 6, j + 11, k + 0, 0);
		world.setBlock(i + 6, j + 11, k + 1, 0);
		world.setBlock(i + 6, j + 11, k + 2, 0);
		world.setBlock(i + 6, j + 11, k + 3, 35);
		world.setBlock(i + 6, j + 11, k + 4, 0);
		world.setBlock(i + 6, j + 11, k + 5, 0);
		world.setBlock(i + 6, j + 11, k + 6, 0);
		world.setBlock(i + 6, j + 11, k + 7, 0);
		world.setBlock(i + 6, j + 11, k + 8, 0);
		world.setBlock(i + 6, j + 11, k + 9, 0);
		world.setBlock(i + 6, j + 11, k + 10, 0);
		world.setBlock(i + 6, j + 11, k + 11, 0);
		world.setBlock(i + 6, j + 11, k + 12, 0);
		world.setBlock(i + 6, j + 11, k + 13, 0);
		world.setBlock(i + 6, j + 11, k + 14, 0);
		world.setBlock(i + 6, j + 11, k + 15, 0);
		world.setBlock(i + 6, j + 11, k + 16, 0);
		world.setBlock(i + 6, j + 11, k + 17, 0);
		world.setBlock(i + 6, j + 11, k + 18, 35);
		world.setBlock(i + 6, j + 11, k + 19, 0);
		world.setBlock(i + 6, j + 11, k + 20, 0);
		world.setBlock(i + 6, j + 12, k + 0, 0);
		world.setBlock(i + 6, j + 12, k + 1, 0);
		world.setBlock(i + 6, j + 12, k + 2, 0);
		world.setBlockAndMetadata(i + 6, j + 12, k + 3, 35, 14);
		world.setBlock(i + 6, j + 12, k + 4, 0);
		world.setBlock(i + 6, j + 12, k + 5, 0);
		world.setBlock(i + 6, j + 12, k + 6, 0);
		world.setBlock(i + 6, j + 12, k + 7, 0);
		world.setBlock(i + 6, j + 12, k + 8, 0);
		world.setBlock(i + 6, j + 12, k + 9, 0);
		world.setBlock(i + 6, j + 12, k + 10, 0);
		world.setBlock(i + 6, j + 12, k + 11, 0);
		world.setBlock(i + 6, j + 12, k + 12, 0);
		world.setBlock(i + 6, j + 12, k + 13, 0);
		world.setBlock(i + 6, j + 12, k + 14, 0);
		world.setBlock(i + 6, j + 12, k + 15, 0);
		world.setBlock(i + 6, j + 12, k + 16, 0);
		world.setBlock(i + 6, j + 12, k + 17, 0);
		world.setBlockAndMetadata(i + 6, j + 12, k + 18, 35, 14);
		world.setBlock(i + 6, j + 12, k + 19, 0);
		world.setBlock(i + 6, j + 12, k + 20, 0);
		world.setBlock(i + 6, j + 13, k + 0, 0);
		world.setBlock(i + 6, j + 13, k + 1, 0);
		world.setBlock(i + 6, j + 13, k + 2, 0);
		world.setBlock(i + 6, j + 13, k + 3, 0);
		world.setBlockAndMetadata(i + 6, j + 13, k + 4, 35, 14);
		world.setBlockAndMetadata(i + 6, j + 13, k + 5, 35, 14);
		world.setBlockAndMetadata(i + 6, j + 13, k + 6, 35, 14);
		world.setBlockAndMetadata(i + 6, j + 13, k + 7, 35, 14);
		world.setBlockAndMetadata(i + 6, j + 13, k + 8, 35, 14);
		world.setBlockAndMetadata(i + 6, j + 13, k + 9, 35, 14);
		world.setBlockAndMetadata(i + 6, j + 13, k + 10, 35, 14);
		world.setBlockAndMetadata(i + 6, j + 13, k + 11, 35, 14);
		world.setBlockAndMetadata(i + 6, j + 13, k + 12, 35, 14);
		world.setBlockAndMetadata(i + 6, j + 13, k + 13, 35, 14);
		world.setBlockAndMetadata(i + 6, j + 13, k + 14, 35, 14);
		world.setBlockAndMetadata(i + 6, j + 13, k + 15, 35, 14);
		world.setBlockAndMetadata(i + 6, j + 13, k + 16, 35, 14);
		world.setBlockAndMetadata(i + 6, j + 13, k + 17, 35, 14);
		world.setBlock(i + 6, j + 13, k + 18, 0);
		world.setBlock(i + 6, j + 13, k + 19, 0);
		world.setBlock(i + 6, j + 13, k + 20, 0);
		world.setBlock(i + 7, j + 0, k + 0, 2);
		world.setBlock(i + 7, j + 0, k + 1, 2);
		world.setBlock(i + 7, j + 0, k + 2, 2);
		world.setBlock(i + 7, j + 0, k + 3, 3);
		world.setBlock(i + 7, j + 0, k + 4, 3);
		world.setBlock(i + 7, j + 0, k + 5, 3);
		world.setBlockAndMetadata(i + 7, j + 0, k + 6, 35, 4);
		world.setBlockAndMetadata(i + 7, j + 0, k + 7, 35, 4);
		world.setBlockAndMetadata(i + 7, j + 0, k + 8, 35, 4);
		world.setBlockAndMetadata(i + 7, j + 0, k + 9, 35, 4);
		world.setBlockAndMetadata(i + 7, j + 0, k + 10, 35, 4);
		world.setBlockAndMetadata(i + 7, j + 0, k + 11, 35, 4);
		world.setBlockAndMetadata(i + 7, j + 0, k + 12, 35, 4);
		world.setBlockAndMetadata(i + 7, j + 0, k + 13, 35, 4);
		world.setBlockAndMetadata(i + 7, j + 0, k + 14, 35, 4);
		world.setBlockAndMetadata(i + 7, j + 0, k + 15, 35, 4);
		world.setBlockAndMetadata(i + 7, j + 0, k + 16, 35, 4);
		world.setBlock(i + 7, j + 0, k + 17, 3);
		world.setBlock(i + 7, j + 0, k + 18, 3);
		world.setBlock(i + 7, j + 0, k + 19, 2);
		world.setBlock(i + 7, j + 0, k + 20, 2);
		world.setBlock(i + 7, j + 1, k + 0, 0);
		world.setBlock(i + 7, j + 1, k + 1, 0);
		world.setBlock(i + 7, j + 1, k + 2, 0);
		world.setBlock(i + 7, j + 1, k + 3, 35);
		world.setBlock(i + 7, j + 1, k + 4, 35);
		world.setBlockAndMetadata(i + 7, j + 1, k + 5, 35, 14);
		world.setBlock(i + 7, j + 1, k + 6, 0);
		world.setBlock(i + 7, j + 1, k + 7, 0);
		world.setBlock(i + 7, j + 1, k + 8, 0);
		world.setBlock(i + 7, j + 1, k + 9, 0);
		world.setBlock(i + 7, j + 1, k + 10, 0);
		world.setBlock(i + 7, j + 1, k + 12, 0);
		world.setBlock(i + 7, j + 1, k + 13, 35);
		world.setBlock(i + 7, j + 1, k + 14, 35);
		world.setBlock(i + 7, j + 1, k + 15, 35);
		world.setBlock(i + 7, j + 1, k + 16, 35);
		world.setBlockAndMetadata(i + 7, j + 1, k + 17, 35, 14);
		world.setBlock(i + 7, j + 1, k + 18, 35);
		world.setBlock(i + 7, j + 1, k + 19, 0);
		world.setBlock(i + 7, j + 1, k + 20, 0);
		world.setBlock(i + 7, j + 2, k + 0, 0);
		world.setBlock(i + 7, j + 2, k + 1, 0);
		world.setBlock(i + 7, j + 2, k + 2, 0);
		world.setBlock(i + 7, j + 2, k + 3, 0);
		world.setBlock(i + 7, j + 2, k + 4, 35);
		world.setBlockAndMetadata(i + 7, j + 2, k + 5, 35, 14);
		world.setBlock(i + 7, j + 2, k + 6, 0);
		world.setBlock(i + 7, j + 2, k + 7, 0);
		world.setBlock(i + 7, j + 2, k + 8, 0);
		world.setBlock(i + 7, j + 2, k + 9, 0);
		world.setBlock(i + 7, j + 2, k + 10, 0);
		world.setBlock(i + 7, j + 2, k + 11, 0);
		world.setBlock(i + 7, j + 2, k + 12, 0);
		world.setBlock(i + 7, j + 2, k + 13, 0);
		world.setBlock(i + 7, j + 2, k + 14, 0);
		world.setBlock(i + 7, j + 2, k + 15, 0);
		world.setBlock(i + 7, j + 2, k + 16, 0);
		world.setBlockAndMetadata(i + 7, j + 2, k + 17, 35, 14);
		world.setBlock(i + 7, j + 2, k + 18, 35);
		world.setBlock(i + 7, j + 2, k + 19, 0);
		world.setBlock(i + 7, j + 2, k + 20, 0);
		world.setBlock(i + 7, j + 3, k + 0, 0);
		world.setBlock(i + 7, j + 3, k + 1, 0);
		world.setBlock(i + 7, j + 3, k + 2, 0);
		world.setBlock(i + 7, j + 3, k + 3, 0);
		world.setBlock(i + 7, j + 3, k + 4, 35);
		world.setBlockAndMetadata(i + 7, j + 3, k + 5, 35, 14);
		world.setBlock(i + 7, j + 3, k + 7, 0);
		world.setBlock(i + 7, j + 3, k + 8, 0);
		world.setBlock(i + 7, j + 3, k + 9, 0);
		world.setBlock(i + 7, j + 3, k + 10, 0);
		world.setBlock(i + 7, j + 3, k + 11, 0);
		world.setBlock(i + 7, j + 3, k + 12, 0);
		world.setBlock(i + 7, j + 3, k + 13, 0);
		world.setBlock(i + 7, j + 3, k + 14, 0);
		world.setBlock(i + 7, j + 3, k + 15, 0);
		world.setBlockAndMetadata(i + 7, j + 3, k + 17, 35, 14);
		world.setBlock(i + 7, j + 3, k + 18, 35);
		world.setBlock(i + 7, j + 3, k + 19, 0);
		world.setBlock(i + 7, j + 3, k + 20, 0);
		world.setBlock(i + 7, j + 4, k + 0, 0);
		world.setBlock(i + 7, j + 4, k + 1, 0);
		world.setBlock(i + 7, j + 4, k + 2, 0);
		world.setBlock(i + 7, j + 4, k + 3, 0);
		world.setBlock(i + 7, j + 4, k + 4, 35);
		world.setBlockAndMetadata(i + 7, j + 4, k + 5, 35, 14);
		world.setBlock(i + 7, j + 4, k + 6, 0);
		world.setBlock(i + 7, j + 4, k + 7, 0);
		world.setBlock(i + 7, j + 4, k + 8, 0);
		world.setBlock(i + 7, j + 4, k + 9, 0);
		world.setBlock(i + 7, j + 4, k + 10, 0);
		world.setBlock(i + 7, j + 4, k + 11, 0);
		world.setBlock(i + 7, j + 4, k + 12, 0);
		world.setBlock(i + 7, j + 4, k + 13, 0);
		world.setBlock(i + 7, j + 4, k + 14, 0);
		world.setBlock(i + 7, j + 4, k + 15, 0);
		world.setBlock(i + 7, j + 4, k + 16, 0);
		world.setBlockAndMetadata(i + 7, j + 4, k + 17, 35, 14);
		world.setBlock(i + 7, j + 4, k + 18, 35);
		world.setBlock(i + 7, j + 4, k + 19, 0);
		world.setBlock(i + 7, j + 4, k + 20, 0);
		world.setBlock(i + 7, j + 5, k + 0, 0);
		world.setBlock(i + 7, j + 5, k + 1, 0);
		world.setBlock(i + 7, j + 5, k + 2, 0);
		world.setBlock(i + 7, j + 5, k + 3, 0);
		world.setBlock(i + 7, j + 5, k + 4, 35);
		world.setBlockAndMetadata(i + 7, j + 5, k + 5, 35, 14);
		world.setBlock(i + 7, j + 5, k + 6, 35);
		world.setBlock(i + 7, j + 5, k + 7, 35);
		world.setBlock(i + 7, j + 5, k + 8, 35);
		world.setBlock(i + 7, j + 5, k + 9, 35);
		world.setBlock(i + 7, j + 5, k + 10, 35);
