/*
*** MADE BY MITHION'S .SCHEMATIC TO JAVA CONVERTING TOOL v1.6 ***
*/

package FunMod.struturas;
import java.util.Random;

import net.minecraft.src.Block;
import net.minecraft.src.World;
import net.minecraft.src.WorldGenerator;

public class WorldGenLabirinto extends WorldGenerator
{
	protected int[] GetValidSpawnBlocks() {
		return new int[] {
			Block.stone.blockID,
			Block.grass.blockID,
			Block.dirt.blockID
		};
	}

	public boolean LocationIsValidSpawn(World world, int i, int j, int k){
		int distanceToAir = 0;
		int checkID = world.getBlockId(i, j, k);

		while (checkID != 0){
			distanceToAir++;
			checkID = world.getBlockId(i, j + distanceToAir, k);
		}

		if (distanceToAir > 3){
			return false;
		}
		j += distanceToAir - 1;

		int blockID = world.getBlockId(i, j, k);
		int blockIDAbove = world.getBlockId(i, j+1, k);
		int blockIDBelow = world.getBlockId(i, j-1, k);
		for (int x : GetValidSpawnBlocks()){
			if (blockIDAbove != 0){
				return false;
			}
			if (blockID == x){
				return true;
			}else if (blockID == Block.snow.blockID && blockIDBelow == x){
				return true;
			}
		}
		return false;
	}

	public WorldGenLabirinto() { }

	public boolean generate(World world, Random rand, int i, int j, int k) {
		//check that each corner is one of the valid spawn blocks
		if(!LocationIsValidSpawn(world, i, j, k) || !LocationIsValidSpawn(world, i + 23, j, k) || !LocationIsValidSpawn(world, i + 23, j, k + 21) || !LocationIsValidSpawn(world, i, j, k + 21))
		{
			return false;
		}

		world.setBlock(i + 0, j + 0, k + 0, Block.grass.blockID);
		world.setBlock(i + 0, j + 0, k + 1, Block.grass.blockID);
		world.setBlock(i + 0, j + 0, k + 2, Block.grass.blockID);
		world.setBlock(i + 0, j + 0, k + 3, Block.grass.blockID);
		world.setBlock(i + 0, j + 0, k + 4, Block.grass.blockID);
		world.setBlock(i + 0, j + 0, k + 5, Block.grass.blockID);
		world.setBlock(i + 0, j + 0, k + 6, Block.grass.blockID);
		world.setBlock(i + 0, j + 0, k + 7, Block.grass.blockID);
		world.setBlock(i + 0, j + 0, k + 8, Block.grass.blockID);
		world.setBlock(i + 0, j + 0, k + 9, Block.grass.blockID);
		world.setBlock(i + 0, j + 0, k + 10, Block.grass.blockID);
		world.setBlock(i + 0, j + 0, k + 11, Block.grass.blockID);
		world.setBlock(i + 0, j + 0, k + 12, Block.grass.blockID);
		world.setBlock(i + 0, j + 0, k + 13, Block.grass.blockID);
		world.setBlock(i + 0, j + 0, k + 14, Block.grass.blockID);
		world.setBlock(i + 0, j + 0, k + 15, Block.grass.blockID);
		world.setBlock(i + 0, j + 0, k + 16, Block.grass.blockID);
		world.setBlock(i + 0, j + 0, k + 17, Block.grass.blockID);
		world.setBlock(i + 0, j + 0, k + 18, Block.grass.blockID);
		world.setBlock(i + 0, j + 0, k + 19, Block.grass.blockID);
		world.setBlock(i + 0, j + 0, k + 20, Block.grass.blockID);
		world.setBlock(i + 0, j + 0, k + 21, Block.grass.blockID);
		world.setBlock(i + 0, j + 1, k + 0, 0);
		world.setBlock(i + 0, j + 1, k + 1, 0);
		world.setBlock(i + 0, j + 1, k + 2, 0);
		world.setBlock(i + 0, j + 1, k + 3, 0);
		world.setBlock(i + 0, j + 1, k + 4, 0);
		world.setBlock(i + 0, j + 1, k + 5, 0);
		world.setBlock(i + 0, j + 1, k + 6, 0);
		world.setBlock(i + 0, j + 1, k + 7, 0);
		world.setBlock(i + 0, j + 1, k + 8, 0);
		world.setBlock(i + 0, j + 1, k + 9, 0);
		world.setBlock(i + 0, j + 1, k + 10, 0);
		world.setBlock(i + 0, j + 1, k + 11, 0);
		world.setBlock(i + 0, j + 1, k + 12, 0);
		world.setBlock(i + 0, j + 1, k + 13, 0);
		world.setBlock(i + 0, j + 1, k + 14, 0);
		world.setBlock(i + 0, j + 1, k + 15, 0);
		world.setBlock(i + 0, j + 1, k + 16, 0);
		world.setBlock(i + 0, j + 1, k + 17, 0);
		world.setBlock(i + 0, j + 1, k + 18, 0);
		world.setBlock(i + 0, j + 1, k + 19, 0);
		world.setBlock(i + 0, j + 1, k + 20, 0);
		world.setBlock(i + 0, j + 1, k + 21, 0);
		world.setBlock(i + 0, j + 2, k + 0, 0);
		world.setBlock(i + 0, j + 2, k + 1, 0);
		world.setBlock(i + 0, j + 2, k + 2, 0);
		world.setBlock(i + 0, j + 2, k + 3, 0);
		world.setBlock(i + 0, j + 2, k + 4, 0);
		world.setBlock(i + 0, j + 2, k + 5, 0);
		world.setBlock(i + 0, j + 2, k + 6, 0);
		world.setBlock(i + 0, j + 2, k + 7, 0);
		world.setBlock(i + 0, j + 2, k + 8, 0);
		world.setBlock(i + 0, j + 2, k + 9, 0);
		world.setBlock(i + 0, j + 2, k + 10, 0);
		world.setBlock(i + 0, j + 2, k + 11, 0);
		world.setBlock(i + 0, j + 2, k + 12, 0);
		world.setBlock(i + 0, j + 2, k + 13, 0);
		world.setBlock(i + 0, j + 2, k + 14, 0);
		world.setBlock(i + 0, j + 2, k + 15, 0);
		world.setBlock(i + 0, j + 2, k + 16, 0);
		world.setBlock(i + 0, j + 2, k + 17, 0);
		world.setBlock(i + 0, j + 2, k + 18, 0);
		world.setBlock(i + 0, j + 2, k + 19, 0);
		world.setBlock(i + 0, j + 2, k + 20, 0);
		world.setBlock(i + 0, j + 2, k + 21, 0);
		world.setBlock(i + 0, j + 3, k + 0, 0);
		world.setBlock(i + 0, j + 3, k + 1, 0);
		world.setBlock(i + 0, j + 3, k + 2, 0);
		world.setBlock(i + 0, j + 3, k + 3, 0);
		world.setBlock(i + 0, j + 3, k + 4, 0);
		world.setBlock(i + 0, j + 3, k + 5, 0);
		world.setBlock(i + 0, j + 3, k + 6, 0);
		world.setBlock(i + 0, j + 3, k + 7, 0);
		world.setBlock(i + 0, j + 3, k + 8, 0);
		world.setBlock(i + 0, j + 3, k + 9, 0);
		world.setBlock(i + 0, j + 3, k + 10, 0);
		world.setBlock(i + 0, j + 3, k + 11, 0);
		world.setBlock(i + 0, j + 3, k + 12, 0);
		world.setBlock(i + 0, j + 3, k + 13, 0);
		world.setBlock(i + 0, j + 3, k + 14, 0);
		world.setBlock(i + 0, j + 3, k + 15, 0);
		world.setBlock(i + 0, j + 3, k + 16, 0);
		world.setBlock(i + 0, j + 3, k + 17, 0);
		world.setBlock(i + 0, j + 3, k + 18, 0);
		world.setBlock(i + 0, j + 3, k + 19, 0);
		world.setBlock(i + 0, j + 3, k + 20, 0);
		world.setBlock(i + 0, j + 3, k + 21, 0);
		world.setBlock(i + 0, j + 4, k + 0, 0);
		world.setBlock(i + 0, j + 4, k + 1, 0);
		world.setBlock(i + 0, j + 4, k + 2, 0);
		world.setBlock(i + 0, j + 4, k + 3, 0);
		world.setBlock(i + 0, j + 4, k + 4, 0);
		world.setBlock(i + 0, j + 4, k + 5, 0);
		world.setBlock(i + 0, j + 4, k + 6, 0);
		world.setBlock(i + 0, j + 4, k + 7, 0);
		world.setBlock(i + 0, j + 4, k + 8, 0);
		world.setBlock(i + 0, j + 4, k + 9, 0);
		world.setBlock(i + 0, j + 4, k + 10, 0);
		world.setBlock(i + 0, j + 4, k + 11, 0);
		world.setBlock(i + 0, j + 4, k + 12, 0);
		world.setBlock(i + 0, j + 4, k + 13, 0);
		world.setBlock(i + 0, j + 4, k + 14, 0);
		world.setBlock(i + 0, j + 4, k + 15, 0);
		world.setBlock(i + 0, j + 4, k + 16, 0);
		world.setBlock(i + 0, j + 4, k + 17, 0);
		world.setBlock(i + 0, j + 4, k + 18, 0);
		world.setBlock(i + 0, j + 4, k + 19, 0);
		world.setBlock(i + 0, j + 4, k + 20, 0);
		world.setBlock(i + 0, j + 4, k + 21, 0);
		world.setBlock(i + 0, j + 5, k + 0, 0);
		world.setBlock(i + 0, j + 5, k + 1, 0);
		world.setBlock(i + 0, j + 5, k + 2, 0);
		world.setBlock(i + 0, j + 5, k + 3, 0);
		world.setBlock(i + 0, j + 5, k + 4, 0);
		world.setBlock(i + 0, j + 5, k + 5, 0);
		world.setBlock(i + 0, j + 5, k + 6, 0);
		world.setBlock(i + 0, j + 5, k + 7, 0);
		world.setBlock(i + 0, j + 5, k + 8, 0);
		world.setBlock(i + 0, j + 5, k + 9, 0);
		world.setBlock(i + 0, j + 5, k + 10, 0);
		world.setBlock(i + 0, j + 5, k + 11, 0);
		world.setBlock(i + 0, j + 5, k + 12, 0);
		world.setBlock(i + 0, j + 5, k + 13, 0);
		world.setBlock(i + 0, j + 5, k + 14, 0);
		world.setBlock(i + 0, j + 5, k + 15, 0);
		world.setBlock(i + 0, j + 5, k + 16, 0);
		world.setBlock(i + 0, j + 5, k + 17, 0);
		world.setBlock(i + 0, j + 5, k + 18, 0);
		world.setBlock(i + 0, j + 5, k + 19, 0);
		world.setBlock(i + 0, j + 5, k + 20, 0);
		world.setBlock(i + 0, j + 5, k + 21, 0);
		world.setBlock(i + 0, j + 6, k + 0, 0);
		world.setBlock(i + 0, j + 6, k + 1, 0);
		world.setBlock(i + 0, j + 6, k + 2, 0);
		world.setBlock(i + 0, j + 6, k + 3, 0);
		world.setBlock(i + 0, j + 6, k + 4, 0);
		world.setBlock(i + 0, j + 6, k + 5, 0);
		world.setBlock(i + 0, j + 6, k + 6, 0);
		world.setBlock(i + 0, j + 6, k + 7, 0);
		world.setBlock(i + 0, j + 6, k + 8, 0);
		world.setBlock(i + 0, j + 6, k + 9, 0);
		world.setBlock(i + 0, j + 6, k + 10, 0);
		world.setBlock(i + 0, j + 6, k + 11, 0);
		world.setBlock(i + 0, j + 6, k + 12, 0);
		world.setBlock(i + 0, j + 6, k + 13, 0);
		world.setBlock(i + 0, j + 6, k + 14, 0);
		world.setBlock(i + 0, j + 6, k + 15, 0);
		world.setBlock(i + 0, j + 6, k + 16, 0);
		world.setBlock(i + 0, j + 6, k + 17, 0);
		world.setBlock(i + 0, j + 6, k + 18, 0);
		world.setBlock(i + 0, j + 6, k + 19, 0);
		world.setBlock(i + 0, j + 6, k + 20, 0);
		world.setBlock(i + 0, j + 6, k + 21, 0);
		world.setBlock(i + 0, j + 7, k + 0, 0);
		world.setBlock(i + 0, j + 7, k + 1, 0);
		world.setBlock(i + 0, j + 7, k + 2, 0);
		world.setBlock(i + 0, j + 7, k + 3, 0);
		world.setBlock(i + 0, j + 7, k + 4, 0);
		world.setBlock(i + 0, j + 7, k + 5, 0);
		world.setBlock(i + 0, j + 7, k + 6, 0);
		world.setBlock(i + 0, j + 7, k + 7, 0);
		world.setBlock(i + 0, j + 7, k + 8, 0);
		world.setBlock(i + 0, j + 7, k + 9, 0);
		world.setBlock(i + 0, j + 7, k + 10, 0);
		world.setBlock(i + 0, j + 7, k + 11, 0);
		world.setBlock(i + 0, j + 7, k + 12, 0);
		world.setBlock(i + 0, j + 7, k + 13, 0);
		world.setBlock(i + 0, j + 7, k + 14, 0);
		world.setBlock(i + 0, j + 7, k + 15, 0);
		world.setBlock(i + 0, j + 7, k + 16, 0);
		world.setBlock(i + 0, j + 7, k + 17, 0);
		world.setBlock(i + 0, j + 7, k + 18, 0);
		world.setBlock(i + 0, j + 7, k + 19, 0);
		world.setBlock(i + 0, j + 7, k + 20, 0);
		world.setBlock(i + 0, j + 7, k + 21, 0);
		world.setBlock(i + 0, j + 8, k + 0, 0);
		world.setBlock(i + 0, j + 8, k + 1, 0);
		world.setBlock(i + 0, j + 8, k + 2, 0);
		world.setBlock(i + 0, j + 8, k + 3, 0);
		world.setBlock(i + 0, j + 8, k + 4, 0);
		world.setBlock(i + 0, j + 8, k + 5, 0);
		world.setBlock(i + 0, j + 8, k + 6, 0);
		world.setBlock(i + 0, j + 8, k + 7, 0);
		world.setBlock(i + 0, j + 8, k + 8, 0);
		world.setBlock(i + 0, j + 8, k + 9, 0);
		world.setBlock(i + 0, j + 8, k + 10, 0);
		world.setBlock(i + 0, j + 8, k + 11, 0);
		world.setBlock(i + 0, j + 8, k + 12, 0);
		world.setBlock(i + 0, j + 8, k + 13, 0);
		world.setBlock(i + 0, j + 8, k + 14, 0);
		world.setBlock(i + 0, j + 8, k + 15, 0);
		world.setBlock(i + 0, j + 8, k + 16, 0);
		world.setBlock(i + 0, j + 8, k + 17, 0);
		world.setBlock(i + 0, j + 8, k + 18, 0);
		world.setBlock(i + 0, j + 8, k + 19, 0);
		world.setBlock(i + 0, j + 8, k + 20, 0);
		world.setBlock(i + 0, j + 8, k + 21, 0);
		world.setBlock(i + 0, j + 9, k + 0, 0);
		world.setBlock(i + 0, j + 9, k + 1, 0);
		world.setBlock(i + 0, j + 9, k + 2, 0);
		world.setBlock(i + 0, j + 9, k + 3, 0);
		world.setBlock(i + 0, j + 9, k + 4, 0);
		world.setBlock(i + 0, j + 9, k + 5, 0);
		world.setBlock(i + 0, j + 9, k + 6, 0);
		world.setBlock(i + 0, j + 9, k + 7, 0);
		world.setBlock(i + 0, j + 9, k + 8, 0);
		world.setBlock(i + 0, j + 9, k + 9, 0);
		world.setBlock(i + 0, j + 9, k + 10, 0);
		world.setBlock(i + 0, j + 9, k + 11, 0);
		world.setBlock(i + 0, j + 9, k + 12, 0);
		world.setBlock(i + 0, j + 9, k + 13, 0);
		world.setBlock(i + 0, j + 9, k + 14, 0);
		world.setBlock(i + 0, j + 9, k + 15, 0);
		world.setBlock(i + 0, j + 9, k + 16, 0);
		world.setBlock(i + 0, j + 9, k + 17, 0);
		world.setBlock(i + 0, j + 9, k + 18, 0);
		world.setBlock(i + 0, j + 9, k + 19, 0);
		world.setBlock(i + 0, j + 9, k + 20, 0);
		world.setBlock(i + 0, j + 9, k + 21, 0);
		world.setBlock(i + 0, j + 10, k + 0, 0);
		world.setBlock(i + 0, j + 10, k + 1, 0);
		world.setBlock(i + 0, j + 10, k + 2, 0);
		world.setBlock(i + 0, j + 10, k + 3, 0);
		world.setBlock(i + 0, j + 10, k + 4, 0);
		world.setBlock(i + 0, j + 10, k + 5, 0);
		world.setBlock(i + 0, j + 10, k + 6, 0);
		world.setBlock(i + 0, j + 10, k + 7, 0);
		world.setBlock(i + 0, j + 10, k + 8, 0);
		world.setBlock(i + 0, j + 10, k + 9, 0);
		world.setBlock(i + 0, j + 10, k + 10, 0);
		world.setBlock(i + 0, j + 10, k + 11, 0);
		world.setBlock(i + 0, j + 10, k + 12, 0);
		world.setBlock(i + 0, j + 10, k + 13, 0);
		world.setBlock(i + 0, j + 10, k + 14, 0);
		world.setBlock(i + 0, j + 10, k + 15, 0);
		world.setBlock(i + 0, j + 10, k + 16, 0);
		world.setBlock(i + 0, j + 10, k + 17, 0);
		world.setBlock(i + 0, j + 10, k + 18, 0);
		world.setBlock(i + 0, j + 10, k + 19, 0);
		world.setBlock(i + 0, j + 10, k + 20, 0);
		world.setBlock(i + 0, j + 10, k + 21, 0);
		world.setBlock(i + 0, j + 11, k + 0, 0);
		world.setBlock(i + 0, j + 11, k + 1, 0);
		world.setBlock(i + 0, j + 11, k + 2, 0);
		world.setBlock(i + 0, j + 11, k + 3, 0);
		world.setBlock(i + 0, j + 11, k + 4, 0);
		world.setBlock(i + 0, j + 11, k + 5, 0);
		world.setBlock(i + 0, j + 11, k + 6, 0);
		world.setBlock(i + 0, j + 11, k + 7, 0);
		world.setBlock(i + 0, j + 11, k + 8, 0);
		world.setBlock(i + 0, j + 11, k + 9, 0);
		world.setBlock(i + 0, j + 11, k + 10, 0);
		world.setBlock(i + 0, j + 11, k + 11, 0);
		world.setBlock(i + 0, j + 11, k + 12, 0);
		world.setBlock(i + 0, j + 11, k + 13, 0);
		world.setBlock(i + 0, j + 11, k + 14, 0);
		world.setBlock(i + 0, j + 11, k + 15, 0);
		world.setBlock(i + 0, j + 11, k + 16, 0);
		world.setBlock(i + 0, j + 11, k + 17, 0);
		world.setBlock(i + 0, j + 11, k + 18, 0);
		world.setBlock(i + 0, j + 11, k + 19, 0);
		world.setBlock(i + 0, j + 11, k + 20, 0);
		world.setBlock(i + 0, j + 11, k + 21, 0);
		world.setBlock(i + 0, j + 12, k + 0, 0);
		world.setBlock(i + 0, j + 12, k + 1, 0);
		world.setBlock(i + 0, j + 12, k + 2, 0);
		world.setBlock(i + 0, j + 12, k + 3, 0);
		world.setBlock(i + 0, j + 12, k + 4, 0);
		world.setBlock(i + 0, j + 12, k + 5, 0);
		world.setBlock(i + 0, j + 12, k + 6, 0);
		world.setBlock(i + 0, j + 12, k + 7, 0);
		world.setBlock(i + 0, j + 12, k + 8, 0);
		world.setBlock(i + 0, j + 12, k + 9, 0);
		world.setBlock(i + 0, j + 12, k + 10, 0);
		world.setBlock(i + 0, j + 12, k + 11, 0);
		world.setBlock(i + 0, j + 12, k + 12, 0);
		world.setBlock(i + 0, j + 12, k + 13, 0);
		world.setBlock(i + 0, j + 12, k + 14, 0);
		world.setBlock(i + 0, j + 12, k + 15, 0);
		world.setBlock(i + 0, j + 12, k + 16, 0);
		world.setBlock(i + 0, j + 12, k + 17, 0);
		world.setBlock(i + 0, j + 12, k + 18, 0);
		world.setBlock(i + 0, j + 12, k + 19, 0);
		world.setBlock(i + 0, j + 12, k + 20, 0);
		world.setBlock(i + 0, j + 12, k + 21, 0);
		world.setBlock(i + 0, j + 13, k + 0, 0);
		world.setBlock(i + 0, j + 13, k + 1, 0);
		world.setBlock(i + 0, j + 13, k + 2, 0);
		world.setBlock(i + 0, j + 13, k + 3, 0);
		world.setBlock(i + 0, j + 13, k + 4, 0);
		world.setBlock(i + 0, j + 13, k + 5, 0);
		world.setBlock(i + 0, j + 13, k + 6, 0);
		world.setBlock(i + 0, j + 13, k + 7, 0);
		world.setBlock(i + 0, j + 13, k + 8, 0);
		world.setBlock(i + 0, j + 13, k + 9, 0);
		world.setBlock(i + 0, j + 13, k + 10, 0);
		world.setBlock(i + 0, j + 13, k + 11, 0);
		world.setBlock(i + 0, j + 13, k + 12, 0);
		world.setBlock(i + 0, j + 13, k + 13, 0);
		world.setBlock(i + 0, j + 13, k + 14, 0);
		world.setBlock(i + 0, j + 13, k + 15, 0);
		world.setBlock(i + 0, j + 13, k + 16, 0);
		world.setBlock(i + 0, j + 13, k + 17, 0);
		world.setBlock(i + 0, j + 13, k + 18, 0);
		world.setBlock(i + 0, j + 13, k + 19, 0);
		world.setBlock(i + 0, j + 13, k + 20, 0);
		world.setBlock(i + 0, j + 13, k + 21, 0);
		world.setBlock(i + 0, j + 14, k + 0, 0);
		world.setBlock(i + 0, j + 14, k + 1, 0);
		world.setBlock(i + 0, j + 14, k + 2, 0);
		world.setBlock(i + 0, j + 14, k + 3, 0);
		world.setBlock(i + 0, j + 14, k + 4, 0);
		world.setBlock(i + 0, j + 14, k + 5, 0);
		world.setBlock(i + 0, j + 14, k + 6, 0);
		world.setBlock(i + 0, j + 14, k + 7, 0);
		world.setBlock(i + 0, j + 14, k + 8, 0);
		world.setBlock(i + 0, j + 14, k + 9, 0);
		world.setBlock(i + 0, j + 14, k + 10, 0);
		world.setBlock(i + 0, j + 14, k + 11, 0);
		world.setBlock(i + 0, j + 14, k + 12, 0);
		world.setBlock(i + 0, j + 14, k + 13, 0);
		world.setBlock(i + 0, j + 14, k + 14, 0);
		world.setBlock(i + 0, j + 14, k + 15, 0);
		world.setBlock(i + 0, j + 14, k + 16, 0);
		world.setBlock(i + 0, j + 14, k + 17, 0);
		world.setBlock(i + 0, j + 14, k + 18, 0);
		world.setBlock(i + 0, j + 14, k + 19, 0);
		world.setBlock(i + 0, j + 14, k + 20, 0);
		world.setBlock(i + 0, j + 14, k + 21, 0);
		world.setBlock(i + 0, j + 15, k + 0, 0);
		world.setBlock(i + 0, j + 15, k + 1, 0);
		world.setBlock(i + 0, j + 15, k + 2, 0);
		world.setBlock(i + 0, j + 15, k + 3, 0);
		world.setBlock(i + 0, j + 15, k + 4, 0);
		world.setBlock(i + 0, j + 15, k + 5, 0);
		world.setBlock(i + 0, j + 15, k + 6, 0);
		world.setBlock(i + 0, j + 15, k + 7, 0);
		world.setBlock(i + 0, j + 15, k + 8, 0);
		world.setBlock(i + 0, j + 15, k + 9, 0);
		world.setBlock(i + 0, j + 15, k + 10, 0);
		world.setBlock(i + 0, j + 15, k + 11, 0);
		world.setBlock(i + 0, j + 15, k + 12, 0);
		world.setBlock(i + 0, j + 15, k + 13, 0);
		world.setBlock(i + 0, j + 15, k + 14, 0);
		world.setBlock(i + 0, j + 15, k + 15, 0);
		world.setBlock(i + 0, j + 15, k + 16, 0);
		world.setBlock(i + 0, j + 15, k + 17, 0);
		world.setBlock(i + 0, j + 15, k + 18, 0);
		world.setBlock(i + 0, j + 15, k + 19, 0);
		world.setBlock(i + 0, j + 15, k + 20, 0);
		world.setBlock(i + 0, j + 15, k + 21, 0);
		world.setBlock(i + 1, j + 0, k + 0, Block.grass.blockID);
		world.setBlock(i + 1, j + 0, k + 1, Block.dirt.blockID);
		world.setBlock(i + 1, j + 0, k + 2, Block.dirt.blockID);
		world.setBlock(i + 1, j + 0, k + 3, Block.dirt.blockID);
		world.setBlock(i + 1, j + 0, k + 4, Block.dirt.blockID);
		world.setBlock(i + 1, j + 0, k + 5, Block.dirt.blockID);
		world.setBlock(i + 1, j + 0, k + 6, Block.dirt.blockID);
		world.setBlock(i + 1, j + 0, k + 7, Block.dirt.blockID);
		world.setBlock(i + 1, j + 0, k + 8, Block.dirt.blockID);
		world.setBlock(i + 1, j + 0, k + 9, Block.dirt.blockID);
		world.setBlock(i + 1, j + 0, k + 10, Block.dirt.blockID);
		world.setBlock(i + 1, j + 0, k + 11, Block.dirt.blockID);
		world.setBlock(i + 1, j + 0, k + 12, Block.dirt.blockID);
		world.setBlock(i + 1, j + 0, k + 13, Block.dirt.blockID);
		world.setBlock(i + 1, j + 0, k + 14, Block.dirt.blockID);
		world.setBlock(i + 1, j + 0, k + 15, Block.dirt.blockID);
		world.setBlock(i + 1, j + 0, k + 16, Block.dirt.blockID);
		world.setBlock(i + 1, j + 0, k + 17, Block.dirt.blockID);
		world.setBlock(i + 1, j + 0, k + 18, Block.dirt.blockID);
		world.setBlock(i + 1, j + 0, k + 19, Block.dirt.blockID);
		world.setBlock(i + 1, j + 0, k + 20, Block.dirt.blockID);
		world.setBlock(i + 1, j + 0, k + 21, Block.dirt.blockID);
		world.setBlock(i + 1, j + 1, k + 0, 0);
		world.setBlockAndMetadata(i + 1, j + 1, k + 1, Block.cloth.blockID, 15);
		world.setBlockAndMetadata(i + 1, j + 1, k + 2, Block.cloth.blockID, 11);
		world.setBlockAndMetadata(i + 1, j + 1, k + 3, Block.cloth.blockID, 11);
		world.setBlockAndMetadata(i + 1, j + 1, k + 4, Block.cloth.blockID, 11);
		world.setBlockAndMetadata(i + 1, j + 1, k + 5, Block.cloth.blockID, 11);
		world.setBlockAndMetadata(i + 1, j + 1, k + 6, Block.cloth.blockID, 11);
		world.setBlockAndMetadata(i + 1, j + 1, k + 7, Block.cloth.blockID, 11);
		world.setBlockAndMetadata(i + 1, j + 1, k + 8, Block.cloth.blockID, 11);
		world.setBlockAndMetadata(i + 1, j + 1, k + 9, Block.cloth.blockID, 11);
		world.setBlockAndMetadata(i + 1, j + 1, k + 10, Block.cloth.blockID, 11);
		world.setBlockAndMetadata(i + 1, j + 1, k + 11, Block.cloth.blockID, 11);
		world.setBlockAndMetadata(i + 1, j + 1, k + 12, Block.cloth.blockID, 11);
		world.setBlockAndMetadata(i + 1, j + 1, k + 13, Block.cloth.blockID, 11);
		world.setBlockAndMetadata(i + 1, j + 1, k + 14, Block.cloth.blockID, 11);
		world.setBlockAndMetadata(i + 1, j + 1, k + 15, Block.cloth.blockID, 11);
		world.setBlockAndMetadata(i + 1, j + 1, k + 16, Block.cloth.blockID, 11);
		world.setBlockAndMetadata(i + 1, j + 1, k + 17, Block.cloth.blockID, 11);
		world.setBlockAndMetadata(i + 1, j + 1, k + 18, Block.cloth.blockID, 11);
		world.setBlockAndMetadata(i + 1, j + 1, k + 19, Block.cloth.blockID, 11);
		world.setBlockAndMetadata(i + 1, j + 1, k + 20, Block.cloth.blockID, 11);
		world.setBlockAndMetadata(i + 1, j + 1, k + 21, Block.cloth.blockID, 15);
		world.setBlock(i + 1, j + 2, k + 0, 0);
		world.setBlockAndMetadata(i + 1, j + 2, k + 1, Block.cloth.blockID, 15);
		world.setBlockAndMetadata(i + 1, j + 2, k + 2, Block.cloth.blockID, 11);
		world.setBlockAndMetadata(i + 1, j + 2, k + 3, Block.cloth.blockID, 11);
		world.setBlockAndMetadata(i + 1, j + 2, k + 4, Block.cloth.blockID, 11);
		world.setBlockAndMetadata(i + 1, j + 2, k + 5, Block.cloth.blockID, 11);
		world.setBlockAndMetadata(i + 1, j + 2, k + 6, Block.cloth.blockID, 11);
		world.setBlockAndMetadata(i + 1, j + 2, k + 7, Block.cloth.blockID, 11);
		world.setBlockAndMetadata(i + 1, j + 2, k + 8, Block.cloth.blockID, 11);
		world.setBlockAndMetadata(i + 1, j + 2, k + 9, Block.cloth.blockID, 11);
		world.setBlockAndMetadata(i + 1, j + 2, k + 10, Block.cloth.blockID, 11);
		world.setBlockAndMetadata(i + 1, j + 2, k + 11, Block.cloth.blockID, 11);
		world.setBlockAndMetadata(i + 1, j + 2, k + 12, Block.cloth.blockID, 11);
		world.setBlockAndMetadata(i + 1, j + 2, k + 13, Block.cloth.blockID, 11);
		world.setBlockAndMetadata(i + 1, j + 2, k + 14, Block.cloth.blockID, 11);
		world.setBlockAndMetadata(i + 1, j + 2, k + 15, Block.cloth.blockID, 11);
		world.setBlockAndMetadata(i + 1, j + 2, k + 16, Block.cloth.blockID, 11);
		world.setBlockAndMetadata(i + 1, j + 2, k + 17, Block.cloth.blockID, 11);
		world.setBlockAndMetadata(i + 1, j + 2, k + 18, Block.cloth.blockID, 11);
		world.setBlockAndMetadata(i + 1, j + 2, k + 19, Block.cloth.blockID, 11);
		world.setBlockAndMetadata(i + 1, j + 2, k + 20, Block.cloth.blockID, 11);
		world.setBlockAndMetadata(i + 1, j + 2, k + 21, Block.cloth.blockID, 15);
		world.setBlock(i + 1, j + 3, k + 0, 0);
		world.setBlockAndMetadata(i + 1, j + 3, k + 1, Block.cloth.blockID, 15);
		world.setBlockAndMetadata(i + 1, j + 3, k + 2, Block.cloth.blockID, 11);
		world.setBlockAndMetadata(i + 1, j + 3, k + 3, Block.cloth.blockID, 11);
		world.setBlockAndMetadata(i + 1, j + 3, k + 4, Block.cloth.blockID, 11);
		world.setBlockAndMetadata(i + 1, j + 3, k + 5, Block.cloth.blockID, 11);
		world.setBlockAndMetadata(i + 1, j + 3, k + 6, Block.cloth.blockID, 11);
		world.setBlockAndMetadata(i + 1, j + 3, k + 7, Block.cloth.blockID, 11);
		world.setBlockAndMetadata(i + 1, j + 3, k + 8, Block.cloth.blockID, 11);
		world.setBlockAndMetadata(i + 1, j + 3, k + 9, Block.cloth.blockID, 11);
		world.setBlockAndMetadata(i + 1, j + 3, k + 10, Block.cloth.blockID, 11);
		world.setBlockAndMetadata(i + 1, j + 3, k + 11, Block.cloth.blockID, 11);
		world.setBlockAndMetadata(i + 1, j + 3, k + 12, Block.cloth.blockID, 11);
		world.setBlockAndMetadata(i + 1, j + 3, k + 13, Block.cloth.blockID, 11);
		world.setBlockAndMetadata(i + 1, j + 3, k + 14, Block.cloth.blockID, 11);
		world.setBlockAndMetadata(i + 1, j + 3, k + 15, Block.cloth.blockID, 11);
		world.setBlockAndMetadata(i + 1, j + 3, k + 16, Block.cloth.blockID, 11);
		world.setBlockAndMetadata(i + 1, j + 3, k + 17, Block.cloth.blockID, 11);
		world.setBlockAndMetadata(i + 1, j + 3, k + 18, Block.cloth.blockID, 11);
		world.setBlockAndMetadata(i + 1, j + 3, k + 19, Block.cloth.blockID, 11);
		world.setBlockAndMetadata(i + 1, j + 3, k + 20, Block.cloth.blockID, 11);
		world.setBlockAndMetadata(i + 1, j + 3, k + 21, Block.cloth.blockID, 15);
		world.setBlock(i + 1, j + 4, k + 0, 0);
		world.setBlockAndMetadata(i + 1, j + 4, k + 1, Block.cloth.blockID, 15);
		world.setBlockAndMetadata(i + 1, j + 4, k + 2, Block.cloth.blockID, 15);
		world.setBlockAndMetadata(i + 1, j + 4, k + 3, Block.cloth.blockID, 15);
		world.setBlockAndMetadata(i + 1, j + 4, k + 4, Block.cloth.blockID, 15);
		world.setBlockAndMetadata(i + 1, j + 4, k + 5, Block.cloth.blockID, 15);
		world.setBlockAndMetadata(i + 1, j + 4, k + 6, Block.cloth.blockID, 15);
		world.setBlockAndMetadata(i + 1, j + 4, k + 7, Block.cloth.blockID, 15);
		world.setBlockAndMetadata(i + 1, j + 4, k + 8, Block.cloth.blockID, 15);
		world.setBlockAndMetadata(i + 1, j + 4, k + 9, Block.cloth.blockID, 15);
		world.setBlockAndMetadata(i + 1, j + 4, k + 10, Block.cloth.blockID, 15);
		world.setBlockAndMetadata(i + 1, j + 4, k + 11, Block.cloth.blockID, 15);
		world.setBlockAndMetadata(i + 1, j + 4, k + 12, Block.cloth.blockID, 15);
		world.setBlockAndMetadata(i + 1, j + 4, k + 13, Block.cloth.blockID, 15);
		world.setBlockAndMetadata(i + 1, j + 4, k + 14, Block.cloth.blockID, 15);
		world.setBlockAndMetadata(i + 1, j + 4, k + 15, Block.cloth.blockID, 15);
		world.setBlockAndMetadata(i + 1, j + 4, k + 16, Block.cloth.blockID, 15);
		world.setBlockAndMetadata(i + 1, j + 4, k + 17, Block.cloth.blockID, 15);
		world.setBlockAndMetadata(i + 1, j + 4, k + 18, Block.cloth.blockID, 15);
		world.setBlockAndMetadata(i + 1, j + 4, k + 19, Block.cloth.blockID, 15);
		world.setBlockAndMetadata(i + 1, j + 4, k + 20, Block.cloth.blockID, 15);
		world.setBlockAndMetadata(i + 1, j + 4, k + 21, Block.cloth.blockID, 15);
		world.setBlock(i + 1, j + 5, k + 0, 0);
		world.setBlock(i + 1, j + 5, k + 1, 0);
		world.setBlock(i + 1, j + 5, k + 2, 0);
		world.setBlock(i + 1, j + 5, k + 3, 0);
		world.setBlock(i + 1, j + 5, k + 4, 0);
		world.setBlock(i + 1, j + 5, k + 5, 0);
		world.setBlock(i + 1, j + 5, k + 6, 0);
		world.setBlock(i + 1, j + 5, k + 7, 0);
		world.setBlock(i + 1, j + 5, k + 8, 0);
		world.setBlock(i + 1, j + 5, k + 9, 0);
		world.setBlock(i + 1, j + 5, k + 10, 0);
		world.setBlock(i + 1, j + 5, k + 11, 0);
		world.setBlock(i + 1, j + 5, k + 12, 0);
		world.setBlock(i + 1, j + 5, k + 13, 0);
		world.setBlock(i + 1, j + 5, k + 14, 0);
		world.setBlock(i + 1, j + 5, k + 15, 0);
		world.setBlock(i + 1, j + 5, k + 16, 0);
		world.setBlock(i + 1, j + 5, k + 17, 0);
		world.setBlock(i + 1, j + 5, k + 18, 0);
		world.setBlock(i + 1, j + 5, k + 19, 0);
		world.setBlock(i + 1, j + 5, k + 20, 0);
		world.setBlock(i + 1, j + 5, k + 21, 0);
		world.setBlock(i + 1, j + 6, k + 0, 0);
		world.setBlock(i + 1, j + 6, k + 1, 0);
		world.setBlock(i + 1, j + 6, k + 2, 0);
		world.setBlock(i + 1, j + 6, k + 3, 0);
		world.setBlock(i + 1, j + 6, k + 4, 0);
		world.setBlock(i + 1, j + 6, k + 5, 0);
		world.setBlock(i + 1, j + 6, k + 6, 0);
		world.setBlock(i + 1, j + 6, k + 7, 0);
		world.setBlock(i + 1, j + 6, k + 8, 0);
		world.setBlock(i + 1, j + 6, k + 9, 0);
		world.setBlock(i + 1, j + 6, k + 10, 0);
		world.setBlock(i + 1, j + 6, k + 11, 0);
		world.setBlock(i + 1, j + 6, k + 12, 0);
		world.setBlock(i + 1, j + 6, k + 13, 0);
		world.setBlock(i + 1, j + 6, k + 14, 0);
		world.setBlock(i + 1, j + 6, k + 15, 0);
		world.setBlock(i + 1, j + 6, k + 16, 0);
		world.setBlock(i + 1, j + 6, k + 17, 0);
		world.setBlock(i + 1, j + 6, k + 18, 0);
		world.setBlock(i + 1, j + 6, k + 19, 0);
		world.setBlock(i + 1, j + 6, k + 20, 0);
		world.setBlock(i + 1, j + 6, k + 21, 0);
		world.setBlock(i + 1, j + 7, k + 0, 0);
		world.setBlock(i + 1, j + 7, k + 1, 0);
		world.setBlock(i + 1, j + 7, k + 2, 0);
		world.setBlock(i + 1, j + 7, k + 3, 0);
		world.setBlock(i + 1, j + 7, k + 4, 0);
		world.setBlock(i + 1, j + 7, k + 5, 0);
		world.setBlock(i + 1, j + 7, k + 6, 0);
		world.setBlock(i + 1, j + 7, k + 7, 0);
		world.setBlock(i + 1, j + 7, k + 8, 0);
		world.setBlock(i + 1, j + 7, k + 9, 0);
		world.setBlock(i + 1, j + 7, k + 10, 0);
		world.setBlock(i + 1, j + 7, k + 11, 0);
		world.setBlock(i + 1, j + 7, k + 12, 0);
		world.setBlock(i + 1, j + 7, k + 13, 0);
		world.setBlock(i + 1, j + 7, k + 14, 0);
		world.setBlock(i + 1, j + 7, k + 15, 0);
		world.setBlock(i + 1, j + 7, k + 16, 0);
		world.setBlock(i + 1, j + 7, k + 17, 0);
		world.setBlock(i + 1, j + 7, k + 18, 0);
		world.setBlock(i + 1, j + 7, k + 19, 0);
		world.setBlock(i + 1, j + 7, k + 20, 0);
		world.setBlock(i + 1, j + 7, k + 21, 0);
		world.setBlock(i + 1, j + 8, k + 0, 0);
		world.setBlock(i + 1, j + 8, k + 1, 0);
		world.setBlock(i + 1, j + 8, k + 2, 0);
		world.setBlock(i + 1, j + 8, k + 3, 0);
		world.setBlock(i + 1, j + 8, k + 4, 0);
		world.setBlock(i + 1, j + 8, k + 5, 0);
		world.setBlock(i + 1, j + 8, k + 6, 0);
		world.setBlock(i + 1, j + 8, k + 7, 0);
		world.setBlock(i + 1, j + 8, k + 8, 0);
		world.setBlock(i + 1, j + 8, k + 9, 0);
		world.setBlock(i + 1, j + 8, k + 10, 0);
		world.setBlock(i + 1, j + 8, k + 11, 0);
		world.setBlock(i + 1, j + 8, k + 12, 0);
		world.setBlock(i + 1, j + 8, k + 13, 0);
		world.setBlock(i + 1, j + 8, k + 14, 0);
		world.setBlock(i + 1, j + 8, k + 15, 0);
		world.setBlock(i + 1, j + 8, k + 16, 0);
		world.setBlock(i + 1, j + 8, k + 17, 0);
		world.setBlock(i + 1, j + 8, k + 18, 0);
		world.setBlock(i + 1, j + 8, k + 19, 0);
		world.setBlock(i + 1, j + 8, k + 20, 0);
		world.setBlock(i + 1, j + 8, k + 21, 0);
		world.setBlock(i + 1, j + 9, k + 0, 0);
		world.setBlock(i + 1, j + 9, k + 1, 0);
		world.setBlock(i + 1, j + 9, k + 2, 0);
		world.setBlock(i + 1, j + 9, k + 3, 0);
		world.setBlock(i + 1, j + 9, k + 4, 0);
		world.setBlock(i + 1, j + 9, k + 5, 0);
		world.setBlock(i + 1, j + 9, k + 6, 0);
		world.setBlock(i + 1, j + 9, k + 7, 0);
		world.setBlock(i + 1, j + 9, k + 8, 0);
		world.setBlock(i + 1, j + 9, k + 9, 0);
		world.setBlock(i + 1, j + 9, k + 10, 0);
		world.setBlock(i + 1, j + 9, k + 11, 0);
		world.setBlock(i + 1, j + 9, k + 12, 0);
		world.setBlock(i + 1, j + 9, k + 13, 0);
		world.setBlock(i + 1, j + 9, k + 14, 0);
		world.setBlock(i + 1, j + 9, k + 15, 0);
		world.setBlock(i + 1, j + 9, k + 16, 0);
		world.setBlock(i + 1, j + 9, k + 17, 0);
		world.setBlock(i + 1, j + 9, k + 18, 0);
		world.setBlock(i + 1, j + 9, k + 19, 0);
		world.setBlock(i + 1, j + 9, k + 20, 0);
		world.setBlock(i + 1, j + 9, k + 21, 0);
		world.setBlock(i + 1, j + 10, k + 0, 0);
		world.setBlock(i + 1, j + 10, k + 1, 0);
		world.setBlock(i + 1, j + 10, k + 2, 0);
		world.setBlock(i + 1, j + 10, k + 3, 0);
		world.setBlock(i + 1, j + 10, k + 4, 0);
		world.setBlock(i + 1, j + 10, k + 5, 0);
		world.setBlock(i + 1, j + 10, k + 6, 0);
		world.setBlock(i + 1, j + 10, k + 7, 0);
		world.setBlock(i + 1, j + 10, k + 8, 0);
		world.setBlock(i + 1, j + 10, k + 9, 0);
		world.setBlock(i + 1, j + 10, k + 10, 0);
		world.setBlock(i + 1, j + 10, k + 11, 0);
		world.setBlock(i + 1, j + 10, k + 12, 0);
		world.setBlock(i + 1, j + 10, k + 13, 0);
		world.setBlock(i + 1, j + 10, k + 14, 0);
		world.setBlock(i + 1, j + 10, k + 15, 0);
		world.setBlock(i + 1, j + 10, k + 16, 0);
		world.setBlock(i + 1, j + 10, k + 17, 0);
		world.setBlock(i + 1, j + 10, k + 18, 0);
		world.setBlock(i + 1, j + 10, k + 19, 0);
		world.setBlock(i + 1, j + 10, k + 20, 0);
		world.setBlock(i + 1, j + 10, k + 21, 0);
		world.setBlock(i + 1, j + 11, k + 0, 0);
		world.setBlock(i + 1, j + 11, k + 1, 0);
		world.setBlock(i + 1, j + 11, k + 2, 0);
		world.setBlock(i + 1, j + 11, k + 3, 0);
		world.setBlock(i + 1, j + 11, k + 4, 0);
		world.setBlock(i + 1, j + 11, k + 5, 0);
		world.setBlock(i + 1, j + 11, k + 6, 0);
		world.setBlock(i + 1, j + 11, k + 7, 0);
		world.setBlock(i + 1, j + 11, k + 8, 0);
		world.setBlock(i + 1, j + 11, k + 9, 0);
		world.setBlock(i + 1, j + 11, k + 10, 0);
		world.setBlock(i + 1, j + 11, k + 11, 0);
		world.setBlock(i + 1, j + 11, k + 12, 0);
		world.setBlock(i + 1, j + 11, k + 13, 0);
		world.setBlock(i + 1, j + 11, k + 14, 0);
		world.setBlock(i + 1, j + 11, k + 15, 0);
		world.setBlock(i + 1, j + 11, k + 16, 0);
		world.setBlock(i + 1, j + 11, k + 17, 0);
		world.setBlock(i + 1, j + 11, k + 18, 0);
		world.setBlock(i + 1, j + 11, k + 19, 0);
		world.setBlock(i + 1, j + 11, k + 20, 0);
		world.setBlock(i + 1, j + 11, k + 21, 0);
		world.setBlock(i + 1, j + 12, k + 0, 0);
		world.setBlock(i + 1, j + 12, k + 1, 0);
		world.setBlock(i + 1, j + 12, k + 2, 0);
		world.setBlock(i + 1, j + 12, k + 3, 0);
		world.setBlock(i + 1, j + 12, k + 4, 0);
		world.setBlock(i + 1, j + 12, k + 5, 0);
		world.setBlock(i + 1, j + 12, k + 6, 0);
		world.setBlock(i + 1, j + 12, k + 7, 0);
		world.setBlock(i + 1, j + 12, k + 8, 0);
		world.setBlock(i + 1, j + 12, k + 9, 0);
		world.setBlock(i + 1, j + 12, k + 10, 0);
		world.setBlock(i + 1, j + 12, k + 11, 0);
		world.setBlock(i + 1, j + 12, k + 12, 0);
		world.setBlock(i + 1, j + 12, k + 13, 0);
		world.setBlock(i + 1, j + 12, k + 14, 0);
		world.setBlock(i + 1, j + 12, k + 15, 0);
		world.setBlock(i + 1, j + 12, k + 16, 0);
		world.setBlock(i + 1, j + 12, k + 17, 0);
		world.setBlock(i + 1, j + 12, k + 18, 0);
		world.setBlock(i + 1, j + 12, k + 19, 0);
		world.setBlock(i + 1, j + 12, k + 20, 0);
		world.setBlock(i + 1, j + 12, k + 21, 0);
		world.setBlock(i + 1, j + 13, k + 0, 0);
		world.setBlock(i + 1, j + 13, k + 1, 0);
		world.setBlock(i + 1, j + 13, k + 2, 0);
		world.setBlock(i + 1, j + 13, k + 3, 0);
		world.setBlock(i + 1, j + 13, k + 4, 0);
		world.setBlock(i + 1, j + 13, k + 5, 0);
		world.setBlock(i + 1, j + 13, k + 6, 0);
		world.setBlock(i + 1, j + 13, k + 7, 0);
		world.setBlock(i + 1, j + 13, k + 8, 0);
		world.setBlock(i + 1, j + 13, k + 9, 0);
		world.setBlock(i + 1, j + 13, k + 10, 0);
		world.setBlock(i + 1, j + 13, k + 11, 0);
		world.setBlock(i + 1, j + 13, k + 12, 0);
		world.setBlock(i + 1, j + 13, k + 13, 0);
		world.setBlock(i + 1, j + 13, k + 14, 0);
		world.setBlock(i + 1, j + 13, k + 15, 0);
		world.setBlock(i + 1, j + 13, k + 16, 0);
		world.setBlock(i + 1, j + 13, k + 17, 0);
		world.setBlock(i + 1, j + 13, k + 18, 0);
		world.setBlock(i + 1, j + 13, k + 19, 0);
		world.setBlock(i + 1, j + 13, k + 20, 0);
		world.setBlock(i + 1, j + 13, k + 21, 0);
		world.setBlock(i + 1, j + 14, k + 0, 0);
		world.setBlock(i + 1, j + 14, k + 1, 0);
		world.setBlock(i + 1, j + 14, k + 2, 0);
		world.setBlock(i + 1, j + 14, k + 3, 0);
		world.setBlock(i + 1, j + 14, k + 4, 0);
		world.setBlock(i + 1, j + 14, k + 5, 0);
		world.setBlock(i + 1, j + 14, k + 6, 0);
		world.setBlock(i + 1, j + 14, k + 7, 0);
		world.setBlock(i + 1, j + 14, k + 8, 0);
		world.setBlock(i + 1, j + 14, k + 9, 0);
		world.setBlock(i + 1, j + 14, k + 10, 0);
		world.setBlock(i + 1, j + 14, k + 11, 0);
		world.setBlock(i + 1, j + 14, k + 12, 0);
		world.setBlock(i + 1, j + 14, k + 13, 0);
		world.setBlock(i + 1, j + 14, k + 14, 0);
		world.setBlock(i + 1, j + 14, k + 15, 0);
		world.setBlock(i + 1, j + 14, k + 16, 0);
		world.setBlock(i + 1, j + 14, k + 17, 0);
		world.setBlock(i + 1, j + 14, k + 18, 0);
		world.setBlock(i + 1, j + 14, k + 19, 0);
		world.setBlock(i + 1, j + 14, k + 20, 0);
		world.setBlock(i + 1, j + 14, k + 21, 0);
		world.setBlock(i + 1, j + 15, k + 0, 0);
		world.setBlock(i + 1, j + 15, k + 1, 0);
		world.setBlock(i + 1, j + 15, k + 2, 0);
		world.setBlock(i + 1, j + 15, k + 3, 0);
		world.setBlock(i + 1, j + 15, k + 4, 0);
		world.setBlock(i + 1, j + 15, k + 5, 0);
		world.setBlock(i + 1, j + 15, k + 6, 0);
		world.setBlock(i + 1, j + 15, k + 7, 0);
		world.setBlock(i + 1, j + 15, k + 8, 0);
		world.setBlock(i + 1, j + 15, k + 9, 0);
		world.setBlock(i + 1, j + 15, k + 10, 0);
		world.setBlock(i + 1, j + 15, k + 11, 0);
		world.setBlock(i + 1, j + 15, k + 12, 0);
		world.setBlock(i + 1, j + 15, k + 13, 0);
		world.setBlock(i + 1, j + 15, k + 14, 0);
		world.setBlock(i + 1, j + 15, k + 15, 0);
		world.setBlock(i + 1, j + 15, k + 16, 0);
		world.setBlock(i + 1, j + 15, k + 17, 0);
		world.setBlock(i + 1, j + 15, k + 18, 0);
		world.setBlock(i + 1, j + 15, k + 19, 0);
		world.setBlock(i + 1, j + 15, k + 20, 0);
		world.setBlock(i + 1, j + 15, k + 21, 0);
		world.setBlock(i + 2, j + 0, k + 0, Block.grass.blockID);
		world.setBlock(i + 2, j + 0, k + 1, Block.dirt.blockID);
		world.setBlockAndMetadata(i + 2, j + 0, k + 2, Block.cloth.blockID, 15);
		world.setBlockAndMetadata(i + 2, j + 0, k + 3, Block.cloth.blockID, 15);
		world.setBlockAndMetadata(i + 2, j + 0, k + 4, Block.cloth.blockID, 15);
		world.setBlockAndMetadata(i + 2, j + 0, k + 5, Block.cloth.blockID, 15);
		world.setBlockAndMetadata(i + 2, j + 0, k + 6, Block.cloth.blockID, 15);
		world.setBlockAndMetadata(i + 2, j + 0, k + 7, Block.cloth.blockID, 15);
		world.setBlockAndMetadata(i + 2, j + 0, k + 8, Block.cloth.blockID, 15);
		world.setBlockAndMetadata(i + 2, j + 0, k + 9, Block.cloth.blockID, 15);
		world.setBlockAndMetadata(i + 2, j + 0, k + 10, Block.cloth.blockID, 15);
		world.setBlockAndMetadata(i + 2, j + 0, k + 11, Block.cloth.blockID, 15);
		world.setBlockAndMetadata(i + 2, j + 0, k + 12, Block.cloth.blockID, 15);
		world.setBlockAndMetadata(i + 2, j + 0, k + 13, Block.cloth.blockID, 15);
		world.setBlockAndMetadata(i + 2, j + 0, k + 14, Block.cloth.blockID, 15);
		world.setBlockAndMetadata(i + 2, j + 0, k + 15, Block.cloth.blockID, 15);
		world.setBlockAndMetadata(i + 2, j + 0, k + 16, Block.cloth.blockID, 15);
		world.setBlockAndMetadata(i + 2, j + 0, k + 17, Block.cloth.blockID, 15);
		world.setBlockAndMetadata(i + 2, j + 0, k + 18, Block.cloth.blockID, 15);
		world.setBlockAndMetadata(i + 2, j + 0, k + 19, Block.cloth.blockID, 15);
		world.setBlockAndMetadata(i + 2, j + 0, k + 20, Block.cloth.blockID, 15);
		world.setBlock(i + 2, j + 0, k + 21, Block.dirt.blockID);
		world.setBlock(i + 2, j + 1, k + 0, 0);
		world.setBlockAndMetadata(i + 2, j + 1, k + 1, Block.cloth.blockID, 11);
		world.setBlockAndMetadata(i + 2, j + 1, k + 21, Block.cloth.blockID, 11);
		world.setBlock(i + 2, j + 2, k + 0, 0);
		world.setBlockAndMetadata(i + 2, j + 2, k + 1, Block.cloth.blockID, 11);
		world.setBlock(i + 2, j + 2, k + 2, 0);
		world.setBlock(i + 2, j + 2, k + 3, 0);
		world.setBlock(i + 2, j + 2, k + 4, 0);
		world.setBlock(i + 2, j + 2, k + 5, 0);
		world.setBlock(i + 2, j + 2, k + 6, 0);
		world.setBlock(i + 2, j + 2, k + 7, 0);
		world.setBlock(i + 2, j + 2, k + 8, 0);
		world.setBlock(i + 2, j + 2, k + 9, 0);
		world.setBlock(i + 2, j + 2, k + 10, 0);
		world.setBlock(i + 2, j + 2, k + 11, 0);
		world.setBlock(i + 2, j + 2, k + 12, 0);
		world.setBlock(i + 2, j + 2, k + 13, 0);
		world.setBlock(i + 2, j + 2, k + 14, 0);
		world.setBlock(i + 2, j + 2, k + 15, 0);
		world.setBlock(i + 2, j + 2, k + 16, 0);
		world.setBlock(i + 2, j + 2, k + 17, 0);
		world.setBlock(i + 2, j + 2, k + 18, 0);
		world.setBlock(i + 2, j + 2, k + 19, 0);
		world.setBlock(i + 2, j + 2, k + 20, 0);
		world.setBlockAndMetadata(i + 2, j + 2, k + 21, Block.cloth.blockID, 11);
		world.setBlock(i + 2, j + 3, k + 0, 0);
		world.setBlockAndMetadata(i + 2, j + 3, k + 1, Block.cloth.blockID, 11);
		world.setBlock(i + 2, j + 3, k + 2, 0);
		world.setBlock(i + 2, j + 3, k + 3, 0);
		world.setBlock(i + 2, j + 3, k + 4, 0);
		world.setBlock(i + 2, j + 3, k + 5, 0);
		world.setBlock(i + 2, j + 3, k + 6, 0);
		world.setBlock(i + 2, j + 3, k + 7, 0);
		world.setBlock(i + 2, j + 3, k + 8, 0);
		world.setBlock(i + 2, j + 3, k + 9, 0);
		world.setBlock(i + 2, j + 3, k + 10, 0);
		world.setBlock(i + 2, j + 3, k + 11, 0);
		world.setBlock(i + 2, j + 3, k + 12, 0);
		world.setBlock(i + 2, j + 3, k + 13, 0);
		world.setBlock(i + 2, j + 3, k + 14, 0);
		world.setBlock(i + 2, j + 3, k + 15, 0);
		world.setBlock(i + 2, j + 3, k + 16, 0);
		world.setBlock(i + 2, j + 3, k + 17, 0);
		world.setBlock(i + 2, j + 3, k + 18, 0);
		world.setBlock(i + 2, j + 3, k + 19, 0);
		world.setBlock(i + 2, j + 3, k + 20, 0);
		world.setBlockAndMetadata(i + 2, j + 3, k + 21, Block.cloth.blockID, 11);
		world.setBlock(i + 2, j + 4, k + 0, 0);
		world.setBlockAndMetadata(i + 2, j + 4, k + 1, Block.cloth.blockID, 15);
		world.setBlockAndMetadata(i + 2, j + 4, k + 2, Block.cloth.blockID, 15);
		world.setBlockAndMetadata(i + 2, j + 4, k + 3, Block.cloth.blockID, 15);
		world.setBlockAndMetadata(i + 2, j + 4, k + 4, Block.cloth.blockID, 15);
		world.setBlockAndMetadata(i + 2, j + 4, k + 5, Block.cloth.blockID, 15);
		world.setBlockAndMetadata(i + 2, j + 4, k + 6, Block.cloth.blockID, 15);
		world.setBlockAndMetadata(i + 2, j + 4, k + 7, Block.cloth.blockID, 15);
		world.setBlockAndMetadata(i + 2, j + 4, k + 8, Block.cloth.blockID, 15);
		world.setBlockAndMetadata(i + 2, j + 4, k + 9, Block.cloth.blockID, 15);
		world.setBlockAndMetadata(i + 2, j + 4, k + 10, Block.cloth.blockID, 15);
		world.setBlockAndMetadata(i + 2, j + 4, k + 11, Block.cloth.blockID, 15);
		world.setBlockAndMetadata(i + 2, j + 4, k + 12, Block.cloth.blockID, 15);
		world.setBlockAndMetadata(i + 2, j + 4, k + 13, Block.cloth.blockID, 15);
		world.setBlockAndMetadata(i + 2, j + 4, k + 14, Block.cloth.blockID, 15);
		world.setBlockAndMetadata(i + 2, j + 4, k + 15, Block.cloth.blockID, 15);
		world.setBlockAndMetadata(i + 2, j + 4, k + 16, Block.cloth.blockID, 15);
		world.setBlockAndMetadata(i + 2, j + 4, k + 17, Block.cloth.blockID, 15);
		world.setBlockAndMetadata(i + 2, j + 4, k + 18, Block.cloth.blockID, 15);
		world.setBlockAndMetadata(i + 2, j + 4, k + 19, Block.cloth.blockID, 15);
		world.setBlockAndMetadata(i + 2, j + 4, k + 20, Block.cloth.blockID, 15);
		world.setBlockAndMetadata(i + 2, j + 4, k + 21, Block.cloth.blockID, 15);
		world.setBlock(i + 2, j + 5, k + 0, 0);
		world.setBlock(i + 2, j + 5, k + 1, 0);
		world.setBlock(i + 2, j + 5, k + 2, 0);
		world.setBlock(i + 2, j + 5, k + 3, 0);
		world.setBlock(i + 2, j + 5, k + 4, 0);
		world.setBlock(i + 2, j + 5, k + 5, 0);
		world.setBlock(i + 2, j + 5, k + 6, 0);
		world.setBlock(i + 2, j + 5, k + 7, 0);
		world.setBlock(i + 2, j + 5, k + 8, 0);
		world.setBlock(i + 2, j + 5, k + 9, 0);
		world.setBlock(i + 2, j + 5, k + 10, 0);
		world.setBlock(i + 2, j + 5, k + 11, 0);
		world.setBlock(i + 2, j + 5, k + 12, 0);
		world.setBlock(i + 2, j + 5, k + 13, 0);
		world.setBlock(i + 2, j + 5, k + 14, 0);
		world.setBlock(i + 2, j + 5, k + 15, 0);
		world.setBlock(i + 2, j + 5, k + 16, 0);
		world.setBlock(i + 2, j + 5, k + 17, 0);
		world.setBlock(i + 2, j + 5, k + 18, 0);
		world.setBlock(i + 2, j + 5, k + 19, 0);
		world.setBlock(i + 2, j + 5, k + 20, 0);
		world.setBlock(i + 2, j + 5, k + 21, 0);
		world.setBlock(i + 2, j + 6, k + 0, 0);
		world.setBlock(i + 2, j + 6, k + 1, 0);
		world.setBlock(i + 2, j + 6, k + 2, 0);
		world.setBlock(i + 2, j + 6, k + 3, 0);
		world.setBlock(i + 2, j + 6, k + 4, 0);
		world.setBlock(i + 2, j + 6, k + 5, 0);
		world.setBlock(i + 2, j + 6, k + 6, 0);
		world.setBlock(i + 2, j + 6, k + 7, 0);
		world.setBlock(i + 2, j + 6, k + 8, 0);
		world.setBlock(i + 2, j + 6, k + 9, 0);
		world.setBlock(i + 2, j + 6, k + 10, 0);
		world.setBlock(i + 2, j + 6, k + 11, 0);
		world.setBlock(i + 2, j + 6, k + 12, 0);
		world.setBlock(i + 2, j + 6, k + 13, 0);
		world.setBlock(i + 2, j + 6, k + 14, 0);
		world.setBlock(i + 2, j + 6, k + 15, 0);
		world.setBlock(i + 2, j + 6, k + 16, 0);
		world.setBlock(i + 2, j + 6, k + 17, 0);
		world.setBlock(i + 2, j + 6, k + 18, 0);
		world.setBlock(i + 2, j + 6, k + 19, 0);
		world.setBlock(i + 2, j + 6, k + 20, 0);
		world.setBlock(i + 2, j + 6, k + 21, 0);
		world.setBlock(i + 2, j + 7, k + 0, 0);
		world.setBlock(i + 2, j + 7, k + 1, 0);
		world.setBlock(i + 2, j + 7, k + 2, 0);
		world.setBlock(i + 2, j + 7, k + 3, 0);
		world.setBlock(i + 2, j + 7, k + 4, 0);
		world.setBlock(i + 2, j + 7, k + 5, 0);
		world.setBlock(i + 2, j + 7, k + 6, 0);
		world.setBlock(i + 2, j + 7, k + 7, 0);
		world.setBlock(i + 2, j + 7, k + 8, 0);
		world.setBlock(i + 2, j + 7, k + 9, 0);
		world.setBlock(i + 2, j + 7, k + 10, 0);
		world.setBlock(i + 2, j + 7, k + 11, 0);
		world.setBlock(i + 2, j + 7, k + 12, 0);
		world.setBlock(i + 2, j + 7, k + 13, 0);
		world.setBlock(i + 2, j + 7, k + 14, 0);
		world.setBlock(i + 2, j + 7, k + 15, 0);
		world.setBlock(i + 2, j + 7, k + 16, 0);
		world.setBlock(i + 2, j + 7, k + 17, 0);
		world.setBlock(i + 2, j + 7, k + 18, 0);
		world.setBlock(i + 2, j + 7, k + 19, 0);
		world.setBlock(i + 2, j + 7, k + 20, 0);
		world.setBlock(i + 2, j + 7, k + 21, 0);
		world.setBlock(i + 2, j + 8, k + 0, 0);
		world.setBlock(i + 2, j + 8, k + 1, 0);
		world.setBlock(i + 2, j + 8, k + 2, 0);
		world.setBlock(i + 2, j + 8, k + 3, 0);
		world.setBlock(i + 2, j + 8, k + 4, 0);
		world.setBlock(i + 2, j + 8, k + 5, 0);
		world.setBlock(i + 2, j + 8, k + 6, 0);
		world.setBlock(i + 2, j + 8, k + 7, 0);
		world.setBlock(i + 2, j + 8, k + 8, 0);
		world.setBlock(i + 2, j + 8, k + 9, 0);
		world.setBlock(i + 2, j + 8, k + 10, 0);
		world.setBlock(i + 2, j + 8, k + 11, 0);
		world.setBlock(i + 2, j + 8, k + 12, 0);
		world.setBlock(i + 2, j + 8, k + 13, 0);
		world.setBlock(i + 2, j + 8, k + 14, 0);
		world.setBlock(i + 2, j + 8, k + 15, 0);
		world.setBlock(i + 2, j + 8, k + 16, 0);
		world.setBlock(i + 2, j + 8, k + 17, 0);
		world.setBlock(i + 2, j + 8, k + 18, 0);
		world.setBlock(i + 2, j + 8, k + 19, 0);
		world.setBlock(i + 2, j + 8, k + 20, 0);
		world.setBlock(i + 2, j + 8, k + 21, 0);
		world.setBlock(i + 2, j + 9, k + 0, 0);
		world.setBlock(i + 2, j + 9, k + 1, 0);
		world.setBlock(i + 2, j + 9, k + 2, 0);
		world.setBlock(i + 2, j + 9, k + 3, 0);
		world.setBlock(i + 2, j + 9, k + 4, 0);
		world.setBlock(i + 2, j + 9, k + 5, 0);
		world.setBlock(i + 2, j + 9, k + 6, 0);
		world.setBlock(i + 2, j + 9, k + 7, 0);
		world.setBlock(i + 2, j + 9, k + 8, 0);
		world.setBlock(i + 2, j + 9, k + 9, 0);
		world.setBlock(i + 2, j + 9, k + 10, 0);
		world.setBlock(i + 2, j + 9, k + 11, 0);
		world.setBlock(i + 2, j + 9, k + 12, 0);
		world.setBlock(i + 2, j + 9, k + 13, 0);
		world.setBlock(i + 2, j + 9, k + 14, 0);
		world.setBlock(i + 2, j + 9, k + 15, 0);
		world.setBlock(i + 2, j + 9, k + 16, 0);
		world.setBlock(i + 2, j + 9, k + 17, 0);
		world.setBlock(i + 2, j + 9, k + 18, 0);
		world.setBlock(i + 2, j + 9, k + 19, 0);
		world.setBlock(i + 2, j + 9, k + 20, 0);
		world.setBlock(i + 2, j + 9, k + 21, 0);
		world.setBlock(i + 2, j + 10, k + 0, 0);
		world.setBlock(i + 2, j + 10, k + 1, 0);
		world.setBlock(i + 2, j + 10, k + 2, 0);
		world.setBlock(i + 2, j + 10, k + 3, 0);
		world.setBlock(i + 2, j + 10, k + 4, 0);
		world.setBlock(i + 2, j + 10, k + 5, 0);
		world.setBlock(i + 2, j + 10, k + 6, 0);
		world.setBlock(i + 2, j + 10, k + 7, 0);
		world.setBlock(i + 2, j + 10, k + 8, 0);
		world.setBlock(i + 2, j + 10, k + 9, 0);
		world.setBlock(i + 2, j + 10, k + 10, 0);
		world.setBlock(i + 2, j + 10, k + 11, 0);
		world.setBlock(i + 2, j + 10, k + 12, 0);
		world.setBlock(i + 2, j + 10, k + 13, 0);
		world.setBlock(i + 2, j + 10, k + 14, 0);
		world.setBlock(i + 2, j + 10, k + 15, 0);
		world.setBlock(i + 2, j + 10, k + 16, 0);
		world.setBlock(i + 2, j + 10, k + 17, 0);
		world.setBlock(i + 2, j + 10, k + 18, 0);
		world.setBlock(i + 2, j + 10, k + 19, 0);
		world.setBlock(i + 2, j + 10, k + 20, 0);
		world.setBlock(i + 2, j + 10, k + 21, 0);
		world.setBlock(i + 2, j + 11, k + 0, 0);
		world.setBlock(i + 2, j + 11, k + 1, 0);
		world.setBlock(i + 2, j + 11, k + 2, 0);
		world.setBlock(i + 2, j + 11, k + 3, 0);
		world.setBlock(i + 2, j + 11, k + 4, 0);
		world.setBlock(i + 2, j + 11, k + 5, 0);
		world.setBlock(i + 2, j + 11, k + 6, 0);
		world.setBlock(i + 2, j + 11, k + 7, 0);
		world.setBlock(i + 2, j + 11, k + 8, 0);
		world.setBlock(i + 2, j + 11, k + 9, 0);
		world.setBlock(i + 2, j + 11, k + 10, 0);
		world.setBlock(i + 2, j + 11, k + 11, 0);
		world.setBlock(i + 2, j + 11, k + 12, 0);
		world.setBlock(i + 2, j + 11, k + 13, 0);
		world.setBlock(i + 2, j + 11, k + 14, 0);
		world.setBlock(i + 2, j + 11, k + 15, 0);
		world.setBlock(i + 2, j + 11, k + 16, 0);
		world.setBlock(i + 2, j + 11, k + 17, 0);
		world.setBlock(i + 2, j + 11, k + 18, 0);
		world.setBlock(i + 2, j + 11, k + 19, 0);
		world.setBlock(i + 2, j + 11, k + 20, 0);
		world.setBlock(i + 2, j + 11, k + 21, 0);
		world.setBlock(i + 2, j + 12, k + 0, 0);
		world.setBlock(i + 2, j + 12, k + 1, 0);
		world.setBlock(i + 2, j + 12, k + 2, 0);
		world.setBlock(i + 2, j + 12, k + 3, 0);
		world.setBlock(i + 2, j + 12, k + 4, 0);
		world.setBlock(i + 2, j + 12, k + 5, 0);
		world.setBlock(i + 2, j + 12, k + 6, 0);
		world.setBlock(i + 2, j + 12, k + 7, 0);
		world.setBlock(i + 2, j + 12, k + 8, 0);
		world.setBlock(i + 2, j + 12, k + 9, 0);
		world.setBlock(i + 2, j + 12, k + 10, 0);
		world.setBlock(i + 2, j + 12, k + 11, 0);
		world.setBlock(i + 2, j + 12, k + 12, 0);
		world.setBlock(i + 2, j + 12, k + 13, 0);
		world.setBlock(i + 2, j + 12, k + 14, 0);
		world.setBlock(i + 2, j + 12, k + 15, 0);
		world.setBlock(i + 2, j + 12, k + 16, 0);
		world.setBlock(i + 2, j + 12, k + 17, 0);
		world.setBlock(i + 2, j + 12, k + 18, 0);
		world.setBlock(i + 2, j + 12, k + 19, 0);
		world.setBlock(i + 2, j + 12, k + 20, 0);
		world.setBlock(i + 2, j + 12, k + 21, 0);
		world.setBlock(i + 2, j + 13, k + 0, 0);
		world.setBlock(i + 2, j + 13, k + 1, 0);
		world.setBlock(i + 2, j + 13, k + 2, 0);
		world.setBlock(i + 2, j + 13, k + 3, 0);
		world.setBlock(i + 2, j + 13, k + 4, 0);
		world.setBlock(i + 2, j + 13, k + 5, 0);
		world.setBlock(i + 2, j + 13, k + 6, 0);
		world.setBlock(i + 2, j + 13, k + 7, 0);
		world.setBlock(i + 2, j + 13, k + 8, 0);
		world.setBlock(i + 2, j + 13, k + 9, 0);
		world.setBlock(i + 2, j + 13, k + 10, 0);
		world.setBlock(i + 2, j + 13, k + 11, 0);
		world.setBlock(i + 2, j + 13, k + 12, 0);
		world.setBlock(i + 2, j + 13, k + 13, 0);
		world.setBlock(i + 2, j + 13, k + 14, 0);
		world.setBlock(i + 2, j + 13, k + 15, 0);
		world.setBlock(i + 2, j + 13, k + 16, 0);
		world.setBlock(i + 2, j + 13, k + 17, 0);
		world.setBlock(i + 2, j + 13, k + 18, 0);
		world.setBlock(i + 2, j + 13, k + 19, 0);
		world.setBlock(i + 2, j + 13, k + 20, 0);
		world.setBlock(i + 2, j + 13, k + 21, 0);
		world.setBlock(i + 2, j + 14, k + 0, 0);
		world.setBlock(i + 2, j + 14, k + 1, 0);
		world.setBlock(i + 2, j + 14, k + 2, 0);
		world.setBlock(i + 2, j + 14, k + 3, 0);
		world.setBlock(i + 2, j + 14, k + 4, 0);
		world.setBlock(i + 2, j + 14, k + 5, 0);
		world.setBlock(i + 2, j + 14, k + 6, 0);
		world.setBlock(i + 2, j + 14, k + 7, 0);
		world.setBlock(i + 2, j + 14, k + 8, 0);
		world.setBlock(i + 2, j + 14, k + 9, 0);
		world.setBlock(i + 2, j + 14, k + 10, 0);
		world.setBlock(i + 2, j + 14, k + 11, 0);
		world.setBlock(i + 2, j + 14, k + 12, 0);
		world.setBlock(i + 2, j + 14, k + 13, 0);
		world.setBlock(i + 2, j + 14, k + 14, 0);
		world.setBlock(i + 2, j + 14, k + 15, 0);
		world.setBlock(i + 2, j + 14, k + 16, 0);
		world.setBlock(i + 2, j + 14, k + 17, 0);
		world.setBlock(i + 2, j + 14, k + 18, 0);
		world.setBlock(i + 2, j + 14, k + 19, 0);
		world.setBlock(i + 2, j + 14, k + 20, 0);
		world.setBlock(i + 2, j + 14, k + 21, 0);
		world.setBlock(i + 2, j + 15, k + 0, 0);
		world.setBlock(i + 2, j + 15, k + 1, 0);
		world.setBlock(i + 2, j + 15, k + 2, 0);
		world.setBlock(i + 2, j + 15, k + 3, 0);
		world.setBlock(i + 2, j + 15, k + 4, 0);
		world.setBlock(i + 2, j + 15, k + 5, 0);
		world.setBlock(i + 2, j + 15, k + 6, 0);
		world.setBlock(i + 2, j + 15, k + 7, 0);
		world.setBlock(i + 2, j + 15, k + 8, 0);
		world.setBlock(i + 2, j + 15, k + 9, 0);
		world.setBlock(i + 2, j + 15, k + 10, 0);
		world.setBlock(i + 2, j + 15, k + 11, 0);
		world.setBlock(i + 2, j + 15, k + 12, 0);
		world.setBlock(i + 2, j + 15, k + 13, 0);
		world.setBlock(i + 2, j + 15, k + 14, 0);
		world.setBlock(i + 2, j + 15, k + 15, 0);
		world.setBlock(i + 2, j + 15, k + 16, 0);
		world.setBlock(i + 2, j + 15, k + 17, 0);
		world.setBlock(i + 2, j + 15, k + 18, 0);
		world.setBlock(i + 2, j + 15, k + 19, 0);
		world.setBlock(i + 2, j + 15, k + 20, 0);
		world.setBlock(i + 2, j + 15, k + 21, 0);
		world.setBlock(i + 3, j + 0, k + 0, Block.grass.blockID);
		world.setBlock(i + 3, j + 0, k + 1, Block.dirt.blockID);
		world.setBlockAndMetadata(i + 3, j + 0, k + 2, Block.cloth.blockID, 15);
		world.setBlock(i + 3, j + 0, k + 3, Block.dirt.blockID);
		world.setBlock(i + 3, j + 0, k + 4, Block.dirt.blockID);
		world.setBlock(i + 3, j + 0, k + 5, Block.dirt.blockID);
		world.setBlock(i + 3, j + 0, k + 6, Block.dirt.blockID);
		world.setBlock(i + 3, j + 0, k + 7, Block.dirt.blockID);
		world.setBlock(i + 3, j + 0, k + 8, Block.dirt.blockID);
		world.setBlock(i + 3, j + 0, k + 9, Block.dirt.blockID);
		world.setBlock(i + 3, j + 0, k + 10, Block.dirt.blockID);
		world.setBlock(i + 3, j + 0, k + 11, Block.dirt.blockID);
		world.setBlock(i + 3, j + 0, k + 12, Block.dirt.blockID);
		world.setBlock(i + 3, j + 0, k + 13, Block.dirt.blockID);
		world.setBlockAndMetadata(i + 3, j + 0, k + 14, Block.cloth.blockID, 15);
		world.setBlock(i + 3, j + 0, k + 15, Block.dirt.blockID);
		world.setBlock(i + 3, j + 0, k + 16, Block.dirt.blockID);
		world.setBlock(i + 3, j + 0, k + 17, Block.dirt.blockID);
		world.setBlock(i + 3, j + 0, k + 18, Block.dirt.blockID);
		world.setBlockAndMetadata(i + 3, j + 0, k + 19, Block.cloth.blockID, 11);
		world.setBlockAndMetadata(i + 3, j + 0, k + 20, Block.cloth.blockID, 15);
		world.setBlock(i + 3, j + 0, k + 21, Block.dirt.blockID);
		world.setBlock(i + 3, j + 1, k + 0, 0);
		world.setBlockAndMetadata(i + 3, j + 1, k + 1, Block.cloth.blockID, 11);
		world.setBlockAndMetadata(i + 3, j + 1, k + 3, Block.cloth.blockID, 11);
		world.setBlockAndMetadata(i + 3, j + 1, k + 4, Block.cloth.blockID, 11);
		world.setBlockAndMetadata(i + 3, j + 1, k + 5, Block.cloth.blockID, 11);
		world.setBlockAndMetadata(i + 3, j + 1, k + 6, Block.cloth.blockID, 11);
		world.setBlockAndMetadata(i + 3, j + 1, k + 7, Block.cloth.blockID, 11);
		world.setBlockAndMetadata(i + 3, j + 1, k + 8, Block.cloth.blockID, 11);
		world.setBlockAndMetadata(i + 3, j + 1, k + 9, Block.cloth.blockID, 11);
		world.setBlockAndMetadata(i + 3, j + 1, k + 10, Block.cloth.blockID, 11);
		world.setBlockAndMetadata(i + 3, j + 1, k + 11, Block.cloth.blockID, 11);
		world.setBlockAndMetadata(i + 3, j + 1, k + 12, Block.cloth.blockID, 11);
		world.setBlockAndMetadata(i + 3, j + 1, k + 13, Block.cloth.blockID, 11);
		world.setBlockAndMetadata(i + 3, j + 1, k + 15, Block.cloth.blockID, 11);
		world.setBlockAndMetadata(i + 3, j + 1, k + 16, Block.cloth.blockID, 11);
		world.setBlockAndMetadata(i + 3, j + 1, k + 17, Block.cloth.blockID, 11);
		world.setBlockAndMetadata(i + 3, j + 1, k + 18, Block.cloth.blockID, 11);
		world.setBlockAndMetadata(i + 3, j + 1, k + 19, Block.cloth.blockID, 11);
		world.setBlockAndMetadata(i + 3, j + 1, k + 21, Block.cloth.blockID, 11);
		world.setBlock(i + 3, j + 2, k + 0, 0);
		world.setBlockAndMetadata(i + 3, j + 2, k + 1, Block.cloth.blockID, 11);
		world.setBlock(i + 3, j + 2, k + 2, 0);
		world.setBlockAndMetadata(i + 3, j + 2, k + 3, Block.cloth.blockID, 11);
		world.setBlockAndMetadata(i + 3, j + 2, k + 4, Block.cloth.blockID, 11);
		world.setBlockAndMetadata(i + 3, j + 2, k + 5, Block.cloth.blockID, 11);
		world.setBlockAndMetadata(i + 3, j + 2, k + 6, Block.cloth.blockID, 11);
		world.setBlockAndMetadata(i + 3, j + 2, k + 7, Block.cloth.blockID, 11);
		world.setBlockAndMetadata(i + 3, j + 2, k + 8, Block.cloth.blockID, 11);
		world.setBlockAndMetadata(i + 3, j + 2, k + 9, Block.cloth.blockID, 11);
		world.setBlockAndMetadata(i + 3, j + 2, k + 10, Block.cloth.blockID, 11);
		world.setBlockAndMetadata(i + 3, j + 2, k + 11, Block.cloth.blockID, 11);
		world.setBlockAndMetadata(i + 3, j + 2, k + 12, Block.cloth.blockID, 11);
		world.setBlockAndMetadata(i + 3, j + 2, k + 13, Block.cloth.blockID, 11);
		world.setBlock(i + 3, j + 2, k + 14, 0);
		world.setBlockAndMetadata(i + 3, j + 2, k + 15, Block.cloth.blockID, 11);
		world.setBlockAndMetadata(i + 3, j + 2, k + 16, Block.cloth.blockID, 11);
		world.setBlockAndMetadata(i + 3, j + 2, k + 17, Block.cloth.blockID, 11);
		world.setBlockAndMetadata(i + 3, j + 2, k + 18, Block.cloth.blockID, 11);
		world.setBlockAndMetadata(i + 3, j + 2, k + 19, Block.cloth.blockID, 11);
		world.setBlock(i + 3, j + 2, k + 20, 0);
		world.setBlockAndMetadata(i + 3, j + 2, k + 21, Block.cloth.blockID, 11);
		world.setBlock(i + 3, j + 3, k + 0, 0);
		world.setBlockAndMetadata(i + 3, j + 3, k + 1, Block.cloth.blockID, 11);
		world.setBlock(i + 3, j + 3, k + 2, 0);
		world.setBlockAndMetadata(i + 3, j + 3, k + 3, Block.cloth.blockID, 11);
		world.setBlockAndMetadata(i + 3, j + 3, k + 4, Block.cloth.blockID, 11);
		world.setBlockAndMetadata(i + 3, j + 3, k + 5, Block.cloth.blockID, 11);
		world.setBlockAndMetadata(i + 3, j + 3, k + 6, Block.cloth.blockID, 11);
		world.setBlockAndMetadata(i + 3, j + 3, k + 7, Block.cloth.blockID, 11);
		world.setBlockAndMetadata(i + 3, j + 3, k + 8, Block.cloth.blockID, 11);
		world.setBlockAndMetadata(i + 3, j + 3, k + 9, Block.cloth.blockID, 11);
		world.setBlockAndMetadata(i + 3, j + 3, k + 10, Block.cloth.blockID, 11);
		world.setBlockAndMetadata(i + 3, j + 3, k + 11, Block.cloth.blockID, 11);
		world.setBlockAndMetadata(i + 3, j + 3, k + 12, Block.cloth.blockID, 11);
		world.setBlockAndMetadata(i + 3, j + 3, k + 13, Block.cloth.blockID, 11);
		world.setBlock(i + 3, j + 3, k + 14, 0);
		world.setBlockAndMetadata(i + 3, j + 3, k + 15, Block.cloth.blockID, 11);
		world.setBlockAndMetadata(i + 3, j + 3, k + 16, Block.cloth.blockID, 11);
		world.setBlockAndMetadata(i + 3, j + 3, k + 17, Block.cloth.blockID, 11);
		world.setBlockAndMetadata(i + 3, j + 3, k + 18, Block.cloth.blockID, 11);
		world.setBlockAndMetadata(i + 3, j + 3, k + 19, Block.cloth.blockID, 11);
		world.setBlock(i + 3, j + 3, k + 20, 0);
		world.setBlockAndMetadata(i + 3, j + 3, k + 21, Block.cloth.blockID, 11);
		world.setBlock(i + 3, j + 4, k + 0, 0);
		world.setBlockAndMetadata(i + 3, j + 4, k + 1, Block.cloth.blockID, 15);
		world.setBlockAndMetadata(i + 3, j + 4, k + 2, Block.cloth.blockID, 15);
		world.setBlockAndMetadata(i + 3, j + 4, k + 3, Block.cloth.blockID, 15);
		world.setBlockAndMetadata(i + 3, j + 4, k + 4, Block.cloth.blockID, 15);
		world.setBlockAndMetadata(i + 3, j + 4, k + 5, Block.cloth.blockID, 15);
		world.setBlockAndMetadata(i + 3, j + 4, k + 6, Block.cloth.blockID, 15);
		world.setBlockAndMetadata(i + 3, j + 4, k + 7, Block.cloth.blockID, 15);
		world.setBlockAndMetadata(i + 3, j + 4, k + 8, Block.cloth.blockID, 15);
		world.setBlockAndMetadata(i + 3, j + 4, k + 9, Block.cloth.blockID, 15);
		world.setBlockAndMetadata(i + 3, j + 4, k + 10, Block.cloth.blockID, 15);
		world.setBlockAndMetadata(i + 3, j + 4, k + 11, Block.cloth.blockID, 15);
		world.setBlockAndMetadata(i + 3, j + 4, k + 12, Block.cloth.blockID, 15);
		world.setBlockAndMetadata(i + 3, j + 4, k + 13, Block.cloth.blockID, 15);
		world.setBlockAndMetadata(i + 3, j + 4, k + 14, Block.cloth.blockID, 15);
		world.setBlockAndMetadata(i + 3, j + 4, k + 15, Block.cloth.blockID, 15);
		world.setBlockAndMetadata(i + 3, j + 4, k + 16, Block.cloth.blockID, 15);
		world.setBlockAndMetadata(i + 3, j + 4, k + 17, Block.cloth.blockID, 15);
		world.setBlockAndMetadata(i + 3, j + 4, k + 18, Block.cloth.blockID, 15);
		world.setBlockAndMetadata(i + 3, j + 4, k + 19, Block.cloth.blockID, 15);
		world.setBlockAndMetadata(i + 3, j + 4, k + 20, Block.cloth.blockID, 15);
		world.setBlockAndMetadata(i + 3, j + 4, k + 21, Block.cloth.blockID, 15);
		world.setBlock(i + 3, j + 5, k + 0, 0);
		world.setBlock(i + 3, j + 5, k + 1, 0);
		world.setBlock(i + 3, j + 5, k + 2, 0);
		world.setBlock(i + 3, j + 5, k + 3, 0);
		world.setBlock(i + 3, j + 5, k + 4, 0);
		world.setBlock(i + 3, j + 5, k + 5, 0);
		world.setBlock(i + 3, j + 5, k + 6, 0);
		world.setBlock(i + 3, j + 5, k + 7, 0);
		world.setBlock(i + 3, j + 5, k + 8, 0);
		world.setBlock(i + 3, j + 5, k + 9, 0);
		world.setBlock(i + 3, j + 5, k + 10, 0);
		world.setBlock(i + 3, j + 5, k + 11, 0);
		world.setBlock(i + 3, j + 5, k + 12, 0);
		world.setBlock(i + 3, j + 5, k + 13, 0);
		world.setBlock(i + 3, j + 5, k + 14, 0);
		world.setBlock(i + 3, j + 5, k + 15, 0);
		world.setBlock(i + 3, j + 5, k + 16, 0);
		world.setBlock(i + 3, j + 5, k + 17, 0);
		world.setBlock(i + 3, j + 5, k + 18, 0);
		world.setBlock(i + 3, j + 5, k + 19, 0);
		world.setBlock(i + 3, j + 5, k + 20, 0);
		world.setBlock(i + 3, j + 5, k + 21, 0);
		world.setBlock(i + 3, j + 6, k + 0, 0);
		world.setBlock(i + 3, j + 6, k + 1, 0);
		world.setBlock(i + 3, j + 6, k + 2, 0);
		world.setBlock(i + 3, j + 6, k + 3, 0);
		world.setBlock(i + 3, j + 6, k + 4, 0);
		world.setBlock(i + 3, j + 6, k + 5, 0);
		world.setBlock(i + 3, j + 6, k + 6, 0);
		world.setBlock(i + 3, j + 6, k + 7, 0);
		world.setBlock(i + 3, j + 6, k + 8, 0);
		world.setBlock(i + 3, j + 6, k + 9, 0);
		world.setBlock(i + 3, j + 6, k + 10, 0);
		world.setBlock(i + 3, j + 6, k + 11, 0);
		world.setBlock(i + 3, j + 6, k + 12, 0);
		world.setBlock(i + 3, j + 6, k + 13, 0);
		world.setBlock(i + 3, j + 6, k + 14, 0);
		world.setBlock(i + 3, j + 6, k + 15, 0);
		world.setBlock(i + 3, j + 6, k + 16, 0);
		world.setBlock(i + 3, j + 6, k + 17, 0);
		world.setBlock(i + 3, j + 6, k + 18, 0);
		world.setBlock(i + 3, j + 6, k + 19, 0);
		world.setBlock(i + 3, j + 6, k + 20, 0);
		world.setBlock(i + 3, j + 6, k + 21, 0);
		world.setBlock(i + 3, j + 7, k + 0, 0);
		world.setBlock(i + 3, j + 7, k + 1, 0);
		world.setBlock(i + 3, j + 7, k + 2, 0);
		world.setBlock(i + 3, j + 7, k + 3, 0);
		world.setBlock(i + 3, j + 7, k + 4, 0);
		world.setBlock(i + 3, j + 7, k + 5, 0);
		world.setBlock(i + 3, j + 7, k + 6, 0);
		world.setBlock(i + 3, j + 7, k + 7, 0);
		world.setBlock(i + 3, j + 7, k + 8, 0);
		world.setBlock(i + 3, j + 7, k + 9, 0);
		world.setBlock(i + 3, j + 7, k + 10, 0);
		world.setBlock(i + 3, j + 7, k + 11, 0);
		world.setBlock(i + 3, j + 7, k + 12, 0);
		world.setBlock(i + 3, j + 7, k + 13, 0);
		world.setBlock(i + 3, j + 7, k + 14, 0);
		world.setBlock(i + 3, j + 7, k + 15, 0);
		world.setBlock(i + 3, j + 7, k + 16, 0);
		world.setBlock(i + 3, j + 7, k + 17, 0);
		world.setBlock(i + 3, j + 7, k + 18, 0);
		world.setBlock(i + 3, j + 7, k + 19, 0);
		world.setBlock(i + 3, j + 7, k + 20, 0);
		world.setBlock(i + 3, j + 7, k + 21, 0);
		world.setBlock(i + 3, j + 8, k + 0, 0);
		world.setBlock(i + 3, j + 8, k + 1, 0);
		world.setBlock(i + 3, j + 8, k + 2, 0);
		world.setBlock(i + 3, j + 8, k + 3, 0);
		world.setBlock(i + 3, j + 8, k + 4, 0);
		world.setBlock(i + 3, j + 8, k + 5, 0);
		world.setBlock(i + 3, j + 8, k + 6, 0);
		world.setBlock(i + 3, j + 8, k + 7, 0);
		world.setBlock(i + 3, j + 8, k + 8, 0);
		world.setBlock(i + 3, j + 8, k + 9, 0);
		world.setBlock(i + 3, j + 8, k + 10, 0);
		world.setBlock(i + 3, j + 8, k + 11, 0);
		world.setBlock(i + 3, j + 8, k + 12, 0);
		world.setBlock(i + 3, j + 8, k + 13, 0);
		world.setBlock(i + 3, j + 8, k + 14, 0);
		world.setBlock(i + 3, j + 8, k + 15, 0);
		world.setBlock(i + 3, j + 8, k + 16, 0);
		world.setBlock(i + 3, j + 8, k + 17, 0);
		world.setBlock(i + 3, j + 8, k + 18, 0);
		world.setBlock(i + 3, j + 8, k + 19, 0);
		world.setBlock(i + 3, j + 8, k + 20, 0);
		world.setBlock(i + 3, j + 8, k + 21, 0);
		world.setBlock(i + 3, j + 9, k + 0, 0);
		world.setBlock(i + 3, j + 9, k + 1, 0);
		world.setBlock(i + 3, j + 9, k + 2, 0);
		world.setBlock(i + 3, j + 9, k + 3, 0);
		world.setBlock(i + 3, j + 9, k + 4, 0);
		world.setBlock(i + 3, j + 9, k + 5, 0);
		world.setBlock(i + 3, j + 9, k + 6, 0);
		world.setBlock(i + 3, j + 9, k + 7, 0);
		world.setBlock(i + 3, j + 9, k + 8, 0);
		world.setBlock(i + 3, j + 9, k + 9, 0);
		world.setBlock(i + 3, j + 9, k + 10, 0);
		world.setBlock(i + 3, j + 9, k + 11, 0);
		world.setBlock(i + 3, j + 9, k + 12, 0);
		world.setBlock(i + 3, j + 9, k + 13, 0);
		world.setBlock(i + 3, j + 9, k + 14, 0);
		world.setBlock(i + 3, j + 9, k + 15, 0);
		world.setBlock(i + 3, j + 9, k + 16, 0);
		world.setBlock(i + 3, j + 9, k + 17, 0);
		world.setBlock(i + 3, j + 9, k + 18, 0);
		world.setBlock(i + 3, j + 9, k + 19, 0);
		world.setBlock(i + 3, j + 9, k + 20, 0);
		world.setBlock(i + 3, j + 9, k + 21, 0);
		world.setBlock(i + 3, j + 10, k + 0, 0);
		world.setBlock(i + 3, j + 10, k + 1, 0);
		world.setBlock(i + 3, j + 10, k + 2, 0);
		world.setBlock(i + 3, j + 10, k + 3, 0);
		world.setBlock(i + 3, j + 10, k + 4, 0);
		world.setBlock(i + 3, j + 10, k + 5, 0);
		world.setBlock(i + 3, j + 10, k + 6, 0);
		world.setBlock(i + 3, j + 10, k + 7, 0);
		world.setBlock(i + 3, j + 10, k + 8, 0);
		world.setBlock(i + 3, j + 10, k + 9, 0);
		world.setBlock(i + 3, j + 10, k + 10, 0);
		world.setBlock(i + 3, j + 10, k + 11, 0);
		world.setBlock(i + 3, j + 10, k + 12, 0);
		world.setBlock(i + 3, j + 10, k + 13, 0);
		world.setBlock(i + 3, j + 10, k + 14, 0);
		world.setBlock(i + 3, j + 10, k + 15, 0);
		world.setBlock(i + 3, j + 10, k + 16, 0);
		world.setBlock(i + 3, j + 10, k + 17, 0);
		world.setBlock(i + 3, j + 10, k + 18, 0);
		world.setBlock(i + 3, j + 10, k + 19, 0);
		world.setBlock(i + 3, j + 10, k + 20, 0);
		world.setBlock(i + 3, j + 10, k + 21, 0);
		world.setBlock(i + 3, j + 11, k + 0, 0);
		world.setBlock(i + 3, j + 11, k + 1, 0);
		world.setBlock(i + 3, j + 11, k + 2, 0);
		world.setBlock(i + 3, j + 11, k + 3, 0);
		world.setBlock(i + 3, j + 11, k + 4, 0);
		world.setBlock(i + 3, j + 11, k + 5, 0);
		world.setBlock(i + 3, j + 11, k + 6, 0);
		world.setBlock(i + 3, j + 11, k + 7, 0);
		world.setBlock(i + 3, j + 11, k + 8, 0);
		world.setBlock(i + 3, j + 11, k + 9, 0);
		world.setBlock(i + 3, j + 11, k + 10, 0);
		world.setBlock(i + 3, j + 11, k + 11, 0);
		world.setBlock(i + 3, j + 11, k + 12, 0);
		world.setBlock(i + 3, j + 11, k + 13, 0);
		world.setBlock(i + 3, j + 11, k + 14, 0);
		world.setBlock(i + 3, j + 11, k + 15, 0);
		world.setBlock(i + 3, j + 11, k + 16, 0);
		world.setBlock(i + 3, j + 11, k + 17, 0);
		world.setBlock(i + 3, j + 11, k + 18, 0);
		world.setBlock(i + 3, j + 11, k + 19, 0);
		world.setBlock(i + 3, j + 11, k + 20, 0);
		world.setBlock(i + 3, j + 11, k + 21, 0);
		world.setBlock(i + 3, j + 12, k + 0, 0);
		world.setBlock(i + 3, j + 12, k + 1, 0);
		world.setBlock(i + 3, j + 12, k + 2, 0);
		world.setBlock(i + 3, j + 12, k + 3, 0);
		world.setBlock(i + 3, j + 12, k + 4, 0);
		world.setBlock(i + 3, j + 12, k + 5, 0);
		world.setBlock(i + 3, j + 12, k + 6, 0);
		world.setBlock(i + 3, j + 12, k + 7, 0);
		world.setBlock(i + 3, j + 12, k + 8, 0);
		world.setBlock(i + 3, j + 12, k + 9, 0);
		world.setBlock(i + 3, j + 12, k + 10, 0);
		world.setBlock(i + 3, j + 12, k + 11, 0);
		world.setBlock(i + 3, j + 12, k + 12, 0);
		world.setBlock(i + 3, j + 12, k + 13, 0);
		world.setBlock(i + 3, j + 12, k + 14, 0);
		world.setBlock(i + 3, j + 12, k + 15, 0);
		world.setBlock(i + 3, j + 12, k + 16, 0);
		world.setBlock(i + 3, j + 12, k + 17, 0);
		world.setBlock(i + 3, j + 12, k + 18, 0);
		world.setBlock(i + 3, j + 12, k + 19, 0);
		world.setBlock(i + 3, j + 12, k + 20, 0);
		world.setBlock(i + 3, j + 12, k + 21, 0);
		world.setBlock(i + 3, j + 13, k + 0, 0);
		world.setBlock(i + 3, j + 13, k + 1, 0);
		world.setBlock(i + 3, j + 13, k + 2, 0);
		world.setBlock(i + 3, j + 13, k + 3, 0);
		world.setBlock(i + 3, j + 13, k + 4, 0);
		world.setBlock(i + 3, j + 13, k + 5, 0);
		world.setBlock(i + 3, j + 13, k + 6, 0);
		world.setBlock(i + 3, j + 13, k + 7, 0);
		world.setBlock(i + 3, j + 13, k + 8, 0);
		world.setBlock(i + 3, j + 13, k + 9, 0);
		world.setBlock(i + 3, j + 13, k + 10, 0);
		world.setBlock(i + 3, j + 13, k + 11, 0);
		world.setBlock(i + 3, j + 13, k + 12, 0);
		world.setBlock(i + 3, j + 13, k + 13, 0);
		world.setBlock(i + 3, j + 13, k + 14, 0);
		world.setBlock(i + 3, j + 13, k + 15, 0);
		world.setBlock(i + 3, j + 13, k + 16, 0);
		world.setBlock(i + 3, j + 13, k + 17, 0);
		world.setBlock(i + 3, j + 13, k + 18, 0);
		world.setBlock(i + 3, j + 13, k + 19, 0);
		world.setBlock(i + 3, j + 13, k + 20, 0);
		world.setBlock(i + 3, j + 13, k + 21, 0);
		world.setBlock(i + 3, j + 14, k + 0, 0);
		world.setBlock(i + 3, j + 14, k + 1, 0);
		world.setBlock(i + 3, j + 14, k + 2, 0);
		world.setBlock(i + 3, j + 14, k + 3, 0);
		world.setBlock(i + 3, j + 14, k + 4, 0);
		world.setBlock(i + 3, j + 14, k + 5, 0);
		world.setBlock(i + 3, j + 14, k + 6, 0);
		world.setBlock(i + 3, j + 14, k + 7, 0);
		world.setBlock(i + 3, j + 14, k + 8, 0);
		world.setBlock(i + 3, j + 14, k + 9, 0);
		world.setBlock(i + 3, j + 14, k + 10, 0);
		world.setBlock(i + 3, j + 14, k + 11, 0);
		world.setBlock(i + 3, j + 14, k + 12, 0);
		world.setBlock(i + 3, j + 14, k + 13, 0);
		world.setBlock(i + 3, j + 14, k + 14, 0);
		world.setBlock(i + 3, j + 14, k + 15, 0);
		world.setBlock(i + 3, j + 14, k + 16, 0);
		world.setBlock(i + 3, j + 14, k + 17, 0);
		world.setBlock(i + 3, j + 14, k + 18, 0);
		world.setBlock(i + 3, j + 14, k + 19, 0);
		world.setBlock(i + 3, j + 14, k + 20, 0);
		world.setBlock(i + 3, j + 14, k + 21, 0);
		world.setBlock(i + 3, j + 15, k + 0, 0);
		world.setBlock(i + 3, j + 15, k + 1, 0);
		world.setBlock(i + 3, j + 15, k + 2, 0);
		world.setBlock(i + 3, j + 15, k + 3, 0);
		world.setBlock(i + 3, j + 15, k + 4, 0);
		world.setBlock(i + 3, j + 15, k + 5, 0);
		world.setBlock(i + 3, j + 15, k + 6, 0);
		world.setBlock(i + 3, j + 15, k + 7, 0);
		world.setBlock(i + 3, j + 15, k + 8, 0);
		world.setBlock(i + 3, j + 15, k + 9, 0);
		world.setBlock(i + 3, j + 15, k + 10, 0);
		world.setBlock(i + 3, j + 15, k + 11, 0);
		world.setBlock(i + 3, j + 15, k + 12, 0);
		world.setBlock(i + 3, j + 15, k + 13, 0);
		world.setBlock(i + 3, j + 15, k + 14, 0);
		world.setBlock(i + 3, j + 15, k + 15, 0);
		world.setBlock(i + 3, j + 15, k + 16, 0);
		world.setBlock(i + 3, j + 15, k + 17, 0);
		world.setBlock(i + 3, j + 15, k + 18, 0);
		world.setBlock(i + 3, j + 15, k + 19, 0);
		world.setBlock(i + 3, j + 15, k + 20, 0);
		world.setBlock(i + 3, j + 15, k + 21, 0);
		world.setBlock(i + 4, j + 0, k + 0, Block.grass.blockID);
		world.setBlock(i + 4, j + 0, k + 1, Block.dirt.blockID);
		world.setBlockAndMetadata(i + 4, j + 0, k + 2, Block.cloth.blockID, 15);
		world.setBlockAndMetadata(i + 4, j + 0, k + 3, Block.cloth.blockID, 15);
		world.setBlockAndMetadata(i + 4, j + 0, k + 4, Block.cloth.blockID, 15);
		world.setBlockAndMetadata(i + 4, j + 0, k + 5, Block.cloth.blockID, 15);
		world.setBlockAndMetadata(i + 4, j + 0, k + 6, Block.cloth.blockID, 11);
		world.setBlockAndMetadata(i + 4, j + 0, k + 7, Block.cloth.blockID, 15);
		world.setBlockAndMetadata(i + 4, j + 0, k + 8, Block.cloth.blockID, 15);
		world.setBlockAndMetadata(i + 4, j + 0, k + 9, Block.cloth.blockID, 15);
		world.setBlockAndMetadata(i + 4, j + 0, k + 10, Block.cloth.blockID, 15);
		world.setBlockAndMetadata(i + 4, j + 0, k + 11, Block.cloth.blockID, 15);
		world.setBlockAndMetadata(i + 4, j + 0, k + 12, Block.cloth.blockID, 15);
		world.setBlock(i + 4, j + 0, k + 13, Block.dirt.blockID);
		world.setBlockAndMetadata(i + 4, j + 0, k + 14, Block.cloth.blockID, 15);
		world.setBlock(i + 4, j + 0, k + 15, Block.dirt.blockID);
		world.setBlock(i + 4, j + 0, k + 16, Block.dirt.blockID);
		world.setBlock(i + 4, j + 0, k + 17, Block.dirt.blockID);
		world.setBlock(i + 4, j + 0, k + 18, Block.dirt.blockID);
		world.setBlockAndMetadata(i + 4, j + 0, k + 19, Block.cloth.blockID, 15);
		world.setBlockAndMetadata(i + 4, j + 0, k + 20, Block.cloth.blockID, 15);
		world.setBlock(i + 4, j + 0, k + 21, Block.dirt.blockID);
		world.setBlock(i + 4, j + 1, k + 0, 0);
		world.setBlockAndMetadata(i + 4, j + 1, k + 1, Block.cloth.blockID, 11);
		world.setBlockAndMetadata(i + 4, j + 1, k + 6, Block.cloth.blockID, 11);
		world.setBlockAndMetadata(i + 4, j + 1, k + 13, Block.cloth.blockID, 11);
		world.setBlockAndMetadata(i + 4, j + 1, k + 15, Block.cloth.blockID, 11);
		world.setBlockAndMetadata(i + 4, j + 1, k + 16, Block.cloth.blockID, 11);
		world.setBlockAndMetadata(i + 4, j + 1, k + 17, Block.cloth.blockID, 11);
		world.setBlockAndMetadata(i + 4, j + 1, k + 18, Block.cloth.blockID, 11);
		world.setBlockAndMetadata(i + 4, j + 1, k + 19, Block.cloth.blockID, 11);
		world.setBlockAndMetadata(i + 4, j + 1, k + 21, Block.cloth.blockID, 11);
		world.setBlock(i + 4, j + 2, k + 0, 0);
		world.setBlockAndMetadata(i + 4, j + 2, k + 1, Block.cloth.blockID, 11);
		world.setBlock(i + 4, j + 2, k + 2, 0);
		world.setBlock(i + 4, j + 2, k + 3, 0);
		world.setBlock(i + 4, j + 2, k + 4, 0);
		world.setBlock(i + 4, j + 2, k + 5, 0);
		world.setBlockAndMetadata(i + 4, j + 2, k + 6, Block.cloth.blockID, 11);
		world.setBlock(i + 4, j + 2, k + 7, 0);
		world.setBlock(i + 4, j + 2, k + 8, 0);
		world.setBlock(i + 4, j + 2, k + 9, 0);
		world.setBlock(i + 4, j + 2, k + 10, 0);
		world.setBlock(i + 4, j + 2, k + 11, 0);
		world.setBlock(i + 4, j + 2, k + 12, 0);
		world.setBlockAndMetadata(i + 4, j + 2, k + 13, Block.cloth.blockID, 11);
		world.setBlock(i + 4, j + 2, k + 14, 0);
		world.setBlockAndMetadata(i + 4, j + 2, k + 15, Block.cloth.blockID, 11);
		world.setBlockAndMetadata(i + 4, j + 2, k + 16, Block.cloth.blockID, 11);
		world.setBlockAndMetadata(i + 4, j + 2, k + 17, Block.cloth.blockID, 11);
		world.setBlockAndMetadata(i + 4, j + 2, k + 18, Block.cloth.blockID, 11);
		world.setBlockAndMetadata(i + 4, j + 2, k + 19, Block.cloth.blockID, 11);
		world.setBlock(i + 4, j + 2, k + 20, 0);
		world.setBlockAndMetadata(i + 4, j + 2, k + 21, Block.cloth.blockID, 11);
		world.setBlock(i + 4, j + 3, k + 0, 0);
		world.setBlockAndMetadata(i + 4, j + 3, k + 1, Block.cloth.blockID, 11);
		world.setBlock(i + 4, j + 3, k + 2, 0);
		world.setBlock(i + 4, j + 3, k + 3, 0);
		world.setBlock(i + 4, j + 3, k + 4, 0);
		world.setBlock(i + 4, j + 3, k + 5, 0);
		world.setBlockAndMetadata(i + 4, j + 3, k + 6, Block.cloth.blockID, 11);
		world.setBlock(i + 4, j + 3, k + 7, 0);
		world.setBlock(i + 4, j + 3, k + 8, 0);
		world.setBlock(i + 4, j + 3, k + 9, 0);
		world.setBlock(i + 4, j + 3, k + 10, 0);
		world.setBlock(i + 4, j + 3, k + 11, 0);
		world.setBlock(i + 4, j + 3, k + 12, 0);
		world.setBlockAndMetadata(i + 4, j + 3, k + 13, Block.cloth.blockID, 11);
		world.setBlock(i + 4, j + 3, k + 14, 0);
		world.setBlockAndMetadata(i + 4, j + 3, k + 15, Block.cloth.blockID, 11);
		world.setBlockAndMetadata(i + 4, j + 3, k + 16, Block.cloth.blockID, 11);
		world.setBlockAndMetadata(i + 4, j + 3, k + 17, Block.cloth.blockID, 11);
		world.setBlockAndMetadata(i + 4, j + 3, k + 18, Block.cloth.blockID, 11);
		world.setBlockAndMetadata(i + 4, j + 3, k + 19, Block.cloth.blockID, 11);
		world.setBlock(i + 4, j + 3, k + 20, 0);
		world.setBlockAndMetadata(i + 4, j + 3, k + 21, Block.cloth.blockID, 11);
		world.setBlock(i + 4, j + 4, k + 0, 0);
		world.setBlockAndMetadata(i + 4, j + 4, k + 1, Block.cloth.blockID, 15);
		world.setBlockAndMetadata(i + 4, j + 4, k + 2, Block.cloth.blockID, 15);
		world.setBlockAndMetadata(i + 4, j + 4, k + 3, Block.cloth.blockID, 15);
		world.setBlockAndMetadata(i + 4, j + 4, k + 4, Block.cloth.blockID, 15);
		world.setBlockAndMetadata(i + 4, j + 4, k + 5, Block.cloth.blockID, 15);
		world.setBlockAndMetadata(i + 4, j + 4, k + 6, Block.cloth.blockID, 15);
		world.setBlockAndMetadata(i + 4, j + 4, k + 7, Block.cloth.blockID, 15);
		world.setBlockAndMetadata(i + 4, j + 4, k + 8, Block.cloth.blockID, 15);
		world.setBlockAndMetadata(i + 4, j + 4, k + 9, Block.cloth.blockID, 15);
		world.setBlockAndMetadata(i + 4, j + 4, k + 10, Block.cloth.blockID, 15);
		world.setBlockAndMetadata(i + 4, j + 4, k + 11, Block.cloth.blockID, 15);
		world.setBlockAndMetadata(i + 4, j + 4, k + 12, Block.cloth.blockID, 15);
		world.setBlockAndMetadata(i + 4, j + 4, k + 13, Block.cloth.blockID, 15);
		world.setBlockAndMetadata(i + 4, j + 4, k + 14, Block.cloth.blockID, 15);
		world.setBlockAndMetadata(i + 4, j + 4, k + 15, Block.cloth.blockID, 15);
		world.setBlockAndMetadata(i + 4, j + 4, k + 16, Block.cloth.blockID, 15);
		world.setBlockAndMetadata(i + 4, j + 4, k + 17, Block.cloth.blockID, 15);
		world.setBlockAndMetadata(i + 4, j + 4, k + 18, Block.cloth.blockID, 15);
		world.setBlockAndMetadata(i + 4, j + 4, k + 19, Block.cloth.blockID, 15);
		world.setBlockAndMetadata(i + 4, j + 4, k + 20, Block.cloth.blockID, 15);
		world.setBlockAndMetadata(i + 4, j + 4, k + 21, Block.cloth.blockID, 15);
		world.setBlock(i + 4, j + 5, k + 0, 0);
		world.setBlock(i + 4, j + 5, k + 1, 0);
		world.setBlock(i + 4, j + 5, k + 2, 0);
		world.setBlock(i + 4, j + 5, k + 3, 0);
		world.setBlockAndMetadata(i + 4, j + 5, k + 4, Block.cloth.blockID, 15);
		world.setBlockAndMetadata(i + 4, j + 5, k + 5, Block.cloth.blockID, 11);
		world.setBlockAndMetadata(i + 4, j + 5, k + 6, Block.cloth.blockID, 11);
		world.setBlockAndMetadata(i + 4, j + 5, k + 7, Block.cloth.blockID, 11);
		world.setBlockAndMetadata(i + 4, j + 5, k + 8, Block.cloth.blockID, 11);
		world.setBlockAndMetadata(i + 4, j + 5, k + 9, Block.cloth.blockID, 11);
		world.setBlockAndMetadata(i + 4, j + 5, k + 10, Block.cloth.blockID, 11);
		world.setBlockAndMetadata(i + 4, j + 5, k + 11, Block.cloth.blockID, 11);
		world.setBlockAndMetadata(i + 4, j + 5, k + 12, Block.cloth.blockID, 11);
		world.setBlockAndMetadata(i + 4, j + 5, k + 13, Block.cloth.blockID, 11);
		world.setBlockAndMetadata(i + 4, j + 5, k + 14, Block.cloth.blockID, 11);
		world.setBlockAndMetadata(i + 4, j + 5, k + 15, Block.cloth.blockID, 11);

		generate2(world, rand, i, j, k);
		return true;
	}

	public boolean generate2(World world, Random rand, int i, int j, int k) {
		world.setBlockAndMetadata(i + 4, j + 5, k + 16, Block.cloth.blockID, 11);
		world.setBlockAndMetadata(i + 4, j + 5, k + 17, Block.cloth.blockID, 11);
		world.setBlockAndMetadata(i + 4, j + 5, k + 18, Block.cloth.blockID, 15);
		world.setBlock(i + 4, j + 5, k + 19, 0);
		world.setBlock(i + 4, j + 5, k + 20, 0);
		world.setBlock(i + 4, j + 5, k + 21, 0);
		world.setBlock(i + 4, j + 6, k + 0, 0);
		world.setBlock(i + 4, j + 6, k + 1, 0);
		world.setBlock(i + 4, j + 6, k + 2, 0);
		world.setBlock(i + 4, j + 6, k + 3, 0);
		world.setBlockAndMetadata(i + 4, j + 6, k + 4, Block.cloth.blockID, 15);
		world.setBlockAndMetadata(i + 4, j + 6, k + 5, Block.cloth.blockID, 11);
		world.setBlockAndMetadata(i + 4, j + 6, k + 6, Block.cloth.blockID, 11);
		world.setBlockAndMetadata(i + 4, j + 6, k + 7, Block.cloth.blockID, 11);
		world.setBlockAndMetadata(i + 4, j + 6, k + 8, Block.cloth.blockID, 11);
		world.setBlockAndMetadata(i + 4, j + 6, k + 9, Block.cloth.blockID, 11);
		world.setBlockAndMetadata(i + 4, j + 6, k + 10, Block.cloth.blockID, 11);
		world.setBlockAndMetadata(i + 4, j + 6, k + 11, Block.cloth.blockID, 11);
		world.setBlockAndMetadata(i + 4, j + 6, k + 12, Block.cloth.blockID, 11);
		world.setBlockAndMetadata(i + 4, j + 6, k + 13, Block.cloth.blockID, 11);
		world.setBlockAndMetadata(i + 4, j + 6, k + 14, Block.cloth.blockID, 11);
		world.setBlockAndMetadata(i + 4, j + 6, k + 15, Block.cloth.blockID, 11);
		world.setBlockAndMetadata(i + 4, j + 6, k + 16, Block.cloth.blockID, 11);
		world.setBlockAndMetadata(i + 4, j + 6, k + 17, Block.cloth.blockID, 11);
		world.setBlockAndMetadata(i + 4, j + 6, k + 18, Block.cloth.blockID, 15);
		world.setBlock(i + 4, j + 6, k + 19, 0);
		world.setBlock(i + 4, j + 6, k + 20, 0);
		world.setBlock(i + 4, j + 6, k + 21, 0);
		world.setBlock(i + 4, j + 7, k + 0, 0);
		world.setBlock(i + 4, j + 7, k + 1, 0);
		world.setBlock(i + 4, j + 7, k + 2, 0);
		world.setBlock(i + 4, j + 7, k + 3, 0);
		world.setBlockAndMetadata(i + 4, j + 7, k + 4, Block.cloth.blockID, 15);
		world.setBlockAndMetadata(i + 4, j + 7, k + 5, Block.cloth.blockID, 11);
		world.setBlockAndMetadata(i + 4, j + 7, k + 6, Block.cloth.blockID, 11);
		world.setBlockAndMetadata(i + 4, j + 7, k + 7, Block.cloth.blockID, 11);
		world.setBlockAndMetadata(i + 4, j + 7, k + 8, Block.cloth.blockID, 11);
		world.setBlockAndMetadata(i + 4, j + 7, k + 9, Block.cloth.blockID, 11);
		world.setBlockAndMetadata(i + 4, j + 7, k + 10, Block.cloth.blockID, 11);
		world.setBlockAndMetadata(i + 4, j + 7, k + 11, Block.cloth.blockID, 11);
		world.setBlockAndMetadata(i + 4, j + 7, k + 12, Block.cloth.blockID, 11);
		world.setBlockAndMetadata(i + 4, j + 7, k + 13, Block.cloth.blockID, 11);
		world.setBlockAndMetadata(i + 4, j + 7, k + 14, Block.cloth.blockID, 11);
		world.setBlockAndMetadata(i + 4, j + 7, k + 15, Block.cloth.blockID, 11);
		world.setBlockAndMetadata(i + 4, j + 7, k + 16, Block.cloth.blockID, 11);
		world.setBlockAndMetadata(i + 4, j + 7, k + 17, Block.cloth.blockID, 11);
		world.setBlockAndMetadata(i + 4, j + 7, k + 18, Block.cloth.blockID, 15);
		world.setBlock(i + 4, j + 7, k + 19, 0);
		world.setBlock(i + 4, j + 7, k + 20, 0);
		world.setBlock(i + 4, j + 7, k + 21, 0);
		world.setBlock(i + 4, j + 8, k + 0, 0);
		world.setBlock(i + 4, j + 8, k + 1, 0);
		world.setBlock(i + 4, j + 8, k + 2, 0);
		world.setBlock(i + 4, j + 8, k + 3, 0);
		world.setBlockAndMetadata(i + 4, j + 8, k + 4, Block.cloth.blockID, 15);
		world.setBlockAndMetadata(i + 4, j + 8, k + 5, Block.cloth.blockID, 11);
		world.setBlockAndMetadata(i + 4, j + 8, k + 6, Block.cloth.blockID, 11);
		world.setBlockAndMetadata(i + 4, j + 8, k + 7, Block.cloth.blockID, 11);
		world.setBlockAndMetadata(i + 4, j + 8, k + 8, Block.cloth.blockID, 11);
		world.setBlockAndMetadata(i + 4, j + 8, k + 9, Block.cloth.blockID, 11);
		world.setBlockAndMetadata(i + 4, j + 8, k + 10, Block.cloth.blockID, 11);
		world.setBlockAndMetadata(i + 4, j + 8, k + 11, Block.cloth.blockID, 11);
		world.setBlockAndMetadata(i + 4, j + 8, k + 12, Block.cloth.blockID, 11);
		world.setBlockAndMetadata(i + 4, j + 8, k + 13, Block.cloth.blockID, 11);
		world.setBlockAndMetadata(i + 4, j + 8, k + 14, Block.cloth.blockID, 11);
		world.setBlockAndMetadata(i + 4, j + 8, k + 15, Block.cloth.blockID, 11);
		world.setBlockAndMetadata(i + 4, j + 8, k + 16, Block.cloth.blockID, 11);
		world.setBlockAndMetadata(i + 4, j + 8, k + 17, Block.cloth.blockID, 11);
		world.setBlockAndMetadata(i + 4, j + 8, k + 18, Block.cloth.blockID, 15);
		world.setBlock(i + 4, j + 8, k + 19, 0);
		world.setBlock(i + 4, j + 8, k + 20, 0);
		world.setBlock(i + 4, j + 8, k + 21, 0);
		world.setBlock(i + 4, j + 9, k + 0, 0);
		world.setBlock(i + 4, j + 9, k + 1, 0);
		world.setBlock(i + 4, j + 9, k + 2, 0);
		world.setBlock(i + 4, j + 9, k + 3, 0);
		world.setBlockAndMetadata(i + 4, j + 9, k + 4, Block.cloth.blockID, 15);
		world.setBlockAndMetadata(i + 4, j + 9, k + 5, Block.cloth.blockID, 15);
		world.setBlockAndMetadata(i + 4, j + 9, k + 6, Block.cloth.blockID, 15);
		world.setBlockAndMetadata(i + 4, j + 9, k + 7, Block.cloth.blockID, 15);
		world.setBlockAndMetadata(i + 4, j + 9, k + 8, Block.cloth.blockID, 15);
		world.setBlockAndMetadata(i + 4, j + 9, k + 9, Block.cloth.blockID, 15);
		world.setBlockAndMetadata(i + 4, j + 9, k + 10, Block.cloth.blockID, 15);
		world.setBlockAndMetadata(i + 4, j + 9, k + 11, Block.cloth.blockID, 15);
		world.setBlockAndMetadata(i + 4, j + 9, k + 12, Block.cloth.blockID, 15);
		world.setBlockAndMetadata(i + 4, j + 9, k + 13, Block.cloth.blockID, 15);
		world.setBlockAndMetadata(i + 4, j + 9, k + 14, Block.cloth.blockID, 15);
		world.setBlockAndMetadata(i + 4, j + 9, k + 15, Block.cloth.blockID, 15);
		world.setBlockAndMetadata(i + 4, j + 9, k + 16, Block.cloth.blockID, 15);
		world.setBlockAndMetadata(i + 4, j + 9, k + 17, Block.cloth.blockID, 15);
		world.setBlockAndMetadata(i + 4, j + 9, k + 18, Block.cloth.blockID, 15);
		world.setBlock(i + 4, j + 9, k + 19, 0);
		world.setBlock(i + 4, j + 9, k + 20, 0);
		world.setBlock(i + 4, j + 9, k + 21, 0);
		world.setBlock(i + 4, j + 10, k + 0, 0);
		world.setBlock(i + 4, j + 10, k + 1, 0);
		world.setBlock(i + 4, j + 10, k + 2, 0);
		world.setBlock(i + 4, j + 10, k + 3, 0);
		world.setBlock(i + 4, j + 10, k + 4, 0);
		world.setBlock(i + 4, j + 10, k + 5, 0);
		world.setBlock(i + 4, j + 10, k + 6, 0);
		world.setBlock(i + 4, j + 10, k + 7, 0);
		world.setBlock(i + 4, j + 10, k + 8, 0);
		world.setBlock(i + 4, j + 10, k + 9, 0);
		world.setBlock(i + 4, j + 10, k + 10, 0);
		world.setBlock(i + 4, j + 10, k + 11, 0);
		world.setBlock(i + 4, j + 10, k + 12, 0);
		world.setBlock(i + 4, j + 10, k + 13, 0);
		world.setBlock(i + 4, j + 10, k + 14, 0);
		world.setBlock(i + 4, j + 10, k + 15, 0);
		world.setBlock(i + 4, j + 10, k + 16, 0);
		world.setBlock(i + 4, j + 10, k + 17, 0);
		world.setBlock(i + 4, j + 10, k + 18, 0);
		world.setBlock(i + 4, j + 10, k + 19, 0);
		world.setBlock(i + 4, j + 10, k + 20, 0);
		world.setBlock(i + 4, j + 10, k + 21, 0);
		world.setBlock(i + 4, j + 11, k + 0, 0);
		world.setBlock(i + 4, j + 11, k + 1, 0);
		world.setBlock(i + 4, j + 11, k + 2, 0);
		world.setBlock(i + 4, j + 11, k + 3, 0);
		world.setBlock(i + 4, j + 11, k + 4, 0);
		world.setBlock(i + 4, j + 11, k + 5, 0);
		world.setBlock(i + 4, j + 11, k + 6, 0);
		world.setBlock(i + 4, j + 11, k + 7, 0);
		world.setBlock(i + 4, j + 11, k + 8, 0);
		world.setBlock(i + 4, j + 11, k + 9, 0);
		world.setBlock(i + 4, j + 11, k + 10, 0);
		world.setBlock(i + 4, j + 11, k + 11, 0);
		world.setBlock(i + 4, j + 11, k + 12, 0);
		world.setBlock(i + 4, j + 11, k + 13, 0);
		world.setBlock(i + 4, j + 11, k + 14, 0);
		world.setBlock(i + 4, j + 11, k + 15, 0);
		world.setBlock(i + 4, j + 11, k + 16, 0);
		world.setBlock(i + 4, j + 11, k + 17, 0);
		world.setBlock(i + 4, j + 11, k + 18, 0);
		world.setBlock(i + 4, j + 11, k + 19, 0);
		world.setBlock(i + 4, j + 11, k + 20, 0);
		world.setBlock(i + 4, j + 11, k + 21, 0);
		world.setBlock(i + 4, j + 12, k + 0, 0);
		world.setBlock(i + 4, j + 12, k + 1, 0);
		world.setBlock(i + 4, j + 12, k + 2, 0);
		world.setBlock(i + 4, j + 12, k + 3, 0);
		world.setBlock(i + 4, j + 12, k + 4, 0);
		world.setBlock(i + 4, j + 12, k + 5, 0);
		world.setBlock(i + 4, j + 12, k + 6, 0);
		world.setBlock(i + 4, j + 12, k + 7, 0);
		world.setBlock(i + 4, j + 12, k + 8, 0);
		world.setBlock(i + 4, j + 12, k + 9, 0);
		world.setBlock(i + 4, j + 12, k + 10, 0);
		world.setBlock(i + 4, j + 12, k + 11, 0);
		world.setBlock(i + 4, j + 12, k + 12, 0);
		world.setBlock(i + 4, j + 12, k + 13, 0);
		world.setBlock(i + 4, j + 12, k + 14, 0);
		world.setBlock(i + 4, j + 12, k + 15, 0);
		world.setBlock(i + 4, j + 12, k + 16, 0);
		world.setBlock(i + 4, j + 12, k + 17, 0);
		world.setBlock(i + 4, j + 12, k + 18, 0);
		world.setBlock(i + 4, j + 12, k + 19, 0);
		world.setBlock(i + 4, j + 12, k + 20, 0);
		world.setBlock(i + 4, j + 12, k + 21, 0);
		world.setBlock(i + 4, j + 13, k + 0, 0);
		world.setBlock(i + 4, j + 13, k + 1, 0);
		world.setBlock(i + 4, j + 13, k + 2, 0);
		world.setBlock(i + 4, j + 13, k + 3, 0);
		world.setBlock(i + 4, j + 13, k + 4, 0);
		world.setBlock(i + 4, j + 13, k + 5, 0);
		world.setBlock(i + 4, j + 13, k + 6, 0);
		world.setBlock(i + 4, j + 13, k + 7, 0);
		world.setBlock(i + 4, j + 13, k + 8, 0);
		world.setBlock(i + 4, j + 13, k + 9, 0);
		world.setBlock(i + 4, j + 13, k + 10, 0);
		world.setBlock(i + 4, j + 13, k + 11, 0);
		world.setBlock(i + 4, j + 13, k + 12, 0);
		world.setBlock(i + 4, j + 13, k + 13, 0);
		world.setBlock(i + 4, j + 13, k + 14, 0);
		world.setBlock(i + 4, j + 13, k + 15, 0);
		world.setBlock(i + 4, j + 13, k + 16, 0);
		world.setBlock(i + 4, j + 13, k + 17, 0);
		world.setBlock(i + 4, j + 13, k + 18, 0);
		world.setBlock(i + 4, j + 13, k + 19, 0);
		world.setBlock(i + 4, j + 13, k + 20, 0);
		world.setBlock(i + 4, j + 13, k + 21, 0);
		world.setBlock(i + 4, j + 14, k + 0, 0);
		world.setBlock(i + 4, j + 14, k + 1, 0);
		world.setBlock(i + 4, j + 14, k + 2, 0);
		world.setBlock(i + 4, j + 14, k + 3, 0);
		world.setBlock(i + 4, j + 14, k + 4, 0);
		world.setBlock(i + 4, j + 14, k + 5, 0);
		world.setBlock(i + 4, j + 14, k + 6, 0);
		world.setBlock(i + 4, j + 14, k + 7, 0);
		world.setBlock(i + 4, j + 14, k + 8, 0);
		world.setBlock(i + 4, j + 14, k + 9, 0);
		world.setBlock(i + 4, j + 14, k + 10, 0);
		world.setBlock(i + 4, j + 14, k + 11, 0);
		world.setBlock(i + 4, j + 14, k + 12, 0);
		world.setBlock(i + 4, j + 14, k + 13, 0);
		world.setBlock(i + 4, j + 14, k + 14, 0);
		world.setBlock(i + 4, j + 14, k + 15, 0);
		world.setBlock(i + 4, j + 14, k + 16, 0);
		world.setBlock(i + 4, j + 14, k + 17, 0);
		world.setBlock(i + 4, j + 14, k + 18, 0);
		world.setBlock(i + 4, j + 14, k + 19, 0);
		world.setBlock(i + 4, j + 14, k + 20, 0);
		world.setBlock(i + 4, j + 14, k + 21, 0);
		world.setBlock(i + 4, j + 15, k + 0, 0);
		world.setBlock(i + 4, j + 15, k + 1, 0);
		world.setBlock(i + 4, j + 15, k + 2, 0);
		world.setBlock(i + 4, j + 15, k + 3, 0);
		world.setBlock(i + 4, j + 15, k + 4, 0);
		world.setBlock(i + 4, j + 15, k + 5, 0);
		world.setBlock(i + 4, j + 15, k + 6, 0);
		world.setBlock(i + 4, j + 15, k + 7, 0);
		world.setBlock(i + 4, j + 15, k + 8, 0);
		world.setBlock(i + 4, j + 15, k + 9, 0);
		world.setBlock(i + 4, j + 15, k + 10, 0);
		world.setBlock(i + 4, j + 15, k + 11, 0);
		world.setBlock(i + 4, j + 15, k + 12, 0);
		world.setBlock(i + 4, j + 15, k + 13, 0);
		world.setBlock(i + 4, j + 15, k + 14, 0);
		world.setBlock(i + 4, j + 15, k + 15, 0);
		world.setBlock(i + 4, j + 15, k + 16, 0);
		world.setBlock(i + 4, j + 15, k + 17, 0);
		world.setBlock(i + 4, j + 15, k + 18, 0);
		world.setBlock(i + 4, j + 15, k + 19, 0);
		world.setBlock(i + 4, j + 15, k + 20, 0);
		world.setBlock(i + 4, j + 15, k + 21, 0);
		world.setBlock(i + 5, j + 0, k + 0, Block.grass.blockID);
		world.setBlock(i + 5, j + 0, k + 1, Block.dirt.blockID);
		world.setBlock(i + 5, j + 0, k + 2, Block.dirt.blockID);
		world.setBlock(i + 5, j + 0, k + 3, Block.dirt.blockID);
		world.setBlock(i + 5, j + 0, k + 4, Block.dirt.blockID);
		world.setBlockAndMetadata(i + 5, j + 0, k + 5, Block.cloth.blockID, 15);
		world.setBlock(i + 5, j + 0, k + 6, Block.dirt.blockID);
		world.setBlockAndMetadata(i + 5, j + 0, k + 7, Block.cloth.blockID, 15);
		world.setBlock(i + 5, j + 0, k + 8, Block.dirt.blockID);
		world.setBlockAndMetadata(i + 5, j + 0, k + 9, Block.cloth.blockID, 15);
		world.setBlock(i + 5, j + 0, k + 10, Block.dirt.blockID);
		world.setBlock(i + 5, j + 0, k + 11, Block.dirt.blockID);
		world.setBlockAndMetadata(i + 5, j + 0, k + 12, Block.cloth.blockID, 15);
		world.setBlock(i + 5, j + 0, k + 13, Block.dirt.blockID);
		world.setBlockAndMetadata(i + 5, j + 0, k + 14, Block.cloth.blockID, 15);
		world.setBlock(i + 5, j + 0, k + 15, Block.dirt.blockID);
		world.setBlockAndMetadata(i + 5, j + 0, k + 16, Block.cloth.blockID, 15);
		world.setBlockAndMetadata(i + 5, j + 0, k + 17, Block.cloth.blockID, 15);
		world.setBlockAndMetadata(i + 5, j + 0, k + 18, Block.cloth.blockID, 15);
		world.setBlockAndMetadata(i + 5, j + 0, k + 19, Block.cloth.blockID, 15);
		world.setBlockAndMetadata(i + 5, j + 0, k + 20, Block.cloth.blockID, 15);
		world.setBlock(i + 5, j + 0, k + 21, Block.dirt.blockID);
		world.setBlock(i + 5, j + 1, k + 0, 0);
		world.setBlockAndMetadata(i + 5, j + 1, k + 1, Block.cloth.blockID, 11);
		world.setBlockAndMetadata(i + 5, j + 1, k + 2, Block.cloth.blockID, 11);
		world.setBlockAndMetadata(i + 5, j + 1, k + 3, Block.cloth.blockID, 11);
		world.setBlockAndMetadata(i + 5, j + 1, k + 4, Block.cloth.blockID, 11);
		world.setBlockAndMetadata(i + 5, j + 1, k + 6, Block.cloth.blockID, 11);
		world.setBlockAndMetadata(i + 5, j + 1, k + 8, Block.cloth.blockID, 11);
		world.setBlockAndMetadata(i + 5, j + 1, k + 10, Block.cloth.blockID, 11);
		world.setBlockAndMetadata(i + 5, j + 1, k + 11, Block.cloth.blockID, 11);
		world.setBlockAndMetadata(i + 5, j + 1, k + 13, Block.cloth.blockID, 11);
		world.setBlockAndMetadata(i + 5, j + 1, k + 15, Block.cloth.blockID, 11);
		world.setBlockAndMetadata(i + 5, j + 1, k + 21, Block.cloth.blockID, 11);
		world.setBlock(i + 5, j + 2, k + 0, 0);
		world.setBlockAndMetadata(i + 5, j + 2, k + 1, Block.cloth.blockID, 11);
		world.setBlockAndMetadata(i + 5, j + 2, k + 2, Block.cloth.blockID, 11);
		world.setBlockAndMetadata(i + 5, j + 2, k + 3, Block.cloth.blockID, 11);
		world.setBlockAndMetadata(i + 5, j + 2, k + 4, Block.cloth.blockID, 11);
		world.setBlock(i + 5, j + 2, k + 5, 0);
		world.setBlockAndMetadata(i + 5, j + 2, k + 6, Block.cloth.blockID, 11);
		world.setBlock(i + 5, j + 2, k + 7, 0);
		world.setBlockAndMetadata(i + 5, j + 2, k + 8, Block.cloth.blockID, 11);
		world.setBlock(i + 5, j + 2, k + 9, 0);
		world.setBlockAndMetadata(i + 5, j + 2, k + 10, Block.cloth.blockID, 11);
		world.setBlockAndMetadata(i + 5, j + 2, k + 11, Block.cloth.blockID, 11);
		world.setBlock(i + 5, j + 2, k + 12, 0);
		world.setBlockAndMetadata(i + 5, j + 2, k + 13, Block.cloth.blockID, 11);
		world.setBlock(i + 5, j + 2, k + 14, 0);
		world.setBlockAndMetadata(i + 5, j + 2, k + 15, Block.cloth.blockID, 11);
		world.setBlock(i + 5, j + 2, k + 16, 0);
		world.setBlock(i + 5, j + 2, k + 17, 0);
		world.setBlock(i + 5, j + 2, k + 18, 0);
		world.setBlock(i + 5, j + 2, k + 19, 0);
		world.setBlock(i + 5, j + 2, k + 20, 0);
		world.setBlockAndMetadata(i + 5, j + 2, k + 21, Block.cloth.blockID, 11);
		world.setBlock(i + 5, j + 3, k + 0, 0);
		world.setBlockAndMetadata(i + 5, j + 3, k + 1, Block.cloth.blockID, 11);
		world.setBlockAndMetadata(i + 5, j + 3, k + 2, Block.cloth.blockID, 11);
		world.setBlockAndMetadata(i + 5, j + 3, k + 3, Block.cloth.blockID, 11);
		world.setBlockAndMetadata(i + 5, j + 3, k + 4, Block.cloth.blockID, 11);
		world.setBlock(i + 5, j + 3, k + 5, 0);
		world.setBlockAndMetadata(i + 5, j + 3, k + 6, Block.cloth.blockID, 11);
		world.setBlock(i + 5, j + 3, k + 7, 0);
		world.setBlockAndMetadata(i + 5, j + 3, k + 8, Block.cloth.blockID, 11);
		world.setBlock(i + 5, j + 3, k + 9, 0);
		world.setBlockAndMetadata(i + 5, j + 3, k + 10, Block.cloth.blockID, 11);
		world.setBlockAndMetadata(i + 5, j + 3, k + 11, Block.cloth.blockID, 11);
		world.setBlock(i + 5, j + 3, k + 12, 0);
		world.setBlockAndMetadata(i + 5, j + 3, k + 13, Block.cloth.blockID, 11);
		world.setBlock(i + 5, j + 3, k + 14, 0);
		world.setBlockAndMetadata(i + 5, j + 3, k + 15, Block.cloth.blockID, 11);
		world.setBlock(i + 5, j + 3, k + 16, 0);
		world.setBlock(i + 5, j + 3, k + 17, 0);
		world.setBlock(i + 5, j + 3, k + 18, 0);
		world.setBlock(i + 5, j + 3, k + 19, 0);
		world.setBlock(i + 5, j + 3, k + 20, 0);
		world.setBlockAndMetadata(i + 5, j + 3, k + 21, Block.cloth.blockID, 11);
		world.setBlock(i + 5, j + 4, k + 0, 0);
		world.setBlockAndMetadata(i + 5, j + 4, k + 1, Block.cloth.blockID, 15);
		world.setBlockAndMetadata(i + 5, j + 4, k + 2, Block.cloth.blockID, 15);
		world.setBlockAndMetadata(i + 5, j + 4, k + 3, Block.cloth.blockID, 15);
		world.setBlockAndMetadata(i + 5, j + 4, k + 4, Block.cloth.blockID, 15);
		world.setBlockAndMetadata(i + 5, j + 4, k + 5, Block.cloth.blockID, 15);
		world.setBlockAndMetadata(i + 5, j + 4, k + 6, Block.cloth.blockID, 15);
		world.setBlockAndMetadata(i + 5, j + 4, k + 7, Block.cloth.blockID, 15);
		world.setBlockAndMetadata(i + 5, j + 4, k + 8, Block.cloth.blockID, 15);
		world.setBlockAndMetadata(i + 5, j + 4, k + 9, Block.cloth.blockID, 15);
		world.setBlockAndMetadata(i + 5, j + 4, k + 10, Block.cloth.blockID, 15);
		world.setBlockAndMetadata(i + 5, j + 4, k + 11, Block.cloth.blockID, 15);
		world.setBlockAndMetadata(i + 5, j + 4, k + 12, Block.cloth.blockID, 15);
		world.setBlockAndMetadata(i + 5, j + 4, k + 13, Block.cloth.blockID, 15);
		world.setBlockAndMetadata(i + 5, j + 4, k + 14, Block.cloth.blockID, 15);
		world.setBlockAndMetadata(i + 5, j + 4, k + 15, Block.cloth.blockID, 15);
		world.setBlockAndMetadata(i + 5, j + 4, k + 16, Block.cloth.blockID, 15);
		world.setBlockAndMetadata(i + 5, j + 4, k + 17, Block.cloth.blockID, 15);
		world.setBlockAndMetadata(i + 5, j + 4, k + 18, Block.cloth.blockID, 15);
		world.setBlockAndMetadata(i + 5, j + 4, k + 19, Block.cloth.blockID, 15);
		world.setBlockAndMetadata(i + 5, j + 4, k + 20, Block.cloth.blockID, 15);
		world.setBlockAndMetadata(i + 5, j + 4, k + 21, Block.cloth.blockID, 15);
		world.setBlock(i + 5, j + 5, k + 0, 0);
		world.setBlock(i + 5, j + 5, k + 1, 0);
		world.setBlock(i + 5, j + 5, k + 2, 0);
		world.setBlock(i + 5, j + 5, k + 3, 0);
		world.setBlockAndMetadata(i + 5, j + 5, k + 4, Block.cloth.blockID, 11);
		world.setBlockAndMetadata(i + 5, j + 5, k + 5, Block.cloth.blockID, 15);
		world.setBlockAndMetadata(i + 5, j + 5, k + 6, Block.cloth.blockID, 15);
		world.setBlockAndMetadata(i + 5, j + 5, k + 7, Block.cloth.blockID, 15);
		world.setBlockAndMetadata(i + 5, j + 5, k + 8, Block.cloth.blockID, 15);
		world.setBlockAndMetadata(i + 5, j + 5, k + 9, Block.cloth.blockID, 4);
		world.setBlockAndMetadata(i + 5, j + 5, k + 10, Block.cloth.blockID, 4);
		world.setBlockAndMetadata(i + 5, j + 5, k + 11, Block.cloth.blockID, 4);
		world.setBlockAndMetadata(i + 5, j + 5, k + 12, Block.cloth.blockID, 4);
		world.setBlockAndMetadata(i + 5, j + 5, k + 13, Block.cloth.blockID, 4);
		world.setBlockAndMetadata(i + 5, j + 5, k + 14, Block.cloth.blockID, 15);
		world.setBlockAndMetadata(i + 5, j + 5, k + 15, Block.cloth.blockID, 15);
		world.setBlockAndMetadata(i + 5, j + 5, k + 16, Block.cloth.blockID, 15);
		world.setBlockAndMetadata(i + 5, j + 5, k + 17, Block.cloth.blockID, 15);
		world.setBlockAndMetadata(i + 5, j + 5, k + 18, Block.cloth.blockID, 11);
		world.setBlock(i + 5, j + 5, k + 19, 0);
		world.setBlock(i + 5, j + 5, k + 20, 0);
		world.setBlock(i + 5, j + 5, k + 21, 0);
		world.setBlock(i + 5, j + 6, k + 0, 0);
		world.setBlock(i + 5, j + 6, k + 1, 0);
		world.setBlock(i + 5, j + 6, k + 2, 0);
		world.setBlock(i + 5, j + 6, k + 3, 0);
		world.setBlockAndMetadata(i + 5, j + 6, k + 4, Block.cloth.blockID, 11);
		world.setBlockAndMetadata(i + 5, j + 6, k + 5, Block.cloth.blockID, 11);
		world.setBlock(i + 5, j + 6, k + 6, 0);
		world.setBlock(i + 5, j + 6, k + 7, 0);
		world.setBlock(i + 5, j + 6, k + 8, 0);
		world.setBlock(i + 5, j + 6, k + 9, 0);
		world.setBlock(i + 5, j + 6, k + 10, 0);
		world.setBlock(i + 5, j + 6, k + 11, 0);
		world.setBlock(i + 5, j + 6, k + 12, 0);
		world.setBlock(i + 5, j + 6, k + 13, 0);
		world.setBlock(i + 5, j + 6, k + 14, 0);
		world.setBlock(i + 5, j + 6, k + 15, 0);
		world.setBlock(i + 5, j + 6, k + 16, 0);
		world.setBlockAndMetadata(i + 5, j + 6, k + 17, Block.cloth.blockID, 11);
		world.setBlockAndMetadata(i + 5, j + 6, k + 18, Block.cloth.blockID, 11);
		world.setBlock(i + 5, j + 6, k + 19, 0);
		world.setBlock(i + 5, j + 6, k + 20, 0);
		world.setBlock(i + 5, j + 6, k + 21, 0);
		world.setBlock(i + 5, j + 7, k + 0, 0);
		world.setBlock(i + 5, j + 7, k + 1, 0);
		world.setBlock(i + 5, j + 7, k + 2, 0);
		world.setBlock(i + 5, j + 7, k + 3, 0);
		world.setBlockAndMetadata(i + 5, j + 7, k + 4, Block.cloth.blockID, 11);
		world.setBlockAndMetadata(i + 5, j + 7, k + 5, Block.cloth.blockID, 11);
		world.setBlock(i + 5, j + 7, k + 6, 0);
		world.setBlock(i + 5, j + 7, k + 7, 0);
		world.setBlock(i + 5, j + 7, k + 8, 0);
		world.setBlock(i + 5, j + 7, k + 9, 0);
		world.setBlock(i + 5, j + 7, k + 10, 0);
		world.setBlock(i + 5, j + 7, k + 11, 0);
		world.setBlock(i + 5, j + 7, k + 12, 0);
		world.setBlock(i + 5, j + 7, k + 13, 0);
		world.setBlock(i + 5, j + 7, k + 14, 0);
		world.setBlock(i + 5, j + 7, k + 15, 0);
		world.setBlock(i + 5, j + 7, k + 16, 0);
		world.setBlockAndMetadata(i + 5, j + 7, k + 17, Block.cloth.blockID, 11);
		world.setBlockAndMetadata(i + 5, j + 7, k + 18, Block.cloth.blockID, 11);
		world.setBlock(i + 5, j + 7, k + 19, 0);
		world.setBlock(i + 5, j + 7, k + 20, 0);
		world.setBlock(i + 5, j + 7, k + 21, 0);
		world.setBlock(i + 5, j + 8, k + 0, 0);
		world.setBlock(i + 5, j + 8, k + 1, 0);
		world.setBlock(i + 5, j + 8, k + 2, 0);
		world.setBlock(i + 5, j + 8, k + 3, 0);
		world.setBlockAndMetadata(i + 5, j + 8, k + 4, Block.cloth.blockID, 11);
		world.setBlockAndMetadata(i + 5, j + 8, k + 5, Block.cloth.blockID, 11);
		world.setBlock(i + 5, j + 8, k + 6, 0);
		world.setBlock(i + 5, j + 8, k + 7, 0);
		world.setBlock(i + 5, j + 8, k + 8, 0);
		world.setBlock(i + 5, j + 8, k + 9, 0);
		world.setBlock(i + 5, j + 8, k + 10, 0);
		world.setBlock(i + 5, j + 8, k + 11, 0);
		world.setBlock(i + 5, j + 8, k + 12, 0);
		world.setBlock(i + 5, j + 8, k + 13, 0);
		world.setBlock(i + 5, j + 8, k + 14, 0);
		world.setBlock(i + 5, j + 8, k + 15, 0);
		world.setBlock(i + 5, j + 8, k + 16, 0);
		world.setBlockAndMetadata(i + 5, j + 8, k + 17, Block.cloth.blockID, 11);
		world.setBlockAndMetadata(i + 5, j + 8, k + 18, Block.cloth.blockID, 11);
		world.setBlock(i + 5, j + 8, k + 19, 0);
		world.setBlock(i + 5, j + 8, k + 20, 0);
		world.setBlock(i + 5, j + 8, k + 21, 0);
		world.setBlock(i + 5, j + 9, k + 0, 0);
		world.setBlock(i + 5, j + 9, k + 1, 0);
		world.setBlock(i + 5, j + 9, k + 2, 0);
		world.setBlock(i + 5, j + 9, k + 3, 0);
		world.setBlockAndMetadata(i + 5, j + 9, k + 4, Block.cloth.blockID, 15);
		world.setBlock(i + 5, j + 9, k + 5, Block.glowStone.blockID);
		world.setBlock(i + 5, j + 9, k + 6, Block.glowStone.blockID);
