/*
*** MADE BY MITHION'S .SCHEMATIC TO JAVA CONVERTING TOOL v1.6 ***
*/

package FunMod.struturas;
import java.util.Random;

import net.minecraft.block.Block;
import net.minecraft.world.World;
import net.minecraft.world.gen.feature.WorldGenerator;

public class WorldGenBowserCastle extends WorldGenerator
{
	protected int[] GetValidSpawnBlocks() {
		return new int[] {
			Block.stone.blockID,
			Block.grass.blockID,
			Block.dirt.blockID
		};
	}

	public boolean LocationIsValidSpawn(World world, int i, int j, int k){
		int distanceToAir = 0;
		int checkID = world.getBlockId(i, j, k);

		while (checkID != 0){
			distanceToAir++;
			checkID = world.getBlockId(i, j + distanceToAir, k);
		}

		if (distanceToAir > 3){
			return false;
		}
		j += distanceToAir - 1;

		int blockID = world.getBlockId(i, j, k);
		int blockIDAbove = world.getBlockId(i, j+1, k);
		int blockIDBelow = world.getBlockId(i, j-1, k);
		for (int x : GetValidSpawnBlocks()){
			if (blockIDAbove != 0){
				return false;
			}
			if (blockID == x){
				return true;
			}else if (blockID == Block.snow.blockID && blockIDBelow == x){
				return true;
			}
		}
		return false;
	}

	public WorldGenBowserCastle() { }

	public boolean generate(World world, Random rand, int i, int j, int k) {
		//check that each corner is one of the valid spawn blocks
		if(!LocationIsValidSpawn(world, i, j, k) || !LocationIsValidSpawn(world, i + 54, j, k) || !LocationIsValidSpawn(world, i + 54, j, k + 44) || !LocationIsValidSpawn(world, i, j, k + 44))
		{
			return false;
		}

		world.setBlock(i + 0, j + 0, k + 0, Block.bedrock.blockID);
		world.setBlock(i + 0, j + 0, k + 1, Block.bedrock.blockID);
		world.setBlock(i + 0, j + 0, k + 2, Block.bedrock.blockID);
		world.setBlock(i + 0, j + 0, k + 3, Block.bedrock.blockID);
		world.setBlock(i + 0, j + 0, k + 4, Block.bedrock.blockID);
		world.setBlock(i + 0, j + 0, k + 5, Block.bedrock.blockID);
		world.setBlock(i + 0, j + 0, k + 6, Block.bedrock.blockID);
		world.setBlock(i + 0, j + 0, k + 7, Block.bedrock.blockID);
		world.setBlock(i + 0, j + 0, k + 8, Block.bedrock.blockID);
		world.setBlock(i + 0, j + 0, k + 9, Block.bedrock.blockID);
		world.setBlock(i + 0, j + 0, k + 10, Block.bedrock.blockID);
		world.setBlock(i + 0, j + 0, k + 11, Block.bedrock.blockID);
		world.setBlock(i + 0, j + 0, k + 12, Block.bedrock.blockID);
		world.setBlock(i + 0, j + 0, k + 13, Block.bedrock.blockID);
		world.setBlock(i + 0, j + 0, k + 14, Block.bedrock.blockID);
		world.setBlock(i + 0, j + 0, k + 15, Block.bedrock.blockID);
		world.setBlock(i + 0, j + 0, k + 16, Block.bedrock.blockID);
		world.setBlock(i + 0, j + 0, k + 17, Block.bedrock.blockID);
		world.setBlock(i + 0, j + 0, k + 18, Block.bedrock.blockID);
		world.setBlock(i + 0, j + 0, k + 19, Block.bedrock.blockID);
		world.setBlock(i + 0, j + 0, k + 20, Block.bedrock.blockID);
		world.setBlock(i + 0, j + 0, k + 21, Block.bedrock.blockID);
		world.setBlock(i + 0, j + 0, k + 22, Block.bedrock.blockID);
		world.setBlock(i + 0, j + 0, k + 23, Block.bedrock.blockID);
		world.setBlock(i + 0, j + 0, k + 24, Block.bedrock.blockID);
		world.setBlock(i + 0, j + 0, k + 25, Block.bedrock.blockID);
		world.setBlock(i + 0, j + 0, k + 26, Block.bedrock.blockID);
		world.setBlock(i + 0, j + 0, k + 27, Block.bedrock.blockID);
		world.setBlock(i + 0, j + 0, k + 28, Block.bedrock.blockID);
		world.setBlock(i + 0, j + 0, k + 29, Block.bedrock.blockID);
		world.setBlock(i + 0, j + 0, k + 30, Block.bedrock.blockID);
		world.setBlock(i + 0, j + 0, k + 31, Block.bedrock.blockID);
		world.setBlock(i + 0, j + 0, k + 32, Block.bedrock.blockID);
		world.setBlock(i + 0, j + 0, k + 33, Block.bedrock.blockID);
		world.setBlock(i + 0, j + 0, k + 34, Block.bedrock.blockID);
		world.setBlock(i + 0, j + 0, k + 35, Block.bedrock.blockID);
		world.setBlock(i + 0, j + 0, k + 36, Block.bedrock.blockID);
		world.setBlock(i + 0, j + 0, k + 37, Block.bedrock.blockID);
		world.setBlock(i + 0, j + 0, k + 38, Block.bedrock.blockID);
		world.setBlock(i + 0, j + 0, k + 39, Block.bedrock.blockID);
		world.setBlock(i + 0, j + 0, k + 40, Block.bedrock.blockID);
		world.setBlock(i + 0, j + 0, k + 41, Block.bedrock.blockID);
		world.setBlock(i + 0, j + 0, k + 42, Block.bedrock.blockID);
		world.setBlock(i + 0, j + 0, k + 43, Block.bedrock.blockID);
		world.setBlock(i + 0, j + 0, k + 44, Block.bedrock.blockID);
		world.setBlock(i + 0, j + 1, k + 0, Block.dirt.blockID);
		world.setBlock(i + 0, j + 1, k + 1, Block.dirt.blockID);
		world.setBlock(i + 0, j + 1, k + 2, Block.dirt.blockID);
		world.setBlock(i + 0, j + 1, k + 3, Block.dirt.blockID);
		world.setBlock(i + 0, j + 1, k + 4, Block.dirt.blockID);
		world.setBlock(i + 0, j + 1, k + 5, Block.dirt.blockID);
		world.setBlock(i + 0, j + 1, k + 6, Block.dirt.blockID);
		world.setBlock(i + 0, j + 1, k + 7, Block.dirt.blockID);
		world.setBlock(i + 0, j + 1, k + 8, Block.dirt.blockID);
		world.setBlock(i + 0, j + 1, k + 9, Block.dirt.blockID);
		world.setBlock(i + 0, j + 1, k + 10, Block.dirt.blockID);
		world.setBlock(i + 0, j + 1, k + 11, Block.dirt.blockID);
		world.setBlock(i + 0, j + 1, k + 12, Block.dirt.blockID);
		world.setBlock(i + 0, j + 1, k + 13, Block.dirt.blockID);
		world.setBlock(i + 0, j + 1, k + 14, Block.dirt.blockID);
		world.setBlock(i + 0, j + 1, k + 15, Block.dirt.blockID);
		world.setBlock(i + 0, j + 1, k + 16, Block.dirt.blockID);
		world.setBlock(i + 0, j + 1, k + 17, Block.dirt.blockID);
		world.setBlock(i + 0, j + 1, k + 18, Block.dirt.blockID);
		world.setBlock(i + 0, j + 1, k + 19, Block.dirt.blockID);
		world.setBlock(i + 0, j + 1, k + 20, Block.dirt.blockID);
		world.setBlock(i + 0, j + 1, k + 21, Block.dirt.blockID);
		world.setBlock(i + 0, j + 1, k + 22, Block.dirt.blockID);
		world.setBlock(i + 0, j + 1, k + 23, Block.dirt.blockID);
		world.setBlock(i + 0, j + 1, k + 24, Block.dirt.blockID);
		world.setBlock(i + 0, j + 1, k + 25, Block.dirt.blockID);
		world.setBlock(i + 0, j + 1, k + 26, Block.dirt.blockID);
		world.setBlock(i + 0, j + 1, k + 27, Block.dirt.blockID);
		world.setBlock(i + 0, j + 1, k + 28, Block.dirt.blockID);
		world.setBlock(i + 0, j + 1, k + 29, Block.dirt.blockID);
		world.setBlock(i + 0, j + 1, k + 30, Block.dirt.blockID);
		world.setBlock(i + 0, j + 1, k + 31, Block.dirt.blockID);
		world.setBlock(i + 0, j + 1, k + 32, Block.dirt.blockID);
		world.setBlock(i + 0, j + 1, k + 33, Block.dirt.blockID);
		world.setBlock(i + 0, j + 1, k + 34, Block.dirt.blockID);
		world.setBlock(i + 0, j + 1, k + 35, Block.dirt.blockID);
		world.setBlock(i + 0, j + 1, k + 36, Block.dirt.blockID);
		world.setBlock(i + 0, j + 1, k + 37, Block.dirt.blockID);
		world.setBlock(i + 0, j + 1, k + 38, Block.dirt.blockID);
		world.setBlock(i + 0, j + 1, k + 39, Block.dirt.blockID);
		world.setBlock(i + 0, j + 1, k + 40, Block.dirt.blockID);
		world.setBlock(i + 0, j + 1, k + 41, Block.dirt.blockID);
		world.setBlock(i + 0, j + 1, k + 42, Block.dirt.blockID);
		world.setBlock(i + 0, j + 1, k + 43, Block.dirt.blockID);
		world.setBlock(i + 0, j + 1, k + 44, Block.dirt.blockID);
		world.setBlock(i + 0, j + 2, k + 0, Block.dirt.blockID);
		world.setBlock(i + 0, j + 2, k + 1, Block.dirt.blockID);
		world.setBlock(i + 0, j + 2, k + 2, Block.dirt.blockID);
		world.setBlock(i + 0, j + 2, k + 3, Block.dirt.blockID);
		world.setBlock(i + 0, j + 2, k + 4, Block.dirt.blockID);
		world.setBlock(i + 0, j + 2, k + 5, Block.dirt.blockID);
		world.setBlock(i + 0, j + 2, k + 6, Block.dirt.blockID);
		world.setBlock(i + 0, j + 2, k + 7, Block.dirt.blockID);
		world.setBlock(i + 0, j + 2, k + 8, Block.dirt.blockID);
		world.setBlock(i + 0, j + 2, k + 9, Block.dirt.blockID);
		world.setBlock(i + 0, j + 2, k + 10, Block.dirt.blockID);
		world.setBlock(i + 0, j + 2, k + 11, Block.dirt.blockID);
		world.setBlock(i + 0, j + 2, k + 12, Block.dirt.blockID);
		world.setBlock(i + 0, j + 2, k + 13, Block.dirt.blockID);
		world.setBlock(i + 0, j + 2, k + 14, Block.dirt.blockID);
		world.setBlock(i + 0, j + 2, k + 15, Block.dirt.blockID);
		world.setBlock(i + 0, j + 2, k + 16, Block.dirt.blockID);
		world.setBlock(i + 0, j + 2, k + 17, Block.dirt.blockID);
		world.setBlock(i + 0, j + 2, k + 18, Block.dirt.blockID);
		world.setBlock(i + 0, j + 2, k + 19, Block.dirt.blockID);
		world.setBlock(i + 0, j + 2, k + 20, Block.dirt.blockID);
		world.setBlock(i + 0, j + 2, k + 21, Block.dirt.blockID);
		world.setBlock(i + 0, j + 2, k + 22, Block.dirt.blockID);
		world.setBlock(i + 0, j + 2, k + 23, Block.dirt.blockID);
		world.setBlock(i + 0, j + 2, k + 24, Block.dirt.blockID);
		world.setBlock(i + 0, j + 2, k + 25, Block.dirt.blockID);
		world.setBlock(i + 0, j + 2, k + 26, Block.dirt.blockID);
		world.setBlock(i + 0, j + 2, k + 27, Block.dirt.blockID);
		world.setBlock(i + 0, j + 2, k + 28, Block.dirt.blockID);
		world.setBlock(i + 0, j + 2, k + 29, Block.dirt.blockID);
		world.setBlock(i + 0, j + 2, k + 30, Block.dirt.blockID);
		world.setBlock(i + 0, j + 2, k + 31, Block.dirt.blockID);
		world.setBlock(i + 0, j + 2, k + 32, Block.dirt.blockID);
		world.setBlock(i + 0, j + 2, k + 33, Block.dirt.blockID);
		world.setBlock(i + 0, j + 2, k + 34, Block.dirt.blockID);
		world.setBlock(i + 0, j + 2, k + 35, Block.dirt.blockID);
		world.setBlock(i + 0, j + 2, k + 36, Block.dirt.blockID);
		world.setBlock(i + 0, j + 2, k + 37, Block.dirt.blockID);
		world.setBlock(i + 0, j + 2, k + 38, Block.dirt.blockID);
		world.setBlock(i + 0, j + 2, k + 39, Block.dirt.blockID);
		world.setBlock(i + 0, j + 2, k + 40, Block.dirt.blockID);
		world.setBlock(i + 0, j + 2, k + 41, Block.dirt.blockID);
		world.setBlock(i + 0, j + 2, k + 42, Block.dirt.blockID);
		world.setBlock(i + 0, j + 2, k + 43, Block.dirt.blockID);
		world.setBlock(i + 0, j + 2, k + 44, Block.dirt.blockID);
		world.setBlock(i + 0, j + 3, k + 0, Block.grass.blockID);
		world.setBlock(i + 0, j + 3, k + 1, Block.grass.blockID);
		world.setBlock(i + 0, j + 3, k + 2, Block.grass.blockID);
		world.setBlock(i + 0, j + 3, k + 3, Block.grass.blockID);
		world.setBlock(i + 0, j + 3, k + 4, Block.grass.blockID);
		world.setBlock(i + 0, j + 3, k + 5, Block.grass.blockID);
		world.setBlock(i + 0, j + 3, k + 6, Block.grass.blockID);
		world.setBlock(i + 0, j + 3, k + 7, Block.grass.blockID);
		world.setBlock(i + 0, j + 3, k + 8, Block.grass.blockID);
		world.setBlock(i + 0, j + 3, k + 9, Block.grass.blockID);
		world.setBlock(i + 0, j + 3, k + 10, Block.grass.blockID);
		world.setBlock(i + 0, j + 3, k + 11, Block.grass.blockID);
		world.setBlock(i + 0, j + 3, k + 12, Block.grass.blockID);
		world.setBlock(i + 0, j + 3, k + 13, Block.grass.blockID);
		world.setBlock(i + 0, j + 3, k + 14, Block.grass.blockID);
		world.setBlock(i + 0, j + 3, k + 15, Block.grass.blockID);
		world.setBlock(i + 0, j + 3, k + 16, Block.grass.blockID);
		world.setBlock(i + 0, j + 3, k + 17, Block.grass.blockID);
		world.setBlock(i + 0, j + 3, k + 18, Block.grass.blockID);
		world.setBlock(i + 0, j + 3, k + 19, Block.grass.blockID);
		world.setBlock(i + 0, j + 3, k + 20, Block.grass.blockID);
		world.setBlock(i + 0, j + 3, k + 21, Block.grass.blockID);
		world.setBlock(i + 0, j + 3, k + 22, Block.grass.blockID);
		world.setBlock(i + 0, j + 3, k + 23, Block.grass.blockID);
		world.setBlock(i + 0, j + 3, k + 24, Block.grass.blockID);
		world.setBlock(i + 0, j + 3, k + 25, Block.grass.blockID);
		world.setBlock(i + 0, j + 3, k + 26, Block.grass.blockID);
		world.setBlock(i + 0, j + 3, k + 27, Block.grass.blockID);
		world.setBlock(i + 0, j + 3, k + 28, Block.grass.blockID);
		world.setBlock(i + 0, j + 3, k + 29, Block.grass.blockID);
		world.setBlock(i + 0, j + 3, k + 30, Block.grass.blockID);
		world.setBlock(i + 0, j + 3, k + 31, Block.grass.blockID);
		world.setBlock(i + 0, j + 3, k + 32, Block.grass.blockID);
		world.setBlock(i + 0, j + 3, k + 33, Block.grass.blockID);
		world.setBlock(i + 0, j + 3, k + 34, Block.grass.blockID);
		world.setBlock(i + 0, j + 3, k + 35, Block.grass.blockID);
		world.setBlock(i + 0, j + 3, k + 36, Block.grass.blockID);
		world.setBlock(i + 0, j + 3, k + 37, Block.grass.blockID);
		world.setBlock(i + 0, j + 3, k + 38, Block.grass.blockID);
		world.setBlock(i + 0, j + 3, k + 39, Block.grass.blockID);
		world.setBlock(i + 0, j + 3, k + 40, Block.grass.blockID);
		world.setBlock(i + 0, j + 3, k + 41, Block.grass.blockID);
		world.setBlock(i + 0, j + 3, k + 42, Block.grass.blockID);
		world.setBlock(i + 0, j + 3, k + 43, Block.grass.blockID);
		world.setBlock(i + 0, j + 3, k + 44, Block.grass.blockID);
		world.setBlock(i + 1, j + 0, k + 0, Block.bedrock.blockID);
		world.setBlock(i + 1, j + 0, k + 1, Block.bedrock.blockID);
		world.setBlock(i + 1, j + 0, k + 2, Block.bedrock.blockID);
		world.setBlock(i + 1, j + 0, k + 3, Block.bedrock.blockID);
		world.setBlock(i + 1, j + 0, k + 4, Block.bedrock.blockID);
		world.setBlock(i + 1, j + 0, k + 5, Block.bedrock.blockID);
		world.setBlock(i + 1, j + 0, k + 6, Block.bedrock.blockID);
		world.setBlock(i + 1, j + 0, k + 7, Block.bedrock.blockID);
		world.setBlock(i + 1, j + 0, k + 8, Block.bedrock.blockID);
		world.setBlock(i + 1, j + 0, k + 9, Block.bedrock.blockID);
		world.setBlock(i + 1, j + 0, k + 10, Block.bedrock.blockID);
		world.setBlock(i + 1, j + 0, k + 11, Block.bedrock.blockID);
		world.setBlock(i + 1, j + 0, k + 12, Block.bedrock.blockID);
		world.setBlock(i + 1, j + 0, k + 13, Block.bedrock.blockID);
		world.setBlock(i + 1, j + 0, k + 14, Block.bedrock.blockID);
		world.setBlock(i + 1, j + 0, k + 15, Block.bedrock.blockID);
		world.setBlock(i + 1, j + 0, k + 16, Block.bedrock.blockID);
		world.setBlock(i + 1, j + 0, k + 17, Block.bedrock.blockID);
		world.setBlock(i + 1, j + 0, k + 18, Block.bedrock.blockID);
		world.setBlock(i + 1, j + 0, k + 19, Block.bedrock.blockID);
		world.setBlock(i + 1, j + 0, k + 20, Block.bedrock.blockID);
		world.setBlock(i + 1, j + 0, k + 21, Block.bedrock.blockID);
		world.setBlock(i + 1, j + 0, k + 22, Block.bedrock.blockID);
		world.setBlock(i + 1, j + 0, k + 23, Block.bedrock.blockID);
		world.setBlock(i + 1, j + 0, k + 24, Block.bedrock.blockID);
		world.setBlock(i + 1, j + 0, k + 25, Block.bedrock.blockID);
		world.setBlock(i + 1, j + 0, k + 26, Block.bedrock.blockID);
		world.setBlock(i + 1, j + 0, k + 27, Block.bedrock.blockID);
		world.setBlock(i + 1, j + 0, k + 28, Block.bedrock.blockID);
		world.setBlock(i + 1, j + 0, k + 29, Block.bedrock.blockID);
		world.setBlock(i + 1, j + 0, k + 30, Block.bedrock.blockID);
		world.setBlock(i + 1, j + 0, k + 31, Block.bedrock.blockID);
		world.setBlock(i + 1, j + 0, k + 32, Block.bedrock.blockID);
		world.setBlock(i + 1, j + 0, k + 33, Block.bedrock.blockID);
		world.setBlock(i + 1, j + 0, k + 34, Block.bedrock.blockID);
		world.setBlock(i + 1, j + 0, k + 35, Block.bedrock.blockID);
		world.setBlock(i + 1, j + 0, k + 36, Block.bedrock.blockID);
		world.setBlock(i + 1, j + 0, k + 37, Block.bedrock.blockID);
		world.setBlock(i + 1, j + 0, k + 38, Block.bedrock.blockID);
		world.setBlock(i + 1, j + 0, k + 39, Block.bedrock.blockID);
		world.setBlock(i + 1, j + 0, k + 40, Block.bedrock.blockID);
		world.setBlock(i + 1, j + 0, k + 41, Block.bedrock.blockID);
		world.setBlock(i + 1, j + 0, k + 42, Block.bedrock.blockID);
		world.setBlock(i + 1, j + 0, k + 43, Block.bedrock.blockID);
		world.setBlock(i + 1, j + 0, k + 44, Block.bedrock.blockID);
		world.setBlock(i + 1, j + 1, k + 0, Block.dirt.blockID);
		world.setBlock(i + 1, j + 1, k + 1, Block.dirt.blockID);
		world.setBlock(i + 1, j + 1, k + 2, Block.dirt.blockID);
		world.setBlock(i + 1, j + 1, k + 3, Block.dirt.blockID);
		world.setBlock(i + 1, j + 1, k + 4, Block.dirt.blockID);
		world.setBlock(i + 1, j + 1, k + 5, Block.dirt.blockID);
		world.setBlock(i + 1, j + 1, k + 6, Block.dirt.blockID);
		world.setBlock(i + 1, j + 1, k + 7, Block.dirt.blockID);
		world.setBlock(i + 1, j + 1, k + 8, Block.dirt.blockID);
		world.setBlock(i + 1, j + 1, k + 9, Block.dirt.blockID);
		world.setBlock(i + 1, j + 1, k + 10, Block.dirt.blockID);
		world.setBlock(i + 1, j + 1, k + 11, Block.dirt.blockID);
		world.setBlock(i + 1, j + 1, k + 12, Block.dirt.blockID);
		world.setBlock(i + 1, j + 1, k + 13, Block.dirt.blockID);
		world.setBlock(i + 1, j + 1, k + 14, Block.dirt.blockID);
		world.setBlock(i + 1, j + 1, k + 15, Block.dirt.blockID);
		world.setBlock(i + 1, j + 1, k + 16, Block.dirt.blockID);
		world.setBlock(i + 1, j + 1, k + 17, Block.dirt.blockID);
		world.setBlock(i + 1, j + 1, k + 18, Block.dirt.blockID);
		world.setBlock(i + 1, j + 1, k + 19, Block.dirt.blockID);
		world.setBlock(i + 1, j + 1, k + 20, Block.dirt.blockID);
		world.setBlock(i + 1, j + 1, k + 21, Block.dirt.blockID);
		world.setBlock(i + 1, j + 1, k + 22, Block.dirt.blockID);
		world.setBlock(i + 1, j + 1, k + 23, Block.dirt.blockID);
		world.setBlock(i + 1, j + 1, k + 24, Block.dirt.blockID);
		world.setBlock(i + 1, j + 1, k + 25, Block.dirt.blockID);
		world.setBlock(i + 1, j + 1, k + 26, Block.dirt.blockID);
		world.setBlock(i + 1, j + 1, k + 27, Block.dirt.blockID);
		world.setBlock(i + 1, j + 1, k + 28, Block.dirt.blockID);
		world.setBlock(i + 1, j + 1, k + 29, Block.dirt.blockID);
		world.setBlock(i + 1, j + 1, k + 30, Block.dirt.blockID);
		world.setBlock(i + 1, j + 1, k + 31, Block.dirt.blockID);
		world.setBlock(i + 1, j + 1, k + 32, Block.dirt.blockID);
		world.setBlock(i + 1, j + 1, k + 33, Block.dirt.blockID);
		world.setBlock(i + 1, j + 1, k + 34, Block.dirt.blockID);
		world.setBlock(i + 1, j + 1, k + 35, Block.dirt.blockID);
		world.setBlock(i + 1, j + 1, k + 36, Block.dirt.blockID);
		world.setBlock(i + 1, j + 1, k + 37, Block.dirt.blockID);
		world.setBlock(i + 1, j + 1, k + 38, Block.dirt.blockID);
		world.setBlock(i + 1, j + 1, k + 39, Block.dirt.blockID);
		world.setBlock(i + 1, j + 1, k + 40, Block.dirt.blockID);
		world.setBlock(i + 1, j + 1, k + 41, Block.dirt.blockID);
		world.setBlock(i + 1, j + 1, k + 42, Block.dirt.blockID);
		world.setBlock(i + 1, j + 1, k + 43, Block.dirt.blockID);
		world.setBlock(i + 1, j + 1, k + 44, Block.dirt.blockID);
		world.setBlock(i + 1, j + 2, k + 0, Block.dirt.blockID);
		world.setBlock(i + 1, j + 2, k + 1, Block.dirt.blockID);
		world.setBlock(i + 1, j + 2, k + 2, Block.dirt.blockID);
		world.setBlock(i + 1, j + 2, k + 3, Block.dirt.blockID);
		world.setBlock(i + 1, j + 2, k + 4, Block.dirt.blockID);
		world.setBlock(i + 1, j + 2, k + 5, Block.dirt.blockID);
		world.setBlock(i + 1, j + 2, k + 6, Block.dirt.blockID);
		world.setBlock(i + 1, j + 2, k + 7, Block.dirt.blockID);
		world.setBlock(i + 1, j + 2, k + 8, Block.dirt.blockID);
		world.setBlock(i + 1, j + 2, k + 9, Block.dirt.blockID);
		world.setBlock(i + 1, j + 2, k + 10, Block.dirt.blockID);
		world.setBlock(i + 1, j + 2, k + 11, Block.dirt.blockID);
		world.setBlock(i + 1, j + 2, k + 12, Block.dirt.blockID);
		world.setBlock(i + 1, j + 2, k + 13, Block.dirt.blockID);
		world.setBlock(i + 1, j + 2, k + 14, Block.dirt.blockID);
		world.setBlock(i + 1, j + 2, k + 15, Block.dirt.blockID);
		world.setBlock(i + 1, j + 2, k + 16, Block.dirt.blockID);
		world.setBlock(i + 1, j + 2, k + 17, Block.dirt.blockID);
		world.setBlock(i + 1, j + 2, k + 18, Block.dirt.blockID);
		world.setBlock(i + 1, j + 2, k + 19, Block.dirt.blockID);
		world.setBlock(i + 1, j + 2, k + 20, Block.dirt.blockID);
		world.setBlock(i + 1, j + 2, k + 21, Block.dirt.blockID);
		world.setBlock(i + 1, j + 2, k + 22, Block.dirt.blockID);
		world.setBlock(i + 1, j + 2, k + 23, Block.dirt.blockID);
		world.setBlock(i + 1, j + 2, k + 24, Block.dirt.blockID);
		world.setBlock(i + 1, j + 2, k + 25, Block.dirt.blockID);
		world.setBlock(i + 1, j + 2, k + 26, Block.dirt.blockID);
		world.setBlock(i + 1, j + 2, k + 27, Block.dirt.blockID);
		world.setBlock(i + 1, j + 2, k + 28, Block.dirt.blockID);
		world.setBlock(i + 1, j + 2, k + 29, Block.dirt.blockID);
		world.setBlock(i + 1, j + 2, k + 30, Block.dirt.blockID);
		world.setBlock(i + 1, j + 2, k + 31, Block.dirt.blockID);
		world.setBlock(i + 1, j + 2, k + 32, Block.dirt.blockID);
		world.setBlock(i + 1, j + 2, k + 33, Block.dirt.blockID);
		world.setBlock(i + 1, j + 2, k + 34, Block.dirt.blockID);
		world.setBlock(i + 1, j + 2, k + 35, Block.dirt.blockID);
		world.setBlock(i + 1, j + 2, k + 36, Block.dirt.blockID);
		world.setBlock(i + 1, j + 2, k + 37, Block.dirt.blockID);
		world.setBlock(i + 1, j + 2, k + 38, Block.dirt.blockID);
		world.setBlock(i + 1, j + 2, k + 39, Block.dirt.blockID);
		world.setBlock(i + 1, j + 2, k + 40, Block.dirt.blockID);
		world.setBlock(i + 1, j + 2, k + 41, Block.dirt.blockID);
		world.setBlock(i + 1, j + 2, k + 42, Block.dirt.blockID);
		world.setBlock(i + 1, j + 2, k + 43, Block.dirt.blockID);
		world.setBlock(i + 1, j + 2, k + 44, Block.dirt.blockID);
		world.setBlock(i + 1, j + 3, k + 0, Block.grass.blockID);
		world.setBlock(i + 1, j + 3, k + 1, Block.grass.blockID);
		world.setBlock(i + 1, j + 3, k + 2, Block.grass.blockID);
		world.setBlock(i + 1, j + 3, k + 3, Block.grass.blockID);
		world.setBlock(i + 1, j + 3, k + 4, Block.grass.blockID);
		world.setBlock(i + 1, j + 3, k + 5, Block.grass.blockID);
		world.setBlock(i + 1, j + 3, k + 6, Block.grass.blockID);
		world.setBlock(i + 1, j + 3, k + 7, Block.grass.blockID);
		world.setBlock(i + 1, j + 3, k + 8, Block.grass.blockID);
		world.setBlock(i + 1, j + 3, k + 9, Block.grass.blockID);
		world.setBlock(i + 1, j + 3, k + 10, Block.grass.blockID);
		world.setBlock(i + 1, j + 3, k + 11, Block.grass.blockID);
		world.setBlock(i + 1, j + 3, k + 12, Block.grass.blockID);
		world.setBlock(i + 1, j + 3, k + 13, Block.grass.blockID);
		world.setBlock(i + 1, j + 3, k + 14, Block.grass.blockID);
		world.setBlock(i + 1, j + 3, k + 15, Block.grass.blockID);
		world.setBlock(i + 1, j + 3, k + 16, Block.grass.blockID);
		world.setBlock(i + 1, j + 3, k + 17, Block.grass.blockID);
		world.setBlock(i + 1, j + 3, k + 18, Block.grass.blockID);
		world.setBlock(i + 1, j + 3, k + 19, Block.grass.blockID);
		world.setBlock(i + 1, j + 3, k + 20, Block.grass.blockID);
		world.setBlock(i + 1, j + 3, k + 21, Block.grass.blockID);
		world.setBlock(i + 1, j + 3, k + 22, Block.grass.blockID);
		world.setBlock(i + 1, j + 3, k + 23, Block.grass.blockID);
		world.setBlock(i + 1, j + 3, k + 24, Block.grass.blockID);
		world.setBlock(i + 1, j + 3, k + 25, Block.grass.blockID);
		world.setBlock(i + 1, j + 3, k + 26, Block.grass.blockID);
		world.setBlock(i + 1, j + 3, k + 27, Block.grass.blockID);
		world.setBlock(i + 1, j + 3, k + 28, Block.grass.blockID);
		world.setBlock(i + 1, j + 3, k + 29, Block.grass.blockID);
		world.setBlock(i + 1, j + 3, k + 30, Block.grass.blockID);
		world.setBlock(i + 1, j + 3, k + 31, Block.grass.blockID);
		world.setBlock(i + 1, j + 3, k + 32, Block.grass.blockID);
		world.setBlock(i + 1, j + 3, k + 33, Block.grass.blockID);
		world.setBlock(i + 1, j + 3, k + 34, Block.grass.blockID);
		world.setBlock(i + 1, j + 3, k + 35, Block.grass.blockID);
		world.setBlock(i + 1, j + 3, k + 36, Block.grass.blockID);
		world.setBlock(i + 1, j + 3, k + 37, Block.grass.blockID);
		world.setBlock(i + 1, j + 3, k + 38, Block.grass.blockID);
		world.setBlock(i + 1, j + 3, k + 39, Block.grass.blockID);
		world.setBlock(i + 1, j + 3, k + 40, Block.grass.blockID);
		world.setBlock(i + 1, j + 3, k + 41, Block.grass.blockID);
		world.setBlock(i + 1, j + 3, k + 42, Block.grass.blockID);
		world.setBlock(i + 1, j + 3, k + 43, Block.grass.blockID);
		world.setBlock(i + 1, j + 3, k + 44, Block.grass.blockID);
		world.setBlock(i + 2, j + 0, k + 0, Block.bedrock.blockID);
		world.setBlock(i + 2, j + 0, k + 1, Block.bedrock.blockID);
		world.setBlock(i + 2, j + 0, k + 2, Block.bedrock.blockID);
		world.setBlock(i + 2, j + 0, k + 3, Block.bedrock.blockID);
		world.setBlock(i + 2, j + 0, k + 4, Block.bedrock.blockID);
		world.setBlock(i + 2, j + 0, k + 5, Block.bedrock.blockID);
		world.setBlock(i + 2, j + 0, k + 6, Block.bedrock.blockID);
		world.setBlock(i + 2, j + 0, k + 7, Block.bedrock.blockID);
		world.setBlock(i + 2, j + 0, k + 8, Block.bedrock.blockID);
		world.setBlock(i + 2, j + 0, k + 9, Block.bedrock.blockID);
		world.setBlock(i + 2, j + 0, k + 10, Block.bedrock.blockID);
		world.setBlock(i + 2, j + 0, k + 11, Block.bedrock.blockID);
		world.setBlock(i + 2, j + 0, k + 12, Block.bedrock.blockID);
		world.setBlock(i + 2, j + 0, k + 13, Block.bedrock.blockID);
		world.setBlock(i + 2, j + 0, k + 14, Block.bedrock.blockID);
		world.setBlock(i + 2, j + 0, k + 15, Block.bedrock.blockID);
		world.setBlock(i + 2, j + 0, k + 16, Block.bedrock.blockID);
		world.setBlock(i + 2, j + 0, k + 17, Block.bedrock.blockID);
		world.setBlock(i + 2, j + 0, k + 18, Block.bedrock.blockID);
		world.setBlock(i + 2, j + 0, k + 19, Block.bedrock.blockID);
		world.setBlock(i + 2, j + 0, k + 20, Block.bedrock.blockID);
		world.setBlock(i + 2, j + 0, k + 21, Block.bedrock.blockID);
		world.setBlock(i + 2, j + 0, k + 22, Block.bedrock.blockID);
		world.setBlock(i + 2, j + 0, k + 23, Block.bedrock.blockID);
		world.setBlock(i + 2, j + 0, k + 24, Block.bedrock.blockID);
		world.setBlock(i + 2, j + 0, k + 25, Block.bedrock.blockID);
		world.setBlock(i + 2, j + 0, k + 26, Block.bedrock.blockID);
		world.setBlock(i + 2, j + 0, k + 27, Block.bedrock.blockID);
		world.setBlock(i + 2, j + 0, k + 28, Block.bedrock.blockID);
		world.setBlock(i + 2, j + 0, k + 29, Block.bedrock.blockID);
		world.setBlock(i + 2, j + 0, k + 30, Block.bedrock.blockID);
		world.setBlock(i + 2, j + 0, k + 31, Block.bedrock.blockID);
		world.setBlock(i + 2, j + 0, k + 32, Block.bedrock.blockID);
		world.setBlock(i + 2, j + 0, k + 33, Block.bedrock.blockID);
		world.setBlock(i + 2, j + 0, k + 34, Block.bedrock.blockID);
		world.setBlock(i + 2, j + 0, k + 35, Block.bedrock.blockID);
		world.setBlock(i + 2, j + 0, k + 36, Block.bedrock.blockID);
		world.setBlock(i + 2, j + 0, k + 37, Block.bedrock.blockID);
		world.setBlock(i + 2, j + 0, k + 38, Block.bedrock.blockID);
		world.setBlock(i + 2, j + 0, k + 39, Block.bedrock.blockID);
		world.setBlock(i + 2, j + 0, k + 40, Block.bedrock.blockID);
		world.setBlock(i + 2, j + 0, k + 41, Block.bedrock.blockID);
		world.setBlock(i + 2, j + 0, k + 42, Block.bedrock.blockID);
		world.setBlock(i + 2, j + 0, k + 43, Block.bedrock.blockID);
		world.setBlock(i + 2, j + 0, k + 44, Block.bedrock.blockID);
		world.setBlock(i + 2, j + 1, k + 0, Block.dirt.blockID);
		world.setBlock(i + 2, j + 1, k + 1, Block.dirt.blockID);
		world.setBlock(i + 2, j + 1, k + 2, Block.dirt.blockID);
		world.setBlock(i + 2, j + 1, k + 3, Block.dirt.blockID);
		world.setBlock(i + 2, j + 1, k + 4, Block.dirt.blockID);
		world.setBlock(i + 2, j + 1, k + 5, Block.dirt.blockID);
		world.setBlock(i + 2, j + 1, k + 6, Block.dirt.blockID);
		world.setBlock(i + 2, j + 1, k + 7, Block.dirt.blockID);
		world.setBlock(i + 2, j + 1, k + 8, Block.dirt.blockID);
		world.setBlock(i + 2, j + 1, k + 9, Block.dirt.blockID);
		world.setBlock(i + 2, j + 1, k + 10, Block.dirt.blockID);
		world.setBlock(i + 2, j + 1, k + 11, Block.dirt.blockID);
		world.setBlock(i + 2, j + 1, k + 12, Block.dirt.blockID);
		world.setBlock(i + 2, j + 1, k + 13, Block.dirt.blockID);
		world.setBlock(i + 2, j + 1, k + 14, Block.dirt.blockID);
		world.setBlock(i + 2, j + 1, k + 15, Block.dirt.blockID);
		world.setBlock(i + 2, j + 1, k + 16, Block.dirt.blockID);
		world.setBlock(i + 2, j + 1, k + 17, Block.dirt.blockID);
		world.setBlock(i + 2, j + 1, k + 18, Block.dirt.blockID);
		world.setBlock(i + 2, j + 1, k + 19, Block.dirt.blockID);
		world.setBlock(i + 2, j + 1, k + 20, Block.dirt.blockID);
		world.setBlock(i + 2, j + 1, k + 21, Block.dirt.blockID);
		world.setBlock(i + 2, j + 1, k + 22, Block.dirt.blockID);
		world.setBlock(i + 2, j + 1, k + 23, Block.dirt.blockID);
		world.setBlock(i + 2, j + 1, k + 24, Block.dirt.blockID);
		world.setBlock(i + 2, j + 1, k + 25, Block.dirt.blockID);
		world.setBlock(i + 2, j + 1, k + 26, Block.dirt.blockID);
		world.setBlock(i + 2, j + 1, k + 27, Block.dirt.blockID);
		world.setBlock(i + 2, j + 1, k + 28, Block.dirt.blockID);
		world.setBlock(i + 2, j + 1, k + 29, Block.dirt.blockID);
		world.setBlock(i + 2, j + 1, k + 30, Block.dirt.blockID);
		world.setBlock(i + 2, j + 1, k + 31, Block.dirt.blockID);
		world.setBlock(i + 2, j + 1, k + 32, Block.dirt.blockID);
		world.setBlock(i + 2, j + 1, k + 33, Block.dirt.blockID);
		world.setBlock(i + 2, j + 1, k + 34, Block.dirt.blockID);
		world.setBlock(i + 2, j + 1, k + 35, Block.dirt.blockID);
		world.setBlock(i + 2, j + 1, k + 36, Block.dirt.blockID);
		world.setBlock(i + 2, j + 1, k + 37, Block.dirt.blockID);
		world.setBlock(i + 2, j + 1, k + 38, Block.dirt.blockID);
		world.setBlock(i + 2, j + 1, k + 39, Block.dirt.blockID);
		world.setBlock(i + 2, j + 1, k + 40, Block.dirt.blockID);
		world.setBlock(i + 2, j + 1, k + 41, Block.dirt.blockID);
		world.setBlock(i + 2, j + 1, k + 42, Block.dirt.blockID);
		world.setBlock(i + 2, j + 1, k + 43, Block.dirt.blockID);
		world.setBlock(i + 2, j + 1, k + 44, Block.dirt.blockID);
		world.setBlock(i + 2, j + 2, k + 0, Block.dirt.blockID);
		world.setBlock(i + 2, j + 2, k + 1, Block.dirt.blockID);
		world.setBlock(i + 2, j + 2, k + 2, Block.dirt.blockID);
		world.setBlock(i + 2, j + 2, k + 3, Block.dirt.blockID);
		world.setBlock(i + 2, j + 2, k + 4, Block.dirt.blockID);
		world.setBlock(i + 2, j + 2, k + 5, Block.dirt.blockID);
		world.setBlock(i + 2, j + 2, k + 6, Block.dirt.blockID);
		world.setBlock(i + 2, j + 2, k + 7, Block.dirt.blockID);
		world.setBlock(i + 2, j + 2, k + 8, Block.dirt.blockID);
		world.setBlock(i + 2, j + 2, k + 9, Block.dirt.blockID);
		world.setBlock(i + 2, j + 2, k + 10, Block.dirt.blockID);
		world.setBlock(i + 2, j + 2, k + 11, Block.dirt.blockID);
		world.setBlock(i + 2, j + 2, k + 12, Block.dirt.blockID);
		world.setBlock(i + 2, j + 2, k + 13, Block.dirt.blockID);
		world.setBlock(i + 2, j + 2, k + 14, Block.dirt.blockID);
		world.setBlock(i + 2, j + 2, k + 15, Block.dirt.blockID);
		world.setBlock(i + 2, j + 2, k + 16, Block.dirt.blockID);
		world.setBlock(i + 2, j + 2, k + 17, Block.dirt.blockID);
		world.setBlock(i + 2, j + 2, k + 18, Block.dirt.blockID);
		world.setBlock(i + 2, j + 2, k + 19, Block.dirt.blockID);
		world.setBlock(i + 2, j + 2, k + 20, Block.dirt.blockID);
		world.setBlock(i + 2, j + 2, k + 21, Block.dirt.blockID);
		world.setBlock(i + 2, j + 2, k + 22, Block.dirt.blockID);
		world.setBlock(i + 2, j + 2, k + 23, Block.dirt.blockID);
		world.setBlock(i + 2, j + 2, k + 24, Block.dirt.blockID);
		world.setBlock(i + 2, j + 2, k + 25, Block.dirt.blockID);
		world.setBlock(i + 2, j + 2, k + 26, Block.dirt.blockID);
		world.setBlock(i + 2, j + 2, k + 27, Block.dirt.blockID);
		world.setBlock(i + 2, j + 2, k + 28, Block.dirt.blockID);
		world.setBlock(i + 2, j + 2, k + 29, Block.dirt.blockID);
		world.setBlock(i + 2, j + 2, k + 30, Block.dirt.blockID);
		world.setBlock(i + 2, j + 2, k + 31, Block.dirt.blockID);
		world.setBlock(i + 2, j + 2, k + 32, Block.dirt.blockID);
		world.setBlock(i + 2, j + 2, k + 33, Block.dirt.blockID);
		world.setBlock(i + 2, j + 2, k + 34, Block.dirt.blockID);
		world.setBlock(i + 2, j + 2, k + 35, Block.dirt.blockID);
		world.setBlock(i + 2, j + 2, k + 36, Block.dirt.blockID);
		world.setBlock(i + 2, j + 2, k + 37, Block.dirt.blockID);
		world.setBlock(i + 2, j + 2, k + 38, Block.dirt.blockID);
		world.setBlock(i + 2, j + 2, k + 39, Block.dirt.blockID);
		world.setBlock(i + 2, j + 2, k + 40, Block.dirt.blockID);
		world.setBlock(i + 2, j + 2, k + 41, Block.dirt.blockID);
		world.setBlock(i + 2, j + 2, k + 42, Block.dirt.blockID);
		world.setBlock(i + 2, j + 2, k + 43, Block.dirt.blockID);
		world.setBlock(i + 2, j + 2, k + 44, Block.dirt.blockID);
		world.setBlock(i + 2, j + 3, k + 0, Block.grass.blockID);
		world.setBlock(i + 2, j + 3, k + 1, Block.grass.blockID);
		world.setBlock(i + 2, j + 3, k + 2, Block.grass.blockID);
		world.setBlock(i + 2, j + 3, k + 3, Block.grass.blockID);
		world.setBlock(i + 2, j + 3, k + 4, Block.grass.blockID);
		world.setBlock(i + 2, j + 3, k + 5, Block.grass.blockID);
		world.setBlock(i + 2, j + 3, k + 6, Block.grass.blockID);
		world.setBlock(i + 2, j + 3, k + 7, Block.grass.blockID);
		world.setBlock(i + 2, j + 3, k + 8, Block.grass.blockID);
		world.setBlock(i + 2, j + 3, k + 9, Block.grass.blockID);
		world.setBlock(i + 2, j + 3, k + 10, Block.grass.blockID);
		world.setBlock(i + 2, j + 3, k + 11, Block.grass.blockID);
		world.setBlock(i + 2, j + 3, k + 12, Block.grass.blockID);
		world.setBlock(i + 2, j + 3, k + 13, Block.grass.blockID);
		world.setBlock(i + 2, j + 3, k + 14, Block.grass.blockID);
		world.setBlock(i + 2, j + 3, k + 15, Block.grass.blockID);
		world.setBlock(i + 2, j + 3, k + 16, Block.grass.blockID);
		world.setBlock(i + 2, j + 3, k + 17, Block.grass.blockID);
		world.setBlock(i + 2, j + 3, k + 18, Block.grass.blockID);
		world.setBlock(i + 2, j + 3, k + 19, Block.grass.blockID);
		world.setBlock(i + 2, j + 3, k + 20, Block.grass.blockID);
		world.setBlock(i + 2, j + 3, k + 21, Block.grass.blockID);
		world.setBlock(i + 2, j + 3, k + 22, Block.grass.blockID);
		world.setBlock(i + 2, j + 3, k + 23, Block.grass.blockID);
		world.setBlock(i + 2, j + 3, k + 24, Block.grass.blockID);
		world.setBlock(i + 2, j + 3, k + 25, Block.grass.blockID);
		world.setBlock(i + 2, j + 3, k + 26, Block.grass.blockID);
		world.setBlock(i + 2, j + 3, k + 27, Block.grass.blockID);
		world.setBlock(i + 2, j + 3, k + 28, Block.grass.blockID);
		world.setBlock(i + 2, j + 3, k + 29, Block.grass.blockID);
		world.setBlock(i + 2, j + 3, k + 30, Block.grass.blockID);
		world.setBlock(i + 2, j + 3, k + 31, Block.grass.blockID);
		world.setBlock(i + 2, j + 3, k + 32, Block.grass.blockID);
		world.setBlock(i + 2, j + 3, k + 33, Block.grass.blockID);
		world.setBlock(i + 2, j + 3, k + 34, Block.grass.blockID);
		world.setBlock(i + 2, j + 3, k + 35, Block.grass.blockID);
		world.setBlock(i + 2, j + 3, k + 36, Block.grass.blockID);
		world.setBlock(i + 2, j + 3, k + 37, Block.grass.blockID);
		world.setBlock(i + 2, j + 3, k + 38, Block.grass.blockID);
		world.setBlock(i + 2, j + 3, k + 39, Block.grass.blockID);
		world.setBlock(i + 2, j + 3, k + 40, Block.grass.blockID);
		world.setBlock(i + 2, j + 3, k + 41, Block.grass.blockID);
		world.setBlock(i + 2, j + 3, k + 42, Block.grass.blockID);
		world.setBlock(i + 2, j + 3, k + 43, Block.grass.blockID);
		world.setBlock(i + 2, j + 3, k + 44, Block.grass.blockID);
		world.setBlock(i + 3, j + 0, k + 0, Block.bedrock.blockID);
		world.setBlock(i + 3, j + 0, k + 1, Block.bedrock.blockID);
		world.setBlock(i + 3, j + 0, k + 2, Block.bedrock.blockID);
		world.setBlock(i + 3, j + 0, k + 3, Block.bedrock.blockID);
		world.setBlock(i + 3, j + 0, k + 4, Block.bedrock.blockID);
		world.setBlock(i + 3, j + 0, k + 5, Block.bedrock.blockID);
		world.setBlock(i + 3, j + 0, k + 6, Block.bedrock.blockID);
		world.setBlock(i + 3, j + 0, k + 7, Block.bedrock.blockID);
		world.setBlock(i + 3, j + 0, k + 8, Block.bedrock.blockID);
		world.setBlock(i + 3, j + 0, k + 9, Block.bedrock.blockID);
		world.setBlock(i + 3, j + 0, k + 10, Block.bedrock.blockID);
		world.setBlock(i + 3, j + 0, k + 11, Block.bedrock.blockID);
		world.setBlock(i + 3, j + 0, k + 12, Block.bedrock.blockID);
		world.setBlock(i + 3, j + 0, k + 13, Block.bedrock.blockID);
		world.setBlock(i + 3, j + 0, k + 14, Block.bedrock.blockID);
		world.setBlock(i + 3, j + 0, k + 15, Block.bedrock.blockID);
		world.setBlock(i + 3, j + 0, k + 16, Block.bedrock.blockID);
		world.setBlock(i + 3, j + 0, k + 17, Block.bedrock.blockID);
		world.setBlock(i + 3, j + 0, k + 18, Block.bedrock.blockID);
		world.setBlock(i + 3, j + 0, k + 19, Block.bedrock.blockID);
		world.setBlock(i + 3, j + 0, k + 20, Block.bedrock.blockID);
		world.setBlock(i + 3, j + 0, k + 21, Block.bedrock.blockID);
		world.setBlock(i + 3, j + 0, k + 22, Block.bedrock.blockID);
		world.setBlock(i + 3, j + 0, k + 23, Block.bedrock.blockID);
		world.setBlock(i + 3, j + 0, k + 24, Block.bedrock.blockID);
		world.setBlock(i + 3, j + 0, k + 25, Block.bedrock.blockID);
		world.setBlock(i + 3, j + 0, k + 26, Block.bedrock.blockID);
		world.setBlock(i + 3, j + 0, k + 27, Block.bedrock.blockID);
		world.setBlock(i + 3, j + 0, k + 28, Block.bedrock.blockID);
		world.setBlock(i + 3, j + 0, k + 29, Block.bedrock.blockID);
		world.setBlock(i + 3, j + 0, k + 30, Block.bedrock.blockID);
		world.setBlock(i + 3, j + 0, k + 31, Block.bedrock.blockID);
		world.setBlock(i + 3, j + 0, k + 32, Block.bedrock.blockID);
		world.setBlock(i + 3, j + 0, k + 33, Block.bedrock.blockID);
		world.setBlock(i + 3, j + 0, k + 34, Block.bedrock.blockID);
		world.setBlock(i + 3, j + 0, k + 35, Block.bedrock.blockID);
		world.setBlock(i + 3, j + 0, k + 36, Block.bedrock.blockID);
		world.setBlock(i + 3, j + 0, k + 37, Block.bedrock.blockID);
		world.setBlock(i + 3, j + 0, k + 38, Block.bedrock.blockID);
		world.setBlock(i + 3, j + 0, k + 39, Block.bedrock.blockID);
		world.setBlock(i + 3, j + 0, k + 40, Block.bedrock.blockID);
		world.setBlock(i + 3, j + 0, k + 41, Block.bedrock.blockID);
		world.setBlock(i + 3, j + 0, k + 42, Block.bedrock.blockID);
		world.setBlock(i + 3, j + 0, k + 43, Block.bedrock.blockID);
		world.setBlock(i + 3, j + 0, k + 44, Block.bedrock.blockID);
		world.setBlock(i + 3, j + 1, k + 0, Block.dirt.blockID);
		world.setBlock(i + 3, j + 1, k + 1, Block.dirt.blockID);
		world.setBlock(i + 3, j + 1, k + 2, Block.dirt.blockID);
		world.setBlock(i + 3, j + 1, k + 3, Block.dirt.blockID);
		world.setBlock(i + 3, j + 1, k + 4, Block.dirt.blockID);
		world.setBlock(i + 3, j + 1, k + 5, Block.dirt.blockID);
		world.setBlock(i + 3, j + 1, k + 6, Block.dirt.blockID);
		world.setBlock(i + 3, j + 1, k + 7, Block.dirt.blockID);
		world.setBlock(i + 3, j + 1, k + 8, Block.dirt.blockID);
		world.setBlock(i + 3, j + 1, k + 9, Block.dirt.blockID);
		world.setBlock(i + 3, j + 1, k + 10, Block.dirt.blockID);
		world.setBlock(i + 3, j + 1, k + 11, Block.dirt.blockID);
		world.setBlock(i + 3, j + 1, k + 12, Block.dirt.blockID);
		world.setBlock(i + 3, j + 1, k + 13, Block.dirt.blockID);
		world.setBlock(i + 3, j + 1, k + 14, Block.dirt.blockID);
		world.setBlock(i + 3, j + 1, k + 15, Block.dirt.blockID);
		world.setBlock(i + 3, j + 1, k + 16, Block.dirt.blockID);
		world.setBlock(i + 3, j + 1, k + 17, Block.dirt.blockID);
		world.setBlock(i + 3, j + 1, k + 18, Block.dirt.blockID);
		world.setBlock(i + 3, j + 1, k + 19, Block.dirt.blockID);
		world.setBlock(i + 3, j + 1, k + 20, Block.dirt.blockID);
		world.setBlock(i + 3, j + 1, k + 21, Block.dirt.blockID);
		world.setBlock(i + 3, j + 1, k + 22, Block.dirt.blockID);
		world.setBlock(i + 3, j + 1, k + 23, Block.dirt.blockID);
		world.setBlock(i + 3, j + 1, k + 24, Block.dirt.blockID);
		world.setBlock(i + 3, j + 1, k + 25, Block.dirt.blockID);
		world.setBlock(i + 3, j + 1, k + 26, Block.dirt.blockID);
		world.setBlock(i + 3, j + 1, k + 27, Block.dirt.blockID);
		world.setBlock(i + 3, j + 1, k + 28, Block.dirt.blockID);
		world.setBlock(i + 3, j + 1, k + 29, Block.dirt.blockID);
		world.setBlock(i + 3, j + 1, k + 30, Block.dirt.blockID);
		world.setBlock(i + 3, j + 1, k + 31, Block.dirt.blockID);
		world.setBlock(i + 3, j + 1, k + 32, Block.dirt.blockID);
		world.setBlock(i + 3, j + 1, k + 33, Block.dirt.blockID);
		world.setBlock(i + 3, j + 1, k + 34, Block.dirt.blockID);
		world.setBlock(i + 3, j + 1, k + 35, Block.dirt.blockID);
		world.setBlock(i + 3, j + 1, k + 36, Block.dirt.blockID);
		world.setBlock(i + 3, j + 1, k + 37, Block.dirt.blockID);
		world.setBlock(i + 3, j + 1, k + 38, Block.dirt.blockID);
		world.setBlock(i + 3, j + 1, k + 39, Block.dirt.blockID);
		world.setBlock(i + 3, j + 1, k + 40, Block.dirt.blockID);
		world.setBlock(i + 3, j + 1, k + 41, Block.dirt.blockID);
		world.setBlock(i + 3, j + 1, k + 42, Block.dirt.blockID);
		world.setBlock(i + 3, j + 1, k + 43, Block.dirt.blockID);
		world.setBlock(i + 3, j + 1, k + 44, Block.dirt.blockID);
		world.setBlock(i + 3, j + 2, k + 0, Block.dirt.blockID);
		world.setBlock(i + 3, j + 2, k + 1, Block.dirt.blockID);
		world.setBlock(i + 3, j + 2, k + 2, Block.dirt.blockID);
		world.setBlock(i + 3, j + 2, k + 3, Block.dirt.blockID);
		world.setBlock(i + 3, j + 2, k + 4, Block.dirt.blockID);
		world.setBlock(i + 3, j + 2, k + 5, Block.dirt.blockID);
		world.setBlock(i + 3, j + 2, k + 6, Block.dirt.blockID);
		world.setBlock(i + 3, j + 2, k + 7, Block.dirt.blockID);
		world.setBlock(i + 3, j + 2, k + 8, Block.dirt.blockID);
		world.setBlock(i + 3, j + 2, k + 9, Block.dirt.blockID);
		world.setBlock(i + 3, j + 2, k + 10, Block.dirt.blockID);
		world.setBlock(i + 3, j + 2, k + 11, Block.dirt.blockID);
		world.setBlock(i + 3, j + 2, k + 12, Block.dirt.blockID);
		world.setBlock(i + 3, j + 2, k + 13, Block.dirt.blockID);
		world.setBlock(i + 3, j + 2, k + 14, Block.dirt.blockID);
		world.setBlock(i + 3, j + 2, k + 15, Block.dirt.blockID);
		world.setBlock(i + 3, j + 2, k + 16, Block.dirt.blockID);
		world.setBlock(i + 3, j + 2, k + 17, Block.dirt.blockID);
		world.setBlock(i + 3, j + 2, k + 18, Block.dirt.blockID);
		world.setBlock(i + 3, j + 2, k + 19, Block.dirt.blockID);
		world.setBlock(i + 3, j + 2, k + 20, Block.dirt.blockID);
		world.setBlock(i + 3, j + 2, k + 21, Block.dirt.blockID);
		world.setBlock(i + 3, j + 2, k + 22, Block.dirt.blockID);
		world.setBlock(i + 3, j + 2, k + 23, Block.dirt.blockID);
		world.setBlock(i + 3, j + 2, k + 24, Block.dirt.blockID);
		world.setBlock(i + 3, j + 2, k + 25, Block.dirt.blockID);
		world.setBlock(i + 3, j + 2, k + 26, Block.dirt.blockID);
		world.setBlock(i + 3, j + 2, k + 27, Block.dirt.blockID);
		world.setBlock(i + 3, j + 2, k + 28, Block.dirt.blockID);
		world.setBlock(i + 3, j + 2, k + 29, Block.dirt.blockID);
		world.setBlock(i + 3, j + 2, k + 30, Block.dirt.blockID);
		world.setBlock(i + 3, j + 2, k + 31, Block.dirt.blockID);
		world.setBlock(i + 3, j + 2, k + 32, Block.dirt.blockID);
		world.setBlock(i + 3, j + 2, k + 33, Block.dirt.blockID);
		world.setBlock(i + 3, j + 2, k + 34, Block.dirt.blockID);
		world.setBlock(i + 3, j + 2, k + 35, Block.dirt.blockID);
		world.setBlock(i + 3, j + 2, k + 36, Block.dirt.blockID);
		world.setBlock(i + 3, j + 2, k + 37, Block.dirt.blockID);
		world.setBlock(i + 3, j + 2, k + 38, Block.dirt.blockID);
		world.setBlock(i + 3, j + 2, k + 39, Block.dirt.blockID);
		world.setBlock(i + 3, j + 2, k + 40, Block.dirt.blockID);
		world.setBlock(i + 3, j + 2, k + 41, Block.dirt.blockID);
		world.setBlock(i + 3, j + 2, k + 42, Block.dirt.blockID);
		world.setBlock(i + 3, j + 2, k + 43, Block.dirt.blockID);
		world.setBlock(i + 3, j + 2, k + 44, Block.dirt.blockID);
		world.setBlock(i + 3, j + 3, k + 0, Block.grass.blockID);
		world.setBlock(i + 3, j + 3, k + 1, Block.grass.blockID);
		world.setBlock(i + 3, j + 3, k + 2, Block.grass.blockID);
		world.setBlock(i + 3, j + 3, k + 3, Block.grass.blockID);
		world.setBlock(i + 3, j + 3, k + 4, Block.grass.blockID);
		world.setBlock(i + 3, j + 3, k + 5, Block.grass.blockID);
		world.setBlock(i + 3, j + 3, k + 6, Block.grass.blockID);
		world.setBlock(i + 3, j + 3, k + 7, Block.grass.blockID);
		world.setBlock(i + 3, j + 3, k + 8, Block.grass.blockID);
		world.setBlock(i + 3, j + 3, k + 9, Block.grass.blockID);
		world.setBlock(i + 3, j + 3, k + 10, Block.grass.blockID);
		world.setBlock(i + 3, j + 3, k + 11, Block.grass.blockID);
		world.setBlock(i + 3, j + 3, k + 12, Block.grass.blockID);
		world.setBlock(i + 3, j + 3, k + 13, Block.grass.blockID);
		world.setBlock(i + 3, j + 3, k + 14, Block.grass.blockID);
		world.setBlock(i + 3, j + 3, k + 15, Block.grass.blockID);
		world.setBlock(i + 3, j + 3, k + 16, Block.grass.blockID);
		world.setBlock(i + 3, j + 3, k + 17, Block.grass.blockID);
		world.setBlock(i + 3, j + 3, k + 18, Block.grass.blockID);
		world.setBlock(i + 3, j + 3, k + 19, Block.grass.blockID);
		world.setBlock(i + 3, j + 3, k + 20, Block.grass.blockID);
		world.setBlock(i + 3, j + 3, k + 21, Block.grass.blockID);
		world.setBlock(i + 3, j + 3, k + 22, Block.grass.blockID);
		world.setBlock(i + 3, j + 3, k + 23, Block.grass.blockID);
		world.setBlock(i + 3, j + 3, k + 24, Block.grass.blockID);
		world.setBlock(i + 3, j + 3, k + 25, Block.grass.blockID);
		world.setBlock(i + 3, j + 3, k + 26, Block.grass.blockID);
		world.setBlock(i + 3, j + 3, k + 27, Block.grass.blockID);
		world.setBlock(i + 3, j + 3, k + 28, Block.grass.blockID);
		world.setBlock(i + 3, j + 3, k + 29, Block.grass.blockID);
		world.setBlock(i + 3, j + 3, k + 30, Block.grass.blockID);
		world.setBlock(i + 3, j + 3, k + 31, Block.grass.blockID);
		world.setBlock(i + 3, j + 3, k + 32, Block.grass.blockID);
		world.setBlock(i + 3, j + 3, k + 33, Block.grass.blockID);
		world.setBlock(i + 3, j + 3, k + 34, Block.grass.blockID);
		world.setBlock(i + 3, j + 3, k + 35, Block.grass.blockID);
		world.setBlock(i + 3, j + 3, k + 36, Block.grass.blockID);
		world.setBlock(i + 3, j + 3, k + 37, Block.grass.blockID);
		world.setBlock(i + 3, j + 3, k + 38, Block.grass.blockID);
		world.setBlock(i + 3, j + 3, k + 39, Block.grass.blockID);
		world.setBlock(i + 3, j + 3, k + 40, Block.grass.blockID);
		world.setBlock(i + 3, j + 3, k + 41, Block.grass.blockID);
		world.setBlock(i + 3, j + 3, k + 42, Block.grass.blockID);
		world.setBlock(i + 3, j + 3, k + 43, Block.grass.blockID);
		world.setBlock(i + 3, j + 3, k + 44, Block.grass.blockID);
		world.setBlock(i + 4, j + 0, k + 0, Block.bedrock.blockID);
		world.setBlock(i + 4, j + 0, k + 1, Block.bedrock.blockID);
		world.setBlock(i + 4, j + 0, k + 2, Block.bedrock.blockID);
		world.setBlock(i + 4, j + 0, k + 3, Block.bedrock.blockID);
		world.setBlock(i + 4, j + 0, k + 4, Block.bedrock.blockID);
		world.setBlock(i + 4, j + 0, k + 5, Block.bedrock.blockID);
		world.setBlock(i + 4, j + 0, k + 6, Block.bedrock.blockID);
		world.setBlock(i + 4, j + 0, k + 7, Block.bedrock.blockID);
		world.setBlock(i + 4, j + 0, k + 8, Block.bedrock.blockID);
		world.setBlock(i + 4, j + 0, k + 9, Block.bedrock.blockID);
		world.setBlock(i + 4, j + 0, k + 10, Block.bedrock.blockID);
		world.setBlock(i + 4, j + 0, k + 11, Block.bedrock.blockID);
		world.setBlock(i + 4, j + 0, k + 12, Block.bedrock.blockID);
		world.setBlock(i + 4, j + 0, k + 13, Block.bedrock.blockID);
		world.setBlock(i + 4, j + 0, k + 14, Block.bedrock.blockID);
		world.setBlock(i + 4, j + 0, k + 15, Block.bedrock.blockID);
		world.setBlock(i + 4, j + 0, k + 16, Block.bedrock.blockID);
		world.setBlock(i + 4, j + 0, k + 17, Block.bedrock.blockID);
		world.setBlock(i + 4, j + 0, k + 18, Block.bedrock.blockID);
		world.setBlock(i + 4, j + 0, k + 19, Block.bedrock.blockID);
		world.setBlock(i + 4, j + 0, k + 20, Block.bedrock.blockID);
		world.setBlock(i + 4, j + 0, k + 21, Block.bedrock.blockID);
		world.setBlock(i + 4, j + 0, k + 22, Block.bedrock.blockID);
		world.setBlock(i + 4, j + 0, k + 23, Block.bedrock.blockID);
		world.setBlock(i + 4, j + 0, k + 24, Block.bedrock.blockID);
		world.setBlock(i + 4, j + 0, k + 25, Block.bedrock.blockID);
		world.setBlock(i + 4, j + 0, k + 26, Block.bedrock.blockID);
		world.setBlock(i + 4, j + 0, k + 27, Block.bedrock.blockID);
		world.setBlock(i + 4, j + 0, k + 28, Block.bedrock.blockID);
		world.setBlock(i + 4, j + 0, k + 29, Block.bedrock.blockID);
		world.setBlock(i + 4, j + 0, k + 30, Block.bedrock.blockID);
		world.setBlock(i + 4, j + 0, k + 31, Block.bedrock.blockID);
		world.setBlock(i + 4, j + 0, k + 32, Block.bedrock.blockID);
		world.setBlock(i + 4, j + 0, k + 33, Block.bedrock.blockID);
		world.setBlock(i + 4, j + 0, k + 34, Block.bedrock.blockID);
		world.setBlock(i + 4, j + 0, k + 35, Block.bedrock.blockID);
		world.setBlock(i + 4, j + 0, k + 36, Block.bedrock.blockID);
		world.setBlock(i + 4, j + 0, k + 37, Block.bedrock.blockID);
		world.setBlock(i + 4, j + 0, k + 38, Block.bedrock.blockID);
		world.setBlock(i + 4, j + 0, k + 39, Block.bedrock.blockID);
		world.setBlock(i + 4, j + 0, k + 40, Block.bedrock.blockID);
		world.setBlock(i + 4, j + 0, k + 41, Block.bedrock.blockID);
		world.setBlock(i + 4, j + 0, k + 42, Block.bedrock.blockID);
		world.setBlock(i + 4, j + 0, k + 43, Block.bedrock.blockID);
		world.setBlock(i + 4, j + 0, k + 44, Block.bedrock.blockID);
		world.setBlock(i + 4, j + 1, k + 0, Block.dirt.blockID);
		world.setBlock(i + 4, j + 1, k + 1, Block.dirt.blockID);
		world.setBlock(i + 4, j + 1, k + 2, Block.dirt.blockID);
		world.setBlock(i + 4, j + 1, k + 3, Block.dirt.blockID);
		world.setBlock(i + 4, j + 1, k + 4, Block.dirt.blockID);
		world.setBlock(i + 4, j + 1, k + 5, Block.dirt.blockID);
		world.setBlock(i + 4, j + 1, k + 6, Block.dirt.blockID);
		world.setBlock(i + 4, j + 1, k + 7, Block.dirt.blockID);
		world.setBlock(i + 4, j + 1, k + 8, Block.dirt.blockID);
		world.setBlock(i + 4, j + 1, k + 9, Block.dirt.blockID);
		world.setBlock(i + 4, j + 1, k + 10, Block.dirt.blockID);
		world.setBlock(i + 4, j + 1, k + 11, Block.dirt.blockID);
		world.setBlock(i + 4, j + 1, k + 12, Block.dirt.blockID);
		world.setBlock(i + 4, j + 1, k + 13, Block.dirt.blockID);
		world.setBlock(i + 4, j + 1, k + 14, Block.dirt.blockID);
		world.setBlock(i + 4, j + 1, k + 15, Block.dirt.blockID);
		world.setBlock(i + 4, j + 1, k + 16, Block.dirt.blockID);
		world.setBlock(i + 4, j + 1, k + 17, Block.dirt.blockID);
		world.setBlock(i + 4, j + 1, k + 18, Block.dirt.blockID);
		world.setBlock(i + 4, j + 1, k + 19, Block.dirt.blockID);
		world.setBlock(i + 4, j + 1, k + 20, Block.dirt.blockID);
		world.setBlock(i + 4, j + 1, k + 21, Block.dirt.blockID);
		world.setBlock(i + 4, j + 1, k + 22, Block.dirt.blockID);
		world.setBlock(i + 4, j + 1, k + 23, Block.dirt.blockID);
		world.setBlock(i + 4, j + 1, k + 24, Block.dirt.blockID);
		world.setBlock(i + 4, j + 1, k + 25, Block.dirt.blockID);
		world.setBlock(i + 4, j + 1, k + 26, Block.dirt.blockID);
		world.setBlock(i + 4, j + 1, k + 27, Block.dirt.blockID);
		world.setBlock(i + 4, j + 1, k + 28, Block.dirt.blockID);
		world.setBlock(i + 4, j + 1, k + 29, Block.dirt.blockID);
		world.setBlock(i + 4, j + 1, k + 30, Block.dirt.blockID);
		world.setBlock(i + 4, j + 1, k + 31, Block.dirt.blockID);
		world.setBlock(i + 4, j + 1, k + 32, Block.dirt.blockID);
		world.setBlock(i + 4, j + 1, k + 33, Block.dirt.blockID);
		world.setBlock(i + 4, j + 1, k + 34, Block.dirt.blockID);
		world.setBlock(i + 4, j + 1, k + 35, Block.dirt.blockID);
		world.setBlock(i + 4, j + 1, k + 36, Block.dirt.blockID);
		world.setBlock(i + 4, j + 1, k + 37, Block.dirt.blockID);
		world.setBlock(i + 4, j + 1, k + 38, Block.dirt.blockID);
		world.setBlock(i + 4, j + 1, k + 39, Block.dirt.blockID);
		world.setBlock(i + 4, j + 1, k + 40, Block.dirt.blockID);
		world.setBlock(i + 4, j + 1, k + 41, Block.dirt.blockID);
		world.setBlock(i + 4, j + 1, k + 42, Block.dirt.blockID);
		world.setBlock(i + 4, j + 1, k + 43, Block.dirt.blockID);
		world.setBlock(i + 4, j + 1, k + 44, Block.dirt.blockID);
		world.setBlock(i + 4, j + 2, k + 0, Block.dirt.blockID);
		world.setBlock(i + 4, j + 2, k + 1, Block.dirt.blockID);
		world.setBlock(i + 4, j + 2, k + 2, Block.dirt.blockID);
		world.setBlock(i + 4, j + 2, k + 3, Block.dirt.blockID);
		world.setBlock(i + 4, j + 2, k + 4, Block.dirt.blockID);
		world.setBlock(i + 4, j + 2, k + 5, Block.dirt.blockID);
		world.setBlock(i + 4, j + 2, k + 6, Block.dirt.blockID);
		world.setBlock(i + 4, j + 2, k + 7, Block.dirt.blockID);
		world.setBlock(i + 4, j + 2, k + 8, Block.dirt.blockID);
		world.setBlock(i + 4, j + 2, k + 9, Block.dirt.blockID);
		world.setBlock(i + 4, j + 2, k + 10, Block.dirt.blockID);
		world.setBlock(i + 4, j + 2, k + 11, Block.dirt.blockID);
		world.setBlock(i + 4, j + 2, k + 12, Block.dirt.blockID);
		world.setBlock(i + 4, j + 2, k + 13, Block.dirt.blockID);
		world.setBlock(i + 4, j + 2, k + 14, Block.dirt.blockID);
		world.setBlock(i + 4, j + 2, k + 15, Block.dirt.blockID);
		world.setBlock(i + 4, j + 2, k + 16, Block.dirt.blockID);
		world.setBlock(i + 4, j + 2, k + 17, Block.dirt.blockID);
		world.setBlock(i + 4, j + 2, k + 18, Block.dirt.blockID);
		world.setBlock(i + 4, j + 2, k + 19, Block.dirt.blockID);
		world.setBlock(i + 4, j + 2, k + 20, Block.dirt.blockID);
		world.setBlock(i + 4, j + 2, k + 21, Block.dirt.blockID);
		world.setBlock(i + 4, j + 2, k + 22, Block.dirt.blockID);
		world.setBlock(i + 4, j + 2, k + 23, Block.dirt.blockID);
		world.setBlock(i + 4, j + 2, k + 24, Block.dirt.blockID);
		world.setBlock(i + 4, j + 2, k + 25, Block.dirt.blockID);
		world.setBlock(i + 4, j + 2, k + 26, Block.dirt.blockID);
		world.setBlock(i + 4, j + 2, k + 27, Block.dirt.blockID);
		world.setBlock(i + 4, j + 2, k + 28, Block.dirt.blockID);
		world.setBlock(i + 4, j + 2, k + 29, Block.dirt.blockID);
		world.setBlock(i + 4, j + 2, k + 30, Block.dirt.blockID);
		world.setBlock(i + 4, j + 2, k + 31, Block.dirt.blockID);
		world.setBlock(i + 4, j + 2, k + 32, Block.dirt.blockID);
		world.setBlock(i + 4, j + 2, k + 33, Block.dirt.blockID);
		world.setBlock(i + 4, j + 2, k + 34, Block.dirt.blockID);
		world.setBlock(i + 4, j + 2, k + 35, Block.dirt.blockID);
		world.setBlock(i + 4, j + 2, k + 36, Block.dirt.blockID);
		world.setBlock(i + 4, j + 2, k + 37, Block.dirt.blockID);
		world.setBlock(i + 4, j + 2, k + 38, Block.dirt.blockID);
		world.setBlock(i + 4, j + 2, k + 39, Block.dirt.blockID);
		world.setBlock(i + 4, j + 2, k + 40, Block.dirt.blockID);
		world.setBlock(i + 4, j + 2, k + 41, Block.dirt.blockID);
		world.setBlock(i + 4, j + 2, k + 42, Block.dirt.blockID);
		world.setBlock(i + 4, j + 2, k + 43, Block.dirt.blockID);
		world.setBlock(i + 4, j + 2, k + 44, Block.dirt.blockID);
		world.setBlock(i + 4, j + 3, k + 0, Block.grass.blockID);
		world.setBlock(i + 4, j + 3, k + 1, Block.grass.blockID);
		world.setBlock(i + 4, j + 3, k + 2, Block.grass.blockID);
		world.setBlock(i + 4, j + 3, k + 3, Block.grass.blockID);
		world.setBlock(i + 4, j + 3, k + 4, Block.grass.blockID);
		world.setBlock(i + 4, j + 3, k + 5, Block.grass.blockID);
		world.setBlock(i + 4, j + 3, k + 6, Block.grass.blockID);
		world.setBlock(i + 4, j + 3, k + 7, Block.grass.blockID);
		world.setBlock(i + 4, j + 3, k + 8, Block.grass.blockID);
		world.setBlock(i + 4, j + 3, k + 9, Block.grass.blockID);
		world.setBlock(i + 4, j + 3, k + 10, Block.grass.blockID);
		world.setBlock(i + 4, j + 3, k + 11, Block.grass.blockID);
		world.setBlock(i + 4, j + 3, k + 12, Block.grass.blockID);
		world.setBlock(i + 4, j + 3, k + 13, Block.grass.blockID);
		world.setBlock(i + 4, j + 3, k + 14, Block.grass.blockID);
		world.setBlock(i + 4, j + 3, k + 15, Block.grass.blockID);
		world.setBlock(i + 4, j + 3, k + 16, Block.grass.blockID);
		world.setBlock(i + 4, j + 3, k + 17, Block.grass.blockID);
		world.setBlock(i + 4, j + 3, k + 18, Block.grass.blockID);
		world.setBlock(i + 4, j + 3, k + 19, Block.grass.blockID);
		world.setBlock(i + 4, j + 3, k + 20, Block.grass.blockID);
		world.setBlock(i + 4, j + 3, k + 21, Block.grass.blockID);
		world.setBlock(i + 4, j + 3, k + 22, Block.grass.blockID);
		world.setBlock(i + 4, j + 3, k + 23, Block.grass.blockID);
		world.setBlock(i + 4, j + 3, k + 24, Block.grass.blockID);
		world.setBlock(i + 4, j + 3, k + 25, Block.grass.blockID);
		world.setBlock(i + 4, j + 3, k + 26, Block.grass.blockID);
		world.setBlock(i + 4, j + 3, k + 27, Block.grass.blockID);
		world.setBlock(i + 4, j + 3, k + 28, Block.grass.blockID);
		world.setBlock(i + 4, j + 3, k + 29, Block.grass.blockID);
		world.setBlock(i + 4, j + 3, k + 30, Block.grass.blockID);
		world.setBlock(i + 4, j + 3, k + 31, Block.grass.blockID);
		world.setBlock(i + 4, j + 3, k + 32, Block.grass.blockID);
		world.setBlock(i + 4, j + 3, k + 33, Block.grass.blockID);
		world.setBlock(i + 4, j + 3, k + 34, Block.grass.blockID);
		world.setBlock(i + 4, j + 3, k + 35, Block.grass.blockID);
		world.setBlock(i + 4, j + 3, k + 36, Block.grass.blockID);
		world.setBlock(i + 4, j + 3, k + 37, Block.grass.blockID);
		world.setBlock(i + 4, j + 3, k + 38, Block.grass.blockID);
		world.setBlock(i + 4, j + 3, k + 39, Block.grass.blockID);
		world.setBlock(i + 4, j + 3, k + 40, Block.grass.blockID);
		world.setBlock(i + 4, j + 3, k + 41, Block.grass.blockID);
		world.setBlock(i + 4, j + 3, k + 42, Block.grass.blockID);
		world.setBlock(i + 4, j + 3, k + 43, Block.grass.blockID);
		world.setBlock(i + 4, j + 3, k + 44, Block.grass.blockID);
		world.setBlock(i + 5, j + 0, k + 0, Block.bedrock.blockID);
		world.setBlock(i + 5, j + 0, k + 1, Block.bedrock.blockID);
		world.setBlock(i + 5, j + 0, k + 2, Block.bedrock.blockID);
		world.setBlock(i + 5, j + 0, k + 3, Block.bedrock.blockID);
		world.setBlock(i + 5, j + 0, k + 4, Block.bedrock.blockID);
		world.setBlock(i + 5, j + 0, k + 5, Block.bedrock.blockID);
		world.setBlock(i + 5, j + 0, k + 6, Block.bedrock.blockID);
		world.setBlock(i + 5, j + 0, k + 7, Block.bedrock.blockID);
		world.setBlock(i + 5, j + 0, k + 8, Block.bedrock.blockID);
		world.setBlock(i + 5, j + 0, k + 9, Block.bedrock.blockID);
		world.setBlock(i + 5, j + 0, k + 10, Block.bedrock.blockID);
		world.setBlock(i + 5, j + 0, k + 11, Block.bedrock.blockID);
		world.setBlock(i + 5, j + 0, k + 12, Block.bedrock.blockID);
		world.setBlock(i + 5, j + 0, k + 13, Block.bedrock.blockID);
		world.setBlock(i + 5, j + 0, k + 14, Block.bedrock.blockID);
		world.setBlock(i + 5, j + 0, k + 15, Block.bedrock.blockID);
		world.setBlock(i + 5, j + 0, k + 16, Block.bedrock.blockID);
		world.setBlock(i + 5, j + 0, k + 17, Block.bedrock.blockID);
		world.setBlock(i + 5, j + 0, k + 18, Block.bedrock.blockID);
		world.setBlock(i + 5, j + 0, k + 19, Block.bedrock.blockID);
		world.setBlock(i + 5, j + 0, k + 20, Block.bedrock.blockID);
		world.setBlock(i + 5, j + 0, k + 21, Block.bedrock.blockID);
		world.setBlock(i + 5, j + 0, k + 22, Block.bedrock.blockID);
		world.setBlock(i + 5, j + 0, k + 23, Block.bedrock.blockID);
		world.setBlock(i + 5, j + 0, k + 24, Block.bedrock.blockID);
		world.setBlock(i + 5, j + 0, k + 25, Block.bedrock.blockID);
		world.setBlock(i + 5, j + 0, k + 26, Block.bedrock.blockID);
		world.setBlock(i + 5, j + 0, k + 27, Block.bedrock.blockID);
		world.setBlock(i + 5, j + 0, k + 28, Block.bedrock.blockID);
		world.setBlock(i + 5, j + 0, k + 29, Block.bedrock.blockID);
		world.setBlock(i + 5, j + 0, k + 30, Block.bedrock.blockID);
		world.setBlock(i + 5, j + 0, k + 31, Block.bedrock.blockID);
		world.setBlock(i + 5, j + 0, k + 32, Block.bedrock.blockID);
		world.setBlock(i + 5, j + 0, k + 33, Block.bedrock.blockID);
		world.setBlock(i + 5, j + 0, k + 34, Block.bedrock.blockID);
		world.setBlock(i + 5, j + 0, k + 35, Block.bedrock.blockID);
		world.setBlock(i + 5, j + 0, k + 36, Block.bedrock.blockID);
		world.setBlock(i + 5, j + 0, k + 37, Block.bedrock.blockID);
		world.setBlock(i + 5, j + 0, k + 38, Block.bedrock.blockID);
		world.setBlock(i + 5, j + 0, k + 39, Block.bedrock.blockID);
		world.setBlock(i + 5, j + 0, k + 40, Block.bedrock.blockID);
		world.setBlock(i + 5, j + 0, k + 41, Block.bedrock.blockID);
		world.setBlock(i + 5, j + 0, k + 42, Block.bedrock.blockID);
		world.setBlock(i + 5, j + 0, k + 43, Block.bedrock.blockID);
		world.setBlock(i + 5, j + 0, k + 44, Block.bedrock.blockID);
		world.setBlock(i + 5, j + 1, k + 0, Block.dirt.blockID);
		world.setBlock(i + 5, j + 1, k + 1, Block.dirt.blockID);
		world.setBlock(i + 5, j + 1, k + 2, Block.dirt.blockID);
		world.setBlock(i + 5, j + 1, k + 3, Block.dirt.blockID);
		world.setBlock(i + 5, j + 1, k + 4, Block.dirt.blockID);
		world.setBlock(i + 5, j + 1, k + 5, Block.dirt.blockID);
		world.setBlock(i + 5, j + 1, k + 6, Block.dirt.blockID);
		world.setBlock(i + 5, j + 1, k + 7, Block.dirt.blockID);
		world.setBlock(i + 5, j + 1, k + 8, Block.dirt.blockID);
		world.setBlock(i + 5, j + 1, k + 9, Block.dirt.blockID);
		world.setBlock(i + 5, j + 1, k + 10, Block.dirt.blockID);
		world.setBlock(i + 5, j + 1, k + 11, Block.dirt.blockID);
		world.setBlock(i + 5, j + 1, k + 12, Block.dirt.blockID);
		world.setBlock(i + 5, j + 1, k + 13, Block.dirt.blockID);
		world.setBlock(i + 5, j + 1, k + 14, Block.dirt.blockID);
		world.setBlock(i + 5, j + 1, k + 15, Block.dirt.blockID);
		world.setBlock(i + 5, j + 1, k + 16, Block.dirt.blockID);
		world.setBlock(i + 5, j + 1, k + 17, Block.dirt.blockID);
		world.setBlock(i + 5, j + 1, k + 18, Block.dirt.blockID);
		world.setBlock(i + 5, j + 1, k + 19, Block.dirt.blockID);
		world.setBlock(i + 5, j + 1, k + 20, Block.dirt.blockID);
		world.setBlock(i + 5, j + 1, k + 21, Block.dirt.blockID);
		world.setBlock(i + 5, j + 1, k + 22, Block.dirt.blockID);
		world.setBlock(i + 5, j + 1, k + 23, Block.dirt.blockID);
		world.setBlock(i + 5, j + 1, k + 24, Block.dirt.blockID);
		world.setBlock(i + 5, j + 1, k + 25, Block.dirt.blockID);
		world.setBlock(i + 5, j + 1, k + 26, Block.dirt.blockID);
		world.setBlock(i + 5, j + 1, k + 27, Block.dirt.blockID);
		world.setBlock(i + 5, j + 1, k + 28, Block.dirt.blockID);
		world.setBlock(i + 5, j + 1, k + 29, Block.dirt.blockID);
		world.setBlock(i + 5, j + 1, k + 30, Block.dirt.blockID);
		world.setBlock(i + 5, j + 1, k + 31, Block.dirt.blockID);
		world.setBlock(i + 5, j + 1, k + 32, Block.dirt.blockID);
		world.setBlock(i + 5, j + 1, k + 33, Block.dirt.blockID);
		world.setBlock(i + 5, j + 1, k + 34, Block.dirt.blockID);
		world.setBlock(i + 5, j + 1, k + 35, Block.dirt.blockID);
		world.setBlock(i + 5, j + 1, k + 36, Block.dirt.blockID);
		world.setBlock(i + 5, j + 1, k + 37, Block.dirt.blockID);
		world.setBlock(i + 5, j + 1, k + 38, Block.dirt.blockID);
		world.setBlock(i + 5, j + 1, k + 39, Block.dirt.blockID);
		world.setBlock(i + 5, j + 1, k + 40, Block.dirt.blockID);
		world.setBlock(i + 5, j + 1, k + 41, Block.dirt.blockID);
		world.setBlock(i + 5, j + 1, k + 42, Block.dirt.blockID);
		world.setBlock(i + 5, j + 1, k + 43, Block.dirt.blockID);
		world.setBlock(i + 5, j + 1, k + 44, Block.dirt.blockID);
		world.setBlock(i + 5, j + 2, k + 0, Block.dirt.blockID);
		world.setBlock(i + 5, j + 2, k + 1, Block.dirt.blockID);
		world.setBlock(i + 5, j + 2, k + 2, Block.dirt.blockID);
		world.setBlock(i + 5, j + 2, k + 3, Block.dirt.blockID);
		world.setBlock(i + 5, j + 2, k + 4, Block.dirt.blockID);
		world.setBlock(i + 5, j + 2, k + 5, Block.dirt.blockID);
		world.setBlock(i + 5, j + 2, k + 6, Block.dirt.blockID);
		world.setBlock(i + 5, j + 2, k + 7, Block.dirt.blockID);
		world.setBlock(i + 5, j + 2, k + 8, Block.dirt.blockID);
		world.setBlock(i + 5, j + 2, k + 9, Block.dirt.blockID);
		world.setBlock(i + 5, j + 2, k + 10, Block.dirt.blockID);
		world.setBlock(i + 5, j + 2, k + 11, Block.dirt.blockID);
		world.setBlock(i + 5, j + 2, k + 12, Block.dirt.blockID);
		world.setBlock(i + 5, j + 2, k + 13, Block.dirt.blockID);
		world.setBlock(i + 5, j + 2, k + 14, Block.dirt.blockID);
		world.setBlock(i + 5, j + 2, k + 15, Block.dirt.blockID);
		world.setBlock(i + 5, j + 2, k + 16, Block.dirt.blockID);
		world.setBlock(i + 5, j + 2, k + 17, Block.dirt.blockID);
		world.setBlock(i + 5, j + 2, k + 18, Block.dirt.blockID);
		world.setBlock(i + 5, j + 2, k + 19, Block.dirt.blockID);
		world.setBlock(i + 5, j + 2, k + 20, Block.dirt.blockID);
		world.setBlock(i + 5, j + 2, k + 21, Block.dirt.blockID);
		world.setBlock(i + 5, j + 2, k + 22, Block.dirt.blockID);
		world.setBlock(i + 5, j + 2, k + 23, Block.dirt.blockID);
		world.setBlock(i + 5, j + 2, k + 24, Block.dirt.blockID);
		world.setBlock(i + 5, j + 2, k + 25, Block.dirt.blockID);
		world.setBlock(i + 5, j + 2, k + 26, Block.dirt.blockID);
		world.setBlock(i + 5, j + 2, k + 27, Block.dirt.blockID);
		world.setBlock(i + 5, j + 2, k + 28, Block.dirt.blockID);
		world.setBlock(i + 5, j + 2, k + 29, Block.dirt.blockID);
		world.setBlock(i + 5, j + 2, k + 30, Block.dirt.blockID);
		world.setBlock(i + 5, j + 2, k + 31, Block.dirt.blockID);
		world.setBlock(i + 5, j + 2, k + 32, Block.dirt.blockID);
		world.setBlock(i + 5, j + 2, k + 33, Block.dirt.blockID);
		world.setBlock(i + 5, j + 2, k + 34, Block.dirt.blockID);
		world.setBlock(i + 5, j + 2, k + 35, Block.dirt.blockID);
		world.setBlock(i + 5, j + 2, k + 36, Block.dirt.blockID);
		world.setBlock(i + 5, j + 2, k + 37, Block.dirt.blockID);
		world.setBlock(i + 5, j + 2, k + 38, Block.dirt.blockID);
		world.setBlock(i + 5, j + 2, k + 39, Block.dirt.blockID);
		world.setBlock(i + 5, j + 2, k + 40, Block.dirt.blockID);
		world.setBlock(i + 5, j + 2, k + 41, Block.dirt.blockID);
		world.setBlock(i + 5, j + 2, k + 42, Block.dirt.blockID);
		world.setBlock(i + 5, j + 2, k + 43, Block.dirt.blockID);
		world.setBlock(i + 5, j + 2, k + 44, Block.dirt.blockID);
		world.setBlock(i + 5, j + 3, k + 0, Block.grass.blockID);
		world.setBlock(i + 5, j + 3, k + 1, Block.grass.blockID);
		world.setBlock(i + 5, j + 3, k + 2, Block.grass.blockID);
		world.setBlock(i + 5, j + 3, k + 3, Block.grass.blockID);
		world.setBlock(i + 5, j + 3, k + 4, Block.grass.blockID);
		world.setBlock(i + 5, j + 3, k + 5, Block.grass.blockID);
		world.setBlock(i + 5, j + 3, k + 6, Block.grass.blockID);
		world.setBlock(i + 5, j + 3, k + 7, Block.grass.blockID);
		world.setBlock(i + 5, j + 3, k + 8, Block.grass.blockID);
		world.setBlock(i + 5, j + 3, k + 9, Block.grass.blockID);
		world.setBlock(i + 5, j + 3, k + 10, Block.grass.blockID);
		world.setBlock(i + 5, j + 3, k + 11, Block.grass.blockID);
		world.setBlock(i + 5, j + 3, k + 12, Block.grass.blockID);
		world.setBlock(i + 5, j + 3, k + 13, Block.grass.blockID);
		world.setBlock(i + 5, j + 3, k + 14, Block.grass.blockID);
		world.setBlock(i + 5, j + 3, k + 15, Block.grass.blockID);
		world.setBlock(i + 5, j + 3, k + 16, Block.grass.blockID);
		world.setBlock(i + 5, j + 3, k + 17, Block.grass.blockID);
		world.setBlock(i + 5, j + 3, k + 18, Block.grass.blockID);
		world.setBlock(i + 5, j + 3, k + 19, Block.grass.blockID);
		world.setBlock(i + 5, j + 3, k + 20, Block.grass.blockID);
		world.setBlock(i + 5, j + 3, k + 21, Block.grass.blockID);
		world.setBlock(i + 5, j + 3, k + 22, Block.grass.blockID);
		world.setBlock(i + 5, j + 3, k + 23, Block.grass.blockID);
		world.setBlock(i + 5, j + 3, k + 24, Block.grass.blockID);
		world.setBlock(i + 5, j + 3, k + 25, Block.grass.blockID);
		world.setBlock(i + 5, j + 3, k + 26, Block.grass.blockID);
		world.setBlock(i + 5, j + 3, k + 27, Block.grass.blockID);
		world.setBlock(i + 5, j + 3, k + 28, Block.grass.blockID);
		world.setBlock(i + 5, j + 3, k + 29, Block.grass.blockID);
		world.setBlock(i + 5, j + 3, k + 30, Block.grass.blockID);
		world.setBlock(i + 5, j + 3, k + 31, Block.grass.blockID);
		world.setBlock(i + 5, j + 3, k + 32, Block.grass.blockID);
		world.setBlock(i + 5, j + 3, k + 33, Block.grass.blockID);
		world.setBlock(i + 5, j + 3, k + 34, Block.grass.blockID);
		world.setBlock(i + 5, j + 3, k + 35, Block.grass.blockID);
		world.setBlock(i + 5, j + 3, k + 36, Block.grass.blockID);
		world.setBlock(i + 5, j + 3, k + 37, Block.grass.blockID);
		world.setBlock(i + 5, j + 3, k + 38, Block.grass.blockID);
		world.setBlock(i + 5, j + 3, k + 39, Block.grass.blockID);
		world.setBlock(i + 5, j + 3, k + 40, Block.grass.blockID);
		world.setBlock(i + 5, j + 3, k + 41, Block.grass.blockID);
		world.setBlock(i + 5, j + 3, k + 42, Block.grass.blockID);
		world.setBlock(i + 5, j + 3, k + 43, Block.grass.blockID);
		world.setBlock(i + 5, j + 3, k + 44, Block.grass.blockID);
		world.setBlock(i + 6, j + 0, k + 0, Block.bedrock.blockID);
		world.setBlock(i + 6, j + 0, k + 1, Block.bedrock.blockID);
		world.setBlock(i + 6, j + 0, k + 2, Block.bedrock.blockID);
		world.setBlock(i + 6, j + 0, k + 3, Block.bedrock.blockID);
		world.setBlock(i + 6, j + 0, k + 4, Block.bedrock.blockID);
		world.setBlock(i + 6, j + 0, k + 5, Block.bedrock.blockID);
		world.setBlock(i + 6, j + 0, k + 6, Block.bedrock.blockID);
		world.setBlock(i + 6, j + 0, k + 7, Block.bedrock.blockID);
		world.setBlock(i + 6, j + 0, k + 8, Block.bedrock.blockID);
		world.setBlock(i + 6, j + 0, k + 9, Block.bedrock.blockID);
		world.setBlock(i + 6, j + 0, k + 10, Block.bedrock.blockID);
		world.setBlock(i + 6, j + 0, k + 11, Block.bedrock.blockID);
		world.setBlock(i + 6, j + 0, k + 12, Block.bedrock.blockID);
		world.setBlock(i + 6, j + 0, k + 13, Block.bedrock.blockID);
		world.setBlock(i + 6, j + 0, k + 14, Block.bedrock.blockID);
		world.setBlock(i + 6, j + 0, k + 15, Block.bedrock.blockID);
		world.setBlock(i + 6, j + 0, k + 16, Block.bedrock.blockID);
		world.setBlock(i + 6, j + 0, k + 17, Block.bedrock.blockID);
		world.setBlock(i + 6, j + 0, k + 18, Block.bedrock.blockID);
		world.setBlock(i + 6, j + 0, k + 19, Block.bedrock.blockID);
		world.setBlock(i + 6, j + 0, k + 20, Block.bedrock.blockID);
		world.setBlock(i + 6, j + 0, k + 21, Block.bedrock.blockID);
		world.setBlock(i + 6, j + 0, k + 22, Block.bedrock.blockID);
		world.setBlock(i + 6, j + 0, k + 23, Block.bedrock.blockID);
		world.setBlock(i + 6, j + 0, k + 24, Block.bedrock.blockID);
		world.setBlock(i + 6, j + 0, k + 25, Block.bedrock.blockID);
		world.setBlock(i + 6, j + 0, k + 26, Block.bedrock.blockID);
		world.setBlock(i + 6, j + 0, k + 27, Block.bedrock.blockID);
		world.setBlock(i + 6, j + 0, k + 28, Block.bedrock.blockID);
		world.setBlock(i + 6, j + 0, k + 29, Block.bedrock.blockID);
		world.setBlock(i + 6, j + 0, k + 30, Block.bedrock.blockID);
		world.setBlock(i + 6, j + 0, k + 31, Block.bedrock.blockID);
		world.setBlock(i + 6, j + 0, k + 32, Block.bedrock.blockID);
		world.setBlock(i + 6, j + 0, k + 33, Block.bedrock.blockID);
		world.setBlock(i + 6, j + 0, k + 34, Block.bedrock.blockID);
		world.setBlock(i + 6, j + 0, k + 35, Block.bedrock.blockID);
		world.setBlock(i + 6, j + 0, k + 36, Block.bedrock.blockID);
		world.setBlock(i + 6, j + 0, k + 37, Block.bedrock.blockID);
		world.setBlock(i + 6, j + 0, k + 38, Block.bedrock.blockID);
		world.setBlock(i + 6, j + 0, k + 39, Block.bedrock.blockID);
		world.setBlock(i + 6, j + 0, k + 40, Block.bedrock.blockID);
		world.setBlock(i + 6, j + 0, k + 41, Block.bedrock.blockID);
		world.setBlock(i + 6, j + 0, k + 42, Block.bedrock.blockID);
		world.setBlock(i + 6, j + 0, k + 43, Block.bedrock.blockID);
		world.setBlock(i + 6, j + 0, k + 44, Block.bedrock.blockID);
		world.setBlock(i + 6, j + 1, k + 0, Block.dirt.blockID);
		world.setBlock(i + 6, j + 1, k + 1, Block.dirt.blockID);
		world.setBlock(i + 6, j + 1, k + 2, Block.dirt.blockID);
		world.setBlock(i + 6, j + 1, k + 3, Block.dirt.blockID);
		world.setBlock(i + 6, j + 1, k + 4, Block.dirt.blockID);
		world.setBlock(i + 6, j + 1, k + 5, Block.dirt.blockID);
		world.setBlock(i + 6, j + 1, k + 6, Block.dirt.blockID);
		world.setBlock(i + 6, j + 1, k + 7, Block.dirt.blockID);
		world.setBlock(i + 6, j + 1, k + 8, Block.dirt.blockID);
		world.setBlock(i + 6, j + 1, k + 9, Block.dirt.blockID);
		world.setBlock(i + 6, j + 1, k + 10, Block.dirt.blockID);
		world.setBlock(i + 6, j + 1, k + 11, Block.dirt.blockID);
		world.setBlock(i + 6, j + 1, k + 12, Block.dirt.blockID);
		world.setBlock(i + 6, j + 1, k + 13, Block.dirt.blockID);
		world.setBlock(i + 6, j + 1, k + 14, Block.dirt.blockID);
		world.setBlock(i + 6, j + 1, k + 15, Block.dirt.blockID);
		world.setBlock(i + 6, j + 1, k + 16, Block.dirt.blockID);
		world.setBlock(i + 6, j + 1, k + 17, Block.dirt.blockID);
		world.setBlock(i + 6, j + 1, k + 18, Block.dirt.blockID);
		world.setBlock(i + 6, j + 1, k + 19, Block.dirt.blockID);
		world.setBlock(i + 6, j + 1, k + 20, Block.dirt.blockID);
		world.setBlock(i + 6, j + 1, k + 21, Block.dirt.blockID);
		world.setBlock(i + 6, j + 1, k + 22, Block.dirt.blockID);
		world.setBlock(i + 6, j + 1, k + 23, Block.dirt.blockID);
		world.setBlock(i + 6, j + 1, k + 24, Block.dirt.blockID);
		world.setBlock(i + 6, j + 1, k + 25, Block.dirt.blockID);
		world.setBlock(i + 6, j + 1, k + 26, Block.dirt.blockID);
		world.setBlock(i + 6, j + 1, k + 27, Block.dirt.blockID);
		world.setBlock(i + 6, j + 1, k + 28, Block.dirt.blockID);
		world.setBlock(i + 6, j + 1, k + 29, Block.dirt.blockID);
		world.setBlock(i + 6, j + 1, k + 30, Block.dirt.blockID);
		world.setBlock(i + 6, j + 1, k + 31, Block.dirt.blockID);
		world.setBlock(i + 6, j + 1, k + 32, Block.dirt.blockID);
		world.setBlock(i + 6, j + 1, k + 33, Block.dirt.blockID);
		world.setBlock(i + 6, j + 1, k + 34, Block.dirt.blockID);
		world.setBlock(i + 6, j + 1, k + 35, Block.dirt.blockID);
		world.setBlock(i + 6, j + 1, k + 36, Block.dirt.blockID);
		world.setBlock(i + 6, j + 1, k + 37, Block.dirt.blockID);
		world.setBlock(i + 6, j + 1, k + 38, Block.dirt.blockID);
		world.setBlock(i + 6, j + 1, k + 39, Block.dirt.blockID);
		world.setBlock(i + 6, j + 1, k + 40, Block.dirt.blockID);
		world.setBlock(i + 6, j + 1, k + 41, Block.dirt.blockID);
		world.setBlock(i + 6, j + 1, k + 42, Block.dirt.blockID);
		world.setBlock(i + 6, j + 1, k + 43, Block.dirt.blockID);
		world.setBlock(i + 6, j + 1, k + 44, Block.dirt.blockID);
		world.setBlock(i + 6, j + 2, k + 0, Block.dirt.blockID);
		world.setBlock(i + 6, j + 2, k + 1, Block.dirt.blockID);
		world.setBlock(i + 6, j + 2, k + 2, Block.dirt.blockID);
		world.setBlock(i + 6, j + 2, k + 3, Block.dirt.blockID);
		world.setBlock(i + 6, j + 2, k + 4, Block.dirt.blockID);
		world.setBlock(i + 6, j + 2, k + 5, Block.dirt.blockID);
		world.setBlock(i + 6, j + 2, k + 6, Block.dirt.blockID);
		world.setBlock(i + 6, j + 2, k + 7, Block.dirt.blockID);
		world.setBlock(i + 6, j + 2, k + 8, Block.dirt.blockID);
		world.setBlock(i + 6, j + 2, k + 9, Block.dirt.blockID);
		world.setBlock(i + 6, j + 2, k + 10, Block.dirt.blockID);
		world.setBlock(i + 6, j + 2, k + 11, Block.dirt.blockID);
		world.setBlock(i + 6, j + 2, k + 12, Block.dirt.blockID);
		world.setBlock(i + 6, j + 2, k + 13, Block.dirt.blockID);
		world.setBlock(i + 6, j + 2, k + 14, Block.dirt.blockID);
		world.setBlock(i + 6, j + 2, k + 15, Block.dirt.blockID);
		world.setBlock(i + 6, j + 2, k + 16, Block.dirt.blockID);
		world.setBlock(i + 6, j + 2, k + 17, Block.dirt.blockID);
		world.setBlock(i + 6, j + 2, k + 18, Block.dirt.blockID);
		world.setBlock(i + 6, j + 2, k + 19, Block.dirt.blockID);
		world.setBlock(i + 6, j + 2, k + 20, Block.dirt.blockID);
		world.setBlock(i + 6, j + 2, k + 21, Block.dirt.blockID);
		world.setBlock(i + 6, j + 2, k + 22, Block.dirt.blockID);
		world.setBlock(i + 6, j + 2, k + 23, Block.dirt.blockID);
		world.setBlock(i + 6, j + 2, k + 24, Block.dirt.blockID);
		world.setBlock(i + 6, j + 2, k + 25, Block.dirt.blockID);
		world.setBlock(i + 6, j + 2, k + 26, Block.dirt.blockID);
		world.setBlock(i + 6, j + 2, k + 27, Block.dirt.blockID);
		world.setBlock(i + 6, j + 2, k + 28, Block.dirt.blockID);
		world.setBlock(i + 6, j + 2, k + 29, Block.dirt.blockID);
		world.setBlock(i + 6, j + 2, k + 30, Block.dirt.blockID);
		world.setBlock(i + 6, j + 2, k + 31, Block.dirt.blockID);
		world.setBlock(i + 6, j + 2, k + 32, Block.dirt.blockID);
		world.setBlock(i + 6, j + 2, k + 33, Block.dirt.blockID);
		world.setBlock(i + 6, j + 2, k + 34, Block.dirt.blockID);
		world.setBlock(i + 6, j + 2, k + 35, Block.dirt.blockID);
		world.setBlock(i + 6, j + 2, k + 36, Block.dirt.blockID);
		world.setBlock(i + 6, j + 2, k + 37, Block.dirt.blockID);
		world.setBlock(i + 6, j + 2, k + 38, Block.dirt.blockID);
		world.setBlock(i + 6, j + 2, k + 39, Block.dirt.blockID);
		world.setBlock(i + 6, j + 2, k + 40, Block.dirt.blockID);
		world.setBlock(i + 6, j + 2, k + 41, Block.dirt.blockID);
		world.setBlock(i + 6, j + 2, k + 42, Block.dirt.blockID);
		world.setBlock(i + 6, j + 2, k + 43, Block.dirt.blockID);
		world.setBlock(i + 6, j + 2, k + 44, Block.dirt.blockID);
		world.setBlock(i + 6, j + 3, k + 0, Block.grass.blockID);
		world.setBlock(i + 6, j + 3, k + 1, Block.grass.blockID);
		world.setBlock(i + 6, j + 3, k + 2, Block.grass.blockID);
		world.setBlock(i + 6, j + 3, k + 3, Block.grass.blockID);
		world.setBlock(i + 6, j + 3, k + 4, Block.grass.blockID);
		world.setBlock(i + 6, j + 3, k + 5, Block.grass.blockID);
		world.setBlock(i + 6, j + 3, k + 6, Block.grass.blockID);
		world.setBlock(i + 6, j + 3, k + 7, Block.grass.blockID);
		world.setBlock(i + 6, j + 3, k + 8, Block.grass.blockID);
		world.setBlock(i + 6, j + 3, k + 9, Block.grass.blockID);
		world.setBlock(i + 6, j + 3, k + 10, Block.grass.blockID);
		world.setBlock(i + 6, j + 3, k + 11, Block.grass.blockID);
		world.setBlock(i + 6, j + 3, k + 12, Block.grass.blockID);
		world.setBlock(i + 6, j + 3, k + 13, Block.grass.blockID);
		world.setBlock(i + 6, j + 3, k + 14, Block.grass.blockID);
		world.setBlock(i + 6, j + 3, k + 15, Block.grass.blockID);
		world.setBlock(i + 6, j + 3, k + 16, Block.grass.blockID);
		world.setBlock(i + 6, j + 3, k + 17, Block.grass.blockID);
		world.setBlock(i + 6, j + 3, k + 18, Block.grass.blockID);
		world.setBlock(i + 6, j + 3, k + 19, Block.grass.blockID);
		world.setBlock(i + 6, j + 3, k + 20, Block.grass.blockID);
		world.setBlock(i + 6, j + 3, k + 21, Block.grass.blockID);
		world.setBlock(i + 6, j + 3, k + 22, Block.grass.blockID);
		world.setBlock(i + 6, j + 3, k + 23, Block.grass.blockID);
		world.setBlock(i + 6, j + 3, k + 24, Block.grass.blockID);
		world.setBlock(i + 6, j + 3, k + 25, Block.grass.blockID);
		world.setBlock(i + 6, j + 3, k + 26, Block.grass.blockID);
		world.setBlock(i + 6, j + 3, k + 27, Block.grass.blockID);
		world.setBlock(i + 6, j + 3, k + 28, Block.grass.blockID);
		world.setBlock(i + 6, j + 3, k + 29, Block.grass.blockID);
		world.setBlock(i + 6, j + 3, k + 30, Block.grass.blockID);
		world.setBlock(i + 6, j + 3, k + 31, Block.grass.blockID);
		world.setBlock(i + 6, j + 3, k + 32, Block.grass.blockID);
		world.setBlock(i + 6, j + 3, k + 33, Block.grass.blockID);
		world.setBlock(i + 6, j + 3, k + 34, Block.grass.blockID);
		world.setBlock(i + 6, j + 3, k + 35, Block.grass.blockID);
		world.setBlock(i + 6, j + 3, k + 36, Block.grass.blockID);
		world.setBlock(i + 6, j + 3, k + 37, Block.grass.blockID);
		world.setBlock(i + 6, j + 3, k + 38, Block.grass.blockID);
		world.setBlock(i + 6, j + 3, k + 39, Block.grass.blockID);
		world.setBlock(i + 6, j + 3, k + 40, Block.grass.blockID);
		world.setBlock(i + 6, j + 3, k + 41, Block.grass.blockID);
		world.setBlock(i + 6, j + 3, k + 42, Block.grass.blockID);
		world.setBlock(i + 6, j + 3, k + 43, Block.grass.blockID);
		world.setBlock(i + 6, j + 3, k + 44, Block.grass.blockID);
		world.setBlock(i + 7, j + 0, k + 0, Block.bedrock.blockID);
		world.setBlock(i + 7, j + 0, k + 1, Block.bedrock.blockID);
		world.setBlock(i + 7, j + 0, k + 2, Block.bedrock.blockID);
		world.setBlock(i + 7, j + 0, k + 3, Block.bedrock.blockID);
		world.setBlock(i + 7, j + 0, k + 4, Block.bedrock.blockID);
		world.setBlock(i + 7, j + 0, k + 5, Block.bedrock.blockID);
		world.setBlock(i + 7, j + 0, k + 6, Block.bedrock.blockID);
		world.setBlock(i + 7, j + 0, k + 7, Block.bedrock.blockID);
		world.setBlock(i + 7, j + 0, k + 8, Block.bedrock.blockID);
		world.setBlock(i + 7, j + 0, k + 9, Block.bedrock.blockID);
		world.setBlock(i + 7, j + 0, k + 10, Block.bedrock.blockID);
		world.setBlock(i + 7, j + 0, k + 11, Block.bedrock.blockID);
		world.setBlock(i + 7, j + 0, k + 12, Block.bedrock.blockID);
		world.setBlock(i + 7, j + 0, k + 13, Block.bedrock.blockID);
		world.setBlock(i + 7, j + 0, k + 14, Block.bedrock.blockID);
		world.setBlock(i + 7, j + 0, k + 15, Block.bedrock.blockID);
		world.setBlock(i + 7, j + 0, k + 16, Block.bedrock.blockID);
		world.setBlock(i + 7, j + 0, k + 17, Block.bedrock.blockID);
		world.setBlock(i + 7, j + 0, k + 18, Block.bedrock.blockID);
		world.setBlock(i + 7, j + 0, k + 19, Block.bedrock.blockID);
		world.setBlock(i + 7, j + 0, k + 20, Block.bedrock.blockID);
		world.setBlock(i + 7, j + 0, k + 21, Block.bedrock.blockID);
		world.setBlock(i + 7, j + 0, k + 22, Block.bedrock.blockID);
		world.setBlock(i + 7, j + 0, k + 23, Block.bedrock.blockID);
		world.setBlock(i + 7, j + 0, k + 24, Block.bedrock.blockID);
		world.setBlock(i + 7, j + 0, k + 25, Block.bedrock.blockID);
		world.setBlock(i + 7, j + 0, k + 26, Block.bedrock.blockID);
		world.setBlock(i + 7, j + 0, k + 27, Block.bedrock.blockID);
		world.setBlock(i + 7, j + 0, k + 28, Block.bedrock.blockID);
		world.setBlock(i + 7, j + 0, k + 29, Block.bedrock.blockID);
		world.setBlock(i + 7, j + 0, k + 30, Block.bedrock.blockID);
		world.setBlock(i + 7, j + 0, k + 31, Block.bedrock.blockID);
		world.setBlock(i + 7, j + 0, k + 32, Block.bedrock.blockID);
		world.setBlock(i + 7, j + 0, k + 33, Block.bedrock.blockID);
		world.setBlock(i + 7, j + 0, k + 34, Block.bedrock.blockID);
		world.setBlock(i + 7, j + 0, k + 35, Block.bedrock.blockID);
		world.setBlock(i + 7, j + 0, k + 36, Block.bedrock.blockID);
		world.setBlock(i + 7, j + 0, k + 37, Block.bedrock.blockID);
		world.setBlock(i + 7, j + 0, k + 38, Block.bedrock.blockID);
		world.setBlock(i + 7, j + 0, k + 39, Block.bedrock.blockID);
		world.setBlock(i + 7, j + 0, k + 40, Block.bedrock.blockID);
		world.setBlock(i + 7, j + 0, k + 41, Block.bedrock.blockID);
		world.setBlock(i + 7, j + 0, k + 42, Block.bedrock.blockID);
		world.setBlock(i + 7, j + 0, k + 43, Block.bedrock.blockID);
		world.setBlock(i + 7, j + 0, k + 44, Block.bedrock.blockID);
		world.setBlock(i + 7, j + 1, k + 0, Block.dirt.blockID);
		world.setBlock(i + 7, j + 1, k + 1, Block.dirt.blockID);
		world.setBlock(i + 7, j + 1, k + 2, Block.dirt.blockID);
		world.setBlock(i + 7, j + 1, k + 3, Block.dirt.blockID);
		world.setBlock(i + 7, j + 1, k + 4, Block.dirt.blockID);
		world.setBlock(i + 7, j + 1, k + 5, Block.dirt.blockID);
		world.setBlock(i + 7, j + 1, k + 6, Block.dirt.blockID);
		world.setBlock(i + 7, j + 1, k + 7, Block.dirt.blockID);
		world.setBlock(i + 7, j + 1, k + 8, Block.dirt.blockID);
		world.setBlock(i + 7, j + 1, k + 9, Block.dirt.blockID);
		world.setBlock(i + 7, j + 1, k + 10, Block.dirt.blockID);
		world.setBlock(i + 7, j + 1, k + 11, Block.dirt.blockID);
		world.setBlock(i + 7, j + 1, k + 12, Block.dirt.blockID);
		world.setBlock(i + 7, j + 1, k + 13, Block.dirt.blockID);
		world.setBlock(i + 7, j + 1, k + 14, Block.dirt.blockID);
		world.setBlock(i + 7, j + 1, k + 15, Block.dirt.blockID);
		world.setBlock(i + 7, j + 1, k + 16, Block.dirt.blockID);
		world.setBlock(i + 7, j + 1, k + 17, Block.dirt.blockID);
		world.setBlock(i + 7, j + 1, k + 18, Block.dirt.blockID);
		world.setBlock(i + 7, j + 1, k + 19, Block.dirt.blockID);
		world.setBlock(i + 7, j + 1, k + 20, Block.dirt.blockID);
		world.setBlock(i + 7, j + 1, k + 21, Block.dirt.blockID);
		world.setBlock(i + 7, j + 1, k + 22, Block.dirt.blockID);
		world.setBlock(i + 7, j + 1, k + 23, Block.dirt.blockID);
		world.setBlock(i + 7, j + 1, k + 24, Block.dirt.blockID);
		world.setBlock(i + 7, j + 1, k + 25, Block.dirt.blockID);
		world.setBlock(i + 7, j + 1, k + 26, Block.dirt.blockID);
		world.setBlock(i + 7, j + 1, k + 27, Block.dirt.blockID);
		world.setBlock(i + 7, j + 1, k + 28, Block.dirt.blockID);
		world.setBlock(i + 7, j + 1, k + 29, Block.dirt.blockID);
		world.setBlock(i + 7, j + 1, k + 30, Block.dirt.blockID);
		world.setBlock(i + 7, j + 1, k + 31, Block.dirt.blockID);
		world.setBlock(i + 7, j + 1, k + 32, Block.dirt.blockID);
		world.setBlock(i + 7, j + 1, k + 33, Block.dirt.blockID);
		world.setBlock(i + 7, j + 1, k + 34, Block.dirt.blockID);
		world.setBlock(i + 7, j + 1, k + 35, Block.dirt.blockID);
		world.setBlock(i + 7, j + 1, k + 36, Block.dirt.blockID);
		world.setBlock(i + 7, j + 1, k + 37, Block.dirt.blockID);
		world.setBlock(i + 7, j + 1, k + 38, Block.dirt.blockID);
		world.setBlock(i + 7, j + 1, k + 39, Block.dirt.blockID);
		world.setBlock(i + 7, j + 1, k + 40, Block.dirt.blockID);
		world.setBlock(i + 7, j + 1, k + 41, Block.dirt.blockID);
		world.setBlock(i + 7, j + 1, k + 42, Block.dirt.blockID);
		world.setBlock(i + 7, j + 1, k + 43, Block.dirt.blockID);
		world.setBlock(i + 7, j + 1, k + 44, Block.dirt.blockID);
		world.setBlock(i + 7, j + 2, k + 0, Block.dirt.blockID);
		world.setBlock(i + 7, j + 2, k + 1, Block.dirt.blockID);
		world.setBlock(i + 7, j + 2, k + 2, Block.dirt.blockID);
		world.setBlock(i + 7, j + 2, k + 3, Block.dirt.blockID);
		world.setBlock(i + 7, j + 2, k + 4, Block.dirt.blockID);
		world.setBlock(i + 7, j + 2, k + 5, Block.dirt.blockID);
		world.setBlock(i + 7, j + 2, k + 6, Block.dirt.blockID);
		world.setBlock(i + 7, j + 2, k + 7, Block.dirt.blockID);
		world.setBlock(i + 7, j + 2, k + 8, Block.dirt.blockID);
		world.setBlock(i + 7, j + 2, k + 9, Block.dirt.blockID);
		world.setBlock(i + 7, j + 2, k + 10, Block.dirt.blockID);
		world.setBlock(i + 7, j + 2, k + 11, Block.dirt.blockID);
		world.setBlock(i + 7, j + 2, k + 12, Block.dirt.blockID);
		world.setBlock(i + 7, j + 2, k + 13, Block.dirt.blockID);
		world.setBlock(i + 7, j + 2, k + 14, Block.dirt.blockID);
		world.setBlock(i + 7, j + 2, k + 15, Block.dirt.blockID);
		world.setBlock(i + 7, j + 2, k + 16, Block.dirt.blockID);
		world.setBlock(i + 7, j + 2, k + 17, Block.dirt.blockID);
		world.setBlock(i + 7, j + 2, k + 18, Block.dirt.blockID);
		world.setBlock(i + 7, j + 2, k + 19, Block.dirt.blockID);
		world.setBlock(i + 7, j + 2, k + 20, Block.dirt.blockID);
		world.setBlock(i + 7, j + 2, k + 21, Block.dirt.blockID);
		world.setBlock(i + 7, j + 2, k + 22, Block.dirt.blockID);
		world.setBlock(i + 7, j + 2, k + 23, Block.dirt.blockID);
		world.setBlock(i + 7, j + 2, k + 24, Block.dirt.blockID);
		world.setBlock(i + 7, j + 2, k + 25, Block.dirt.blockID);
		world.setBlock(i + 7, j + 2, k + 26, Block.dirt.blockID);
		world.setBlock(i + 7, j + 2, k + 27, Block.dirt.blockID);
		world.setBlock(i + 7, j + 2, k + 28, Block.dirt.blockID);
		world.setBlock(i + 7, j + 2, k + 29, Block.dirt.blockID);
		world.setBlock(i + 7, j + 2, k + 30, Block.dirt.blockID);
		world.setBlock(i + 7, j + 2, k + 31, Block.dirt.blockID);
		world.setBlock(i + 7, j + 2, k + 32, Block.dirt.blockID);
		world.setBlock(i + 7, j + 2, k + 33, Block.dirt.blockID);
		world.setBlock(i + 7, j + 2, k + 34, Block.dirt.blockID);
		world.setBlock(i + 7, j + 2, k + 35, Block.dirt.blockID);
		world.setBlock(i + 7, j + 2, k + 36, Block.dirt.blockID);
		world.setBlock(i + 7, j + 2, k + 37, Block.dirt.blockID);
		world.setBlock(i + 7, j + 2, k + 38, Block.dirt.blockID);
		world.setBlock(i + 7, j + 2, k + 39, Block.dirt.blockID);
		world.setBlock(i + 7, j + 2, k + 40, Block.dirt.blockID);
		world.setBlock(i + 7, j + 2, k + 41, Block.dirt.blockID);
		world.setBlock(i + 7, j + 2, k + 42, Block.dirt.blockID);
		world.setBlock(i + 7, j + 2, k + 43, Block.dirt.blockID);
		world.setBlock(i + 7, j + 2, k + 44, Block.dirt.blockID);
		world.setBlock(i + 7, j + 3, k + 0, Block.grass.blockID);
		world.setBlock(i + 7, j + 3, k + 1, Block.grass.blockID);
		world.setBlock(i + 7, j + 3, k + 2, Block.grass.blockID);
		world.setBlock(i + 7, j + 3, k + 3, Block.grass.blockID);
		world.setBlock(i + 7, j + 3, k + 4, Block.grass.blockID);
		world.setBlock(i + 7, j + 3, k + 5, Block.grass.blockID);
		world.setBlock(i + 7, j + 3, k + 6, Block.grass.blockID);
		world.setBlock(i + 7, j + 3, k + 7, Block.grass.blockID);
		world.setBlock(i + 7, j + 3, k + 8, Block.grass.blockID);
		world.setBlock(i + 7, j + 3, k + 9, Block.grass.blockID);
		world.setBlock(i + 7, j + 3, k + 10, Block.grass.blockID);
		world.setBlock(i + 7, j + 3, k + 11, Block.grass.blockID);
		world.setBlock(i + 7, j + 3, k + 12, Block.grass.blockID);
		world.setBlock(i + 7, j + 3, k + 13, Block.grass.blockID);
		world.setBlock(i + 7, j + 3, k + 14, Block.grass.blockID);
		world.setBlock(i + 7, j + 3, k + 15, Block.grass.blockID);
		world.setBlock(i + 7, j + 3, k + 16, Block.grass.blockID);
		world.setBlock(i + 7, j + 3, k + 17, Block.grass.blockID);
		world.setBlock(i + 7, j + 3, k + 18, Block.grass.blockID);
		world.setBlock(i + 7, j + 3, k + 19, Block.grass.blockID);
		world.setBlock(i + 7, j + 3, k + 20, Block.grass.blockID);
		world.setBlock(i + 7, j + 3, k + 21, Block.grass.blockID);
		world.setBlock(i + 7, j + 3, k + 22, Block.grass.blockID);
		world.setBlock(i + 7, j + 3, k + 23, Block.grass.blockID);
		world.setBlock(i + 7, j + 3, k + 24, Block.grass.blockID);
		world.setBlock(i + 7, j + 3, k + 25, Block.grass.blockID);
		world.setBlock(i + 7, j + 3, k + 26, Block.grass.blockID);
		world.setBlock(i + 7, j + 3, k + 27, Block.grass.blockID);
		world.setBlock(i + 7, j + 3, k + 28, Block.grass.blockID);
		world.setBlock(i + 7, j + 3, k + 29, Block.grass.blockID);
		world.setBlock(i + 7, j + 3, k + 30, Block.grass.blockID);
		world.setBlock(i + 7, j + 3, k + 31, Block.grass.blockID);
		world.setBlock(i + 7, j + 3, k + 32, Block.grass.blockID);
		world.setBlock(i + 7, j + 3, k + 33, Block.grass.blockID);
		world.setBlock(i + 7, j + 3, k + 34, Block.grass.blockID);
		world.setBlock(i + 7, j + 3, k + 35, Block.grass.blockID);
		world.setBlock(i + 7, j + 3, k + 36, Block.grass.blockID);
		world.setBlock(i + 7, j + 3, k + 37, Block.grass.blockID);
		world.setBlock(i + 7, j + 3, k + 38, Block.grass.blockID);
		world.setBlock(i + 7, j + 3, k + 39, Block.grass.blockID);
		world.setBlock(i + 7, j + 3, k + 40, Block.grass.blockID);
		world.setBlock(i + 7, j + 3, k + 41, Block.grass.blockID);
		world.setBlock(i + 7, j + 3, k + 42, Block.grass.blockID);
		world.setBlock(i + 7, j + 3, k + 43, Block.grass.blockID);
		world.setBlock(i + 7, j + 3, k + 44, Block.grass.blockID);
		world.setBlock(i + 8, j + 0, k + 0, Block.bedrock.blockID);
		world.setBlock(i + 8, j + 0, k + 1, Block.bedrock.blockID);
		world.setBlock(i + 8, j + 0, k + 2, Block.bedrock.blockID);
		world.setBlock(i + 8, j + 0, k + 3, Block.bedrock.blockID);
		world.setBlock(i + 8, j + 0, k + 4, Block.bedrock.blockID);
		world.setBlock(i + 8, j + 0, k + 5, Block.bedrock.blockID);
		world.setBlock(i + 8, j + 0, k + 6, Block.bedrock.blockID);
		world.setBlock(i + 8, j + 0, k + 7, Block.bedrock.blockID);
		world.setBlock(i + 8, j + 0, k + 8, Block.bedrock.blockID);
		world.setBlock(i + 8, j + 0, k + 9, Block.bedrock.blockID);
		world.setBlock(i + 8, j + 0, k + 10, Block.bedrock.blockID);
		world.setBlock(i + 8, j + 0, k + 11, Block.bedrock.blockID);
		world.setBlock(i + 8, j + 0, k + 12, Block.bedrock.blockID);
		world.setBlock(i + 8, j + 0, k + 13, Block.bedrock.blockID);
		world.setBlock(i + 8, j + 0, k + 14, Block.bedrock.blockID);
		world.setBlock(i + 8, j + 0, k + 15, Block.bedrock.blockID);
		world.setBlock(i + 8, j + 0, k + 16, Block.bedrock.blockID);
		world.setBlock(i + 8, j + 0, k + 17, Block.bedrock.blockID);
		world.setBlock(i + 8, j + 0, k + 18, Block.bedrock.blockID);
		world.setBlock(i + 8, j + 0, k + 19, Block.bedrock.blockID);
		world.setBlock(i + 8, j + 0, k + 20, Block.bedrock.blockID);
		world.setBlock(i + 8, j + 0, k + 21, Block.bedrock.blockID);
		world.setBlock(i + 8, j + 0, k + 22, Block.bedrock.blockID);
		world.setBlock(i + 8, j + 0, k + 23, Block.bedrock.blockID);
		world.setBlock(i + 8, j + 0, k + 24, Block.bedrock.blockID);
		world.setBlock(i + 8, j + 0, k + 25, Block.bedrock.blockID);
		world.setBlock(i + 8, j + 0, k + 26, Block.bedrock.blockID);
		world.setBlock(i + 8, j + 0, k + 27, Block.bedrock.blockID);
		world.setBlock(i + 8, j + 0, k + 28, Block.bedrock.blockID);
		world.setBlock(i + 8, j + 0, k + 29, Block.bedrock.blockID);
		world.setBlock(i + 8, j + 0, k + 30, Block.bedrock.blockID);
		world.setBlock(i + 8, j + 0, k + 31, Block.bedrock.blockID);
		world.setBlock(i + 8, j + 0, k + 32, Block.bedrock.blockID);
		world.setBlock(i + 8, j + 0, k + 33, Block.bedrock.blockID);
		world.setBlock(i + 8, j + 0, k + 34, Block.bedrock.blockID);
		world.setBlock(i + 8, j + 0, k + 35, Block.bedrock.blockID);
		world.setBlock(i + 8, j + 0, k + 36, Block.bedrock.blockID);
		world.setBlock(i + 8, j + 0, k + 37, Block.bedrock.blockID);
		world.setBlock(i + 8, j + 0, k + 38, Block.bedrock.blockID);
		world.setBlock(i + 8, j + 0, k + 39, Block.bedrock.blockID);
		world.setBlock(i + 8, j + 0, k + 40, Block.bedrock.blockID);
		world.setBlock(i + 8, j + 0, k + 41, Block.bedrock.blockID);
		world.setBlock(i + 8, j + 0, k + 42, Block.bedrock.blockID);
		world.setBlock(i + 8, j + 0, k + 43, Block.bedrock.blockID);
		world.setBlock(i + 8, j + 0, k + 44, Block.bedrock.blockID);
		world.setBlock(i + 8, j + 1, k + 0, Block.dirt.blockID);
		world.setBlock(i + 8, j + 1, k + 1, Block.dirt.blockID);
		world.setBlock(i + 8, j + 1, k + 2, Block.dirt.blockID);
		world.setBlock(i + 8, j + 1, k + 3, Block.dirt.blockID);
		world.setBlock(i + 8, j + 1, k + 4, Block.dirt.blockID);
		world.setBlock(i + 8, j + 1, k + 5, Block.dirt.blockID);
		world.setBlock(i + 8, j + 1, k + 6, Block.dirt.blockID);
		world.setBlock(i + 8, j + 1, k + 7, Block.dirt.blockID);
		world.setBlock(i + 8, j + 1, k + 8, Block.dirt.blockID);
		world.setBlock(i + 8, j + 1, k + 9, Block.dirt.blockID);
		world.setBlock(i + 8, j + 1, k + 10, Block.dirt.blockID);
		world.setBlock(i + 8, j + 1, k + 11, Block.dirt.blockID);
		world.setBlock(i + 8, j + 1, k + 12, Block.dirt.blockID);
		world.setBlock(i + 8, j + 1, k + 13, Block.dirt.blockID);
		world.setBlock(i + 8, j + 1, k + 14, Block.dirt.blockID);

		generate2(world, rand, i, j, k);
		return true;
	}

	public boolean generate2(World world, Random rand, int i, int j, int k) {
		world.setBlock(i + 8, j + 1, k + 15, Block.dirt.blockID);
		world.setBlock(i + 8, j + 1, k + 16, Block.dirt.blockID);
		world.setBlock(i + 8, j + 1, k + 17, Block.dirt.blockID);
		world.setBlock(i + 8, j + 1, k + 18, Block.dirt.blockID);
		world.setBlock(i + 8, j + 1, k + 19, Block.dirt.blockID);
		world.setBlock(i + 8, j + 1, k + 20, Block.dirt.blockID);
		world.setBlock(i + 8, j + 1, k + 21, Block.dirt.blockID);
		world.setBlock(i + 8, j + 1, k + 22, Block.dirt.blockID);
		world.setBlock(i + 8, j + 1, k + 23, Block.dirt.blockID);
		world.setBlock(i + 8, j + 1, k + 24, Block.dirt.blockID);
		world.setBlock(i + 8, j + 1, k + 25, Block.dirt.blockID);
		world.setBlock(i + 8, j + 1, k + 26, Block.dirt.blockID);
		world.setBlock(i + 8, j + 1, k + 27, Block.dirt.blockID);
		world.setBlock(i + 8, j + 1, k + 28, Block.dirt.blockID);
		world.setBlock(i + 8, j + 1, k + 29, Block.dirt.blockID);
		world.setBlock(i + 8, j + 1, k + 30, Block.dirt.blockID);
		world.setBlock(i + 8, j + 1, k + 31, Block.dirt.blockID);
		world.setBlock(i + 8, j + 1, k + 32, Block.dirt.blockID);
		world.setBlock(i + 8, j + 1, k + 33, Block.dirt.blockID);
		world.setBlock(i + 8, j + 1, k + 34, Block.dirt.blockID);
		world.setBlock(i + 8, j + 1, k + 35, Block.dirt.blockID);
		world.setBlock(i + 8, j + 1, k + 36, Block.dirt.blockID);
		world.setBlock(i + 8, j + 1, k + 37, Block.dirt.blockID);
		world.setBlock(i + 8, j + 1, k + 38, Block.dirt.blockID);
		world.setBlock(i + 8, j + 1, k + 39, Block.dirt.blockID);
		world.setBlock(i + 8, j + 1, k + 40, Block.dirt.blockID);
		world.setBlock(i + 8, j + 1, k + 41, Block.dirt.blockID);
		world.setBlock(i + 8, j + 1, k + 42, Block.dirt.blockID);
		world.setBlock(i + 8, j + 1, k + 43, Block.dirt.blockID);
		world.setBlock(i + 8, j + 1, k + 44, Block.dirt.blockID);
		world.setBlock(i + 8, j + 2, k + 0, Block.dirt.blockID);
		world.setBlock(i + 8, j + 2, k + 1, Block.dirt.blockID);
		world.setBlock(i + 8, j + 2, k + 2, Block.dirt.blockID);
		world.setBlock(i + 8, j + 2, k + 3, Block.dirt.blockID);
		world.setBlock(i + 8, j + 2, k + 4, Block.dirt.blockID);
		world.setBlock(i + 8, j + 2, k + 5, Block.dirt.blockID);
		world.setBlock(i + 8, j + 2, k + 6, Block.dirt.blockID);
		world.setBlock(i + 8, j + 2, k + 7, Block.dirt.blockID);
		world.setBlock(i + 8, j + 2, k + 8, Block.dirt.blockID);
		world.setBlock(i + 8, j + 2, k + 9, Block.dirt.blockID);
		world.setBlock(i + 8, j + 2, k + 10, Block.dirt.blockID);
		world.setBlock(i + 8, j + 2, k + 11, Block.dirt.blockID);
		world.setBlock(i + 8, j + 2, k + 12, Block.dirt.blockID);
		world.setBlock(i + 8, j + 2, k + 13, Block.dirt.blockID);
		world.setBlock(i + 8, j + 2, k + 14, Block.dirt.blockID);
		world.setBlock(i + 8, j + 2, k + 15, Block.dirt.blockID);
		world.setBlock(i + 8, j + 2, k + 16, Block.dirt.blockID);
		world.setBlock(i + 8, j + 2, k + 17, Block.dirt.blockID);
		world.setBlock(i + 8, j + 2, k + 18, Block.dirt.blockID);
		world.setBlock(i + 8, j + 2, k + 19, Block.dirt.blockID);
		world.setBlock(i + 8, j + 2, k + 20, Block.dirt.blockID);
		world.setBlock(i + 8, j + 2, k + 21, Block.dirt.blockID);
		world.setBlock(i + 8, j + 2, k + 22, Block.dirt.blockID);
		world.setBlock(i + 8, j + 2, k + 23, Block.dirt.blockID);
		world.setBlock(i + 8, j + 2, k + 24, Block.dirt.blockID);
		world.setBlock(i + 8, j + 2, k + 25, Block.dirt.blockID);
		world.setBlock(i + 8, j + 2, k + 26, Block.dirt.blockID);
		world.setBlock(i + 8, j + 2, k + 27, Block.dirt.blockID);
		world.setBlock(i + 8, j + 2, k + 28, Block.dirt.blockID);
		world.setBlock(i + 8, j + 2, k + 29, Block.dirt.blockID);
		world.setBlock(i + 8, j + 2, k + 30, Block.dirt.blockID);
		world.setBlock(i + 8, j + 2, k + 31, Block.dirt.blockID);
		world.setBlock(i + 8, j + 2, k + 32, Block.dirt.blockID);
		world.setBlock(i + 8, j + 2, k + 33, Block.dirt.blockID);
		world.setBlock(i + 8, j + 2, k + 34, Block.dirt.blockID);
		world.setBlock(i + 8, j + 2, k + 35, Block.dirt.blockID);
		world.setBlock(i + 8, j + 2, k + 36, Block.dirt.blockID);
		world.setBlock(i + 8, j + 2, k + 37, Block.dirt.blockID);
		world.setBlock(i + 8, j + 2, k + 38, Block.dirt.blockID);
		world.setBlock(i + 8, j + 2, k + 39, Block.dirt.blockID);
		world.setBlock(i + 8, j + 2, k + 40, Block.dirt.blockID);
		world.setBlock(i + 8, j + 2, k + 41, Block.dirt.blockID);
		world.setBlock(i + 8, j + 2, k + 42, Block.dirt.blockID);
		world.setBlock(i + 8, j + 2, k + 43, Block.dirt.blockID);
		world.setBlock(i + 8, j + 2, k + 44, Block.dirt.blockID);
		world.setBlock(i + 8, j + 3, k + 0, Block.grass.blockID);
		world.setBlock(i + 8, j + 3, k + 1, Block.grass.blockID);
		world.setBlock(i + 8, j + 3, k + 2, Block.grass.blockID);
		world.setBlock(i + 8, j + 3, k + 3, Block.grass.blockID);
		world.setBlock(i + 8, j + 3, k + 4, Block.grass.blockID);
		world.setBlock(i + 8, j + 3, k + 5, Block.grass.blockID);
		world.setBlock(i + 8, j + 3, k + 6, Block.grass.blockID);
		world.setBlock(i + 8, j + 3, k + 7, Block.grass.blockID);
		world.setBlock(i + 8, j + 3, k + 8, Block.grass.blockID);
		world.setBlock(i + 8, j + 3, k + 9, Block.grass.blockID);
		world.setBlock(i + 8, j + 3, k + 10, Block.grass.blockID);
		world.setBlock(i + 8, j + 3, k + 11, Block.grass.blockID);
		world.setBlock(i + 8, j + 3, k + 12, Block.grass.blockID);
		world.setBlock(i + 8, j + 3, k + 13, Block.grass.blockID);
		world.setBlock(i + 8, j + 3, k + 14, Block.grass.blockID);
		world.setBlock(i + 8, j + 3, k + 15, Block.grass.blockID);
		world.setBlock(i + 8, j + 3, k + 16, Block.grass.blockID);
		world.setBlock(i + 8, j + 3, k + 17, Block.grass.blockID);
		world.setBlock(i + 8, j + 3, k + 18, Block.grass.blockID);
		world.setBlock(i + 8, j + 3, k + 19, Block.grass.blockID);
		world.setBlock(i + 8, j + 3, k + 20, Block.grass.blockID);
		world.setBlock(i + 8, j + 3, k + 21, Block.grass.blockID);
		world.setBlock(i + 8, j + 3, k + 22, Block.grass.blockID);
		world.setBlock(i + 8, j + 3, k + 23, Block.grass.blockID);
		world.setBlock(i + 8, j + 3, k + 24, Block.grass.blockID);
		world.setBlock(i + 8, j + 3, k + 25, Block.grass.blockID);
		world.setBlock(i + 8, j + 3, k + 26, Block.grass.blockID);
		world.setBlock(i + 8, j + 3, k + 27, Block.grass.blockID);
		world.setBlock(i + 8, j + 3, k + 28, Block.grass.blockID);
		world.setBlock(i + 8, j + 3, k + 29, Block.grass.blockID);
		world.setBlock(i + 8, j + 3, k + 30, Block.grass.blockID);
		world.setBlock(i + 8, j + 3, k + 31, Block.grass.blockID);
		world.setBlock(i + 8, j + 3, k + 32, Block.grass.blockID);
		world.setBlock(i + 8, j + 3, k + 33, Block.grass.blockID);
		world.setBlock(i + 8, j + 3, k + 34, Block.grass.blockID);
		world.setBlock(i + 8, j + 3, k + 35, Block.grass.blockID);
		world.setBlock(i + 8, j + 3, k + 36, Block.grass.blockID);
		world.setBlock(i + 8, j + 3, k + 37, Block.grass.blockID);
		world.setBlock(i + 8, j + 3, k + 38, Block.grass.blockID);
		world.setBlock(i + 8, j + 3, k + 39, Block.grass.blockID);
		world.setBlock(i + 8, j + 3, k + 40, Block.grass.blockID);
		world.setBlock(i + 8, j + 3, k + 41, Block.grass.blockID);
